<mujoco model="multi_robot_env">
    <compiler angle="radian" />
    <option timestep="0.002" />

    <asset>
        <texture name="checker" type="2d" builtin="checker" width="512" height="512" />
        <material name="grid" texture="checker" texuniform="true" reflectance="0.2"/>
    </asset>

    <worldbody>
        <light name="main_light" pos="0 0 2" dir="0 0 -1" diffuse="1 1 1" />

        <!-- 替换地面 -->
        <geom name="floor" size="0 0 0.05" type="plane" material="grid"/>

        <!-- 保持墙壁 -->
        <geom name="wall_left_1" type="box" pos="-5 0 0.1" size="0.1 5 0.2" rgba="0.3 0.3 0.3 1" />
        <geom name="wall_right_1" type="box" pos="-1 0 0.1" size="0.1 5 0.2" rgba="0.3 0.3 0.3 1" />
        <geom name="wall_front_1" type="box" pos="-3 -5 0.1" size="2 0.1 0.2" rgba="0.3 0.3 0.3 1" />
        <geom name="wall_back_1" type="box" pos="-3 5 0.1" size="2 0.1 0.2" rgba="0.3 0.3 0.3 1" />

        <geom name="wall_left_2" type="box" pos="1 0 0.1" size="0.1 5 0.2" rgba="0.3 0.3 0.3 1" />
        <geom name="wall_right_2" type="box" pos="5 0 0.1" size="0.1 5 0.2" rgba="0.3 0.3 0.3 1" />
        <geom name="wall_front_2" type="box" pos="3 -5 0.1" size="2 0.1 0.2" rgba="0.3 0.3 0.3 1" />
        <geom name="wall_back_2" type="box" pos="3 5 0.1" size="2 0.1 0.2" rgba="0.3 0.3 0.3 1" />

        <!-- 机器人 1 -->
        <body name="base1" pos="-3.0 0.0 0.5">
            <freejoint />
            <geom type="box" size="0.2 0.2 0.1" rgba="0.8 0.8 0.8 1" />

            <body name="LF_HIP" pos="0.277 0.116 0">
                <joint name="LF_HAA" type="hinge" axis="1 0 0" pos="0.277 0.116 0" range="-0.5 0.5" />
                <geom type="cylinder" size="0.05 0.1" rgba="1 0 0 1" />
            </body>

            <body name="RF_HIP" pos="0.277 -0.116 0">
                <joint name="RF_HAA" type="hinge" axis="1 0 0" pos="0.277 -0.116 0" range="-0.5 0.5" />
                <geom type="cylinder" size="0.05 0.1" rgba="0 0 1 1" />
            </body>
        </body>

        <!-- 机器人 2 -->
        <body name="base2" pos="3.0 0.0 0.5">
            <freejoint />
            <geom type="box" size="0.2 0.2 0.1" rgba="0.7 0.7 0.7 1" />

            <body name="LB_HIP" pos="0.277 0.116 0">
                <joint name="LB_HAA" type="hinge" axis="1 0 0" pos="0.277 0.116 0" range="-0.5 0.5" />
                <geom type="cylinder" size="0.05 0.1" rgba="0 1 0 1" />
            </body>

            <body name="RB_HIP" pos="0.277 -0.116 0">
                <joint name="RB_HAA" type="hinge" axis="1 0 0" pos="0.277 -0.116 0" range="-0.5 0.5" />
                <geom type="cylinder" size="0.05 0.1" rgba="1 1 0 1" />
            </body>
        </body>
    </worldbody>

    <actuator>
        <motor name="LF_HAA_motor" joint="LF_HAA" ctrlrange="-1 1" gear="10" />
        <motor name="RF_HAA_motor" joint="RF_HAA" ctrlrange="-1 1" gear="10" />
        <motor name="LB_HAA_motor" joint="LB_HAA" ctrlrange="-1 1" gear="10" />
        <motor name="RB_HAA_motor" joint="RB_HAA" ctrlrange="-1 1" gear="10" />
    </actuator>
</mujoco>
