<?xml version="1.0"?>
<robot name="evolved_robot">
  <material name="metal">
    <color rgba="0.7 0.7 0.7 1.0"/>
  </material>
  <material name="plastic">
    <color rgba="0.3 0.3 0.9 1.0"/>
  </material>
  <material name="rubber">
    <color rgba="0.1 0.1 0.1 1.0"/>
  </material>
  <material name="red">
    <color rgba="1.0 0.0 0.0 1.0"/>
  </material>
  <material name="wheel_material">
    <color rgba="0.2 0.2 0.2 1.0"/>
  </material>
  <link name="base_link">
    <visual>
      <geometry><box size="0.19016621796855407 0.11144871832192313 0.08687678275105115"/></geometry>
      <material name="plastic"/>
    </visual>
    <collision>
      <geometry><box size="0.19016621796855407 0.11144871832192313 0.08687678275105115"/></geometry>
    </collision>
    <inertial>
      <mass value="5.0"/>
      <inertia ixx="0.016640326830643922" ixy="0" ixz="0" 
               iyy="0.03642563819803079" iyz="0" 
               izz="0.04048667272671915"/>
    </inertial>
  </link>
  <link name="link1">
    <visual>
      <geometry><box size="0.24952785725997095 0.1568098828793223 0.09687558353741348"/></geometry>
      <material name="metal"/>
    </visual>
    <collision>
      <geometry><box size="0.24952785725997095 0.1568098828793223 0.09687558353741348"/></geometry>
    </collision>
    <inertial>
      <mass value="0.5"/>
      <inertia ixx="0.0028311848378617627" ixy="0" ixz="0" 
               iyy="0.005970752519538901" iyz="0" 
               izz="0.007237790909781601"/>
    </inertial>
  </link>
  <joint name="joint1" type="prismatic">
    <parent link="base_link"/>
    <child link="link1"/>
    <origin xyz="0 0 0.043438391375525576" rpy="0 0 0"/>
    <axis xyz="-0.5189022187489976 -0.23325517469000684 -0.822394376718191"/>
    <dynamics damping="0.8760193275171044" friction="0.1"/>
    <limit lower="-2.1067511052931525" upper="1.3549062246613846" effort="100" velocity="100"/>
  </joint>
  <link name="link2">
    <visual>
      <geometry>
        <cylinder radius="0.04067756669870335" length="0.047459825690282814"/>
      </geometry>
      <material name="wheel_material"/>
    </visual>
    <collision>
      <geometry>
        <cylinder radius="0.04067756669870335" length="0.047459825690282814"/>
      </geometry>
    </collision>
    <inertial>
      <mass value="1.0"/>
      <inertia ixx="0.000601369029344534" ixy="0" ixz="0" 
               iyy="0.000601369029344534" iyz="0" 
               izz="0.0008273322162637299"/>
    </inertial>
  </link>
  <joint name="joint2" type="continuous">
    <parent link="base_link"/>
    <child link="link2"/>
    <origin xyz="0 0 0" rpy="1.5708 0 0"/>
    <axis xyz="0 1 0"/>
    <dynamics damping="0.16218323847909075" friction="0.1"/>
  </joint>
  <link name="link3">
    <visual>
      <geometry><box size="0.16637375523679443 0.14520141662434605 0.16189115600878834"/></geometry>
      <material name="rubber"/>
    </visual>
    <collision>
      <geometry><box size="0.16637375523679443 0.14520141662434605 0.16189115600878834"/></geometry>
    </collision>
    <inertial>
      <mass value="0.5"/>
      <inertia ixx="0.003941016481964897" ixy="0" ixz="0" 
               iyy="0.004490747735454552" iyz="0" 
               izz="0.004063639818442475"/>
    </inertial>
  </link>
  <joint name="joint3" type="floating">
    <parent link="base_link"/>
    <child link="link3"/>
    <origin xyz="0 0 0.09343839137552558" rpy="0 0 0"/>
    <axis xyz="0.9982348018936864 0.02616411279139667 -0.05331715943401187"/>
    <dynamics damping="0.6460829683878936" friction="0.1"/>
  </joint>
</robot>