<?xml version="1.0"?>
<robot name="evolved_robot">
  <material name="metal">
    <color rgba="0.7 0.7 0.7 1.0"/>
  </material>
  <material name="plastic">
    <color rgba="0.3 0.3 0.9 1.0"/>
  </material>
  <material name="rubber">
    <color rgba="0.1 0.1 0.1 1.0"/>
  </material>
  <material name="red">
    <color rgba="1.0 0.0 0.0 1.0"/>
  </material>
  <material name="wheel_material">
    <color rgba="0.2 0.2 0.2 1.0"/>
  </material>
  <link name="base_link">
    <visual>
      <geometry><box size="0.19801559195021387 0.11144871832192313 0.08167441603244525"/></geometry>
      <material name="plastic"/>
    </visual>
    <collision>
      <geometry><box size="0.19801559195021387 0.11144871832192313 0.08167441603244525"/></geometry>
    </collision>
    <inertial>
      <mass value="5.0"/>
      <inertia ixx="0.015909605874866926" ixy="0" ixz="0" 
               iyy="0.038234070741362126" iyz="0" 
               izz="0.04302582622582748"/>
    </inertial>
  </link>
  <link name="link1">
    <visual>
      <geometry>
        <cylinder radius="0.09983475004098984" length="0.052042964863796684"/>
      </geometry>
      <material name="wheel_material"/>
    </visual>
    <collision>
      <geometry>
        <cylinder radius="0.09983475004098984" length="0.052042964863796684"/>
      </geometry>
    </collision>
    <inertial>
      <mass value="1.0"/>
      <inertia ixx="0.002717450178254595" ixy="0" ixz="0" 
               iyy="0.002717450178254595" iyz="0" 
               izz="0.00498348865787346"/>
    </inertial>
  </link>
  <joint name="joint1" type="continuous">
    <parent link="base_link"/>
    <child link="link1"/>
    <origin xyz="0 0 0" rpy="1.5708 0 0"/>
    <axis xyz="0 1 0"/>
    <dynamics damping="0.538765284308765" friction="0.1"/>
  </joint>
  <link name="link2">
    <visual>
      <geometry><sphere radius="0.042118701975785294"/></geometry>
      <material name="plastic"/>
    </visual>
    <collision>
      <geometry><sphere radius="0.042118701975785294"/></geometry>
    </collision>
    <inertial>
      <mass value="0.5"/>
      <inertia ixx="0.000709594022450008" ixy="0" ixz="0" 
               iyy="0.000709594022450008" iyz="0" 
               izz="0.000709594022450008"/>
    </inertial>
  </link>
  <joint name="joint2" type="revolute">
    <parent link="base_link"/>
    <child link="link2"/>
    <origin xyz="0 0 0.04083720801622263" rpy="0 0 0"/>
    <axis xyz="0.5843404962639244 -0.32414476865246655 -0.7439599138268606"/>
    <dynamics damping="0.16218323847909075" friction="0.1"/>
    <limit lower="-1.6462805319562854" upper="0.9985262269434444" effort="100" velocity="100"/>
  </joint>
  <link name="link3">
    <visual>
      <geometry><box size="0.08388393625158302 0.1455028613393299 0.15896329571780166"/></geometry>
      <material name="rubber"/>
    </visual>
    <collision>
      <geometry><box size="0.08388393625158302 0.1455028613393299 0.15896329571780166"/></geometry>
    </collision>
    <inertial>
      <mass value="0.5"/>
      <inertia ixx="0.0038700343369497936" ixy="0" ixz="0" 
               iyy="0.0026921536788770753" iyz="0" 
               izz="0.002350633118249326"/>
    </inertial>
  </link>
  <joint name="joint3" type="revolute">
    <parent link="base_link"/>
    <child link="link3"/>
    <origin xyz="0 0 0.09083720801622264" rpy="0 0 0"/>
    <axis xyz="0.5797481687798887 0.028614241846408223 0.8142931204179003"/>
    <dynamics damping="0.6460829683878936" friction="0.1"/>
    <limit lower="-1.3552609935748683" upper="1.302399780524804" effort="100" velocity="100"/>
  </joint>
</robot>