<?xml version="1.0"?>
<robot name="evolved_robot">
  <material name="metal">
    <color rgba="0.7 0.7 0.7 1.0"/>
  </material>
  <material name="plastic">
    <color rgba="0.3 0.3 0.9 1.0"/>
  </material>
  <material name="rubber">
    <color rgba="0.1 0.1 0.1 1.0"/>
  </material>
  <material name="red">
    <color rgba="1.0 0.0 0.0 1.0"/>
  </material>
  <material name="wheel_material">
    <color rgba="0.2 0.2 0.2 1.0"/>
  </material>
  <link name="base_link">
    <visual>
      <geometry><box size="0.33999999999999997 0.42000000000000004 0.09000000000000001"/></geometry>
      <material name="metal"/>
    </visual>
    <collision>
      <geometry><box size="0.33999999999999997 0.42000000000000004 0.09000000000000001"/></geometry>
    </collision>
    <inertial>
      <mass value="5.0"/>
      <inertia ixx="0.15375000000000003" ixy="0" ixz="0" 
               iyy="0.1030833333333333" iyz="0" 
               izz="0.24333333333333337"/>
    </inertial>
  </link>
  <link name="link1">
    <visual>
      <geometry>
        <cylinder radius="0.065" length="0.05"/>
      </geometry>
      <material name="wheel_material"/>
    </visual>
    <collision>
      <geometry>
        <cylinder radius="0.065" length="0.05"/>
      </geometry>
    </collision>
    <inertial>
      <mass value="1.0"/>
      <inertia ixx="0.0012645833333333335" ixy="0" ixz="0" 
               iyy="0.0012645833333333335" iyz="0" 
               izz="0.0021125000000000002"/>
    </inertial>
  </link>
  <joint name="joint1" type="continuous">
    <parent link="base_link"/>
    <child link="link1"/>
    <origin xyz="0.15 0.21000000000000002 -0.045000000000000005" rpy="1.5708 0 0"/>
    <axis xyz="0 1 0"/>
    <dynamics damping="1.0" friction="0.1"/>
  </joint>
  <link name="link2">
    <visual>
      <geometry>
        <cylinder radius="0.065" length="0.05"/>
      </geometry>
      <material name="wheel_material"/>
    </visual>
    <collision>
      <geometry>
        <cylinder radius="0.065" length="0.05"/>
      </geometry>
    </collision>
    <inertial>
      <mass value="1.0"/>
      <inertia ixx="0.0012645833333333335" ixy="0" ixz="0" 
               iyy="0.0012645833333333335" iyz="0" 
               izz="0.0021125000000000002"/>
    </inertial>
  </link>
  <joint name="joint2" type="continuous">
    <parent link="base_link"/>
    <child link="link2"/>
    <origin xyz="0.15 -0.21000000000000002 -0.045000000000000005" rpy="1.5708 0 0"/>
    <axis xyz="0 1 0"/>
    <dynamics damping="1.0" friction="0.1"/>
  </joint>
  <link name="link3">
    <visual>
      <geometry>
        <cylinder radius="0.065" length="0.05"/>
      </geometry>
      <material name="wheel_material"/>
    </visual>
    <collision>
      <geometry>
        <cylinder radius="0.065" length="0.05"/>
      </geometry>
    </collision>
    <inertial>
      <mass value="1.0"/>
      <inertia ixx="0.0012645833333333335" ixy="0" ixz="0" 
               iyy="0.0012645833333333335" iyz="0" 
               izz="0.0021125000000000002"/>
    </inertial>
  </link>
  <joint name="joint3" type="continuous">
    <parent link="base_link"/>
    <child link="link3"/>
    <origin xyz="-0.15 0.21000000000000002 -0.045000000000000005" rpy="1.5708 0 0"/>
    <axis xyz="0 1 0"/>
    <dynamics damping="1.0" friction="0.1"/>
  </joint>
  <link name="link4">
    <visual>
      <geometry>
        <cylinder radius="0.065" length="0.05"/>
      </geometry>
      <material name="wheel_material"/>
    </visual>
    <collision>
      <geometry>
        <cylinder radius="0.065" length="0.05"/>
      </geometry>
    </collision>
    <inertial>
      <mass value="1.0"/>
      <inertia ixx="0.0012645833333333335" ixy="0" ixz="0" 
               iyy="0.0012645833333333335" iyz="0" 
               izz="0.0021125000000000002"/>
    </inertial>
  </link>
  <joint name="joint4" type="continuous">
    <parent link="base_link"/>
    <child link="link4"/>
    <origin xyz="-0.15 -0.21000000000000002 -0.045000000000000005" rpy="1.5708 0 0"/>
    <axis xyz="0 1 0"/>
    <dynamics damping="0.1" friction="0.1"/>
  </joint>
</robot>