<?xml version="1.0"?>
<robot name="evolved_robot">
  <material name="metal">
    <color rgba="0.7 0.7 0.7 1.0"/>
  </material>
  <material name="plastic">
    <color rgba="0.3 0.3 0.9 1.0"/>
  </material>
  <material name="rubber">
    <color rgba="0.1 0.1 0.1 1.0"/>
  </material>
  <material name="red">
    <color rgba="1.0 0.0 0.0 1.0"/>
  </material>
  <material name="wheel_material">
    <color rgba="0.2 0.2 0.2 1.0"/>
  </material>
  <link name="base_link">
    <visual>
      <geometry><box size="0.36293699291770254 0.39802988926891547 0.11877815702370191"/></geometry>
      <material name="metal"/>
    </visual>
    <collision>
      <geometry><box size="0.36293699291770254 0.39802988926891547 0.11877815702370191"/></geometry>
    </collision>
    <inertial>
      <mass value="5.0"/>
      <inertia ixx="0.1437800361144769" ixy="0" ixz="0" 
               iyy="0.12152625951174305" iyz="0" 
               izz="0.24179254464964128"/>
    </inertial>
  </link>
  <link name="link1">
    <visual>
      <geometry><box size="0.1101125690481089 0.23272315737002336 0.07850883860666177"/></geometry>
      <material name="rubber"/>
    </visual>
    <collision>
      <geometry><box size="0.1101125690481089 0.23272315737002336 0.07850883860666177"/></geometry>
    </collision>
    <inertial>
      <mass value="0.5"/>
      <inertia ixx="0.005026975476303294" ixy="0" ixz="0" 
               iyy="0.0015240346334784514" iyz="0" 
               izz="0.005523737153220601"/>
    </inertial>
  </link>
  <joint name="joint1" type="revolute">
    <parent link="base_link"/>
    <child link="link1"/>
    <origin xyz="0 0 0.059389078511850955" rpy="0 0 0"/>
    <axis xyz="-0.57597496467459 -0.6964865568534538 0.42797116280250186"/>
    <dynamics damping="0.7284404466419445" friction="0.1"/>
    <limit lower="-1.0495338218377648" upper="0.8178784390715127" effort="100" velocity="100"/>
  </joint>
  <link name="link2">
    <visual>
      <geometry><sphere radius="0.08401713258504231"/></geometry>
      <material name="rubber"/>
    </visual>
    <collision>
      <geometry><sphere radius="0.08401713258504231"/></geometry>
    </collision>
    <inertial>
      <mass value="0.5"/>
      <inertia ixx="0.0028235514271250316" ixy="0" ixz="0" 
               iyy="0.0028235514271250316" iyz="0" 
               izz="0.0028235514271250316"/>
    </inertial>
  </link>
  <joint name="joint2" type="revolute">
    <parent link="base_link"/>
    <child link="link2"/>
    <origin xyz="0 0 0.10938907851185095" rpy="0 0 0"/>
    <axis xyz="-0.7952839715505099 -0.606169438569321 -0.009056287285752857"/>
    <dynamics damping="0.9860015820705923" friction="0.1"/>
    <limit lower="-1.9316344969948975" upper="0.4876155156080496" effort="100" velocity="100"/>
  </joint>
  <link name="link3">
    <visual>
      <geometry><cylinder radius="0.04162996341320238" length="0.18471811729226006"/></geometry>
      <material name="plastic"/>
    </visual>
    <collision>
      <geometry><cylinder radius="0.04162996341320238" length="0.18471811729226006"/></geometry>
    </collision>
    <inertial>
      <mass value="0.5"/>
      <inertia ixx="0.0032766620347792377" ixy="0" ixz="0" 
               iyy="0.0032766620347792377" iyz="0" 
               izz="0.0008665269268922844"/>
    </inertial>
  </link>
  <joint name="joint3" type="fixed">
    <parent link="base_link"/>
    <child link="link3"/>
    <origin xyz="0 0 0.15938907851185097" rpy="0 0 0"/>
    <axis xyz="-0.03609250357389638 0.5936010180946992 0.803949726352777"/>
    <dynamics damping="0.6136898146820715" friction="0.1"/>
  </joint>
</robot>