<?xml version="1.0"?>
<robot name="evolved_robot">
  <material name="metal">
    <color rgba="0.7 0.7 0.7 1.0"/>
  </material>
  <material name="plastic">
    <color rgba="0.3 0.3 0.9 1.0"/>
  </material>
  <material name="rubber">
    <color rgba="0.1 0.1 0.1 1.0"/>
  </material>
  <material name="red">
    <color rgba="1.0 0.0 0.0 1.0"/>
  </material>
  <material name="wheel_material">
    <color rgba="0.2 0.2 0.2 1.0"/>
  </material>
  <link name="base_link">
    <visual>
      <geometry><box size="0.36947027690204315 0.2679192204188403 0.0882178935021293"/></geometry>
      <material name="metal"/>
    </visual>
    <collision>
      <geometry><box size="0.36947027690204315 0.2679192204188403 0.0882178935021293"/></geometry>
    </collision>
    <inertial>
      <mass value="5.0"/>
      <inertia ixx="0.06630258783649347" ixy="0" ixz="0" 
               iyy="0.12024223520668788" iyz="0" 
               izz="0.17357416181992633"/>
    </inertial>
  </link>
  <link name="link1">
    <visual>
      <geometry><sphere radius="0.025718812988674455"/></geometry>
      <material name="plastic"/>
    </visual>
    <collision>
      <geometry><sphere radius="0.025718812988674455"/></geometry>
    </collision>
    <inertial>
      <mass value="0.5"/>
      <inertia ixx="0.000264582936618564" ixy="0" ixz="0" 
               iyy="0.000264582936618564" iyz="0" 
               izz="0.000264582936618564"/>
    </inertial>
  </link>
  <joint name="joint1" type="revolute">
    <parent link="base_link"/>
    <child link="link1"/>
    <origin xyz="0 0 0.04410894675106465" rpy="0 0 0"/>
    <axis xyz="0.47161456261082824 -0.25099917231975494 -0.8453278179666129"/>
    <dynamics damping="0.7286138770830853" friction="0.1"/>
    <limit lower="-1.4056571553439232" upper="2.0410000000000004" effort="100" velocity="100"/>
  </joint>
  <link name="link2">
    <visual>
      <geometry><cylinder radius="0.04748461868768916" length="0.17589081206456914"/></geometry>
      <material name="metal"/>
    </visual>
    <collision>
      <geometry><cylinder radius="0.04748461868768916" length="0.17589081206456914"/></geometry>
    </collision>
    <inertial>
      <mass value="0.5"/>
      <inertia ixx="0.003141828733706608" ixy="0" ixz="0" 
               iyy="0.003141828733706608" iyz="0" 
               izz="0.0011273945059576194"/>
    </inertial>
  </link>
  <joint name="joint2" type="prismatic">
    <parent link="base_link"/>
    <child link="link2"/>
    <origin xyz="0 0 0.09410894675106465" rpy="0 0 0"/>
    <axis xyz="-0.1213542826155272 0.7814084394354781 -0.6121061908442696"/>
    <dynamics damping="0.783134629361819" friction="0.1"/>
    <limit lower="-2.1013286057260827" upper="2.0410000000000004" effort="100" velocity="100"/>
  </joint>
  <link name="link3">
    <visual>
      <geometry><sphere radius="0.038102241333459304"/></geometry>
      <material name="rubber"/>
    </visual>
    <collision>
      <geometry><sphere radius="0.038102241333459304"/></geometry>
    </collision>
    <inertial>
      <mass value="0.5"/>
      <inertia ixx="0.0005807123178532698" ixy="0" ixz="0" 
               iyy="0.0005807123178532698" iyz="0" 
               izz="0.0005807123178532698"/>
    </inertial>
  </link>
  <joint name="joint3" type="prismatic">
    <parent link="base_link"/>
    <child link="link3"/>
    <origin xyz="0 0 0.14410894675106467" rpy="0 0 0"/>
    <axis xyz="-0.3754868914110858 0.12877369787497456 0.9178381824232659"/>
    <dynamics damping="0.8258192548819009" friction="0.1"/>
    <limit lower="-1.9722058560484295" upper="1.4325630966673342" effort="100" velocity="100"/>
  </joint>
  <link name="link4">
    <visual>
      <geometry>
        <cylinder radius="0.06458918892878783" length="0.05724263080501997"/>
      </geometry>
      <material name="wheel_material"/>
    </visual>
    <collision>
      <geometry>
        <cylinder radius="0.06458918892878783" length="0.05724263080501997"/>
      </geometry>
    </collision>
    <inertial>
      <mass value="1.0"/>
      <inertia ixx="0.0013160007300763138" ixy="0" ixz="0" 
               iyy="0.0013160007300763138" iyz="0" 
               izz="0.002085881663239324"/>
    </inertial>
  </link>
  <joint name="joint4" type="continuous">
    <parent link="base_link"/>
    <child link="link4"/>
    <origin xyz="0 0 0" rpy="1.5708 0 0"/>
    <axis xyz="0 1 0"/>
    <dynamics damping="0.811539504510677" friction="0.1"/>
  </joint>
</robot>