<?xml version="1.0"?>
<robot name="evolved_robot">
  <material name="metal">
    <color rgba="0.7 0.7 0.7 1.0"/>
  </material>
  <material name="plastic">
    <color rgba="0.3 0.3 0.9 1.0"/>
  </material>
  <material name="rubber">
    <color rgba="0.1 0.1 0.1 1.0"/>
  </material>
  <material name="red">
    <color rgba="1.0 0.0 0.0 1.0"/>
  </material>
  <material name="wheel_material">
    <color rgba="0.2 0.2 0.2 1.0"/>
  </material>
  <link name="base_link">
    <visual>
      <geometry><box size="0.30694219765450376 0.2987526563359437 0.09179737753504208"/></geometry>
      <material name="metal"/>
    </visual>
    <collision>
      <geometry><box size="0.30694219765450376 0.2987526563359437 0.09179737753504208"/></geometry>
    </collision>
    <inertial>
      <mass value="5.0"/>
      <inertia ixx="0.08139992349174462" ixy="0" ixz="0" 
               iyy="0.08553355935273958" iyz="0" 
               izz="0.15288888530729913"/>
    </inertial>
  </link>
  <link name="link1">
    <visual>
      <geometry><cylinder radius="0.07570620283655916" length="0.2082732204995585"/></geometry>
      <material name="rubber"/>
    </visual>
    <collision>
      <geometry><cylinder radius="0.07570620283655916" length="0.2082732204995585"/></geometry>
    </collision>
    <inertial>
      <mass value="0.5"/>
      <inertia ixx="0.005047668485087369" ixy="0" ixz="0" 
               iyy="0.005047668485087369" iyz="0" 
               izz="0.0028657145739651186"/>
    </inertial>
  </link>
  <joint name="joint1" type="prismatic">
    <parent link="base_link"/>
    <child link="link1"/>
    <origin xyz="0 0 0.04589868876752104" rpy="0 0 0"/>
    <axis xyz="0.0 0.8501483675232039 -0.5265432111400082"/>
    <dynamics damping="0.8843855161457318" friction="0.1"/>
    <limit lower="-1.6942143091198556" upper="0.942" effort="100" velocity="100"/>
  </joint>
  <link name="link2">
    <visual>
      <geometry><cylinder radius="0.07483314033406659" length="0.11696022994158331"/></geometry>
      <material name="rubber"/>
    </visual>
    <collision>
      <geometry><cylinder radius="0.07483314033406659" length="0.11696022994158331"/></geometry>
    </collision>
    <inertial>
      <mass value="0.5"/>
      <inertia ixx="0.0025399743387301958" ixy="0" ixz="0" 
               iyy="0.0025399743387301958" iyz="0" 
               izz="0.0027999994461290517"/>
    </inertial>
  </link>
  <joint name="joint2" type="revolute">
    <parent link="base_link"/>
    <child link="link2"/>
    <origin xyz="0 0 0.09589868876752104" rpy="0 0 0"/>
    <axis xyz="0.8244815465120449 0.0 -0.5658888401984147"/>
    <dynamics damping="0.21473641413641037" friction="0.1"/>
    <limit lower="-2.501339023958599" upper="0.31400000000000006" effort="100" velocity="100"/>
  </joint>
  <link name="link3">
    <visual>
      <geometry><sphere radius="0.04049513125186626"/></geometry>
      <material name="plastic"/>
    </visual>
    <collision>
      <geometry><sphere radius="0.04049513125186626"/></geometry>
    </collision>
    <inertial>
      <mass value="0.5"/>
      <inertia ixx="0.0006559422620423502" ixy="0" ixz="0" 
               iyy="0.0006559422620423502" iyz="0" 
               izz="0.0006559422620423502"/>
    </inertial>
  </link>
  <joint name="joint3" type="fixed">
    <parent link="base_link"/>
    <child link="link3"/>
    <origin xyz="0 0 0.14589868876752105" rpy="0 0 0"/>
    <axis xyz="0.7807898475891004 -0.33295268921905913 0.5286867887923681"/>
    <dynamics damping="0.8006336577116039" friction="0.1"/>
  </joint>
  <link name="link4">
    <visual>
      <geometry><cylinder radius="0.06656798904426811" length="0.23730455389415234"/></geometry>
      <material name="metal"/>
    </visual>
    <collision>
      <geometry><cylinder radius="0.06656798904426811" length="0.23730455389415234"/></geometry>
    </collision>
    <inertial>
      <mass value="0.5"/>
      <inertia ixx="0.005800611899591337" ixy="0" ixz="0" 
               iyy="0.005800611899591337" iyz="0" 
               izz="0.0022156485826988997"/>
    </inertial>
  </link>
  <joint name="joint4" type="prismatic">
    <parent link="base_link"/>
    <child link="link4"/>
    <origin xyz="0 0 0.19589868876752106" rpy="0 0 0"/>
    <axis xyz="-1.267056625870882e-16 -0.9130105197007076 -0.40793601326169265"/>
    <dynamics damping="0.30098287863004475" friction="0.1"/>
    <limit lower="-1.782429157228089" upper="0.31400000000000006" effort="100" velocity="100"/>
  </joint>
  <link name="link5">
    <visual>
      <geometry><box size="0.2304896288690484 0.18362976107223616 0.21169919374858331"/></geometry>
      <material name="rubber"/>
    </visual>
    <collision>
      <geometry><box size="0.2304896288690484 0.18362976107223616 0.21169919374858331"/></geometry>
    </collision>
    <inertial>
      <mass value="0.5"/>
      <inertia ixx="0.006544703148770563" ixy="0" ixz="0" 
               iyy="0.00816183480416599" iyz="0" 
               izz="0.007237113180636517"/>
    </inertial>
  </link>
  <joint name="joint5" type="fixed">
    <parent link="base_link"/>
    <child link="link5"/>
    <origin xyz="0 0 0.24589868876752105" rpy="0 0 0"/>
    <axis xyz="0.7672100492102856 0.4033357712595115 -0.4987073250046027"/>
    <dynamics damping="0.3688987113063372" friction="0.1"/>
  </joint>
  <link name="link6">
    <visual>
      <geometry><sphere radius="0.051346996492291734"/></geometry>
      <material name="metal"/>
    </visual>
    <collision>
      <geometry><sphere radius="0.051346996492291734"/></geometry>
    </collision>
    <inertial>
      <mass value="0.5"/>
      <inertia ixx="0.001054605619511768" ixy="0" ixz="0" 
               iyy="0.001054605619511768" iyz="0" 
               izz="0.001054605619511768"/>
    </inertial>
  </link>
  <joint name="joint6" type="fixed">
    <parent link="base_link"/>
    <child link="link6"/>
    <origin xyz="0 0 0.295898688767521" rpy="0 0 0"/>
    <axis xyz="-0.8813528690894579 -0.15222645485110534 -0.4472630395988982"/>
    <dynamics damping="0.8598203663009973" friction="0.1"/>
  </joint>
</robot>