<?xml version="1.0"?>
<robot name="evolved_robot">
  <material name="metal">
    <color rgba="0.7 0.7 0.7 1.0"/>
  </material>
  <material name="plastic">
    <color rgba="0.3 0.3 0.9 1.0"/>
  </material>
  <material name="rubber">
    <color rgba="0.1 0.1 0.1 1.0"/>
  </material>
  <material name="red">
    <color rgba="1.0 0.0 0.0 1.0"/>
  </material>
  <material name="wheel_material">
    <color rgba="0.2 0.2 0.2 1.0"/>
  </material>
  <link name="base_link">
    <visual>
      <geometry><box size="0.33793404865689625 0.3368519893441706 0.08606384013105609"/></geometry>
      <material name="rubber"/>
    </visual>
    <collision>
      <geometry><box size="0.33793404865689625 0.3368519893441706 0.08606384013105609"/></geometry>
    </collision>
    <inertial>
      <mass value="5.0"/>
      <inertia ixx="0.10073020608602434" ixy="0" ixz="0" 
               iyy="0.10133867151645458" iyz="0" 
               izz="0.18972390330563896"/>
    </inertial>
  </link>
  <link name="link1">
    <visual>
      <geometry><box size="0.06725438337886802 0.06377533354768701 0.12268429060328084"/></geometry>
      <material name="rubber"/>
    </visual>
    <collision>
      <geometry><box size="0.06725438337886802 0.06377533354768701 0.12268429060328084"/></geometry>
    </collision>
    <inertial>
      <mass value="0.5"/>
      <inertia ixx="0.001593227360829083" ixy="0" ixz="0" 
               iyy="0.001631215603708502" iyz="0" 
               izz="0.000715870437732541"/>
    </inertial>
  </link>
  <joint name="joint1" type="fixed">
    <parent link="base_link"/>
    <child link="link1"/>
    <origin xyz="0 0 0.04303192006552804" rpy="0 0 0"/>
    <axis xyz="0.608183397911418 0.15500293230351223 0.7785159250023307"/>
    <dynamics damping="0.40381828413553666" friction="0.1"/>
  </joint>
  <link name="link2">
    <visual>
      <geometry><sphere radius="0.02881662979090126"/></geometry>
      <material name="metal"/>
    </visual>
    <collision>
      <geometry><sphere radius="0.02881662979090126"/></geometry>
    </collision>
    <inertial>
      <mass value="0.5"/>
      <inertia ixx="0.0003321592610023432" ixy="0" ixz="0" 
               iyy="0.0003321592610023432" iyz="0" 
               izz="0.0003321592610023432"/>
    </inertial>
  </link>
  <joint name="joint2" type="fixed">
    <parent link="base_link"/>
    <child link="link2"/>
    <origin xyz="0 0 0.09303192006552805" rpy="0 0 0"/>
    <axis xyz="0.08608239307458743 -0.6837666693530072 0.724605384664265"/>
    <dynamics damping="0.939412580183492" friction="0.1"/>
  </joint>
  <link name="link3">
    <visual>
      <geometry><cylinder radius="0.05766771463379714" length="0.218808580950834"/></geometry>
      <material name="rubber"/>
    </visual>
    <collision>
      <geometry><cylinder radius="0.05766771463379714" length="0.218808580950834"/></geometry>
    </collision>
    <inertial>
      <mass value="0.5"/>
      <inertia ixx="0.004821157585914404" ixy="0" ixz="0" 
               iyy="0.004821157585914404" iyz="0" 
               izz="0.0016627826555425304"/>
    </inertial>
  </link>
  <joint name="joint3" type="prismatic">
    <parent link="base_link"/>
    <child link="link3"/>
    <origin xyz="0 0 0.14303192006552806" rpy="0 0 0"/>
    <axis xyz="-0.35890568426186226 0.6216428802668194 -0.6962376312855383"/>
    <dynamics damping="0.41378074056414016" friction="0.1"/>
    <limit lower="-2.105846918404932" upper="0.31400000000000006" effort="100" velocity="100"/>
  </joint>
  <link name="link4">
    <visual>
      <geometry><box size="0.19244850971636918 0.11832355509302468 0.22629642735363747"/></geometry>
      <material name="metal"/>
    </visual>
    <collision>
      <geometry><box size="0.19244850971636918 0.11832355509302468 0.22629642735363747"/></geometry>
    </collision>
    <inertial>
      <mass value="0.5"/>
      <inertia ixx="0.00543421139357268" ixy="0" ixz="0" 
               iyy="0.00735387516042263" iyz="0" 
               izz="0.004253074381825291"/>
    </inertial>
  </link>
  <joint name="joint4" type="fixed">
    <parent link="base_link"/>
    <child link="link4"/>
    <origin xyz="0 0 0.19303192006552805" rpy="0 0 0"/>
    <axis xyz="0.9456068302218003 0.12145168612989012 0.3017900107261441"/>
    <dynamics damping="0.7601423444826052" friction="0.1"/>
  </joint>
  <link name="link5">
    <visual>
      <geometry><cylinder radius="0.06884817482875846" length="0.10566367258815734"/></geometry>
      <material name="metal"/>
    </visual>
    <collision>
      <geometry><cylinder radius="0.06884817482875846" length="0.10566367258815734"/></geometry>
    </collision>
    <inertial>
      <mass value="0.5"/>
      <inertia ixx="0.0021154187697142654" ixy="0" ixz="0" 
               iyy="0.0021154187697142654" iyz="0" 
               izz="0.002370035588625645"/>
    </inertial>
  </link>
  <joint name="joint5" type="prismatic">
    <parent link="base_link"/>
    <child link="link5"/>
    <origin xyz="0 0 0.24303192006552804" rpy="0 0 0"/>
    <axis xyz="-0.470186717808476 -0.8143872842883296 -0.340143795454175"/>
    <dynamics damping="0.9317489935448394" friction="0.1"/>
    <limit lower="-1.1019783636896798" upper="2.0410000000000004" effort="100" velocity="100"/>
  </joint>
  <link name="link6">
    <visual>
      <geometry><sphere radius="0.05280702184412922"/></geometry>
      <material name="rubber"/>
    </visual>
    <collision>
      <geometry><sphere radius="0.05280702184412922"/></geometry>
    </collision>
    <inertial>
      <mass value="0.5"/>
      <inertia ixx="0.0011154326224185362" ixy="0" ixz="0" 
               iyy="0.0011154326224185362" iyz="0" 
               izz="0.0011154326224185362"/>
    </inertial>
  </link>
  <joint name="joint6" type="prismatic">
    <parent link="base_link"/>
    <child link="link6"/>
    <origin xyz="0 0 0.29303192006552803" rpy="0 0 0"/>
    <axis xyz="0.823640907974663 0.0 -0.5671116774592748"/>
    <dynamics damping="0.23992172247795157" friction="0.1"/>
    <limit lower="-0.9955105425504531" upper="0.31400000000000006" effort="100" velocity="100"/>
  </joint>
</robot>