<?xml version="1.0"?>
<robot name="evolved_robot">
  <material name="metal">
    <color rgba="0.7 0.7 0.7 1.0"/>
  </material>
  <material name="plastic">
    <color rgba="0.3 0.3 0.9 1.0"/>
  </material>
  <material name="rubber">
    <color rgba="0.1 0.1 0.1 1.0"/>
  </material>
  <material name="red">
    <color rgba="1.0 0.0 0.0 1.0"/>
  </material>
  <material name="wheel_material">
    <color rgba="0.2 0.2 0.2 1.0"/>
  </material>
  <link name="base_link">
    <visual>
      <geometry><box size="0.314937614659212 0.3361883288096972 0.08684391380071729"/></geometry>
      <material name="plastic"/>
    </visual>
    <collision>
      <geometry><box size="0.314937614659212 0.3361883288096972 0.08684391380071729"/></geometry>
    </collision>
    <inertial>
      <mass value="5.0"/>
      <inertia ixx="0.10047038149340291" ixy="0" ixz="0" 
               iyy="0.08893963874288395" iyz="0" 
               izz="0.17684024462924278"/>
    </inertial>
  </link>
  <link name="link1">
    <visual>
      <geometry>
        <cylinder radius="0.06255185810306499" length="0.059851785901877536"/>
      </geometry>
      <material name="wheel_material"/>
    </visual>
    <collision>
      <geometry>
        <cylinder radius="0.06255185810306499" length="0.059851785901877536"/>
      </geometry>
    </collision>
    <inertial>
      <mass value="1.0"/>
      <inertia ixx="0.0012767034276735098" ixy="0" ixz="0" 
               iyy="0.0012767034276735098" iyz="0" 
               izz="0.0019563674760729884"/>
    </inertial>
  </link>
  <joint name="joint1" type="continuous">
    <parent link="base_link"/>
    <child link="link1"/>
    <origin xyz="0.137468807329606 0.1680941644048486 -0.043421956900358646" rpy="1.5708 0 0"/>
    <axis xyz="0 0 1"/>
    <dynamics damping="0.7784477715973885" friction="0.1"/>
  </joint>
  <link name="link2">
    <visual>
      <geometry>
        <cylinder radius="0.07578756342487761" length="0.042797147168368375"/>
      </geometry>
      <material name="wheel_material"/>
    </visual>
    <collision>
      <geometry>
        <cylinder radius="0.07578756342487761" length="0.042797147168368375"/>
      </geometry>
    </collision>
    <inertial>
      <mass value="1.0"/>
      <inertia ixx="0.0015885716762825432" ixy="0" ixz="0" 
               iyy="0.0015885716762825432" iyz="0" 
               izz="0.002871877384939923"/>
    </inertial>
  </link>
  <joint name="joint2" type="continuous">
    <parent link="base_link"/>
    <child link="link2"/>
    <origin xyz="0.137468807329606 -0.1680941644048486 -0.043421956900358646" rpy="1.5708 0 0"/>
    <axis xyz="0 0 1"/>
    <dynamics damping="0.9332973929305248" friction="0.1"/>
  </joint>
  <link name="link3">
    <visual>
      <geometry>
        <cylinder radius="0.06341371124760828" length="0.045823926981774545"/>
      </geometry>
      <material name="wheel_material"/>
    </visual>
    <collision>
      <geometry>
        <cylinder radius="0.06341371124760828" length="0.045823926981774545"/>
      </geometry>
    </collision>
    <inertial>
      <mass value="1.0"/>
      <inertia ixx="0.0011803107172180106" ixy="0" ixz="0" 
               iyy="0.0011803107172180106" iyz="0" 
               izz="0.0020106493870975205"/>
    </inertial>
  </link>
  <joint name="joint3" type="continuous">
    <parent link="base_link"/>
    <child link="link3"/>
    <origin xyz="-0.137468807329606 0.1680941644048486 -0.043421956900358646" rpy="1.5708 0 0"/>
    <axis xyz="0 0 1"/>
    <dynamics damping="0.43936669472471734" friction="0.1"/>
  </joint>
  <link name="link4">
    <visual>
      <geometry>
        <cylinder radius="0.07730006879916773" length="0.054359798864031916"/>
      </geometry>
      <material name="wheel_material"/>
    </visual>
    <collision>
      <geometry>
        <cylinder radius="0.07730006879916773" length="0.054359798864031916"/>
      </geometry>
    </collision>
    <inertial>
      <mass value="1.0"/>
      <inertia ixx="0.0017400741368005165" ixy="0" ixz="0" 
               iyy="0.0017400741368005165" iyz="0" 
               izz="0.002987650318178032"/>
    </inertial>
  </link>
  <joint name="joint4" type="continuous">
    <parent link="base_link"/>
    <child link="link4"/>
    <origin xyz="-0.137468807329606 -0.1680941644048486 -0.043421956900358646" rpy="1.5708 0 0"/>
    <axis xyz="0 0 1"/>
    <dynamics damping="0.6057419292639447" friction="0.1"/>
  </joint>
  <link name="link5">
    <visual>
      <geometry><box size="0.09626638882656657 0.15894820778350122 0.24381854726456892"/></geometry>
      <material name="rubber"/>
    </visual>
    <collision>
      <geometry><box size="0.09626638882656657 0.15894820778350122 0.24381854726456892"/></geometry>
    </collision>
    <inertial>
      <mass value="0.5"/>
      <inertia ixx="0.007059334728982659" ixy="0" ixz="0" 
               iyy="0.005726225133992711" iyz="0" 
               izz="0.0028776458646078986"/>
    </inertial>
  </link>
  <joint name="joint5" type="prismatic">
    <parent link="base_link"/>
    <child link="link5"/>
    <origin xyz="0 0 0.043421956900358646" rpy="0 0 0"/>
    <axis xyz="-0.4844001897994877 0.8045047724404462 0.3436983084665478"/>
    <dynamics damping="0.7425486986853486" friction="0.1"/>
    <limit lower="-0.9497299366794374" upper="1.1447330603144588" effort="100" velocity="100"/>
  </joint>
</robot>