<?xml version="1.0"?>
<robot name="evolved_robot">
  <material name="metal">
    <color rgba="0.7 0.7 0.7 1.0"/>
  </material>
  <material name="plastic">
    <color rgba="0.3 0.3 0.9 1.0"/>
  </material>
  <material name="rubber">
    <color rgba="0.1 0.1 0.1 1.0"/>
  </material>
  <material name="red">
    <color rgba="1.0 0.0 0.0 1.0"/>
  </material>
  <material name="wheel_material">
    <color rgba="0.2 0.2 0.2 1.0"/>
  </material>
  <link name="base_link">
    <visual>
      <geometry><sphere radius="0.11184482731263425"/></geometry>
      <material name="rubber"/>
    </visual>
    <collision>
      <geometry><sphere radius="0.11184482731263425"/></geometry>
    </collision>
    <inertial>
      <mass value="5.0"/>
      <inertia ixx="0.0500370615863719" ixy="0" ixz="0" 
               iyy="0.0500370615863719" iyz="0" 
               izz="0.0500370615863719"/>
    </inertial>
  </link>
  <link name="link1">
    <visual>
      <geometry><cylinder radius="0.058852211180721245" length="0.14419782190316577"/></geometry>
      <material name="metal"/>
    </visual>
    <collision>
      <geometry><cylinder radius="0.058852211180721245" length="0.14419782190316577"/></geometry>
    </collision>
    <inertial>
      <mass value="0.5"/>
      <inertia ixx="0.0025986466770164785" ixy="0" ixz="0" 
               iyy="0.0025986466770164785" iyz="0" 
               izz="0.0017317913804301053"/>
    </inertial>
  </link>
  <joint name="joint1" type="prismatic">
    <parent link="base_link"/>
    <child link="link1"/>
    <origin xyz="0 0 0.040923881314346724" rpy="0 0 0"/>
    <axis xyz="0.6366138779369415 0.7699174097081446 0.044158268154332776"/>
    <dynamics damping="0.8607549115547044" friction="0.1"/>
    <limit lower="-1.482553113149272" upper="1.1798967854745552" effort="100" velocity="100"/>
  </joint>
  <link name="link2">
    <visual>
      <geometry><cylinder radius="0.04493365824800573" length="0.15561033324587772"/></geometry>
      <material name="metal"/>
    </visual>
    <collision>
      <geometry><cylinder radius="0.04493365824800573" length="0.15561033324587772"/></geometry>
    </collision>
    <inertial>
      <mass value="0.5"/>
      <inertia ixx="0.0025226397286282364" ixy="0" ixz="0" 
               iyy="0.0025226397286282364" iyz="0" 
               izz="0.0010095168217742867"/>
    </inertial>
  </link>
  <joint name="joint2" type="revolute">
    <parent link="base_link"/>
    <child link="link2"/>
    <origin xyz="0 0 0.09092388131434673" rpy="0 0 0"/>
    <axis xyz="0.17068088249903568 0.6742651155709855 -0.7184946696207257"/>
    <dynamics damping="0.9327619503618296" friction="0.1"/>
    <limit lower="-1.0342708593125645" upper="1.1965535084965258" effort="100" velocity="100"/>
  </joint>
  <link name="link3">
    <visual>
      <geometry><cylinder radius="0.036136221472128346" length="0.0822543906844797"/></geometry>
      <material name="rubber"/>
    </visual>
    <collision>
      <geometry><cylinder radius="0.036136221472128346" length="0.0822543906844797"/></geometry>
    </collision>
    <inertial>
      <mass value="0.5"/>
      <inertia ixx="0.0008902720244769293" ixy="0" ixz="0" 
               iyy="0.0008902720244769293" iyz="0" 
               izz="0.0006529132511413549"/>
    </inertial>
  </link>
  <joint name="joint3" type="revolute">
    <parent link="base_link"/>
    <child link="link3"/>
    <origin xyz="0 0 0.14092388131434674" rpy="0 0 0"/>
    <axis xyz="-0.6363775055751835 -0.7676177809980034 0.07606978831052802"/>
    <dynamics damping="0.9661564945648872" friction="0.1"/>
    <limit lower="-1.9477677111407616" upper="0.3269065870470448" effort="100" velocity="100"/>
  </joint>
  <link name="link4">
    <visual>
      <geometry>
        <cylinder radius="0.05388269810814987" length="0.03741854528710674"/>
      </geometry>
      <material name="wheel_material"/>
    </visual>
    <collision>
      <geometry>
        <cylinder radius="0.05388269810814987" length="0.03741854528710674"/>
      </geometry>
    </collision>
    <inertial>
      <mass value="1.0"/>
      <inertia ixx="0.0008425152498037758" ixy="0" ixz="0" 
               iyy="0.0008425152498037758" iyz="0" 
               izz="0.0014516725777070087"/>
    </inertial>
  </link>
  <joint name="joint4" type="fixed">
    <parent link="base_link"/>
    <child link="link4"/>
    <origin xyz="0 0 0" rpy="1.5708 0 0"/>
    <axis xyz="0 1 0"/>
    <dynamics damping="0.714084682254789" friction="0.1"/>
  </joint>
  <link name="link5">
    <visual>
      <geometry><sphere radius="0.04797323500075234"/></geometry>
      <material name="metal"/>
    </visual>
    <collision>
      <geometry><sphere radius="0.04797323500075234"/></geometry>
    </collision>
    <inertial>
      <mass value="0.5"/>
      <inertia ixx="0.0009205725105749636" ixy="0" ixz="0" 
               iyy="0.0009205725105749636" iyz="0" 
               izz="0.0009205725105749636"/>
    </inertial>
  </link>
  <joint name="joint5" type="revolute">
    <parent link="base_link"/>
    <child link="link5"/>
    <origin xyz="0 0 0.19092388131434673" rpy="0 0 0"/>
    <axis xyz="0.9452817001885043 0.3230863103454839 0.045362356156533876"/>
    <dynamics damping="0.23320726527206692" friction="0.1"/>
    <limit lower="-1.3610953420342446" upper="1.4696322596988438" effort="100" velocity="100"/>
  </joint>
  <link name="link6">
    <visual>
      <geometry><cylinder radius="0.076660834712553" length="0.20969266245970059"/></geometry>
      <material name="rubber"/>
    </visual>
    <collision>
      <geometry><cylinder radius="0.076660834712553" length="0.20969266245970059"/></geometry>
    </collision>
    <inertial>
      <mass value="0.5"/>
      <inertia ixx="0.005133471952159503" ixy="0" ixz="0" 
               iyy="0.005133471952159503" iyz="0" 
               izz="0.0029384417894126854"/>
    </inertial>
  </link>
  <joint name="joint6" type="revolute">
    <parent link="base_link"/>
    <child link="link6"/>
    <origin xyz="0 0 0.24092388131434672" rpy="0 0 0"/>
    <axis xyz="-0.5695545828168672 -0.23716326355750206 0.7869950213381651"/>
    <dynamics damping="0.9328317076675361" friction="0.1"/>
    <limit lower="-2.1943446992290454" upper="0.31400000000000006" effort="100" velocity="100"/>
  </joint>
</robot>