<?xml version="1.0"?>
<robot name="evolved_robot">
  <material name="metal">
    <color rgba="0.7 0.7 0.7 1.0"/>
  </material>
  <material name="plastic">
    <color rgba="0.3 0.3 0.9 1.0"/>
  </material>
  <material name="rubber">
    <color rgba="0.1 0.1 0.1 1.0"/>
  </material>
  <material name="red">
    <color rgba="1.0 0.0 0.0 1.0"/>
  </material>
  <material name="wheel_material">
    <color rgba="0.2 0.2 0.2 1.0"/>
  </material>
  <link name="base_link">
    <visual>
      <geometry><cylinder radius="0.15382927939700256" length="0.07850034267839781"/></geometry>
      <material name="metal"/>
    </visual>
    <collision>
      <geometry><cylinder radius="0.15382927939700256" length="0.07850034267839781"/></geometry>
    </collision>
    <inertial>
      <mass value="5.0"/>
      <inertia ixx="0.06429387116669093" ixy="0" ixz="0" 
               iyy="0.06429387116669093" iyz="0" 
               izz="0.11831723599900537"/>
    </inertial>
  </link>
  <link name="link1">
    <visual>
      <geometry><box size="0.17519830839208272 0.183601067012174 0.17115775961517782"/></geometry>
      <material name="rubber"/>
    </visual>
    <collision>
      <geometry><box size="0.17519830839208272 0.183601067012174 0.17115775961517782"/></geometry>
    </collision>
    <inertial>
      <mass value="0.5"/>
      <inertia ixx="0.0052503608737079835" ixy="0" ixz="0" 
               iyy="0.00499911882832786" iyz="0" 
               izz="0.005366983255954677"/>
    </inertial>
  </link>
  <joint name="joint1" type="prismatic">
    <parent link="base_link"/>
    <child link="link1"/>
    <origin xyz="0 0 0.039250171339198905" rpy="0 0 0"/>
    <axis xyz="-0.5834783414454731 -0.4995768975707236 0.6402936423842196"/>
    <dynamics damping="0.7756290107676767" friction="0.1"/>
    <limit lower="-1.8508781419898999" upper="1.2616069225743036" effort="100" velocity="100"/>
  </joint>
  <link name="link2">
    <visual>
      <geometry><cylinder radius="0.061168260744445924" length="0.05"/></geometry>
      <material name="rubber"/>
    </visual>
    <collision>
      <geometry><cylinder radius="0.061168260744445924" length="0.05"/></geometry>
    </collision>
    <inertial>
      <mass value="0.5"/>
      <inertia ixx="0.0011437223639584645" ixy="0" ixz="0" 
               iyy="0.0011437223639584645" iyz="0" 
               izz="0.001870778061250262"/>
    </inertial>
  </link>
  <joint name="joint2" type="revolute">
    <parent link="base_link"/>
    <child link="link2"/>
    <origin xyz="0 0 0.08925017133919891" rpy="0 0 0"/>
    <axis xyz="0.004036345972824024 0.9999102312649011 0.012776436238622084"/>
    <dynamics damping="0.6237323492205411" friction="0.1"/>
    <limit lower="-1.167996821882725" upper="0.3291637689285097" effort="100" velocity="100"/>
  </joint>
  <link name="link3">
    <visual>
      <geometry><cylinder radius="0.05648714263540267" length="0.21069213350351157"/></geometry>
      <material name="metal"/>
    </visual>
    <collision>
      <geometry><cylinder radius="0.05648714263540267" length="0.21069213350351157"/></geometry>
    </collision>
    <inertial>
      <mass value="0.5"/>
      <inertia ixx="0.00449696391413321" ixy="0" ixz="0" 
               iyy="0.00449696391413321" iyz="0" 
               izz="0.0015953986415561633"/>
    </inertial>
  </link>
  <joint name="joint3" type="fixed">
    <parent link="base_link"/>
    <child link="link3"/>
    <origin xyz="0 0 0.13925017133919892" rpy="0 0 0"/>
    <axis xyz="-0.4392312433782156 0.5473213081910046 -0.712401081161809"/>
    <dynamics damping="0.7578348276463946" friction="0.1"/>
  </joint>
  <link name="link4">
    <visual>
      <geometry>
        <cylinder radius="0.07431988027820463" length="0.0475468977467914"/>
      </geometry>
      <material name="wheel_material"/>
    </visual>
    <collision>
      <geometry>
        <cylinder radius="0.07431988027820463" length="0.0475468977467914"/>
      </geometry>
    </collision>
    <inertial>
      <mass value="1.0"/>
      <inertia ixx="0.0015692534415869873" ixy="0" ixz="0" 
               iyy="0.0015692534415869873" iyz="0" 
               izz="0.002761722302283335"/>
    </inertial>
  </link>
  <joint name="joint4" type="continuous">
    <parent link="base_link"/>
    <child link="link4"/>
    <origin xyz="0.13985519542031713 0.147803363373688 -0.039250171339198905" rpy="1.5708 0 0"/>
    <axis xyz="0 1 0"/>
    <dynamics damping="0.4505874175558846" friction="0.1"/>
  </joint>
  <link name="link5">
    <visual>
      <geometry><box size="0.17621994370962157 0.13213922379327636 0.06508690518799387"/></geometry>
      <material name="metal"/>
    </visual>
    <collision>
      <geometry><box size="0.17621994370962157 0.13213922379327636 0.06508690518799387"/></geometry>
    </collision>
    <inertial>
      <mass value="0.5"/>
      <inertia ixx="0.001808089974303373" ixy="0" ixz="0" 
               iyy="0.0029408144823310917" iyz="0" 
               izz="0.00404285358547598"/>
    </inertial>
  </link>
  <joint name="joint5" type="revolute">
    <parent link="base_link"/>
    <child link="link5"/>
    <origin xyz="0 0 0.1892501713391989" rpy="0 0 0"/>
    <axis xyz="-0.6232689634309198 0.28684034522542107 0.7275014883659746"/>
    <dynamics damping="0.9085849821180177" friction="0.1"/>
    <limit lower="-0.9449634106549294" upper="1.031742174438291" effort="100" velocity="100"/>
  </joint>
  <link name="link6">
    <visual>
      <geometry>
        <cylinder radius="0.06308729785767267" length="0.04215283204978924"/>
      </geometry>
      <material name="wheel_material"/>
    </visual>
    <collision>
      <geometry>
        <cylinder radius="0.06308729785767267" length="0.04215283204978924"/>
      </geometry>
    </collision>
    <inertial>
      <mass value="1.0"/>
      <inertia ixx="0.0011430735585638225" ixy="0" ixz="0" 
               iyy="0.0011430735585638225" iyz="0" 
               izz="0.0019900035754913553"/>
    </inertial>
  </link>
  <joint name="joint6" type="continuous">
    <parent link="base_link"/>
    <child link="link6"/>
    <origin xyz="-0.13985519542031713 0.147803363373688 -0.039250171339198905" rpy="1.5708 0 0"/>
    <axis xyz="0 1 0"/>
    <dynamics damping="0.5100125765798248" friction="0.1"/>
  </joint>
</robot>