<?xml version="1.0"?>
<robot name="evolved_robot">
  <material name="metal">
    <color rgba="0.7 0.7 0.7 1.0"/>
  </material>
  <material name="plastic">
    <color rgba="0.3 0.3 0.9 1.0"/>
  </material>
  <material name="rubber">
    <color rgba="0.1 0.1 0.1 1.0"/>
  </material>
  <material name="red">
    <color rgba="1.0 0.0 0.0 1.0"/>
  </material>
  <material name="wheel_material">
    <color rgba="0.2 0.2 0.2 1.0"/>
  </material>
  <link name="base_link">
    <visual>
      <geometry><box size="0.2781581222899774 0.3739528256750301 0.12047451448317992"/></geometry>
      <material name="plastic"/>
    </visual>
    <collision>
      <geometry><box size="0.2781581222899774 0.3739528256750301 0.12047451448317992"/></geometry>
    </collision>
    <inertial>
      <mass value="5.0"/>
      <inertia ixx="0.12862902039191446" ixy="0" ixz="0" 
               iyy="0.07657170802986996" iyz="0" 
               izz="0.18101054735518787"/>
    </inertial>
  </link>
  <link name="link1">
    <visual>
      <geometry><box size="0.1500158224353627 0.0902779075223667 0.1166910226070632"/></geometry>
      <material name="rubber"/>
    </visual>
    <collision>
      <geometry><box size="0.1500158224353627 0.0902779075223667 0.1166910226070632"/></geometry>
    </collision>
    <inertial>
      <mass value="0.5"/>
      <inertia ixx="0.0018139079453082605" ixy="0" ixz="0" 
               iyy="0.0030101284781700343" iyz="0" 
               izz="0.0025545706306312724"/>
    </inertial>
  </link>
  <joint name="joint1" type="fixed">
    <parent link="base_link"/>
    <child link="link1"/>
    <origin xyz="0 0 0.06023725724158996" rpy="0 0 0"/>
    <axis xyz="-0.6294383714801838 -0.2944237727698373 0.7191119374174992"/>
    <dynamics damping="0.9475607656109023" friction="0.1"/>
  </joint>
  <link name="link2">
    <visual>
      <geometry><sphere radius="0.0686968807996716"/></geometry>
      <material name="plastic"/>
    </visual>
    <collision>
      <geometry><sphere radius="0.0686968807996716"/></geometry>
    </collision>
    <inertial>
      <mass value="0.5"/>
      <inertia ixx="0.0018877045726417151" ixy="0" ixz="0" 
               iyy="0.0018877045726417151" iyz="0" 
               izz="0.0018877045726417151"/>
    </inertial>
  </link>
  <joint name="joint2" type="fixed">
    <parent link="base_link"/>
    <child link="link2"/>
    <origin xyz="0 0 0.11023725724158996" rpy="0 0 0"/>
    <axis xyz="0.802993834590659 -0.5923869848484455 0.06541071618287715"/>
    <dynamics damping="0.698665672160521" friction="0.1"/>
  </joint>
  <link name="link3">
    <visual>
      <geometry><box size="0.13191980449005813 0.145218197137653 0.09431883426255927"/></geometry>
      <material name="metal"/>
    </visual>
    <collision>
      <geometry><box size="0.13191980449005813 0.145218197137653 0.09431883426255927"/></geometry>
    </collision>
    <inertial>
      <mass value="0.5"/>
      <inertia ixx="0.0024986972730465314" ixy="0" ixz="0" 
               iyy="0.002191573109445274" iyz="0" 
               izz="0.003207596633050451"/>
    </inertial>
  </link>
  <joint name="joint3" type="floating">
    <parent link="base_link"/>
    <child link="link3"/>
    <origin xyz="0 0 0.16023725724158996" rpy="0 0 0"/>
    <axis xyz="-0.00844357191485646 -0.1752183636232804 0.9844933880643885"/>
    <dynamics damping="0.2866828248029867" friction="0.1"/>
  </joint>
  <link name="link4">
    <visual>
      <geometry><cylinder radius="0.05448446269041668" length="0.10246528480598105"/></geometry>
      <material name="rubber"/>
    </visual>
    <collision>
      <geometry><cylinder radius="0.05448446269041668" length="0.10246528480598105"/></geometry>
    </collision>
    <inertial>
      <mass value="0.5"/>
      <inertia ixx="0.0016170670511967526" ixy="0" ixz="0" 
               iyy="0.0016170670511967526" iyz="0" 
               izz="0.0014842783373317035"/>
    </inertial>
  </link>
  <joint name="joint4" type="fixed">
    <parent link="base_link"/>
    <child link="link4"/>
    <origin xyz="0 0 0.21023725724158998" rpy="0 0 0"/>
    <axis xyz="-0.8687554485396898 0.37174054402450407 0.32722001552620233"/>
    <dynamics damping="0.3724402879621216" friction="0.1"/>
  </joint>
  <link name="link5">
    <visual>
      <geometry><sphere radius="0.02638153123708216"/></geometry>
      <material name="metal"/>
    </visual>
    <collision>
      <geometry><sphere radius="0.02638153123708216"/></geometry>
    </collision>
    <inertial>
      <mass value="0.5"/>
      <inertia ixx="0.00027839407616525667" ixy="0" ixz="0" 
               iyy="0.00027839407616525667" iyz="0" 
               izz="0.00027839407616525667"/>
    </inertial>
  </link>
  <joint name="joint5" type="prismatic">
    <parent link="base_link"/>
    <child link="link5"/>
    <origin xyz="0 0 0.26023725724158997" rpy="0 0 0"/>
    <axis xyz="0.6437978595403788 0.5424854833993221 0.5396608345546583"/>
    <dynamics damping="0.8366085572429733" friction="0.1"/>
    <limit lower="-2.844163976110992" upper="1.5325606017750952" effort="100" velocity="100"/>
  </joint>
  <link name="link6">
    <visual>
      <geometry><box size="0.2248738714098747 0.10310209383206413 0.21832004370199348"/></geometry>
      <material name="metal"/>
    </visual>
    <collision>
      <geometry><box size="0.2248738714098747 0.10310209383206413 0.21832004370199348"/></geometry>
    </collision>
    <inertial>
      <mass value="0.5"/>
      <inertia ixx="0.004857806936216342" ixy="0" ixz="0" 
               iyy="0.008185991627075433" iyz="0" 
               izz="0.005099858316285052"/>
    </inertial>
  </link>
  <joint name="joint6" type="revolute">
    <parent link="base_link"/>
    <child link="link6"/>
    <origin xyz="0 0 0.31023725724158996" rpy="0 0 0"/>
    <axis xyz="0.6705199260274887 0.18636277116561134 -0.7181030192970677"/>
    <dynamics damping="0.4273329463005927" friction="0.1"/>
    <limit lower="-0.333794321286992" upper="1.9474029542668914" effort="100" velocity="100"/>
  </joint>
</robot>