<?xml version="1.0"?>
<robot name="evolved_robot">
  <material name="metal">
    <color rgba="0.7 0.7 0.7 1.0"/>
  </material>
  <material name="plastic">
    <color rgba="0.3 0.3 0.9 1.0"/>
  </material>
  <material name="rubber">
    <color rgba="0.1 0.1 0.1 1.0"/>
  </material>
  <material name="red">
    <color rgba="1.0 0.0 0.0 1.0"/>
  </material>
  <material name="wheel_material">
    <color rgba="0.2 0.2 0.2 1.0"/>
  </material>
  <link name="base_link">
    <visual>
      <geometry><box size="0.4229596400917953 0.3446729242588785 0.07690886759529983"/></geometry>
      <material name="metal"/>
    </visual>
    <collision>
      <geometry><box size="0.4229596400917953 0.3446729242588785 0.07690886759529983"/></geometry>
    </collision>
    <inertial>
      <mass value="5.0"/>
      <inertia ixx="0.10392866552663164" ixy="0" ixz="0" 
               iyy="0.15400819255114367" iyz="0" 
               izz="0.24807856821978969"/>
    </inertial>
  </link>
  <link name="link1">
    <visual>
      <geometry>
        <cylinder radius="0.03842956847556405" length="0.040573280776250026"/>
      </geometry>
      <material name="wheel_material"/>
    </visual>
    <collision>
      <geometry>
        <cylinder radius="0.03842956847556405" length="0.040573280776250026"/>
      </geometry>
    </collision>
    <inertial>
      <mass value="1.0"/>
      <inertia ixx="0.0005063905260502182" ixy="0" ixz="0" 
               iyy="0.0005063905260502182" iyz="0" 
               izz="0.0007384158666090331"/>
    </inertial>
  </link>
  <joint name="joint1" type="prismatic">
    <parent link="base_link"/>
    <child link="link1"/>
    <origin xyz="0.19147982004589767 0.17233646212943926 -0.038454433797649915" rpy="1.5708 0 0"/>
    <axis xyz="0 1 0"/>
    <dynamics damping="0.9620773342175082" friction="0.1"/>
  </joint>
  <link name="link2">
    <visual>
      <geometry>
        <cylinder radius="0.09411244893630778" length="0.06357497189143543"/>
      </geometry>
      <material name="wheel_material"/>
    </visual>
    <collision>
      <geometry>
        <cylinder radius="0.09411244893630778" length="0.06357497189143543"/>
      </geometry>
    </collision>
    <inertial>
      <mass value="1.0"/>
      <inertia ixx="0.002551103015447019" ixy="0" ixz="0" 
               iyy="0.002551103015447019" iyz="0" 
               izz="0.00442857652239457"/>
    </inertial>
  </link>
  <joint name="joint2" type="floating">
    <parent link="base_link"/>
    <child link="link2"/>
    <origin xyz="0.19147982004589767 -0.17233646212943926 -0.038454433797649915" rpy="1.5708 0 0"/>
    <axis xyz="0 1 0"/>
    <dynamics damping="0.9511788792221783" friction="0.1"/>
  </joint>
  <link name="link3">
    <visual>
      <geometry>
        <cylinder radius="0.07843540050517425" length="0.06346825080929239"/>
      </geometry>
      <material name="wheel_material"/>
    </visual>
    <collision>
      <geometry>
        <cylinder radius="0.07843540050517425" length="0.06346825080929239"/>
      </geometry>
    </collision>
    <inertial>
      <mass value="1.0"/>
      <inertia ixx="0.0018737129181677094" ixy="0" ixz="0" 
               iyy="0.0018737129181677094" iyz="0" 
               izz="0.0030760560262035447"/>
    </inertial>
  </link>
  <joint name="joint3" type="continuous">
    <parent link="base_link"/>
    <child link="link3"/>
    <origin xyz="-0.19147982004589767 0.17233646212943926 -0.038454433797649915" rpy="1.5708 0 0"/>
    <axis xyz="0 1 0"/>
    <dynamics damping="0.7850074824219392" friction="0.1"/>
  </joint>
  <link name="link4">
    <visual>
      <geometry>
        <cylinder radius="0.09302128140791992" length="0.04117632854146757"/>
      </geometry>
      <material name="wheel_material"/>
    </visual>
    <collision>
      <geometry>
        <cylinder radius="0.09302128140791992" length="0.04117632854146757"/>
      </geometry>
    </collision>
    <inertial>
      <mass value="1.0"/>
      <inertia ixx="0.0023045305347057636" ixy="0" ixz="0" 
               iyy="0.0023045305347057636" iyz="0" 
               izz="0.004326479397385714"/>
    </inertial>
  </link>
  <joint name="joint4" type="continuous">
    <parent link="base_link"/>
    <child link="link4"/>
    <origin xyz="-0.19147982004589767 -0.17233646212943926 -0.038454433797649915" rpy="1.5708 0 0"/>
    <axis xyz="0 1 0"/>
    <dynamics damping="0.724065632719656" friction="0.1"/>
  </joint>
  <link name="link5">
    <visual>
      <geometry><cylinder radius="0.08881825082730221" length="0.0960845816393998"/></geometry>
      <material name="rubber"/>
    </visual>
    <collision>
      <geometry><cylinder radius="0.08881825082730221" length="0.0960845816393998"/></geometry>
    </collision>
    <inertial>
      <mass value="0.5"/>
      <inertia ixx="0.002741524322406933" ixy="0" ixz="0" 
               iyy="0.002741524322406933" iyz="0" 
               izz="0.003944340840010785"/>
    </inertial>
  </link>
  <joint name="joint5" type="revolute">
    <parent link="base_link"/>
    <child link="link5"/>
    <origin xyz="0 0 0.038454433797649915" rpy="0 0 0"/>
    <axis xyz="0.0 0.7454133210911001 0.6666025658065954"/>
    <dynamics damping="0.6399789341093577" friction="0.1"/>
    <limit lower="-0.827567834315494" upper="1.283811247704254" effort="100" velocity="100"/>
  </joint>
  <link name="link6">
    <visual>
      <geometry>
        <cylinder radius="0.09728576832582488" length="0.04546005297529622"/>
      </geometry>
      <material name="wheel_material"/>
    </visual>
    <collision>
      <geometry>
        <cylinder radius="0.09728576832582488" length="0.04546005297529622"/>
      </geometry>
    </collision>
    <inertial>
      <mass value="1.0"/>
      <inertia ixx="0.0025383482143962457" ixy="0" ixz="0" 
               iyy="0.0025383482143962457" iyz="0" 
               izz="0.004732260359373035"/>
    </inertial>
  </link>
  <joint name="joint6" type="continuous">
    <parent link="base_link"/>
    <child link="link6"/>
    <origin xyz="0 -0.22978194950591901 -0.038454433797649915" rpy="1.5708 0 0"/>
    <axis xyz="0 1 0"/>
    <dynamics damping="0.9384190659020333" friction="0.1"/>
  </joint>
  <link name="link7">
    <visual>
      <geometry>
        <cylinder radius="0.04224674775365732" length="0.03656617970180511"/>
      </geometry>
      <material name="wheel_material"/>
    </visual>
    <collision>
      <geometry>
        <cylinder radius="0.04224674775365732" length="0.03656617970180511"/>
      </geometry>
    </collision>
    <inertial>
      <mass value="1.0"/>
      <inertia ixx="0.0005576207154390127" ixy="0" ixz="0" 
               iyy="0.0005576207154390127" iyz="0" 
               izz="0.0008923938478805748"/>
    </inertial>
  </link>
  <joint name="joint7" type="continuous">
    <parent link="base_link"/>
    <child link="link7"/>
    <origin xyz="0 1.770218050494081 -0.038454433797649915" rpy="1.5708 0 0"/>
    <axis xyz="0 1 0"/>
    <dynamics damping="0.1" friction="0.1"/>
  </joint>
</robot>