<?xml version="1.0"?>
<robot name="evolved_robot">
  <material name="metal">
    <color rgba="0.7 0.7 0.7 1.0"/>
  </material>
  <material name="plastic">
    <color rgba="0.3 0.3 0.9 1.0"/>
  </material>
  <material name="rubber">
    <color rgba="0.1 0.1 0.1 1.0"/>
  </material>
  <material name="red">
    <color rgba="1.0 0.0 0.0 1.0"/>
  </material>
  <material name="wheel_material">
    <color rgba="0.2 0.2 0.2 1.0"/>
  </material>
  <link name="base_link">
    <visual>
      <geometry><box size="0.47191978031443116 0.3439452515871238 0.10917641224025697"/></geometry>
      <material name="metal"/>
    </visual>
    <collision>
      <geometry><box size="0.47191978031443116 0.3439452515871238 0.10917641224025697"/></geometry>
    </collision>
    <inertial>
      <mass value="5.0"/>
      <inertia ixx="0.10851485423248704" ixy="0" ixz="0" 
               iyy="0.1955231400347296" iyz="0" 
               izz="0.2841721792844591"/>
    </inertial>
  </link>
  <link name="link1">
    <visual>
      <geometry><cylinder radius="0.07461464031961021" length="0.14789621696584562"/></geometry>
      <material name="rubber"/>
    </visual>
    <collision>
      <geometry><cylinder radius="0.07461464031961021" length="0.14789621696584562"/></geometry>
    </collision>
    <inertial>
      <mass value="0.5"/>
      <inertia ixx="0.0032146103869069072" ixy="0" ixz="0" 
               iyy="0.0032146103869069072" iyz="0" 
               izz="0.002783672275012401"/>
    </inertial>
  </link>
  <joint name="joint1" type="revolute">
    <parent link="base_link"/>
    <child link="link1"/>
    <origin xyz="0 0 0.054588206120128484" rpy="0 0 0"/>
    <axis xyz="-0.030185344301609345 0.9995441346793484 0.0006064796005810541"/>
    <dynamics damping="0.800080736609337" friction="0.1"/>
    <limit lower="-1.2927364263293877" upper="2.4450951794141735" effort="100" velocity="100"/>
  </joint>
  <link name="link2">
    <visual>
      <geometry>
        <cylinder radius="0.08411711869646316" length="0.07340695400580502"/>
      </geometry>
      <material name="wheel_material"/>
    </visual>
    <collision>
      <geometry>
        <cylinder radius="0.08411711869646316" length="0.07340695400580502"/>
      </geometry>
    </collision>
    <inertial>
      <mass value="1.0"/>
      <inertia ixx="0.0022179708224829156" ixy="0" ixz="0" 
               iyy="0.0022179708224829156" iyz="0" 
               izz="0.0035378448288974356"/>
    </inertial>
  </link>
  <joint name="joint2" type="floating">
    <parent link="base_link"/>
    <child link="link2"/>
    <origin xyz="0 0 0" rpy="1.5708 0 0"/>
    <axis xyz="0 1 0"/>
    <dynamics damping="0.826558863225983" friction="0.1"/>
  </joint>
  <link name="link3">
    <visual>
      <geometry><cylinder radius="0.08553632720091998" length="0.05"/></geometry>
      <material name="rubber"/>
    </visual>
    <collision>
      <geometry><cylinder radius="0.08553632720091998" length="0.05"/></geometry>
    </collision>
    <inertial>
      <mass value="0.5"/>
      <inertia ixx="0.0020374491510890443" ixy="0" ixz="0" 
               iyy="0.0020374491510890443" iyz="0" 
               izz="0.003658231635511422"/>
    </inertial>
  </link>
  <joint name="joint3" type="revolute">
    <parent link="base_link"/>
    <child link="link3"/>
    <origin xyz="0 0 0.10458820612012848" rpy="0 0 0"/>
    <axis xyz="0.0 1.0 0.0"/>
    <dynamics damping="0.6576799168298725" friction="0.1"/>
    <limit lower="-1.5104028582426605" upper="1.3489058596284162" effort="100" velocity="100"/>
  </joint>
</robot>