<?xml version="1.0"?>
<robot name="evolved_robot">
  <material name="metal">
    <color rgba="0.7 0.7 0.7 1.0"/>
  </material>
  <material name="plastic">
    <color rgba="0.3 0.3 0.9 1.0"/>
  </material>
  <material name="rubber">
    <color rgba="0.1 0.1 0.1 1.0"/>
  </material>
  <material name="red">
    <color rgba="1.0 0.0 0.0 1.0"/>
  </material>
  <material name="wheel_material">
    <color rgba="0.2 0.2 0.2 1.0"/>
  </material>
  <link name="base_link">
    <visual>
      <geometry><cylinder radius="0.2015375313686143" length="0.10965485293996191"/></geometry>
      <material name="metal"/>
    </visual>
    <collision>
      <geometry><cylinder radius="0.2015375313686143" length="0.10965485293996191"/></geometry>
    </collision>
    <inertial>
      <mass value="5.0"/>
      <inertia ixx="0.11156359701979186" ixy="0" ixz="0" 
               iyy="0.11156359701979186" iyz="0" 
               izz="0.20308688275077594"/>
    </inertial>
  </link>
  <link name="link1">
    <visual>
      <geometry><box size="0.14300869500315572 0.08661028060162165 0.05402501841348908"/></geometry>
      <material name="rubber"/>
    </visual>
    <collision>
      <geometry><box size="0.14300869500315572 0.08661028060162165 0.05402501841348908"/></geometry>
    </collision>
    <inertial>
      <mass value="0.5"/>
      <inertia ixx="0.0008683369433724562" ixy="0" ixz="0" 
               iyy="0.0019475157884236208" iyz="0" 
               izz="0.0023294022960331042"/>
    </inertial>
  </link>
  <joint name="joint1" type="fixed">
    <parent link="base_link"/>
    <child link="link1"/>
    <origin xyz="0 0 0.054827426469980955" rpy="0 0 0"/>
    <axis xyz="-0.5360109014980572 0.8436318364723533 0.031267202713463664"/>
    <dynamics damping="0.1029057953056492" friction="0.1"/>
  </joint>
  <link name="link2">
    <visual>
      <geometry><box size="0.20462174089061386 0.22877229965037643 0.19182219904361414"/></geometry>
      <material name="metal"/>
    </visual>
    <collision>
      <geometry><box size="0.20462174089061386 0.22877229965037643 0.19182219904361414"/></geometry>
    </collision>
    <inertial>
      <mass value="0.5"/>
      <inertia ixx="0.007427710094437462" ixy="0" ixz="0" 
               iyy="0.0065554844075861205" iyz="0" 
               izz="0.007850568494368928"/>
    </inertial>
  </link>
  <joint name="joint2" type="floating">
    <parent link="base_link"/>
    <child link="link2"/>
    <origin xyz="0 0 0.10482742646998096" rpy="0 0 0"/>
    <axis xyz="-0.7956639677660139 0.34601387757606467 -0.4971853245255933"/>
    <dynamics damping="0.13317693757816318" friction="0.1"/>
  </joint>
  <link name="link3">
    <visual>
      <geometry><cylinder radius="0.08250382730163829" length="0.18297875091889787"/></geometry>
      <material name="rubber"/>
    </visual>
    <collision>
      <geometry><cylinder radius="0.08250382730163829" length="0.18297875091889787"/></geometry>
    </collision>
    <inertial>
      <mass value="0.5"/>
      <inertia ixx="0.004491822320507978" ixy="0" ixz="0" 
               iyy="0.004491822320507978" iyz="0" 
               izz="0.0034034407597092775"/>
    </inertial>
  </link>
  <joint name="joint3" type="floating">
    <parent link="base_link"/>
    <child link="link3"/>
    <origin xyz="0 0 0.15482742646998096" rpy="0 0 0"/>
    <axis xyz="0.038120554180783854 0.995864478770266 0.08246674040227502"/>
    <dynamics damping="0.6136062229199455" friction="0.1"/>
  </joint>
</robot>