<?xml version="1.0"?>
<robot name="evolved_robot">
  <material name="metal">
    <color rgba="0.7 0.7 0.7 1.0"/>
  </material>
  <material name="plastic">
    <color rgba="0.3 0.3 0.9 1.0"/>
  </material>
  <material name="rubber">
    <color rgba="0.1 0.1 0.1 1.0"/>
  </material>
  <material name="red">
    <color rgba="1.0 0.0 0.0 1.0"/>
  </material>
  <material name="wheel_material">
    <color rgba="0.2 0.2 0.2 1.0"/>
  </material>
  <link name="base_link">
    <visual>
      <geometry><box size="0.3103064321044853 0.3449757257669055 0.09465545728106738"/></geometry>
      <material name="rubber"/>
    </visual>
    <collision>
      <geometry><box size="0.3103064321044853 0.3449757257669055 0.09465545728106738"/></geometry>
    </collision>
    <inertial>
      <mass value="5.0"/>
      <inertia ixx="0.1066399224679093" ixy="0" ixz="0" 
               iyy="0.08770811449875292" iyz="0" 
               izz="0.1794152776448489"/>
    </inertial>
  </link>
  <link name="link1">
    <visual>
      <geometry><cylinder radius="0.06248101097200438" length="0.1411185146127364"/></geometry>
      <material name="rubber"/>
    </visual>
    <collision>
      <geometry><cylinder radius="0.06248101097200438" length="0.1411185146127364"/></geometry>
    </collision>
    <inertial>
      <mass value="0.5"/>
      <inertia ixx="0.002635505446896358" ixy="0" ixz="0" 
               iyy="0.002635505446896358" iyz="0" 
               izz="0.0019519383660418662"/>
    </inertial>
  </link>
  <joint name="joint1" type="revolute">
    <parent link="base_link"/>
    <child link="link1"/>
    <origin xyz="0 0 0.04732772864053369" rpy="0 0 0"/>
    <axis xyz="-0.8833914139910871 -0.14371737089719355 -0.4460548475123056"/>
    <dynamics damping="0.8714185890660273" friction="0.1"/>
    <limit lower="-0.45198415874903025" upper="1.2790866222000055" effort="100" velocity="100"/>
  </joint>
  <link name="link2">
    <visual>
      <geometry><sphere radius="0.04733285133433901"/></geometry>
      <material name="plastic"/>
    </visual>
    <collision>
      <geometry><sphere radius="0.04733285133433901"/></geometry>
    </collision>
    <inertial>
      <mass value="0.5"/>
      <inertia ixx="0.0008961595261754553" ixy="0" ixz="0" 
               iyy="0.0008961595261754553" iyz="0" 
               izz="0.0008961595261754553"/>
    </inertial>
  </link>
  <joint name="joint2" type="revolute">
    <parent link="base_link"/>
    <child link="link2"/>
    <origin xyz="0 0 0.09732772864053368" rpy="0 0 0"/>
    <axis xyz="0.16752966538603056 -0.9566839720563673 0.23809575558185897"/>
    <dynamics damping="0.3292061639449561" friction="0.1"/>
    <limit lower="-1.6677514980918702" upper="0.31400000000000006" effort="100" velocity="100"/>
  </joint>
  <link name="link3">
    <visual>
      <geometry><cylinder radius="0.03776639351583298" length="0.058922781868258084"/></geometry>
      <material name="plastic"/>
    </visual>
    <collision>
      <geometry><cylinder radius="0.03776639351583298" length="0.058922781868258084"/></geometry>
    </collision>
    <inertial>
      <mass value="0.5"/>
      <inertia ixx="0.0006458996383893815" ixy="0" ixz="0" 
               iyy="0.0006458996383893815" iyz="0" 
               izz="0.0007131502395963758"/>
    </inertial>
  </link>
  <joint name="joint3" type="fixed">
    <parent link="base_link"/>
    <child link="link3"/>
    <origin xyz="0 0 0.1473277286405337" rpy="0 0 0"/>
    <axis xyz="0.9842905946025723 -0.13333313376117406 -0.11573374969445827"/>
    <dynamics damping="0.43814001752848686" friction="0.1"/>
  </joint>
  <link name="link4">
    <visual>
      <geometry><box size="0.09292702060085448 0.14973028667105592 0.1671417502097104"/></geometry>
      <material name="metal"/>
    </visual>
    <collision>
      <geometry><box size="0.09292702060085448 0.14973028667105592 0.1671417502097104"/></geometry>
    </collision>
    <inertial>
      <mass value="0.5"/>
      <inertia ixx="0.0041962936174801515" ixy="0" ixz="0" 
               iyy="0.0030476496517430718" iyz="0" 
               izz="0.0025878824920290183"/>
    </inertial>
  </link>
  <joint name="joint4" type="revolute">
    <parent link="base_link"/>
    <child link="link4"/>
    <origin xyz="0 0 0.19732772864053372" rpy="0 0 0"/>
    <axis xyz="0.7228398395297391 0.2736602653499128 -0.6345176321878189"/>
    <dynamics damping="0.7867909126212331" friction="0.1"/>
    <limit lower="-1.5929920037548284" upper="2.0410000000000004" effort="100" velocity="100"/>
  </joint>
</robot>