<?xml version="1.0"?>
<robot name="evolved_robot">
  <material name="metal">
    <color rgba="0.7 0.7 0.7 1.0"/>
  </material>
  <material name="plastic">
    <color rgba="0.3 0.3 0.9 1.0"/>
  </material>
  <material name="rubber">
    <color rgba="0.1 0.1 0.1 1.0"/>
  </material>
  <material name="red">
    <color rgba="1.0 0.0 0.0 1.0"/>
  </material>
  <material name="wheel_material">
    <color rgba="0.2 0.2 0.2 1.0"/>
  </material>
  <link name="base_link">
    <visual>
      <geometry><cylinder radius="0.212961433969338" length="0.12805529624665182"/></geometry>
      <material name="rubber"/>
    </visual>
    <collision>
      <geometry><cylinder radius="0.212961433969338" length="0.12805529624665182"/></geometry>
    </collision>
    <inertial>
      <mass value="5.0"/>
      <inertia ixx="0.12704656330970657" ixy="0" ixz="0" 
               iyy="0.12704656330970657" iyz="0" 
               izz="0.22676286179138355"/>
    </inertial>
  </link>
  <link name="link1">
    <visual>
      <geometry><cylinder radius="0.05973700902867758" length="0.07570931910548462"/></geometry>
      <material name="plastic"/>
    </visual>
    <collision>
      <geometry><cylinder radius="0.05973700902867758" length="0.07570931910548462"/></geometry>
    </collision>
    <inertial>
      <mass value="0.5"/>
      <inertia ixx="0.001369785978541085" ixy="0" ixz="0" 
               iyy="0.001369785978541085" iyz="0" 
               izz="0.0017842551238461534"/>
    </inertial>
  </link>
  <joint name="joint1" type="prismatic">
    <parent link="base_link"/>
    <child link="link1"/>
    <origin xyz="0 0 0.06402764812332591" rpy="0 0 0"/>
    <axis xyz="0.015433249640714922 -0.3727810649990402 0.9277909745108047"/>
    <dynamics damping="0.4916464604882881" friction="0.1"/>
    <limit lower="-2.3564205883477847" upper="2.6787050389928373" effort="100" velocity="100"/>
  </joint>
  <link name="link2">
    <visual>
      <geometry><box size="0.0913633703432995 0.11184456898806504 0.24986356730430942"/></geometry>
      <material name="plastic"/>
    </visual>
    <collision>
      <geometry><box size="0.0913633703432995 0.11184456898806504 0.24986356730430942"/></geometry>
    </collision>
    <inertial>
      <mass value="0.5"/>
      <inertia ixx="0.006245084156513433" ixy="0" ixz="0" 
               iyy="0.005898255642210172" iyz="0" 
               izz="0.0017380394210510782"/>
    </inertial>
  </link>
  <joint name="joint2" type="floating">
    <parent link="base_link"/>
    <child link="link2"/>
    <origin xyz="0 0 0.11402764812332591" rpy="0 0 0"/>
    <axis xyz="0.4125926684597669 0.36699732108545624 0.8337147331367889"/>
    <dynamics damping="0.8918216140598217" friction="0.1"/>
  </joint>
  <link name="link3">
    <visual>
      <geometry><box size="0.1964524818974509 0.23692683161391276 0.177448172397545"/></geometry>
      <material name="plastic"/>
    </visual>
    <collision>
      <geometry><box size="0.1964524818974509 0.23692683161391276 0.177448172397545"/></geometry>
    </collision>
    <inertial>
      <mass value="0.5"/>
      <inertia ixx="0.0073018481188196855" ixy="0" ixz="0" 
               iyy="0.005840119294241428" iyz="0" 
               izz="0.007893991765189637"/>
    </inertial>
  </link>
  <joint name="joint3" type="fixed">
    <parent link="base_link"/>
    <child link="link3"/>
    <origin xyz="0 0 0.16402764812332593" rpy="0 0 0"/>
    <axis xyz="0.23210899487847153 0.7282443911255468 -0.644814330866403"/>
    <dynamics damping="0.21045667114747402" friction="0.1"/>
  </joint>
  <link name="link4">
    <visual>
      <geometry><sphere radius="0.025453429318842497"/></geometry>
      <material name="rubber"/>
    </visual>
    <collision>
      <geometry><sphere radius="0.025453429318842497"/></geometry>
    </collision>
    <inertial>
      <mass value="0.5"/>
      <inertia ixx="0.0002591508256357243" ixy="0" ixz="0" 
               iyy="0.0002591508256357243" iyz="0" 
               izz="0.0002591508256357243"/>
    </inertial>
  </link>
  <joint name="joint4" type="revolute">
    <parent link="base_link"/>
    <child link="link4"/>
    <origin xyz="0 0 0.21402764812332592" rpy="0 0 0"/>
    <axis xyz="-0.536072329896902 0.35531257427288937 0.7657541587758304"/>
    <dynamics damping="0.29303774938440097" friction="0.1"/>
    <limit lower="-0.0" upper="1.8389894793553705" effort="100" velocity="100"/>
  </joint>
  <link name="link5">
    <visual>
      <geometry><box size="0.12355306470508931 0.14218849330853667 0.09456781277942478"/></geometry>
      <material name="rubber"/>
    </visual>
    <collision>
      <geometry><box size="0.12355306470508931 0.14218849330853667 0.09456781277942478"/></geometry>
    </collision>
    <inertial>
      <mass value="0.5"/>
      <inertia ixx="0.002430053236936343" ixy="0" ixz="0" 
               iyy="0.002017369250992027" iyz="0" 
               izz="0.0029569106189476467"/>
    </inertial>
  </link>
  <joint name="joint5" type="prismatic">
    <parent link="base_link"/>
    <child link="link5"/>
    <origin xyz="0 0 0.2640276481233259" rpy="0 0 0"/>
    <axis xyz="0.49370504508167085 -0.6328515977681178 0.5964513254769795"/>
    <dynamics damping="0.9190691409169894" friction="0.1"/>
    <limit lower="-0.06631870370802115" upper="0.8761247470282771" effort="100" velocity="100"/>
  </joint>
  <link name="link6">
    <visual>
      <geometry><cylinder radius="0.09243443535594412" length="0.1309749899245123"/></geometry>
      <material name="metal"/>
    </visual>
    <collision>
      <geometry><cylinder radius="0.09243443535594412" length="0.1309749899245123"/></geometry>
    </collision>
    <inertial>
      <mass value="0.5"/>
      <inertia ixx="0.0035655685420368944" ixy="0" ixz="0" 
               iyy="0.0035655685420368944" iyz="0" 
               izz="0.004272062419786106"/>
    </inertial>
  </link>
  <joint name="joint6" type="revolute">
    <parent link="base_link"/>
    <child link="link6"/>
    <origin xyz="0 0 0.3140276481233259" rpy="0 0 0"/>
    <axis xyz="-0.2547044275269864 0.9289603853082379 0.2686228901752795"/>
    <dynamics damping="0.4531494086200656" friction="0.1"/>
    <limit lower="-0.45957136471378096" upper="1.7748438257456958" effort="100" velocity="100"/>
  </joint>
</robot>