<?xml version="1.0"?>
<robot name="evolved_robot">
  <material name="metal">
    <color rgba="0.7 0.7 0.7 1.0"/>
  </material>
  <material name="plastic">
    <color rgba="0.3 0.3 0.9 1.0"/>
  </material>
  <material name="rubber">
    <color rgba="0.1 0.1 0.1 1.0"/>
  </material>
  <material name="red">
    <color rgba="1.0 0.0 0.0 1.0"/>
  </material>
  <material name="wheel_material">
    <color rgba="0.2 0.2 0.2 1.0"/>
  </material>
  <link name="base_link">
    <visual>
      <geometry><box size="0.30973124463305235 0.2637592270063851 0.09137525855552422"/></geometry>
      <material name="rubber"/>
    </visual>
    <collision>
      <geometry><box size="0.30973124463305235 0.2637592270063851 0.09137525855552422"/></geometry>
    </collision>
    <inertial>
      <mass value="5.0"/>
      <inertia ixx="0.06493197308924557" ixy="0" ixz="0" 
               iyy="0.08690240148169052" iyz="0" 
               izz="0.1379186447774546"/>
    </inertial>
  </link>
  <link name="link1">
    <visual>
      <geometry><cylinder radius="0.07022127573045568" length="0.20604416309823792"/></geometry>
      <material name="rubber"/>
    </visual>
    <collision>
      <geometry><cylinder radius="0.07022127573045568" length="0.20604416309823792"/></geometry>
    </collision>
    <inertial>
      <mass value="0.5"/>
      <inertia ixx="0.004770606653540944" ixy="0" ixz="0" 
               iyy="0.004770606653540944" iyz="0" 
               izz="0.002465513782606342"/>
    </inertial>
  </link>
  <joint name="joint1" type="prismatic">
    <parent link="base_link"/>
    <child link="link1"/>
    <origin xyz="0 0 0.04568762927776211" rpy="0 0 0"/>
    <axis xyz="-0.6712321116053033 -0.10920155303055626 0.7331592413422886"/>
    <dynamics damping="0.4036131886502018" friction="0.1"/>
    <limit lower="-0.45198415874903025" upper="0.2996938549239752" effort="100" velocity="100"/>
  </joint>
  <link name="link2">
    <visual>
      <geometry><sphere radius="0.04774140146365198"/></geometry>
      <material name="rubber"/>
    </visual>
    <collision>
      <geometry><sphere radius="0.04774140146365198"/></geometry>
    </collision>
    <inertial>
      <mass value="0.5"/>
      <inertia ixx="0.0009116965654854366" ixy="0" ixz="0" 
               iyy="0.0009116965654854366" iyz="0" 
               izz="0.0009116965654854366"/>
    </inertial>
  </link>
  <joint name="joint2" type="fixed">
    <parent link="base_link"/>
    <child link="link2"/>
    <origin xyz="0 0 0.09568762927776212" rpy="0 0 0"/>
    <axis xyz="0.7994870752066272 -0.3189058024417348 -0.5090378234930545"/>
    <dynamics damping="0.32429681390972" friction="0.1"/>
  </joint>
  <link name="link3">
    <visual>
      <geometry><cylinder radius="0.037788071872525975" length="0.055289034378760475"/></geometry>
      <material name="plastic"/>
    </visual>
    <collision>
      <geometry><cylinder radius="0.037788071872525975" length="0.055289034378760475"/></geometry>
    </collision>
    <inertial>
      <mass value="0.5"/>
      <inertia ixx="0.000611724370838777" ixy="0" ixz="0" 
               iyy="0.000611724370838777" iyz="0" 
               izz="0.0007139691879215944"/>
    </inertial>
  </link>
  <joint name="joint3" type="fixed">
    <parent link="base_link"/>
    <child link="link3"/>
    <origin xyz="0 0 0.14568762927776213" rpy="0 0 0"/>
    <axis xyz="0.885884819037277 -0.14288856271358436 0.44135127284843867"/>
    <dynamics damping="0.6617432306237528" friction="0.1"/>
  </joint>
  <link name="link4">
    <visual>
      <geometry><box size="0.09246010463648308 0.15026105879309354 0.16692978989059037"/></geometry>
      <material name="metal"/>
    </visual>
    <collision>
      <geometry><box size="0.09246010463648308 0.15026105879309354 0.16692978989059037"/></geometry>
    </collision>
    <inertial>
      <mass value="0.5"/>
      <inertia ixx="0.00420366171187818" ixy="0" ixz="0" 
               iyy="0.0030345354751921704" iyz="0" 
               izz="0.002593938061584243"/>
    </inertial>
  </link>
  <joint name="joint4" type="revolute">
    <parent link="base_link"/>
    <child link="link4"/>
    <origin xyz="0 0 0.19568762927776212" rpy="0 0 0"/>
    <axis xyz="0.7103423009173693 -0.46365404839060986 -0.5295646692694062"/>
    <dynamics damping="0.3040877062144236" friction="0.1"/>
    <limit lower="-1.5929920037548284" upper="2.0410000000000004" effort="100" velocity="100"/>
  </joint>
  <link name="link5">
    <visual>
      <geometry><cylinder radius="0.08721994617563467" length="0.0802752767765072"/></geometry>
      <material name="rubber"/>
    </visual>
    <collision>
      <geometry><cylinder radius="0.08721994617563467" length="0.0802752767765072"/></geometry>
    </collision>
    <inertial>
      <mass value="0.5"/>
      <inertia ixx="0.002438839757848888" ixy="0" ixz="0" 
               iyy="0.002438839757848888" iyz="0" 
               izz="0.0038036595054403042"/>
    </inertial>
  </link>
  <joint name="joint5" type="prismatic">
    <parent link="base_link"/>
    <child link="link5"/>
    <origin xyz="0 0 0.2456876292777621" rpy="0 0 0"/>
    <axis xyz="-0.832632235254255 0.0 0.5538262911920153"/>
    <dynamics damping="0.3192390020596607" friction="0.1"/>
    <limit lower="-3.0024683931493623" upper="0.31400000000000006" effort="100" velocity="100"/>
  </joint>
  <link name="link6">
    <visual>
      <geometry><cylinder radius="0.06346534658035433" length="0.24130320195547167"/></geometry>
      <material name="plastic"/>
    </visual>
    <collision>
      <geometry><cylinder radius="0.06346534658035433" length="0.24130320195547167"/></geometry>
    </collision>
    <inertial>
      <mass value="0.5"/>
      <inertia ixx="0.005859232160304719" ixy="0" ixz="0" 
               iyy="0.005859232160304719" iyz="0" 
               izz="0.002013925108282246"/>
    </inertial>
  </link>
  <joint name="joint6" type="fixed">
    <parent link="base_link"/>
    <child link="link6"/>
    <origin xyz="0 0 0.2956876292777621" rpy="0 0 0"/>
    <axis xyz="0.6305133116292092 0.1405575344390185 0.7633456251075208"/>
    <dynamics damping="0.2025334459637101" friction="0.1"/>
  </joint>
  <link name="link7">
    <visual>
      <geometry><sphere radius="0.05156707607986047"/></geometry>
      <material name="plastic"/>
    </visual>
    <collision>
      <geometry><sphere radius="0.05156707607986047"/></geometry>
    </collision>
    <inertial>
      <mass value="0.5"/>
      <inertia ixx="0.001063665334170447" ixy="0" ixz="0" 
               iyy="0.001063665334170447" iyz="0" 
               izz="0.001063665334170447"/>
    </inertial>
  </link>
  <joint name="joint7" type="fixed">
    <parent link="base_link"/>
    <child link="link7"/>
    <origin xyz="0 0 0.34568762927776214" rpy="0 0 0"/>
    <axis xyz="-0.9362728796917996 0.050194514128967964 -0.3476688158362522"/>
    <dynamics damping="0.1" friction="0.1"/>
  </joint>
</robot>