<?xml version="1.0"?>
<robot name="evolved_robot">
  <material name="metal">
    <color rgba="0.7 0.7 0.7 1.0"/>
  </material>
  <material name="plastic">
    <color rgba="0.3 0.3 0.9 1.0"/>
  </material>
  <material name="rubber">
    <color rgba="0.1 0.1 0.1 1.0"/>
  </material>
  <material name="red">
    <color rgba="1.0 0.0 0.0 1.0"/>
  </material>
  <material name="wheel_material">
    <color rgba="0.2 0.2 0.2 1.0"/>
  </material>
  <link name="base_link">
    <visual>
      <geometry><cylinder radius="0.11970264810051975" length="0.1199156323389618"/></geometry>
      <material name="rubber"/>
    </visual>
    <collision>
      <geometry><cylinder radius="0.11970264810051975" length="0.1199156323389618"/></geometry>
    </collision>
    <inertial>
      <mass value="5.0"/>
      <inertia ixx="0.047804942305069716" ixy="0" ixz="0" 
               iyy="0.047804942305069716" iyz="0" 
               izz="0.07164361981138433"/>
    </inertial>
  </link>
  <link name="link1">
    <visual>
      <geometry><cylinder radius="0.06403741267114624" length="0.1427863277072362"/></geometry>
      <material name="plastic"/>
    </visual>
    <collision>
      <geometry><cylinder radius="0.06403741267114624" length="0.1427863277072362"/></geometry>
    </collision>
    <inertial>
      <mass value="0.5"/>
      <inertia ixx="0.002724192170413524" ixy="0" ixz="0" 
               iyy="0.002724192170413524" iyz="0" 
               izz="0.0020503951108073403"/>
    </inertial>
  </link>
  <joint name="joint1" type="prismatic">
    <parent link="base_link"/>
    <child link="link1"/>
    <origin xyz="0 0 0.0599578161694809" rpy="0 0 0"/>
    <axis xyz="0.9256208165441667 -0.2972260463162054 0.23427074373755477"/>
    <dynamics damping="0.728903685836349" friction="0.1"/>
    <limit lower="-0.9295483361181153" upper="0.9438424306910559" effort="100" velocity="100"/>
  </joint>
  <link name="link2">
    <visual>
      <geometry>
        <cylinder radius="0.0721658289576909" length="0.03928715276134653"/>
      </geometry>
      <material name="wheel_material"/>
    </visual>
    <collision>
      <geometry>
        <cylinder radius="0.0721658289576909" length="0.03928715276134653"/>
      </geometry>
    </collision>
    <inertial>
      <mass value="1.0"/>
      <inertia ixx="0.0014306000816287894" ixy="0" ixz="0" 
               iyy="0.0014306000816287894" iyz="0" 
               izz="0.0026039534345753492"/>
    </inertial>
  </link>
  <joint name="joint2" type="continuous">
    <parent link="base_link"/>
    <child link="link2"/>
    <origin xyz="0 0 0" rpy="1.5708 0 0"/>
    <axis xyz="0 1 0"/>
    <dynamics damping="0.6987224260398152" friction="0.1"/>
  </joint>
  <link name="link3">
    <visual>
      <geometry><box size="0.10954831570781301 0.1546841230916416 0.21569095734275118"/></geometry>
      <material name="metal"/>
    </visual>
    <collision>
      <geometry><box size="0.10954831570781301 0.1546841230916416 0.21569095734275118"/></geometry>
    </collision>
    <inertial>
      <mass value="0.5"/>
      <inertia ixx="0.0058708139180052195" ixy="0" ixz="0" 
               iyy="0.004876951879487598" iyz="0" 
               izz="0.0029940009509207333"/>
    </inertial>
  </link>
  <joint name="joint3" type="prismatic">
    <parent link="base_link"/>
    <child link="link3"/>
    <origin xyz="0 0 0.1099578161694809" rpy="0 0 0"/>
    <axis xyz="0.45716278544646854 0.601431115929411 0.6551967646400045"/>
    <dynamics damping="0.7568208550436643" friction="0.1"/>
    <limit lower="-1.6464221671866734" upper="1.9719597524889452" effort="100" velocity="100"/>
  </joint>
  <link name="link4">
    <visual>
      <geometry><cylinder radius="0.08681122301726178" length="0.055857159394075075"/></geometry>
      <material name="plastic"/>
    </visual>
    <collision>
      <geometry><cylinder radius="0.08681122301726178" length="0.055857159394075075"/></geometry>
    </collision>
    <inertial>
      <mass value="0.5"/>
      <inertia ixx="0.0021440489650694497" ixy="0" ixz="0" 
               iyy="0.0021440489650694497" iyz="0" 
               izz="0.003768094220876381"/>
    </inertial>
  </link>
  <joint name="joint4" type="prismatic">
    <parent link="base_link"/>
    <child link="link4"/>
    <origin xyz="0 0 0.1599578161694809" rpy="0 0 0"/>
    <axis xyz="-0.03564313883615143 0.999358191662282 0.0035737111523613868"/>
    <dynamics damping="0.7584390846827209" friction="0.1"/>
    <limit lower="-0.6705610024174679" upper="1.2738710232739712" effort="100" velocity="100"/>
  </joint>
</robot>