<?xml version="1.0"?>
<robot name="evolved_robot">
  <material name="metal">
    <color rgba="0.7 0.7 0.7 1.0"/>
  </material>
  <material name="plastic">
    <color rgba="0.3 0.3 0.9 1.0"/>
  </material>
  <material name="rubber">
    <color rgba="0.1 0.1 0.1 1.0"/>
  </material>
  <material name="red">
    <color rgba="1.0 0.0 0.0 1.0"/>
  </material>
  <material name="wheel_material">
    <color rgba="0.2 0.2 0.2 1.0"/>
  </material>
  <link name="base_link">
    <visual>
      <geometry><box size="0.3588430422223714 0.3356601332094503 0.13021725611391466"/></geometry>
      <material name="metal"/>
    </visual>
    <collision>
      <geometry><box size="0.3588430422223714 0.3356601332094503 0.13021725611391466"/></geometry>
    </collision>
    <inertial>
      <mass value="5.0"/>
      <inertia ixx="0.108020215680019" ixy="0" ixz="0" 
               iyy="0.1214373856177029" iyz="0" 
               izz="0.2011967116479938"/>
    </inertial>
  </link>
  <link name="link1">
    <visual>
      <geometry><box size="0.11100754966870965 0.23815891753357044 0.1448564714609724"/></geometry>
      <material name="rubber"/>
    </visual>
    <collision>
      <geometry><box size="0.11100754966870965 0.23815891753357044 0.1448564714609724"/></geometry>
    </collision>
    <inertial>
      <mass value="0.5"/>
      <inertia ixx="0.006475255610407127" ixy="0" ixz="0" 
               iyy="0.00277550611729788" iyz="0" 
               izz="0.005753528840351087"/>
    </inertial>
  </link>
  <joint name="joint1" type="fixed">
    <parent link="base_link"/>
    <child link="link1"/>
    <origin xyz="0 0 0.06510862805695733" rpy="0 0 0"/>
    <axis xyz="-0.1318327969860067 0.46147522198878566 0.8773031021997172"/>
    <dynamics damping="0.7357064402630092" friction="0.1"/>
  </joint>
  <link name="link2">
    <visual>
      <geometry>
        <cylinder radius="0.08415372744292407" length="0.05646776150965256"/>
      </geometry>
      <material name="wheel_material"/>
    </visual>
    <collision>
      <geometry>
        <cylinder radius="0.08415372744292407" length="0.05646776150965256"/>
      </geometry>
    </collision>
    <inertial>
      <mass value="1.0"/>
      <inertia ixx="0.0020361798014604045" ixy="0" ixz="0" 
               iyy="0.0020361798014604045" iyz="0" 
               izz="0.003540924921268976"/>
    </inertial>
  </link>
  <joint name="joint2" type="continuous">
    <parent link="base_link"/>
    <child link="link2"/>
    <origin xyz="0 0 0" rpy="1.5708 0 0"/>
    <axis xyz="0 1 0"/>
    <dynamics damping="0.13067949907705373" friction="0.1"/>
  </joint>
  <link name="link3">
    <visual>
      <geometry><cylinder radius="0.0416896329384882" length="0.17150842750349904"/></geometry>
      <material name="rubber"/>
    </visual>
    <collision>
      <geometry><cylinder radius="0.0416896329384882" length="0.17150842750349904"/></geometry>
    </collision>
    <inertial>
      <mass value="0.5"/>
      <inertia ixx="0.002885768099030052" ixy="0" ixz="0" 
               iyy="0.002885768099030052" iyz="0" 
               izz="0.0008690127472729402"/>
    </inertial>
  </link>
  <joint name="joint3" type="floating">
    <parent link="base_link"/>
    <child link="link3"/>
    <origin xyz="0 0 0.11510862805695733" rpy="0 0 0"/>
    <axis xyz="0.2355597440628866 0.5842222870844075 0.7766568909440587"/>
    <dynamics damping="0.6031108395751124" friction="0.1"/>
  </joint>
  <link name="link4">
    <visual>
      <geometry><sphere radius="0.06576905041169442"/></geometry>
      <material name="metal"/>
    </visual>
    <collision>
      <geometry><sphere radius="0.06576905041169442"/></geometry>
    </collision>
    <inertial>
      <mass value="0.5"/>
      <inertia ixx="0.0017302271968224008" ixy="0" ixz="0" 
               iyy="0.0017302271968224008" iyz="0" 
               izz="0.0017302271968224008"/>
    </inertial>
  </link>
  <joint name="joint4" type="fixed">
    <parent link="base_link"/>
    <child link="link4"/>
    <origin xyz="0 0 0.16510862805695734" rpy="0 0 0"/>
    <axis xyz="0.12274448331453577 0.5877326911680862 -0.7996899871501248"/>
    <dynamics damping="0.34081495170592757" friction="0.1"/>
  </joint>
  <link name="link5">
    <visual>
      <geometry><sphere radius="0.06916783705541782"/></geometry>
      <material name="plastic"/>
    </visual>
    <collision>
      <geometry><sphere radius="0.06916783705541782"/></geometry>
    </collision>
    <inertial>
      <mass value="0.5"/>
      <inertia ixx="0.0019136758731699323" ixy="0" ixz="0" 
               iyy="0.0019136758731699323" iyz="0" 
               izz="0.0019136758731699323"/>
    </inertial>
  </link>
  <joint name="joint5" type="prismatic">
    <parent link="base_link"/>
    <child link="link5"/>
    <origin xyz="0 0 0.21510862805695735" rpy="0 0 0"/>
    <axis xyz="-0.6898048299861356 -0.12397600391151752 -0.7133016521654287"/>
    <dynamics damping="0.2189141536096495" friction="0.1"/>
    <limit lower="-0.6607034117201511" upper="2.8036612568495847" effort="100" velocity="100"/>
  </joint>
  <link name="link6">
    <visual>
      <geometry><sphere radius="0.09784801037040222"/></geometry>
      <material name="plastic"/>
    </visual>
    <collision>
      <geometry><sphere radius="0.09784801037040222"/></geometry>
    </collision>
    <inertial>
      <mass value="0.5"/>
      <inertia ixx="0.0038296932533785364" ixy="0" ixz="0" 
               iyy="0.0038296932533785364" iyz="0" 
               izz="0.0038296932533785364"/>
    </inertial>
  </link>
  <joint name="joint6" type="floating">
    <parent link="base_link"/>
    <child link="link6"/>
    <origin xyz="0 0 0.26510862805695734" rpy="0 0 0"/>
    <axis xyz="-0.24387719190276463 -0.9381684305121742 -0.2456906820779857"/>
    <dynamics damping="0.2990492328567435" friction="0.1"/>
  </joint>
</robot>