<?xml version="1.0"?>
<robot name="evolved_robot">
  <material name="metal">
    <color rgba="0.7 0.7 0.7 1.0"/>
  </material>
  <material name="plastic">
    <color rgba="0.3 0.3 0.9 1.0"/>
  </material>
  <material name="rubber">
    <color rgba="0.1 0.1 0.1 1.0"/>
  </material>
  <material name="red">
    <color rgba="1.0 0.0 0.0 1.0"/>
  </material>
  <material name="wheel_material">
    <color rgba="0.2 0.2 0.2 1.0"/>
  </material>
  <link name="base_link">
    <visual>
      <geometry><sphere radius="0.11127265058944924"/></geometry>
      <material name="rubber"/>
    </visual>
    <collision>
      <geometry><sphere radius="0.11127265058944924"/></geometry>
    </collision>
    <inertial>
      <mass value="5.0"/>
      <inertia ixx="0.04952641107680663" ixy="0" ixz="0" 
               iyy="0.04952641107680663" iyz="0" 
               izz="0.04952641107680663"/>
    </inertial>
  </link>
  <link name="link1">
    <visual>
      <geometry><cylinder radius="0.06461690782080083" length="0.222763523738771"/></geometry>
      <material name="plastic"/>
    </visual>
    <collision>
      <geometry><cylinder radius="0.06461690782080083" length="0.222763523738771"/></geometry>
    </collision>
    <inertial>
      <mass value="0.5"/>
      <inertia ixx="0.0051791351531233" ixy="0" ixz="0" 
               iyy="0.0051791351531233" iyz="0" 
               izz="0.0020876723881609357"/>
    </inertial>
  </link>
  <joint name="joint1" type="revolute">
    <parent link="base_link"/>
    <child link="link1"/>
    <origin xyz="0 0 0.054809192242424254" rpy="0 0 0"/>
    <axis xyz="-0.6238258749805112 -0.5672342990279865 -0.5376676740432033"/>
    <dynamics damping="0.6376090538927046" friction="0.1"/>
    <limit lower="-1.2613525729896713" upper="1.4150721101817274" effort="100" velocity="100"/>
  </joint>
  <link name="link2">
    <visual>
      <geometry>
        <cylinder radius="0.054725586248147544" length="0.05017284003282977"/>
      </geometry>
      <material name="wheel_material"/>
    </visual>
    <collision>
      <geometry>
        <cylinder radius="0.054725586248147544" length="0.05017284003282977"/>
      </geometry>
    </collision>
    <inertial>
      <mass value="1.0"/>
      <inertia ixx="0.000958498603964186" ixy="0" ixz="0" 
               iyy="0.000958498603964186" iyz="0" 
               izz="0.0014974448951017177"/>
    </inertial>
  </link>
  <joint name="joint2" type="continuous">
    <parent link="base_link"/>
    <child link="link2"/>
    <origin xyz="0.16026085789164765 0.09874790163427583 -0.054809192242424254" rpy="1.5708 0 0"/>
    <axis xyz="0 1 0"/>
    <dynamics damping="0.5427877111602113" friction="0.1"/>
  </joint>
  <link name="link3">
    <visual>
      <geometry>
        <cylinder radius="0.05354885574299693" length="0.06481733612685017"/>
      </geometry>
      <material name="wheel_material"/>
    </visual>
    <collision>
      <geometry>
        <cylinder radius="0.05354885574299693" length="0.06481733612685017"/>
      </geometry>
    </collision>
    <inertial>
      <mass value="1.0"/>
      <inertia ixx="0.0010669772430611634" ixy="0" ixz="0" 
               iyy="0.0010669772430611634" iyz="0" 
               izz="0.0014337399756921476"/>
    </inertial>
  </link>
  <joint name="joint3" type="continuous">
    <parent link="base_link"/>
    <child link="link3"/>
    <origin xyz="0.16026085789164765 -0.09874790163427583 -0.054809192242424254" rpy="1.5708 0 0"/>
    <axis xyz="0 1 0"/>
    <dynamics damping="0.9361071883416644" friction="0.1"/>
  </joint>
  <link name="link4">
    <visual>
      <geometry>
        <cylinder radius="0.08875857303974351" length="0.047561744494496905"/>
      </geometry>
      <material name="wheel_material"/>
    </visual>
    <collision>
      <geometry>
        <cylinder radius="0.08875857303974351" length="0.047561744494496905"/>
      </geometry>
    </collision>
    <inertial>
      <mass value="1.0"/>
      <inertia ixx="0.0021580310336261877" ixy="0" ixz="0" 
               iyy="0.0021580310336261877" iyz="0" 
               izz="0.003939042144025741"/>
    </inertial>
  </link>
  <joint name="joint4" type="continuous">
    <parent link="base_link"/>
    <child link="link4"/>
    <origin xyz="-0.16026085789164765 0.09874790163427583 -0.054809192242424254" rpy="1.5708 0 0"/>
    <axis xyz="0 1 0"/>
    <dynamics damping="0.4434849910735845" friction="0.1"/>
  </joint>
  <link name="link5">
    <visual>
      <geometry><box size="0.1224750609236127 0.07158364043844442 0.1283965184327871"/></geometry>
      <material name="rubber"/>
    </visual>
    <collision>
      <geometry><box size="0.1224750609236127 0.07158364043844442 0.1283965184327871"/></geometry>
    </collision>
    <inertial>
      <mass value="0.5"/>
      <inertia ixx="0.0018008236270067944" ixy="0" ixz="0" 
               iyy="0.0026238172078253065" iyz="0" 
               izz="0.001677029843888595"/>
    </inertial>
  </link>
  <joint name="joint5" type="fixed">
    <parent link="base_link"/>
    <child link="link5"/>
    <origin xyz="0 0 0.10480919224242426" rpy="0 0 0"/>
    <axis xyz="-0.5659210040455624 -0.7039867086944422 0.4291108611555166"/>
    <dynamics damping="0.7872694871185734" friction="0.1"/>
  </joint>
  <link name="link6">
    <visual>
      <geometry>
        <cylinder radius="0.0745586118969245" length="0.05403690651694784"/>
      </geometry>
      <material name="wheel_material"/>
    </visual>
    <collision>
      <geometry>
        <cylinder radius="0.0745586118969245" length="0.05403690651694784"/>
      </geometry>
    </collision>
    <inertial>
      <mass value="1.0"/>
      <inertia ixx="0.0016330789241591666" ixy="0" ixz="0" 
               iyy="0.0016330789241591666" iyz="0" 
               izz="0.0027794933039981063"/>
    </inertial>
  </link>
  <joint name="joint6" type="continuous">
    <parent link="base_link"/>
    <child link="link6"/>
    <origin xyz="-0.16026085789164765 -0.09874790163427583 -0.054809192242424254" rpy="1.5708 0 0"/>
    <axis xyz="0 1 0"/>
    <dynamics damping="0.9270203448565811" friction="0.1"/>
  </joint>
  <link name="link7">
    <visual>
      <geometry><cylinder radius="0.05355776187341256" length="0.23802857992927146"/></geometry>
      <material name="metal"/>
    </visual>
    <collision>
      <geometry><cylinder radius="0.05355776187341256" length="0.23802857992927146"/></geometry>
    </collision>
    <inertial>
      <mass value="0.5"/>
      <inertia ixx="0.005438575536151089" ixy="0" ixz="0" 
               iyy="0.005438575536151089" iyz="0" 
               izz="0.001434216928444582"/>
    </inertial>
  </link>
  <joint name="joint7" type="revolute">
    <parent link="base_link"/>
    <child link="link7"/>
    <origin xyz="0 0 0.15480919224242426" rpy="0 0 0"/>
    <axis xyz="0.15026216234492387 0.8468559181441082 0.5101532480262447"/>
    <dynamics damping="0.1" friction="0.1"/>
    <limit lower="-1.6841203627512558" upper="0.0" effort="100" velocity="100"/>
  </joint>
</robot>