<?xml version="1.0"?>
<robot name="evolved_robot">
  <material name="metal">
    <color rgba="0.7 0.7 0.7 1.0"/>
  </material>
  <material name="plastic">
    <color rgba="0.3 0.3 0.9 1.0"/>
  </material>
  <material name="rubber">
    <color rgba="0.1 0.1 0.1 1.0"/>
  </material>
  <material name="red">
    <color rgba="1.0 0.0 0.0 1.0"/>
  </material>
  <material name="wheel_material">
    <color rgba="0.2 0.2 0.2 1.0"/>
  </material>
  <link name="base_link">
    <visual>
      <geometry><box size="0.2765366376697145 0.2648084809701977 0.09397881144871108"/></geometry>
      <material name="rubber"/>
    </visual>
    <collision>
      <geometry><box size="0.2765366376697145 0.2648084809701977 0.09397881144871108"/></geometry>
    </collision>
    <inertial>
      <mass value="5.0"/>
      <inertia ixx="0.06579629049587997" ixy="0" ixz="0" 
               iyy="0.0710871074791528" iyz="0" 
               izz="0.12216336963951209"/>
    </inertial>
  </link>
  <link name="link1">
    <visual>
      <geometry><cylinder radius="0.058456050730506665" length="0.13346988358562126"/></geometry>
      <material name="rubber"/>
    </visual>
    <collision>
      <geometry><cylinder radius="0.058456050730506665" length="0.13346988358562126"/></geometry>
    </collision>
    <inertial>
      <mass value="0.5"/>
      <inertia ixx="0.0023387949521151666" ixy="0" ixz="0" 
               iyy="0.0023387949521151666" iyz="0" 
               izz="0.0017085549335037844"/>
    </inertial>
  </link>
  <joint name="joint1" type="prismatic">
    <parent link="base_link"/>
    <child link="link1"/>
    <origin xyz="0 0 0.04698940572435554" rpy="0 0 0"/>
    <axis xyz="0.8724546664425253 -0.16358646737037474 -0.4605022504786953"/>
    <dynamics damping="0.41966141190574124" friction="0.1"/>
    <limit lower="-0.45198415874903025" upper="0.31400000000000006" effort="100" velocity="100"/>
  </joint>
  <link name="link2">
    <visual>
      <geometry><cylinder radius="0.06323251585473746" length="0.1647170331719247"/></geometry>
      <material name="plastic"/>
    </visual>
    <collision>
      <geometry><cylinder radius="0.06323251585473746" length="0.1647170331719247"/></geometry>
    </collision>
    <inertial>
      <mass value="0.5"/>
      <inertia ixx="0.0032605628500766517" ixy="0" ixz="0" 
               iyy="0.0032605628500766517" iyz="0" 
               izz="0.0019991755306598123"/>
    </inertial>
  </link>
  <joint name="joint2" type="fixed">
    <parent link="base_link"/>
    <child link="link2"/>
    <origin xyz="0 0 0.09698940572435555" rpy="0 0 0"/>
    <axis xyz="0.17187766442225982 -0.9489731835814094 0.2644011446951656"/>
    <dynamics damping="0.32429681390972" friction="0.1"/>
  </joint>
  <link name="link3">
    <visual>
      <geometry><box size="0.09754319482283905 0.05360909266726486 0.06895527574152845"/></geometry>
      <material name="plastic"/>
    </visual>
    <collision>
      <geometry><box size="0.09754319482283905 0.05360909266726486 0.06895527574152845"/></geometry>
    </collision>
    <inertial>
      <mass value="0.5"/>
      <inertia ixx="0.0006357304057664677" ixy="0" ixz="0" 
               iyy="0.001189125409069713" iyz="0" 
               izz="0.0010323841394044772"/>
    </inertial>
  </link>
  <joint name="joint3" type="fixed">
    <parent link="base_link"/>
    <child link="link3"/>
    <origin xyz="0 0 0.14698940572435554" rpy="0 0 0"/>
    <axis xyz="0.6094496486419922 -0.6511158611521061 -0.4523486057525806"/>
    <dynamics damping="0.6585776546594031" friction="0.1"/>
  </joint>
</robot>