<?xml version="1.0"?>
<robot name="evolved_robot">
  <material name="metal">
    <color rgba="0.7 0.7 0.7 1.0"/>
  </material>
  <material name="plastic">
    <color rgba="0.3 0.3 0.9 1.0"/>
  </material>
  <material name="rubber">
    <color rgba="0.1 0.1 0.1 1.0"/>
  </material>
  <material name="red">
    <color rgba="1.0 0.0 0.0 1.0"/>
  </material>
  <material name="wheel_material">
    <color rgba="0.2 0.2 0.2 1.0"/>
  </material>
  <link name="base_link">
    <visual>
      <geometry><cylinder radius="0.14136862802083966" length="0.08967099717663922"/></geometry>
      <material name="rubber"/>
    </visual>
    <collision>
      <geometry><cylinder radius="0.14136862802083966" length="0.08967099717663922"/></geometry>
    </collision>
    <inertial>
      <mass value="5.0"/>
      <inertia ixx="0.056663462250113684" ixy="0" ixz="0" 
               iyy="0.056663462250113684" iyz="0" 
               izz="0.09992544494247266"/>
    </inertial>
  </link>
  <link name="link1">
    <visual>
      <geometry><cylinder radius="0.06407593774871916" length="0.1427863277072362"/></geometry>
      <material name="plastic"/>
    </visual>
    <collision>
      <geometry><cylinder radius="0.06407593774871916" length="0.1427863277072362"/></geometry>
    </collision>
    <inertial>
      <mass value="0.5"/>
      <inertia ixx="0.0027254260646042867" ixy="0" ixz="0" 
               iyy="0.0027254260646042867" iyz="0" 
               izz="0.002052862899188866"/>
    </inertial>
  </link>
  <joint name="joint1" type="prismatic">
    <parent link="base_link"/>
    <child link="link1"/>
    <origin xyz="0 0 0.04483549858831961" rpy="0 0 0"/>
    <axis xyz="0.906113677164216 -0.3589202130908461 0.22390686610902424"/>
    <dynamics damping="0.7293403050006334" friction="0.1"/>
    <limit lower="-0.9547526151349045" upper="0.9438424306910559" effort="100" velocity="100"/>
  </joint>
  <link name="link2">
    <visual>
      <geometry><cylinder radius="0.08083269291082423" length="0.05266415619830942"/></geometry>
      <material name="rubber"/>
    </visual>
    <collision>
      <geometry><cylinder radius="0.08083269291082423" length="0.05266415619830942"/></geometry>
    </collision>
    <inertial>
      <mass value="0.5"/>
      <inertia ixx="0.0018646071731438978" ixy="0" ixz="0" 
               iyy="0.0018646071731438978" iyz="0" 
               izz="0.003266962121607807"/>
    </inertial>
  </link>
  <joint name="joint2" type="revolute">
    <parent link="base_link"/>
    <child link="link2"/>
    <origin xyz="0 0 0.0948354985883196" rpy="0 0 0"/>
    <axis xyz="0.12793577622601485 0.9916634348867461 0.015364539370490132"/>
    <dynamics damping="0.6963105089517138" friction="0.1"/>
    <limit lower="-0.9769207231415241" upper="0.3088238549099797" effort="100" velocity="100"/>
  </joint>
  <link name="link3">
    <visual>
      <geometry><box size="0.15197306139109826 0.15755732544313733 0.06773367558203931"/></geometry>
      <material name="rubber"/>
    </visual>
    <collision>
      <geometry><box size="0.15197306139109826 0.15755732544313733 0.06773367558203931"/></geometry>
    </collision>
    <inertial>
      <mass value="0.5"/>
      <inertia ixx="0.002451013467387303" ixy="0" ixz="0" 
               iyy="0.0023069718497029557" iyz="0" 
               izz="0.003993343515781434"/>
    </inertial>
  </link>
  <joint name="joint3" type="fixed">
    <parent link="base_link"/>
    <child link="link3"/>
    <origin xyz="0 0 0.14483549858831962" rpy="0 0 0"/>
    <axis xyz="0.5199554780873281 0.4175381768539448 0.7451900238707319"/>
    <dynamics damping="0.5887855533223098" friction="0.1"/>
  </joint>
  <link name="link4">
    <visual>
      <geometry><sphere radius="0.06896209589531067"/></geometry>
      <material name="plastic"/>
    </visual>
    <collision>
      <geometry><sphere radius="0.06896209589531067"/></geometry>
    </collision>
    <inertial>
      <mass value="0.5"/>
      <inertia ixx="0.00190230826810961" ixy="0" ixz="0" 
               iyy="0.00190230826810961" iyz="0" 
               izz="0.00190230826810961"/>
    </inertial>
  </link>
  <joint name="joint4" type="prismatic">
    <parent link="base_link"/>
    <child link="link4"/>
    <origin xyz="0 0 0.19483549858831964" rpy="0 0 0"/>
    <axis xyz="-0.08577462351648497 -0.8935830553339809 -0.44062686842791726"/>
    <dynamics damping="0.7617778135493298" friction="0.1"/>
    <limit lower="-0.6705610024174679" upper="1.2717046001244015" effort="100" velocity="100"/>
  </joint>
</robot>