<?xml version="1.0"?>
<robot name="evolved_robot">
  <material name="metal">
    <color rgba="0.7 0.7 0.7 1.0"/>
  </material>
  <material name="plastic">
    <color rgba="0.3 0.3 0.9 1.0"/>
  </material>
  <material name="rubber">
    <color rgba="0.1 0.1 0.1 1.0"/>
  </material>
  <material name="red">
    <color rgba="1.0 0.0 0.0 1.0"/>
  </material>
  <material name="wheel_material">
    <color rgba="0.2 0.2 0.2 1.0"/>
  </material>
  <link name="base_link">
    <visual>
      <geometry><cylinder radius="0.15919559784818307" length="0.10696531036507993"/></geometry>
      <material name="plastic"/>
    </visual>
    <collision>
      <geometry><cylinder radius="0.15919559784818307" length="0.10696531036507993"/></geometry>
    </collision>
    <inertial>
      <mass value="5.0"/>
      <inertia ixx="0.07289274395351597" ixy="0" ixz="0" 
               iyy="0.07289274395351597" iyz="0" 
               izz="0.12671619187120214"/>
    </inertial>
  </link>
  <link name="link1">
    <visual>
      <geometry><sphere radius="0.038968192844657516"/></geometry>
      <material name="rubber"/>
    </visual>
    <collision>
      <geometry><sphere radius="0.038968192844657516"/></geometry>
    </collision>
    <inertial>
      <mass value="0.5"/>
      <inertia ixx="0.0006074080214313669" ixy="0" ixz="0" 
               iyy="0.0006074080214313669" iyz="0" 
               izz="0.0006074080214313669"/>
    </inertial>
  </link>
  <joint name="joint1" type="revolute">
    <parent link="base_link"/>
    <child link="link1"/>
    <origin xyz="0 0 0.053482655182539966" rpy="0 0 0"/>
    <axis xyz="0.621145700548614 -0.7058397825632913 -0.34054106953637375"/>
    <dynamics damping="0.7907198547146193" friction="0.1"/>
    <limit lower="-1.0519210964026422" upper="1.5065430279141798" effort="100" velocity="100"/>
  </joint>
  <link name="link2">
    <visual>
      <geometry><cylinder radius="0.08703728253224653" length="0.05273362702564697"/></geometry>
      <material name="metal"/>
    </visual>
    <collision>
      <geometry><cylinder radius="0.08703728253224653" length="0.05273362702564697"/></geometry>
    </collision>
    <inertial>
      <mass value="0.5"/>
      <inertia ixx="0.0021256084225895304" ixy="0" ixz="0" 
               iyy="0.0021256084225895304" iyz="0" 
               izz="0.0037877442752990535"/>
    </inertial>
  </link>
  <joint name="joint2" type="revolute">
    <parent link="base_link"/>
    <child link="link2"/>
    <origin xyz="0 0 0.10348265518253996" rpy="0 0 0"/>
    <axis xyz="0.0 0.999999998354316 5.737044490218253e-05"/>
    <dynamics damping="0.6247021823949106" friction="0.1"/>
    <limit lower="-1.010946319447928" upper="2.826" effort="100" velocity="100"/>
  </joint>
  <link name="link3">
    <visual>
      <geometry>
        <cylinder radius="0.05079073287635513" length="0.06360191760646075"/>
      </geometry>
      <material name="wheel_material"/>
    </visual>
    <collision>
      <geometry>
        <cylinder radius="0.05079073287635513" length="0.06360191760646075"/>
      </geometry>
    </collision>
    <inertial>
      <mass value="1.0"/>
      <inertia ixx="0.000982024963464234" ixy="0" ixz="0" 
               iyy="0.000982024963464234" iyz="0" 
               izz="0.001289849273058631"/>
    </inertial>
  </link>
  <joint name="joint3" type="floating">
    <parent link="base_link"/>
    <child link="link3"/>
    <origin xyz="0.15500333243222905 0.1433878632641371 -0.053482655182539966" rpy="1.5708 0 0"/>
    <axis xyz="0 1 0"/>
    <dynamics damping="0.9386368848209998" friction="0.1"/>
  </joint>
  <link name="link4">
    <visual>
      <geometry>
        <cylinder radius="0.06079505596454446" length="0.058975169780921946"/>
      </geometry>
      <material name="wheel_material"/>
    </visual>
    <collision>
      <geometry>
        <cylinder radius="0.06079505596454446" length="0.058975169780921946"/>
      </geometry>
    </collision>
    <inertial>
      <mass value="1.0"/>
      <inertia ixx="0.0012138489283237373" ixy="0" ixz="0" 
               iyy="0.0012138489283237373" iyz="0" 
               izz="0.0018480194148660465"/>
    </inertial>
  </link>
  <joint name="joint4" type="continuous">
    <parent link="base_link"/>
    <child link="link4"/>
    <origin xyz="-0.15500333243222905 0.1433878632641371 -0.053482655182539966" rpy="1.5708 0 0"/>
    <axis xyz="0 1 0"/>
    <dynamics damping="0.4546223756437424" friction="0.1"/>
  </joint>
</robot>