<?xml version="1.0"?>
<robot name="evolved_robot">
  <material name="metal">
    <color rgba="0.7 0.7 0.7 1.0"/>
  </material>
  <material name="plastic">
    <color rgba="0.3 0.3 0.9 1.0"/>
  </material>
  <material name="rubber">
    <color rgba="0.1 0.1 0.1 1.0"/>
  </material>
  <material name="red">
    <color rgba="1.0 0.0 0.0 1.0"/>
  </material>
  <material name="wheel_material">
    <color rgba="0.2 0.2 0.2 1.0"/>
  </material>
  <link name="base_link">
    <visual>
      <geometry><box size="0.30885406755078415 0.4915286942678372 0.10917641224025697"/></geometry>
      <material name="metal"/>
    </visual>
    <collision>
      <geometry><box size="0.30885406755078415 0.4915286942678372 0.10917641224025697"/></geometry>
    </collision>
    <inertial>
      <mass value="5.0"/>
      <inertia ixx="0.21126662189858292" ixy="0" ixz="0" 
               iyy="0.08942527002693239" iyz="0" 
               izz="0.28082607694275774"/>
    </inertial>
  </link>
  <link name="link1">
    <visual>
      <geometry>
        <cylinder radius="0.06276374789163566" length="0.0514543559049874"/>
      </geometry>
      <material name="wheel_material"/>
    </visual>
    <collision>
      <geometry>
        <cylinder radius="0.06276374789163566" length="0.0514543559049874"/>
      </geometry>
    </collision>
    <inertial>
      <mass value="1.0"/>
      <inertia ixx="0.001205451240817626" ixy="0" ixz="0" 
               iyy="0.001205451240817626" iyz="0" 
               izz="0.0019696440247024"/>
    </inertial>
  </link>
  <joint name="joint1" type="continuous">
    <parent link="base_link"/>
    <child link="link1"/>
    <origin xyz="0.13442703377539209 0.2457643471339186 -0.054588206120128484" rpy="1.5708 0 0"/>
    <axis xyz="0 1 0"/>
    <dynamics damping="0.800080736609337" friction="0.1"/>
  </joint>
  <link name="link2">
    <visual>
      <geometry><cylinder radius="0.11007786804061091" length="0.05"/></geometry>
      <material name="rubber"/>
    </visual>
    <collision>
      <geometry><cylinder radius="0.11007786804061091" length="0.05"/></geometry>
    </collision>
    <inertial>
      <mass value="0.5"/>
      <inertia ixx="0.003237617591424871" ixy="0" ixz="0" 
               iyy="0.003237617591424871" iyz="0" 
               izz="0.006058568516183075"/>
    </inertial>
  </link>
  <joint name="joint2" type="revolute">
    <parent link="base_link"/>
    <child link="link2"/>
    <origin xyz="0 0 0.054588206120128484" rpy="0 0 0"/>
    <axis xyz="0.0 0.9935421703900417 0.11346345515911926"/>
    <dynamics damping="0.856863713544254" friction="0.1"/>
    <limit lower="-1.2667756610529117" upper="1.5556918148797805" effort="100" velocity="100"/>
  </joint>
  <link name="link3">
    <visual>
      <geometry>
        <cylinder radius="0.0886510096061919" length="0.04105152901828271"/>
      </geometry>
      <material name="wheel_material"/>
    </visual>
    <collision>
      <geometry>
        <cylinder radius="0.0886510096061919" length="0.04105152901828271"/>
      </geometry>
    </collision>
    <inertial>
      <mass value="1.0"/>
      <inertia ixx="0.002105186045610858" ixy="0" ixz="0" 
               iyy="0.002105186045610858" iyz="0" 
               izz="0.003929500752098565"/>
    </inertial>
  </link>
  <joint name="joint3" type="continuous">
    <parent link="base_link"/>
    <child link="link3"/>
    <origin xyz="0.13442703377539209 -0.2457643471339186 -0.054588206120128484" rpy="1.5708 0 0"/>
    <axis xyz="0 1 0"/>
    <dynamics damping="0.8573772911950069" friction="0.1"/>
  </joint>
  <link name="link4">
    <visual>
      <geometry>
        <cylinder radius="0.04364683632620496" length="0.07712029603936439"/>
      </geometry>
      <material name="wheel_material"/>
    </visual>
    <collision>
      <geometry>
        <cylinder radius="0.04364683632620496" length="0.07712029603936439"/>
      </geometry>
    </collision>
    <inertial>
      <mass value="1.0"/>
      <inertia ixx="0.0009718899187548981" ixy="0" ixz="0" 
               iyy="0.0009718899187548981" iyz="0" 
               izz="0.0009525231606432624"/>
    </inertial>
  </link>
  <joint name="joint4" type="continuous">
    <parent link="base_link"/>
    <child link="link4"/>
    <origin xyz="-0.13442703377539209 0.2457643471339186 -0.054588206120128484" rpy="1.5708 0 0"/>
    <axis xyz="0 1 0"/>
    <dynamics damping="0.3991414187573311" friction="0.1"/>
  </joint>
  <link name="link5">
    <visual>
      <geometry><box size="0.05759607160511873 0.23717176276530344 0.11067024599114919"/></geometry>
      <material name="metal"/>
    </visual>
    <collision>
      <geometry><box size="0.05759607160511873 0.23717176276530344 0.11067024599114919"/></geometry>
    </collision>
    <inertial>
      <mass value="0.5"/>
      <inertia ixx="0.005708195700078571" ixy="0" ixz="0" 
               iyy="0.001297100901006953" iyz="0" 
               izz="0.004963979376461945"/>
    </inertial>
  </link>
  <joint name="joint5" type="floating">
    <parent link="base_link"/>
    <child link="link5"/>
    <origin xyz="0 0 0.10458820612012848" rpy="0 0 0"/>
    <axis xyz="-0.8614842203874079 -0.47321916721917606 0.18414276472316077"/>
    <dynamics damping="0.6722266996412448" friction="0.1"/>
  </joint>
  <link name="link6">
    <visual>
      <geometry>
        <cylinder radius="0.056216930861431924" length="0.04658615893413927"/>
      </geometry>
      <material name="wheel_material"/>
    </visual>
    <collision>
      <geometry>
        <cylinder radius="0.056216930861431924" length="0.04658615893413927"/>
      </geometry>
    </collision>
    <inertial>
      <mass value="1.0"/>
      <inertia ixx="0.000970941679222828" ixy="0" ixz="0" 
               iyy="0.000970941679222828" iyz="0" 
               izz="0.0015801716577395085"/>
    </inertial>
  </link>
  <joint name="joint6" type="continuous">
    <parent link="base_link"/>
    <child link="link6"/>
    <origin xyz="-0.13442703377539209 -0.2457643471339186 -0.054588206120128484" rpy="1.5708 0 0"/>
    <axis xyz="0 1 0"/>
    <dynamics damping="0.47291917500060554" friction="0.1"/>
  </joint>
</robot>