<?xml version="1.0"?>
<robot name="evolved_robot">
  <material name="metal">
    <color rgba="0.7 0.7 0.7 1.0"/>
  </material>
  <material name="plastic">
    <color rgba="0.3 0.3 0.9 1.0"/>
  </material>
  <material name="rubber">
    <color rgba="0.1 0.1 0.1 1.0"/>
  </material>
  <material name="red">
    <color rgba="1.0 0.0 0.0 1.0"/>
  </material>
  <material name="wheel_material">
    <color rgba="0.2 0.2 0.2 1.0"/>
  </material>
  <link name="base_link">
    <visual>
      <geometry><sphere radius="0.11778849344417112"/></geometry>
      <material name="metal"/>
    </visual>
    <collision>
      <geometry><sphere radius="0.11778849344417112"/></geometry>
    </collision>
    <inertial>
      <mass value="5.0"/>
      <inertia ixx="0.05549651675139018" ixy="0" ixz="0" 
               iyy="0.05549651675139018" iyz="0" 
               izz="0.05549651675139018"/>
    </inertial>
  </link>
  <link name="link1">
    <visual>
      <geometry><cylinder radius="0.06881490202577381" length="0.19527266366108598"/></geometry>
      <material name="plastic"/>
    </visual>
    <collision>
      <geometry><cylinder radius="0.06881490202577381" length="0.19527266366108598"/></geometry>
    </collision>
    <inertial>
      <mass value="0.5"/>
      <inertia ixx="0.0043614904496455135" ixy="0" ixz="0" 
               iyy="0.0043614904496455135" iyz="0" 
               izz="0.002367745370408424"/>
    </inertial>
  </link>
  <joint name="joint1" type="revolute">
    <parent link="base_link"/>
    <child link="link1"/>
    <origin xyz="0 0 0.0639981772847387" rpy="0 0 0"/>
    <axis xyz="-0.6665710486624863 -0.18646974723615306 0.7217423851005832"/>
    <dynamics damping="0.12740985007843206" friction="0.1"/>
    <limit lower="-0.6865337371664445" upper="0.07322227772249763" effort="100" velocity="100"/>
  </joint>
  <link name="link2">
    <visual>
      <geometry><box size="0.1207828709484049 0.12245717128177022 0.09757899011843829"/></geometry>
      <material name="rubber"/>
    </visual>
    <collision>
      <geometry><box size="0.1207828709484049 0.12245717128177022 0.09757899011843829"/></geometry>
    </collision>
    <inertial>
      <mass value="0.5"/>
      <inertia ixx="0.0020431181759055905" ixy="0" ixz="0" 
               iyy="0.002009180102256109" iyz="0" 
               izz="0.0024653550594059864"/>
    </inertial>
  </link>
  <joint name="joint2" type="fixed">
    <parent link="base_link"/>
    <child link="link2"/>
    <origin xyz="0 0 0.1139981772847387" rpy="0 0 0"/>
    <axis xyz="0.5405573840613302 0.73986872228039 0.4004896856698744"/>
    <dynamics damping="0.32217045040889225" friction="0.1"/>
  </joint>
  <link name="link3">
    <visual>
      <geometry><sphere radius="0.06664626284379745"/></geometry>
      <material name="plastic"/>
    </visual>
    <collision>
      <geometry><sphere radius="0.06664626284379745"/></geometry>
    </collision>
    <inertial>
      <mass value="0.5"/>
      <inertia ixx="0.0017766897404178146" ixy="0" ixz="0" 
               iyy="0.0017766897404178146" iyz="0" 
               izz="0.0017766897404178146"/>
    </inertial>
  </link>
  <joint name="joint3" type="prismatic">
    <parent link="base_link"/>
    <child link="link3"/>
    <origin xyz="0 0 0.1639981772847387" rpy="0 0 0"/>
    <axis xyz="0.01108440517267698 0.949077770641911 0.31484682186000934"/>
    <dynamics damping="0.4117828208540274" friction="0.1"/>
    <limit lower="-2.8289879891267073" upper="1.65076405813098" effort="100" velocity="100"/>
  </joint>
  <link name="link4">
    <visual>
      <geometry><cylinder radius="0.05435130960907877" length="0.19377988260076867"/></geometry>
      <material name="rubber"/>
    </visual>
    <collision>
      <geometry><cylinder radius="0.05435130960907877" length="0.19377988260076867"/></geometry>
    </collision>
    <inertial>
      <mass value="0.5"/>
      <inertia ixx="0.0038677364557861255" ixy="0" ixz="0" 
               iyy="0.0038677364557861255" iyz="0" 
               izz="0.0014770324281109689"/>
    </inertial>
  </link>
  <joint name="joint4" type="prismatic">
    <parent link="base_link"/>
    <child link="link4"/>
    <origin xyz="0 0 0.21399817728473872" rpy="0 0 0"/>
    <axis xyz="0.9248506022457607 -0.09491423267899927 0.3682969616499848"/>
    <dynamics damping="0.2888799852650854" friction="0.1"/>
    <limit lower="-1.4471671154645713" upper="3.1176989047034307" effort="100" velocity="100"/>
  </joint>
</robot>