<?xml version="1.0"?>
<robot name="evolved_robot">
  <material name="metal">
    <color rgba="0.7 0.7 0.7 1.0"/>
  </material>
  <material name="plastic">
    <color rgba="0.3 0.3 0.9 1.0"/>
  </material>
  <material name="rubber">
    <color rgba="0.1 0.1 0.1 1.0"/>
  </material>
  <material name="red">
    <color rgba="1.0 0.0 0.0 1.0"/>
  </material>
  <material name="wheel_material">
    <color rgba="0.2 0.2 0.2 1.0"/>
  </material>
  <link name="base_link">
    <visual>
      <geometry><box size="0.28200543666407374 0.19277832457260408 0.09720927208536406"/></geometry>
      <material name="metal"/>
    </visual>
    <collision>
      <geometry><box size="0.28200543666407374 0.19277832457260408 0.09720927208536406"/></geometry>
    </collision>
    <inertial>
      <mass value="5.0"/>
      <inertia ixx="0.03884427083698886" ixy="0" ixz="0" 
               iyy="0.0741472574062177" iyz="0" 
               izz="0.09724212394426264"/>
    </inertial>
  </link>
  <link name="link1">
    <visual>
      <geometry>
        <cylinder radius="0.05276887741149976" length="0.040581285150848495"/>
      </geometry>
      <material name="wheel_material"/>
    </visual>
    <collision>
      <geometry>
        <cylinder radius="0.05276887741149976" length="0.040581285150848495"/>
      </geometry>
    </collision>
    <inertial>
      <mass value="1.0"/>
      <inertia ixx="0.000833375331192012" ixy="0" ixz="0" 
               iyy="0.000833375331192012" iyz="0" 
               izz="0.0013922772116349445"/>
    </inertial>
  </link>
  <joint name="joint1" type="continuous">
    <parent link="base_link"/>
    <child link="link1"/>
    <origin xyz="0.12100271833203687 0.09638916228630204 -0.04860463604268203" rpy="1.5708 0 0"/>
    <axis xyz="0 0 1"/>
    <dynamics damping="0.7818402829444023" friction="0.1"/>
  </joint>
  <link name="link2">
    <visual>
      <geometry><cylinder radius="0.09218080847006109" length="0.05"/></geometry>
      <material name="plastic"/>
    </visual>
    <collision>
      <geometry><cylinder radius="0.09218080847006109" length="0.05"/></geometry>
    </collision>
    <inertial>
      <mass value="0.5"/>
      <inertia ixx="0.002332658695881855" ixy="0" ixz="0" 
               iyy="0.002332658695881855" iyz="0" 
               izz="0.004248650725097043"/>
    </inertial>
  </link>
  <joint name="joint2" type="revolute">
    <parent link="base_link"/>
    <child link="link2"/>
    <origin xyz="0 0 0.04860463604268203" rpy="0 0 0"/>
    <axis xyz="0.7056202527143156 -0.5413176906883189 -0.45724743488318337"/>
    <dynamics damping="0.8524918096531522" friction="0.1"/>
    <limit lower="-1.9273850581548186" upper="1.0937068410650614" effort="100" velocity="100"/>
  </joint>
  <link name="link3">
    <visual>
      <geometry>
        <cylinder radius="0.07063797436999575" length="0.042093354478068126"/>
      </geometry>
      <material name="wheel_material"/>
    </visual>
    <collision>
      <geometry>
        <cylinder radius="0.07063797436999575" length="0.042093354478068126"/>
      </geometry>
    </collision>
    <inertial>
      <mass value="1.0"/>
      <inertia ixx="0.001395085063375402" ixy="0" ixz="0" 
               iyy="0.001395085063375402" iyz="0" 
               izz="0.002494861711548088"/>
    </inertial>
  </link>
  <joint name="joint3" type="continuous">
    <parent link="base_link"/>
    <child link="link3"/>
    <origin xyz="0.12100271833203687 -0.09638916228630204 -0.04860463604268203" rpy="1.5708 0 0"/>
    <axis xyz="0 0 1"/>
    <dynamics damping="0.69190020288255" friction="0.1"/>
  </joint>
  <link name="link4">
    <visual>
      <geometry>
        <cylinder radius="0.07908787434849454" length="0.048557610339922924"/>
      </geometry>
      <material name="wheel_material"/>
    </visual>
    <collision>
      <geometry>
        <cylinder radius="0.07908787434849454" length="0.048557610339922924"/>
      </geometry>
    </collision>
    <inertial>
      <mass value="1.0"/>
      <inertia ixx="0.0017602097607344643" ixy="0" ixz="0" 
               iyy="0.0017602097607344643" iyz="0" 
               izz="0.0031274459344816305"/>
    </inertial>
  </link>
  <joint name="joint4" type="continuous">
    <parent link="base_link"/>
    <child link="link4"/>
    <origin xyz="-0.12100271833203687 0.09638916228630204 -0.04860463604268203" rpy="1.5708 0 0"/>
    <axis xyz="0 0 1"/>
    <dynamics damping="0.6849628307493921" friction="0.1"/>
  </joint>
  <link name="link5">
    <visual>
      <geometry><sphere radius="0.04915514420561673"/></geometry>
      <material name="metal"/>
    </visual>
    <collision>
      <geometry><sphere radius="0.04915514420561673"/></geometry>
    </collision>
    <inertial>
      <mass value="0.5"/>
      <inertia ixx="0.0009664912807499903" ixy="0" ixz="0" 
               iyy="0.0009664912807499903" iyz="0" 
               izz="0.0009664912807499903"/>
    </inertial>
  </link>
  <joint name="joint5" type="prismatic">
    <parent link="base_link"/>
    <child link="link5"/>
    <origin xyz="0 0 0.09860463604268203" rpy="0 0 0"/>
    <axis xyz="-0.6862888858142306 0.6373425381039485 -0.35043124051813507"/>
    <dynamics damping="0.7028373833923687" friction="0.1"/>
    <limit lower="-0.3644232264120007" upper="0.9926335345686322" effort="100" velocity="100"/>
  </joint>
  <link name="link6">
    <visual>
      <geometry>
        <cylinder radius="0.0805953329017795" length="0.054859577616518704"/>
      </geometry>
      <material name="wheel_material"/>
    </visual>
    <collision>
      <geometry>
        <cylinder radius="0.0805953329017795" length="0.054859577616518704"/>
      </geometry>
    </collision>
    <inertial>
      <mass value="1.0"/>
      <inertia ixx="0.0018746996927424021" ixy="0" ixz="0" 
               iyy="0.0018746996927424021" iyz="0" 
               izz="0.003247803842774331"/>
    </inertial>
  </link>
  <joint name="joint6" type="continuous">
    <parent link="base_link"/>
    <child link="link6"/>
    <origin xyz="-0.12100271833203687 -0.09638916228630204 -0.04860463604268203" rpy="1.5708 0 0"/>
    <axis xyz="0 0 1"/>
    <dynamics damping="0.9270004068807279" friction="0.1"/>
  </joint>
</robot>