<?xml version="1.0"?>
<robot name="evolved_robot">
  <material name="metal">
    <color rgba="0.7 0.7 0.7 1.0"/>
  </material>
  <material name="plastic">
    <color rgba="0.3 0.3 0.9 1.0"/>
  </material>
  <material name="rubber">
    <color rgba="0.1 0.1 0.1 1.0"/>
  </material>
  <material name="red">
    <color rgba="1.0 0.0 0.0 1.0"/>
  </material>
  <material name="wheel_material">
    <color rgba="0.2 0.2 0.2 1.0"/>
  </material>
  <link name="base_link">
    <visual>
      <geometry><box size="0.31577586228805876 0.3097515015297141 0.08684391380071729"/></geometry>
      <material name="plastic"/>
    </visual>
    <collision>
      <geometry><box size="0.31577586228805876 0.3097515015297141 0.08684391380071729"/></geometry>
    </collision>
    <inertial>
      <mass value="5.0"/>
      <inertia ixx="0.08623988172011575" ixy="0" ixz="0" 
               iyy="0.08938021713999456" iyz="0" 
               izz="0.16305032325306626"/>
    </inertial>
  </link>
  <link name="link1">
    <visual>
      <geometry>
        <cylinder radius="0.06255185810306499" length="0.059851785901877536"/>
      </geometry>
      <material name="wheel_material"/>
    </visual>
    <collision>
      <geometry>
        <cylinder radius="0.06255185810306499" length="0.059851785901877536"/>
      </geometry>
    </collision>
    <inertial>
      <mass value="1.0"/>
      <inertia ixx="0.0012767034276735098" ixy="0" ixz="0" 
               iyy="0.0012767034276735098" iyz="0" 
               izz="0.0019563674760729884"/>
    </inertial>
  </link>
  <joint name="joint1" type="fixed">
    <parent link="base_link"/>
    <child link="link1"/>
    <origin xyz="0.1378879311440294 0.15487575076485705 -0.043421956900358646" rpy="1.5708 0 0"/>
    <axis xyz="0 0 1"/>
    <dynamics damping="0.7638679325233487" friction="0.1"/>
  </joint>
  <link name="link2">
    <visual>
      <geometry>
        <cylinder radius="0.07541677612483186" length="0.04608649390531437"/>
      </geometry>
      <material name="wheel_material"/>
    </visual>
    <collision>
      <geometry>
        <cylinder radius="0.07541677612483186" length="0.04608649390531437"/>
      </geometry>
    </collision>
    <inertial>
      <mass value="1.0"/>
      <inertia ixx="0.0015989196069728002" ixy="0" ixz="0" 
               iyy="0.0015989196069728002" iyz="0" 
               izz="0.002843845060531504"/>
    </inertial>
  </link>
  <joint name="joint2" type="continuous">
    <parent link="base_link"/>
    <child link="link2"/>
    <origin xyz="0.1378879311440294 -0.15487575076485705 -0.043421956900358646" rpy="1.5708 0 0"/>
    <axis xyz="0 0 1"/>
    <dynamics damping="0.9332973929305248" friction="0.1"/>
  </joint>
  <link name="link3">
    <visual>
      <geometry>
        <cylinder radius="0.06369274714863107" length="0.0742813757786009"/>
      </geometry>
      <material name="wheel_material"/>
    </visual>
    <collision>
      <geometry>
        <cylinder radius="0.06369274714863107" length="0.0742813757786009"/>
      </geometry>
    </collision>
    <inertial>
      <mass value="1.0"/>
      <inertia ixx="0.0014740017421316727" ixy="0" ixz="0" 
               iyy="0.0014740017421316727" iyz="0" 
               izz="0.002028383019669726"/>
    </inertial>
  </link>
  <joint name="joint3" type="continuous">
    <parent link="base_link"/>
    <child link="link3"/>
    <origin xyz="-0.1378879311440294 0.15487575076485705 -0.043421956900358646" rpy="1.5708 0 0"/>
    <axis xyz="0 0 1"/>
    <dynamics damping="0.43936669472471734" friction="0.1"/>
  </joint>
  <link name="link4">
    <visual>
      <geometry>
        <cylinder radius="0.07483854874119761" length="0.05495786161961812"/>
      </geometry>
      <material name="wheel_material"/>
    </visual>
    <collision>
      <geometry>
        <cylinder radius="0.07483854874119761" length="0.05495786161961812"/>
      </geometry>
    </collision>
    <inertial>
      <mass value="1.0"/>
      <inertia ixx="0.0016518993072389104" ixy="0" ixz="0" 
               iyy="0.0016518993072389104" iyz="0" 
               izz="0.002800404188844305"/>
    </inertial>
  </link>
  <joint name="joint4" type="continuous">
    <parent link="base_link"/>
    <child link="link4"/>
    <origin xyz="-0.1378879311440294 -0.15487575076485705 -0.043421956900358646" rpy="1.5708 0 0"/>
    <axis xyz="0 0 1"/>
    <dynamics damping="0.7063054413195338" friction="0.1"/>
  </joint>
  <link name="link5">
    <visual>
      <geometry><cylinder radius="0.07954449144988582" length="0.24215862870814509"/></geometry>
      <material name="rubber"/>
    </visual>
    <collision>
      <geometry><cylinder radius="0.07954449144988582" length="0.24215862870814509"/></geometry>
    </collision>
    <inertial>
      <mass value="0.5"/>
      <inertia ixx="0.006468564984822678" ixy="0" ixz="0" 
               iyy="0.006468564984822678" iyz="0" 
               izz="0.003163663060010479"/>
    </inertial>
  </link>
  <joint name="joint5" type="prismatic">
    <parent link="base_link"/>
    <child link="link5"/>
    <origin xyz="0 0 0.043421956900358646" rpy="0 0 0"/>
    <axis xyz="0.0006039214767013428 0.36101893599283097 -0.9325582894025736"/>
    <dynamics damping="0.3147096256611319" friction="0.1"/>
    <limit lower="-2.3787570138441776" upper="1.2000851268044384" effort="100" velocity="100"/>
  </joint>
</robot>