<?xml version="1.0"?>
<robot name="evolved_robot">
  <material name="metal">
    <color rgba="0.7 0.7 0.7 1.0"/>
  </material>
  <material name="plastic">
    <color rgba="0.3 0.3 0.9 1.0"/>
  </material>
  <material name="rubber">
    <color rgba="0.1 0.1 0.1 1.0"/>
  </material>
  <material name="red">
    <color rgba="1.0 0.0 0.0 1.0"/>
  </material>
  <material name="wheel_material">
    <color rgba="0.2 0.2 0.2 1.0"/>
  </material>
  <link name="base_link">
    <visual>
      <geometry><cylinder radius="0.16069086020135437" length="0.1301065557292387"/></geometry>
      <material name="metal"/>
    </visual>
    <collision>
      <geometry><cylinder radius="0.16069086020135437" length="0.1301065557292387"/></geometry>
    </collision>
    <inertial>
      <mass value="5.0"/>
      <inertia ixx="0.07866031125039928" ixy="0" ixz="0" 
               iyy="0.07866031125039928" iyz="0" 
               izz="0.12910776276125607"/>
    </inertial>
  </link>
  <link name="link1">
    <visual>
      <geometry><box size="0.13418867020242448 0.08591909022609032 0.14453061571277626"/></geometry>
      <material name="rubber"/>
    </visual>
    <collision>
      <geometry><box size="0.13418867020242448 0.08591909022609032 0.14453061571277626"/></geometry>
    </collision>
    <inertial>
      <mass value="0.5"/>
      <inertia ixx="0.0023559324119661047" ixy="0" ixz="0" 
               iyy="0.0032413081740841044" iyz="0" 
               izz="0.002115724106331174"/>
    </inertial>
  </link>
  <joint name="joint1" type="fixed">
    <parent link="base_link"/>
    <child link="link1"/>
    <origin xyz="0 0 0.06505327786461935" rpy="0 0 0"/>
    <axis xyz="-0.5683316138997706 0.6543038399177311 0.49888441718597937"/>
    <dynamics damping="0.1029057953056492" friction="0.1"/>
  </joint>
  <link name="link2">
    <visual>
      <geometry><cylinder radius="0.10993525097909042" length="0.19182219904361414"/></geometry>
      <material name="metal"/>
    </visual>
    <collision>
      <geometry><cylinder radius="0.10993525097909042" length="0.19182219904361414"/></geometry>
    </collision>
    <inertial>
      <mass value="0.5"/>
      <inertia ixx="0.006087752855786226" ixy="0" ixz="0" 
               iyy="0.006087752855786226" iyz="0" 
               izz="0.0060428797039178"/>
    </inertial>
  </link>
  <joint name="joint2" type="floating">
    <parent link="base_link"/>
    <child link="link2"/>
    <origin xyz="0 0 0.11505327786461936" rpy="0 0 0"/>
    <axis xyz="-0.5041731583712482 0.48815088000124596 -0.7124030774301648"/>
    <dynamics damping="0.12578708678342743" friction="0.1"/>
  </joint>
  <link name="link3">
    <visual>
      <geometry><cylinder radius="0.08164965642623613" length="0.16976906113014034"/></geometry>
      <material name="rubber"/>
    </visual>
    <collision>
      <geometry><cylinder radius="0.08164965642623613" length="0.16976906113014034"/></geometry>
    </collision>
    <inertial>
      <mass value="0.5"/>
      <inertia ixx="0.004068461108381378" ixy="0" ixz="0" 
               iyy="0.004068461108381378" iyz="0" 
               izz="0.0033333331972612017"/>
    </inertial>
  </link>
  <joint name="joint3" type="floating">
    <parent link="base_link"/>
    <child link="link3"/>
    <origin xyz="0 0 0.16505327786461937" rpy="0 0 0"/>
    <axis xyz="0.49317600671729234 0.7708723087581292 0.40315420125343704"/>
    <dynamics damping="0.6041715049229968" friction="0.1"/>
  </joint>
  <link name="link4">
    <visual>
      <geometry><sphere radius="0.04384822215266718"/></geometry>
      <material name="metal"/>
    </visual>
    <collision>
      <geometry><sphere radius="0.04384822215266718"/></geometry>
    </collision>
    <inertial>
      <mass value="0.5"/>
      <inertia ixx="0.000769066634379861" ixy="0" ixz="0" 
               iyy="0.000769066634379861" iyz="0" 
               izz="0.000769066634379861"/>
    </inertial>
  </link>
  <joint name="joint4" type="prismatic">
    <parent link="base_link"/>
    <child link="link4"/>
    <origin xyz="0 0 0.21505327786461936" rpy="0 0 0"/>
    <axis xyz="-0.44155416081648213 0.7002001604206751 0.5610255416757003"/>
    <dynamics damping="0.39116741689795687" friction="0.1"/>
    <limit lower="-1.7139746193075147" upper="2.6350249001616186" effort="100" velocity="100"/>
  </joint>
  <link name="link5">
    <visual>
      <geometry><cylinder radius="0.056196796538329305" length="0.21701985515282202"/></geometry>
      <material name="metal"/>
    </visual>
    <collision>
      <geometry><cylinder radius="0.056196796538329305" length="0.21701985515282202"/></geometry>
    </collision>
    <inertial>
      <mass value="0.5"/>
      <inertia ixx="0.004714321446171916" ixy="0" ixz="0" 
               iyy="0.004714321446171916" iyz="0" 
               izz="0.0015790399705851903"/>
    </inertial>
  </link>
  <joint name="joint5" type="floating">
    <parent link="base_link"/>
    <child link="link5"/>
    <origin xyz="0 0 0.26505327786461935" rpy="0 0 0"/>
    <axis xyz="-0.5458957571543982 0.8326276618116261 0.09342911273757734"/>
    <dynamics damping="0.5907926047945831" friction="0.1"/>
  </joint>
  <link name="link6">
    <visual>
      <geometry><sphere radius="0.06092791577671576"/></geometry>
      <material name="metal"/>
    </visual>
    <collision>
      <geometry><sphere radius="0.06092791577671576"/></geometry>
    </collision>
    <inertial>
      <mass value="0.5"/>
      <inertia ixx="0.0014848843683578279" ixy="0" ixz="0" 
               iyy="0.0014848843683578279" iyz="0" 
               izz="0.0014848843683578279"/>
    </inertial>
  </link>
  <joint name="joint6" type="fixed">
    <parent link="base_link"/>
    <child link="link6"/>
    <origin xyz="0 0 0.31505327786461934" rpy="0 0 0"/>
    <axis xyz="-0.36199013213675785 0.7793601723974896 0.5114302160766099"/>
    <dynamics damping="0.47740478372994777" friction="0.1"/>
  </joint>
</robot>