<?xml version="1.0"?>
<robot name="evolved_robot">
  <material name="metal">
    <color rgba="0.7 0.7 0.7 1.0"/>
  </material>
  <material name="plastic">
    <color rgba="0.3 0.3 0.9 1.0"/>
  </material>
  <material name="rubber">
    <color rgba="0.1 0.1 0.1 1.0"/>
  </material>
  <material name="red">
    <color rgba="1.0 0.0 0.0 1.0"/>
  </material>
  <material name="wheel_material">
    <color rgba="0.2 0.2 0.2 1.0"/>
  </material>
  <link name="base_link">
    <visual>
      <geometry><box size="0.2782065296935696 0.3130306021335339 0.0939747855253997"/></geometry>
      <material name="plastic"/>
    </visual>
    <collision>
      <geometry><box size="0.2782065296935696 0.3130306021335339 0.0939747855253997"/></geometry>
    </collision>
    <inertial>
      <mass value="5.0"/>
      <inertia ixx="0.08901618182218973" ixy="0" ixz="0" 
               iyy="0.07185844456556993" iyz="0" 
               izz="0.1461558591968515"/>
    </inertial>
  </link>
  <link name="link1">
    <visual>
      <geometry><cylinder radius="0.07158522055848092" length="0.11932034292552557"/></geometry>
      <material name="rubber"/>
    </visual>
    <collision>
      <geometry><cylinder radius="0.07158522055848092" length="0.11932034292552557"/></geometry>
    </collision>
    <inertial>
      <mass value="0.5"/>
      <inertia ixx="0.0024675563035903413" ixy="0" ixz="0" 
               iyy="0.0024675563035903413" iyz="0" 
               izz="0.0025622219012031797"/>
    </inertial>
  </link>
  <joint name="joint1" type="prismatic">
    <parent link="base_link"/>
    <child link="link1"/>
    <origin xyz="0 0 0.04698739276269985" rpy="0 0 0"/>
    <axis xyz="0.9162275239977837 0.0 -0.40065836353293605"/>
    <dynamics damping="0.40154759364569137" friction="0.1"/>
    <limit lower="-0.4373221712677814" upper="0.942" effort="100" velocity="100"/>
  </joint>
  <link name="link2">
    <visual>
      <geometry><sphere radius="0.05930375874053482"/></geometry>
      <material name="plastic"/>
    </visual>
    <collision>
      <geometry><sphere radius="0.05930375874053482"/></geometry>
    </collision>
    <inertial>
      <mass value="0.5"/>
      <inertia ixx="0.001406774320302224" ixy="0" ixz="0" 
               iyy="0.001406774320302224" iyz="0" 
               izz="0.001406774320302224"/>
    </inertial>
  </link>
  <joint name="joint2" type="revolute">
    <parent link="base_link"/>
    <child link="link2"/>
    <origin xyz="0 0 0.09698739276269985" rpy="0 0 0"/>
    <axis xyz="0.06924333471532548 -0.465906071218334 -0.8821206796121482"/>
    <dynamics damping="0.4562130730949524" friction="0.1"/>
    <limit lower="-1.3592207787626347" upper="0.31400000000000006" effort="100" velocity="100"/>
  </joint>
  <link name="link3">
    <visual>
      <geometry><box size="0.10010991640666202 0.24785417138997268 0.06217577530324774"/></geometry>
      <material name="plastic"/>
    </visual>
    <collision>
      <geometry><box size="0.10010991640666202 0.24785417138997268 0.06217577530324774"/></geometry>
    </collision>
    <inertial>
      <mass value="0.5"/>
      <inertia ixx="0.005441459775830825" ixy="0" ixz="0" 
               iyy="0.001157318533125734" iyz="0" 
               izz="0.005954473803196567"/>
    </inertial>
  </link>
  <joint name="joint3" type="fixed">
    <parent link="base_link"/>
    <child link="link3"/>
    <origin xyz="0 0 0.14698739276269984" rpy="0 0 0"/>
    <axis xyz="0.8223284599852578 0.05212374979236044 -0.5666207008271562"/>
    <dynamics damping="0.7639415923927636" friction="0.1"/>
  </joint>
</robot>