<?xml version="1.0"?>
<robot name="evolved_robot">
  <material name="metal">
    <color rgba="0.7 0.7 0.7 1.0"/>
  </material>
  <material name="plastic">
    <color rgba="0.3 0.3 0.9 1.0"/>
  </material>
  <material name="rubber">
    <color rgba="0.1 0.1 0.1 1.0"/>
  </material>
  <material name="red">
    <color rgba="1.0 0.0 0.0 1.0"/>
  </material>
  <material name="wheel_material">
    <color rgba="0.2 0.2 0.2 1.0"/>
  </material>
  <link name="base_link">
    <visual>
      <geometry><sphere radius="0.11321044881892887"/></geometry>
      <material name="plastic"/>
    </visual>
    <collision>
      <geometry><sphere radius="0.11321044881892887"/></geometry>
    </collision>
    <inertial>
      <mass value="5.0"/>
      <inertia ixx="0.051266422887133255" ixy="0" ixz="0" 
               iyy="0.051266422887133255" iyz="0" 
               izz="0.051266422887133255"/>
    </inertial>
  </link>
  <link name="link1">
    <visual>
      <geometry><sphere radius="0.05969199609016949"/></geometry>
      <material name="plastic"/>
    </visual>
    <collision>
      <geometry><sphere radius="0.05969199609016949"/></geometry>
    </collision>
    <inertial>
      <mass value="0.5"/>
      <inertia ixx="0.0014252537588915236" ixy="0" ixz="0" 
               iyy="0.0014252537588915236" iyz="0" 
               izz="0.0014252537588915236"/>
    </inertial>
  </link>
  <joint name="joint1" type="revolute">
    <parent link="base_link"/>
    <child link="link1"/>
    <origin xyz="0 0 0.06062258693086314" rpy="0 0 0"/>
    <axis xyz="-0.40868413475462495 -0.5548385751095031 -0.724659529413862"/>
    <dynamics damping="0.7487907624693755" friction="0.1"/>
    <limit lower="-1.256164154549568" upper="1.1811303853171582" effort="100" velocity="100"/>
  </joint>
  <link name="link2">
    <visual>
      <geometry>
        <cylinder radius="0.054725586248147544" length="0.04083191864288376"/>
      </geometry>
      <material name="wheel_material"/>
    </visual>
    <collision>
      <geometry>
        <cylinder radius="0.054725586248147544" length="0.04083191864288376"/>
      </geometry>
    </collision>
    <inertial>
      <mass value="1.0"/>
      <inertia ixx="0.0008876595792224487" ixy="0" ixz="0" 
               iyy="0.0008876595792224487" iyz="0" 
               izz="0.0014974448951017177"/>
    </inertial>
  </link>
  <joint name="joint2" type="continuous">
    <parent link="base_link"/>
    <child link="link2"/>
    <origin xyz="0.16026085789164765 0.09874790163427583 -0.06062258693086314" rpy="1.5708 0 0"/>
    <axis xyz="0 1 0"/>
    <dynamics damping="0.5367394424279552" friction="0.1"/>
  </joint>
  <link name="link3">
    <visual>
      <geometry><sphere radius="0.03706003956894172"/></geometry>
      <material name="plastic"/>
    </visual>
    <collision>
      <geometry><sphere radius="0.03706003956894172"/></geometry>
    </collision>
    <inertial>
      <mass value="0.5"/>
      <inertia ixx="0.0005493786131406105" ixy="0" ixz="0" 
               iyy="0.0005493786131406105" iyz="0" 
               izz="0.0005493786131406105"/>
    </inertial>
  </link>
  <joint name="joint3" type="revolute">
    <parent link="base_link"/>
    <child link="link3"/>
    <origin xyz="0 0 0.11062258693086315" rpy="0 0 0"/>
    <axis xyz="0.39404557001477847 0.9035360023946903 0.1683769020036611"/>
    <dynamics damping="0.7689334316933646" friction="0.1"/>
    <limit lower="-1.372779221461513" upper="1.174895297719542" effort="100" velocity="100"/>
  </joint>
  <link name="link4">
    <visual>
      <geometry>
        <cylinder radius="0.08875857303974351" length="0.025222020492338057"/>
      </geometry>
      <material name="wheel_material"/>
    </visual>
    <collision>
      <geometry>
        <cylinder radius="0.08875857303974351" length="0.025222020492338057"/>
      </geometry>
    </collision>
    <inertial>
      <mass value="1.0"/>
      <inertia ixx="0.0020225335984891974" ixy="0" ixz="0" 
               iyy="0.0020225335984891974" iyz="0" 
               izz="0.003939042144025741"/>
    </inertial>
  </link>
  <joint name="joint4" type="continuous">
    <parent link="base_link"/>
    <child link="link4"/>
    <origin xyz="-0.16026085789164765 0.09874790163427583 -0.06062258693086314" rpy="1.5708 0 0"/>
    <axis xyz="0 1 0"/>
    <dynamics damping="0.6478494759876156" friction="0.1"/>
  </joint>
  <link name="link5">
    <visual>
      <geometry><sphere radius="0.03606119450787221"/></geometry>
      <material name="rubber"/>
    </visual>
    <collision>
      <geometry><sphere radius="0.03606119450787221"/></geometry>
    </collision>
    <inertial>
      <mass value="0.5"/>
      <inertia ixx="0.000520163899733837" ixy="0" ixz="0" 
               iyy="0.000520163899733837" iyz="0" 
               izz="0.000520163899733837"/>
    </inertial>
  </link>
  <joint name="joint5" type="prismatic">
    <parent link="base_link"/>
    <child link="link5"/>
    <origin xyz="0 0 0.16062258693086315" rpy="0 0 0"/>
    <axis xyz="-0.5677213251139246 -0.7027704675307052 0.4287262144744169"/>
    <dynamics damping="0.7872694871185734" friction="0.1"/>
    <limit lower="-1.8599310123773998" upper="1.104568933900026" effort="100" velocity="100"/>
  </joint>
  <link name="link6">
    <visual>
      <geometry>
        <cylinder radius="0.07533663714733194" length="0.052724950445477134"/>
      </geometry>
      <material name="wheel_material"/>
    </visual>
    <collision>
      <geometry>
        <cylinder radius="0.07533663714733194" length="0.052724950445477134"/>
      </geometry>
    </collision>
    <inertial>
      <mass value="1.0"/>
      <inertia ixx="0.0016505622574570235" ixy="0" ixz="0" 
               iyy="0.0016505622574570235" iyz="0" 
               izz="0.002837804448334377"/>
    </inertial>
  </link>
  <joint name="joint6" type="continuous">
    <parent link="base_link"/>
    <child link="link6"/>
    <origin xyz="-0.16026085789164765 -0.09874790163427583 -0.06062258693086314" rpy="1.5708 0 0"/>
    <axis xyz="0 1 0"/>
    <dynamics damping="0.9270203448565811" friction="0.1"/>
  </joint>
  <link name="link7">
    <visual>
      <geometry><cylinder radius="0.027385799034400318" length="0.23802857992927146"/></geometry>
      <material name="metal"/>
    </visual>
    <collision>
      <geometry><cylinder radius="0.027385799034400318" length="0.23802857992927146"/></geometry>
    </collision>
    <inertial>
      <mass value="0.5"/>
      <inertia ixx="0.004908962569116938" ixy="0" ixz="0" 
               iyy="0.004908962569116938" iyz="0" 
               izz="0.0003749909943762807"/>
    </inertial>
  </link>
  <joint name="joint7" type="revolute">
    <parent link="base_link"/>
    <child link="link7"/>
    <origin xyz="0 0 0.21062258693086316" rpy="0 0 0"/>
    <axis xyz="-0.8278270482789273 0.48945466213422706 0.2741104008476656"/>
    <dynamics damping="0.1" friction="0.1"/>
    <limit lower="-2.1282907022556143" upper="0.0" effort="100" velocity="100"/>
  </joint>
</robot>