<?xml version="1.0"?>
<robot name="evolved_robot">
  <material name="metal">
    <color rgba="0.7 0.7 0.7 1.0"/>
  </material>
  <material name="plastic">
    <color rgba="0.3 0.3 0.9 1.0"/>
  </material>
  <material name="rubber">
    <color rgba="0.1 0.1 0.1 1.0"/>
  </material>
  <material name="red">
    <color rgba="1.0 0.0 0.0 1.0"/>
  </material>
  <material name="wheel_material">
    <color rgba="0.2 0.2 0.2 1.0"/>
  </material>
  <link name="base_link">
    <visual>
      <geometry><cylinder radius="0.21648124333150892" length="0.12833373530773956"/></geometry>
      <material name="metal"/>
    </visual>
    <collision>
      <geometry><cylinder radius="0.21648124333150892" length="0.12833373530773956"/></geometry>
    </collision>
    <inertial>
      <mass value="5.0"/>
      <inertia ixx="0.13088494480092075" ixy="0" ixz="0" 
               iyy="0.13088494480092075" iyz="0" 
               izz="0.23432064357177987"/>
    </inertial>
  </link>
  <link name="link1">
    <visual>
      <geometry><box size="0.13329368958323384 0.07929365657114801 0.14729008550842207"/></geometry>
      <material name="rubber"/>
    </visual>
    <collision>
      <geometry><box size="0.13329368958323384 0.07929365657114801 0.14729008550842207"/></geometry>
    </collision>
    <inertial>
      <mass value="0.5"/>
      <inertia ixx="0.0023318211051251204" ixy="0" ixz="0" 
               iyy="0.003288464747649149" iyz="0" 
               izz="0.0020045576379278886"/>
    </inertial>
  </link>
  <joint name="joint1" type="revolute">
    <parent link="base_link"/>
    <child link="link1"/>
    <origin xyz="0 0 0.06416686765386978" rpy="0 0 0"/>
    <axis xyz="0.6363548122776973 0.7713881741349623 0.0035829730316739167"/>
    <dynamics damping="0.11404203751238937" friction="0.1"/>
    <limit lower="-1.6013271767710382" upper="2.4621390184665732" effort="100" velocity="100"/>
  </joint>
  <link name="link2">
    <visual>
      <geometry><sphere radius="0.09591109952180707"/></geometry>
      <material name="metal"/>
    </visual>
    <collision>
      <geometry><sphere radius="0.09591109952180707"/></geometry>
    </collision>
    <inertial>
      <mass value="0.5"/>
      <inertia ixx="0.003679575604592792" ixy="0" ixz="0" 
               iyy="0.003679575604592792" iyz="0" 
               izz="0.003679575604592792"/>
    </inertial>
  </link>
  <joint name="joint2" type="floating">
    <parent link="base_link"/>
    <child link="link2"/>
    <origin xyz="0 0 0.11416686765386978" rpy="0 0 0"/>
    <axis xyz="-0.3548204443899593 -0.7330347206274189 -0.5803124594540374"/>
    <dynamics damping="0.9725577042361875" friction="0.1"/>
  </joint>
  <link name="link3">
    <visual>
      <geometry><sphere radius="0.057545544923637754"/></geometry>
      <material name="plastic"/>
    </visual>
    <collision>
      <geometry><sphere radius="0.057545544923637754"/></geometry>
    </collision>
    <inertial>
      <mass value="0.5"/>
      <inertia ixx="0.0013245958962233644" ixy="0" ixz="0" 
               iyy="0.0013245958962233644" iyz="0" 
               izz="0.0013245958962233644"/>
    </inertial>
  </link>
  <joint name="joint3" type="fixed">
    <parent link="base_link"/>
    <child link="link3"/>
    <origin xyz="0 0 0.16416686765386979" rpy="0 0 0"/>
    <axis xyz="0.029203565256355837 0.904731144870546 0.4249808316589688"/>
    <dynamics damping="0.613708214320177" friction="0.1"/>
  </joint>
</robot>