<?xml version="1.0"?>
<robot name="evolved_robot">
  <material name="metal">
    <color rgba="0.7 0.7 0.7 1.0"/>
  </material>
  <material name="plastic">
    <color rgba="0.3 0.3 0.9 1.0"/>
  </material>
  <material name="rubber">
    <color rgba="0.1 0.1 0.1 1.0"/>
  </material>
  <material name="red">
    <color rgba="1.0 0.0 0.0 1.0"/>
  </material>
  <material name="wheel_material">
    <color rgba="0.2 0.2 0.2 1.0"/>
  </material>
  <link name="base_link">
    <visual>
      <geometry><box size="0.44746861283657113 0.4915286942678372 0.10917641224025697"/></geometry>
      <material name="metal"/>
    </visual>
    <collision>
      <geometry><box size="0.44746861283657113 0.4915286942678372 0.10917641224025697"/></geometry>
    </collision>
    <inertial>
      <mass value="5.0"/>
      <inertia ixx="0.21126662189858292" ixy="0" ixz="0" 
               iyy="0.17678970705294975" iyz="0" 
               izz="0.3681905139687751"/>
    </inertial>
  </link>
  <link name="link1">
    <visual>
      <geometry>
        <cylinder radius="0.0862927089160751" length="0.0514543559049874"/>
      </geometry>
      <material name="wheel_material"/>
    </visual>
    <collision>
      <geometry>
        <cylinder radius="0.0862927089160751" length="0.0514543559049874"/>
      </geometry>
    </collision>
    <inertial>
      <mass value="1.0"/>
      <inertia ixx="0.0020822371314850427" ixy="0" ixz="0" 
               iyy="0.0020822371314850427" iyz="0" 
               izz="0.0037232158060372337"/>
    </inertial>
  </link>
  <joint name="joint1" type="continuous">
    <parent link="base_link"/>
    <child link="link1"/>
    <origin xyz="0.20373430641828558 0.2457643471339186 -0.054588206120128484" rpy="1.5708 0 0"/>
    <axis xyz="0 1 0"/>
    <dynamics damping="0.7762428993012911" friction="0.1"/>
  </joint>
  <link name="link2">
    <visual>
      <geometry>
        <cylinder radius="0.08407643651479826" length="0.07410620414702414"/>
      </geometry>
      <material name="wheel_material"/>
    </visual>
    <collision>
      <geometry>
        <cylinder radius="0.08407643651479826" length="0.07410620414702414"/>
      </geometry>
    </collision>
    <inertial>
      <mass value="1.0"/>
      <inertia ixx="0.0022248559186800938" ixy="0" ixz="0" 
               iyy="0.0022248559186800938" iyz="0" 
               izz="0.0035344235885134516"/>
    </inertial>
  </link>
  <joint name="joint2" type="continuous">
    <parent link="base_link"/>
    <child link="link2"/>
    <origin xyz="-0.20373430641828558 0.2457643471339186 -0.054588206120128484" rpy="1.5708 0 0"/>
    <axis xyz="0 1 0"/>
    <dynamics damping="0.778149546484746" friction="0.1"/>
  </joint>
  <link name="link3">
    <visual>
      <geometry>
        <cylinder radius="0.09883865301051092" length="0.041259720650463134"/>
      </geometry>
      <material name="wheel_material"/>
    </visual>
    <collision>
      <geometry>
        <cylinder radius="0.09883865301051092" length="0.041259720650463134"/>
      </geometry>
    </collision>
    <inertial>
      <mass value="1.0"/>
      <inertia ixx="0.002584133544579233" ixy="0" ixz="0" 
               iyy="0.002584133544579233" iyz="0" 
               izz="0.00488453966446609"/>
    </inertial>
  </link>
  <joint name="joint3" type="continuous">
    <parent link="base_link"/>
    <child link="link3"/>
    <origin xyz="-0.20373430641828558 -0.2457643471339186 -0.054588206120128484" rpy="1.5708 0 0"/>
    <axis xyz="0 1 0"/>
    <dynamics damping="0.8575088415712022" friction="0.1"/>
  </joint>
</robot>