<?xml version="1.0"?>
<robot name="evolved_robot">
  <material name="metal">
    <color rgba="0.7 0.7 0.7 1.0"/>
  </material>
  <material name="plastic">
    <color rgba="0.3 0.3 0.9 1.0"/>
  </material>
  <material name="rubber">
    <color rgba="0.1 0.1 0.1 1.0"/>
  </material>
  <material name="red">
    <color rgba="1.0 0.0 0.0 1.0"/>
  </material>
  <material name="wheel_material">
    <color rgba="0.2 0.2 0.2 1.0"/>
  </material>
  <link name="base_link">
    <visual>
      <geometry><cylinder radius="0.15696084448586667" length="0.08057375223532857"/></geometry>
      <material name="metal"/>
    </visual>
    <collision>
      <geometry><cylinder radius="0.15696084448586667" length="0.08057375223532857"/></geometry>
    </collision>
    <inertial>
      <mass value="5.0"/>
      <inertia ixx="0.0670018747120245" ixy="0" ixz="0" 
               iyy="0.0670018747120245" iyz="0" 
               izz="0.1231835335085821"/>
    </inertial>
  </link>
  <link name="link1">
    <visual>
      <geometry><cylinder radius="0.07385908815871652" length="0.22681827617820438"/></geometry>
      <material name="rubber"/>
    </visual>
    <collision>
      <geometry><cylinder radius="0.07385908815871652" length="0.22681827617820438"/></geometry>
    </collision>
    <inertial>
      <mass value="0.5"/>
      <inertia ixx="0.0056510020932802815" ixy="0" ixz="0" 
               iyy="0.0056510020932802815" iyz="0" 
               izz="0.0027275824518185293"/>
    </inertial>
  </link>
  <joint name="joint1" type="prismatic">
    <parent link="base_link"/>
    <child link="link1"/>
    <origin xyz="0 0 0.04028687611766429" rpy="0 0 0"/>
    <axis xyz="-0.6687704300685842 -0.5496122064397928 0.5006720827031039"/>
    <dynamics damping="0.7765132943335169" friction="0.1"/>
    <limit lower="-0.7875041135189271" upper="1.2616069225743036" effort="100" velocity="100"/>
  </joint>
  <link name="link2">
    <visual>
      <geometry>
        <cylinder radius="0.06003331527035953" length="0.05858802622512754"/>
      </geometry>
      <material name="wheel_material"/>
    </visual>
    <collision>
      <geometry>
        <cylinder radius="0.06003331527035953" length="0.05858802622512754"/>
      </geometry>
    </collision>
    <inertial>
      <mass value="1.0"/>
      <inertia ixx="0.001187046137000615" ixy="0" ixz="0" 
               iyy="0.001187046137000615" iyz="0" 
               izz="0.0018019994711751914"/>
    </inertial>
  </link>
  <joint name="joint2" type="continuous">
    <parent link="base_link"/>
    <child link="link2"/>
    <origin xyz="0 0 0" rpy="1.5708 0 0"/>
    <axis xyz="0 1 0"/>
    <dynamics damping="0.6416339646955268" friction="0.1"/>
  </joint>
  <link name="link3">
    <visual>
      <geometry><cylinder radius="0.069873774119808" length="0.05002511268028795"/></geometry>
      <material name="rubber"/>
    </visual>
    <collision>
      <geometry><cylinder radius="0.069873774119808" length="0.05002511268028795"/></geometry>
    </collision>
    <inertial>
      <mass value="0.5"/>
      <inertia ixx="0.0014291287356594463" ixy="0" ixz="0" 
               iyy="0.0014291287356594463" iyz="0" 
               izz="0.002441172154872975"/>
    </inertial>
  </link>
  <joint name="joint3" type="revolute">
    <parent link="base_link"/>
    <child link="link3"/>
    <origin xyz="0 0 0.09028687611766428" rpy="0 0 0"/>
    <axis xyz="-0.4849432643344249 0.7978208495886778 -0.35820653586760864"/>
    <dynamics damping="0.8238788567566303" friction="0.1"/>
    <limit lower="-0.6651017420408223" upper="1.2169395730998822" effort="100" velocity="100"/>
  </joint>
</robot>