<?xml version="1.0"?>
<robot name="evolved_robot">
  <material name="metal">
    <color rgba="0.7 0.7 0.7 1.0"/>
  </material>
  <material name="plastic">
    <color rgba="0.3 0.3 0.9 1.0"/>
  </material>
  <material name="rubber">
    <color rgba="0.1 0.1 0.1 1.0"/>
  </material>
  <material name="red">
    <color rgba="1.0 0.0 0.0 1.0"/>
  </material>
  <material name="wheel_material">
    <color rgba="0.2 0.2 0.2 1.0"/>
  </material>
  <link name="base_link">
    <visual>
      <geometry><box size="0.34411303922620823 0.27981552353627326 0.10256335374591175"/></geometry>
      <material name="plastic"/>
    </visual>
    <collision>
      <geometry><box size="0.34411303922620823 0.27981552353627326 0.10256335374591175"/></geometry>
    </collision>
    <inertial>
      <mass value="5.0"/>
      <inertia ixx="0.07401330728623977" ixy="0" ixz="0" 
               iyy="0.10744418774758913" iyz="0" 
               izz="0.16392542581448052"/>
    </inertial>
  </link>
  <link name="link1">
    <visual>
      <geometry>
        <cylinder radius="0.051554381537950625" length="0.04828264802290038"/>
      </geometry>
      <material name="wheel_material"/>
    </visual>
    <collision>
      <geometry>
        <cylinder radius="0.051554381537950625" length="0.04828264802290038"/>
      </geometry>
    </collision>
    <inertial>
      <mass value="1.0"/>
      <inertia ixx="0.00085873140561542" ixy="0" ixz="0" 
               iyy="0.00085873140561542" iyz="0" 
               izz="0.0013289271278802922"/>
    </inertial>
  </link>
  <joint name="joint1" type="continuous">
    <parent link="base_link"/>
    <child link="link1"/>
    <origin xyz="0.15205651961310412 0.13990776176813663 -0.05128167687295587" rpy="1.5708 0 0"/>
    <axis xyz="0 0 1"/>
    <dynamics damping="0.6661406666244551" friction="0.1"/>
  </joint>
  <link name="link2">
    <visual>
      <geometry><cylinder radius="0.0729829788216498" length="0.050752840492383"/></geometry>
      <material name="rubber"/>
    </visual>
    <collision>
      <geometry><cylinder radius="0.0729829788216498" length="0.050752840492383"/></geometry>
    </collision>
    <inertial>
      <mass value="0.5"/>
      <inertia ixx="0.0015462830342574516" ixy="0" ixz="0" 
               iyy="0.0015462830342574516" iyz="0" 
               izz="0.002663257598840691"/>
    </inertial>
  </link>
  <joint name="joint2" type="revolute">
    <parent link="base_link"/>
    <child link="link2"/>
    <origin xyz="0 0 0.05128167687295587" rpy="0 0 0"/>
    <axis xyz="0.0 0.6867904345195073 -0.726855487048496"/>
    <dynamics damping="0.46869221797893834" friction="0.1"/>
    <limit lower="-1.3571484268149911" upper="1.253268333753351" effort="100" velocity="100"/>
  </joint>
  <link name="link3">
    <visual>
      <geometry>
        <cylinder radius="0.07388801847784493" length="0.07935625141699179"/>
      </geometry>
      <material name="wheel_material"/>
    </visual>
    <collision>
      <geometry>
        <cylinder radius="0.07388801847784493" length="0.07935625141699179"/>
      </geometry>
    </collision>
    <inertial>
      <mass value="1.0"/>
      <inertia ixx="0.0018896443718919896" ixy="0" ixz="0" 
               iyy="0.0018896443718919896" iyz="0" 
               izz="0.002729719637291177"/>
    </inertial>
  </link>
  <joint name="joint3" type="continuous">
    <parent link="base_link"/>
    <child link="link3"/>
    <origin xyz="-0.15205651961310412 0.13990776176813663 -0.05128167687295587" rpy="1.5708 0 0"/>
    <axis xyz="0 0 1"/>
    <dynamics damping="0.784606199382442" friction="0.1"/>
  </joint>
</robot>