<?xml version="1.0"?>
<robot name="evolved_robot">
  <material name="metal">
    <color rgba="0.7 0.7 0.7 1.0"/>
  </material>
  <material name="plastic">
    <color rgba="0.3 0.3 0.9 1.0"/>
  </material>
  <material name="rubber">
    <color rgba="0.1 0.1 0.1 1.0"/>
  </material>
  <material name="red">
    <color rgba="1.0 0.0 0.0 1.0"/>
  </material>
  <material name="wheel_material">
    <color rgba="0.2 0.2 0.2 1.0"/>
  </material>
  <link name="base_link">
    <visual>
      <geometry><cylinder radius="0.14140624607870966" length="0.08906482229332736"/></geometry>
      <material name="rubber"/>
    </visual>
    <collision>
      <geometry><cylinder radius="0.14140624607870966" length="0.08906482229332736"/></geometry>
    </collision>
    <inertial>
      <mass value="5.0"/>
      <inertia ixx="0.05659976821696646" ixy="0" ixz="0" 
               iyy="0.05659976821696646" iyz="0" 
               izz="0.09997863215036296"/>
    </inertial>
  </link>
  <link name="link1">
    <visual>
      <geometry><box size="0.12342174421978416 0.13643111657026336 0.1427863277072362"/></geometry>
      <material name="plastic"/>
    </visual>
    <collision>
      <geometry><box size="0.12342174421978416 0.13643111657026336 0.1427863277072362"/></geometry>
    </collision>
    <inertial>
      <mass value="0.5"/>
      <inertia ixx="0.0032501154123939203" ixy="0" ixz="0" 
               iyy="0.0029684051938643394" iyz="0" 
               izz="0.0028205313762385514"/>
    </inertial>
  </link>
  <joint name="joint1" type="prismatic">
    <parent link="base_link"/>
    <child link="link1"/>
    <origin xyz="0 0 0.04453241114666368" rpy="0 0 0"/>
    <axis xyz="-0.6398376731273089 -0.6238147353935081 -0.44884621860160356"/>
    <dynamics damping="0.6439134469997867" friction="0.1"/>
    <limit lower="-0.9295483361181153" upper="1.116764629231451" effort="100" velocity="100"/>
  </joint>
  <link name="link2">
    <visual>
      <geometry>
        <cylinder radius="0.0721658289576909" length="0.05085709238639688"/>
      </geometry>
      <material name="wheel_material"/>
    </visual>
    <collision>
      <geometry>
        <cylinder radius="0.0721658289576909" length="0.05085709238639688"/>
      </geometry>
    </collision>
    <inertial>
      <mass value="1.0"/>
      <inertia ixx="0.0015175137044542168" ixy="0" ixz="0" 
               iyy="0.0015175137044542168" iyz="0" 
               izz="0.0026039534345753492"/>
    </inertial>
  </link>
  <joint name="joint2" type="continuous">
    <parent link="base_link"/>
    <child link="link2"/>
    <origin xyz="0.11100288783856134 0.15180960431885798 -0.04453241114666368" rpy="1.5708 0 0"/>
    <axis xyz="0 1 0"/>
    <dynamics damping="0.6987224260398152" friction="0.1"/>
  </joint>
  <link name="link3">
    <visual>
      <geometry><box size="0.10715585173854075 0.15601743773970136 0.20291855682027354"/></geometry>
      <material name="rubber"/>
    </visual>
    <collision>
      <geometry><box size="0.10715585173854075 0.15601743773970136 0.20291855682027354"/></geometry>
    </collision>
    <inertial>
      <mass value="0.5"/>
      <inertia ixx="0.0054597817984070145" ixy="0" ixz="0" 
               iyy="0.004388193105319559" iyz="0" 
               izz="0.002985318120056143"/>
    </inertial>
  </link>
  <joint name="joint3" type="prismatic">
    <parent link="base_link"/>
    <child link="link3"/>
    <origin xyz="0 0 0.09453241114666369" rpy="0 0 0"/>
    <axis xyz="-0.2445164498077766 0.8592455832747465 -0.4493425568497177"/>
    <dynamics damping="0.7797290613230804" friction="0.1"/>
    <limit lower="-1.6464221671866734" upper="1.9731577111366114" effort="100" velocity="100"/>
  </joint>
  <link name="link4">
    <visual>
      <geometry>
        <cylinder radius="0.06185335141870561" length="0.05801654852392829"/>
      </geometry>
      <material name="wheel_material"/>
    </visual>
    <collision>
      <geometry>
        <cylinder radius="0.06185335141870561" length="0.05801654852392829"/>
      </geometry>
    </collision>
    <inertial>
      <mass value="1.0"/>
      <inertia ixx="0.0012369525956505835" ixy="0" ixz="0" 
               iyy="0.0012369525956505835" iyz="0" 
               izz="0.0019129185408629458"/>
    </inertial>
  </link>
  <joint name="joint4" type="continuous">
    <parent link="base_link"/>
    <child link="link4"/>
    <origin xyz="-0.11100288783856134 0.15180960431885798 -0.04453241114666368" rpy="1.5708 0 0"/>
    <axis xyz="0 1 0"/>
    <dynamics damping="0.7617778135493298" friction="0.1"/>
  </joint>
</robot>