<?xml version="1.0"?>
<robot name="evolved_robot">
  <material name="metal">
    <color rgba="0.7 0.7 0.7 1.0"/>
  </material>
  <material name="plastic">
    <color rgba="0.3 0.3 0.9 1.0"/>
  </material>
  <material name="rubber">
    <color rgba="0.1 0.1 0.1 1.0"/>
  </material>
  <material name="red">
    <color rgba="1.0 0.0 0.0 1.0"/>
  </material>
  <material name="wheel_material">
    <color rgba="0.2 0.2 0.2 1.0"/>
  </material>
  <link name="base_link">
    <visual>
      <geometry><cylinder radius="0.16691049582872597" length="0.12522916229259243"/></geometry>
      <material name="rubber"/>
    </visual>
    <collision>
      <geometry><cylinder radius="0.16691049582872597" length="0.12522916229259243"/></geometry>
    </collision>
    <inertial>
      <mass value="5.0"/>
      <inertia ixx="0.08271640328489825" ixy="0" ixz="0" 
               iyy="0.08271640328489825" iyz="0" 
               izz="0.13929556808895574"/>
    </inertial>
  </link>
  <link name="link1">
    <visual>
      <geometry><cylinder radius="0.09211245339088595" length="0.07593534628456418"/></geometry>
      <material name="metal"/>
    </visual>
    <collision>
      <geometry><cylinder radius="0.09211245339088595" length="0.07593534628456418"/></geometry>
    </collision>
    <inertial>
      <mass value="0.5"/>
      <inertia ixx="0.0026016907520350903" ixy="0" ixz="0" 
               iyy="0.0026016907520350903" iyz="0" 
               izz="0.004242352034844068"/>
    </inertial>
  </link>
  <joint name="joint1" type="prismatic">
    <parent link="base_link"/>
    <child link="link1"/>
    <origin xyz="0 0 0.06261458114629621" rpy="0 0 0"/>
    <axis xyz="0.01936073509213312 0.775982958042439 0.6304566684272589"/>
    <dynamics damping="0.1259254720192044" friction="0.1"/>
    <limit lower="-2.349081321379396" upper="2.7161765588283378" effort="100" velocity="100"/>
  </joint>
  <link name="link2">
    <visual>
      <geometry><box size="0.09107775807378744 0.11316454820688669 0.24986356730430942"/></geometry>
      <material name="plastic"/>
    </visual>
    <collision>
      <geometry><box size="0.09107775807378744 0.11316454820688669 0.24986356730430942"/></geometry>
    </collision>
    <inertial>
      <mass value="0.5"/>
      <inertia ixx="0.006269834769741995" ixy="0" ixz="0" 
               iyy="0.00589391335681521" iyz="0" 
               izz="0.001758447748884678"/>
    </inertial>
  </link>
  <joint name="joint2" type="floating">
    <parent link="base_link"/>
    <child link="link2"/>
    <origin xyz="0 0 0.11261458114629622" rpy="0 0 0"/>
    <axis xyz="0.27859987236654477 0.7781125276613622 0.5629591507505589"/>
    <dynamics damping="0.8738560499960275" friction="0.1"/>
  </joint>
  <link name="link3">
    <visual>
      <geometry><box size="0.14555210657132778 0.23692683161391276 0.177448172397545"/></geometry>
      <material name="plastic"/>
    </visual>
    <collision>
      <geometry><box size="0.14555210657132778 0.23692683161391276 0.177448172397545"/></geometry>
    </collision>
    <inertial>
      <mass value="0.5"/>
      <inertia ixx="0.0073018481188196855" ixy="0" ixz="0" 
               iyy="0.0043894391345483345" iyz="0" 
               izz="0.006443311605496545"/>
    </inertial>
  </link>
  <joint name="joint3" type="fixed">
    <parent link="base_link"/>
    <child link="link3"/>
    <origin xyz="0 0 0.16261458114629623" rpy="0 0 0"/>
    <axis xyz="0.42495071324914696 0.8879421209577194 0.17599909414013534"/>
    <dynamics damping="0.21045667114747402" friction="0.1"/>
  </joint>
  <link name="link4">
    <visual>
      <geometry>
        <cylinder radius="0.09365626173624765" length="0.046474526636084534"/>
      </geometry>
      <material name="wheel_material"/>
    </visual>
    <collision>
      <geometry>
        <cylinder radius="0.09365626173624765" length="0.046474526636084534"/>
      </geometry>
    </collision>
    <inertial>
      <mass value="1.0"/>
      <inertia ixx="0.0023728639761061423" ixy="0" ixz="0" 
               iyy="0.0023728639761061423" iyz="0" 
               izz="0.004385747681204263"/>
    </inertial>
  </link>
  <joint name="joint4" type="continuous">
    <parent link="base_link"/>
    <child link="link4"/>
    <origin xyz="0 0 0" rpy="1.5708 0 0"/>
    <axis xyz="0 1 0"/>
    <dynamics damping="0.5080480360255609" friction="0.1"/>
  </joint>
  <link name="link5">
    <visual>
      <geometry><box size="0.12709257113936256 0.23956601722592846 0.09456781277942478"/></geometry>
      <material name="rubber"/>
    </visual>
    <collision>
      <geometry><box size="0.12709257113936256 0.23956601722592846 0.09456781277942478"/></geometry>
    </collision>
    <inertial>
      <mass value="0.5"/>
      <inertia ixx="0.005527912318614849" ixy="0" ixz="0" 
               iyy="0.002091299404391523" iyz="0" 
               izz="0.006128699854025649"/>
    </inertial>
  </link>
  <joint name="joint5" type="prismatic">
    <parent link="base_link"/>
    <child link="link5"/>
    <origin xyz="0 0 0.21261458114629622" rpy="0 0 0"/>
    <axis xyz="0.48854453231786377 -0.6426020827629668 0.5902430034917965"/>
    <dynamics damping="0.7911030398693526" friction="0.1"/>
    <limit lower="-0.06631870370802115" upper="1.362571305234858" effort="100" velocity="100"/>
  </joint>
  <link name="link6">
    <visual>
      <geometry><cylinder radius="0.09219783476561011" length="0.1309749899245123"/></geometry>
      <material name="metal"/>
    </visual>
    <collision>
      <geometry><cylinder radius="0.09219783476561011" length="0.1309749899245123"/></geometry>
    </collision>
    <inertial>
      <mass value="0.5"/>
      <inertia ixx="0.003554647516010527" ixy="0" ixz="0" 
               iyy="0.003554647516010527" iyz="0" 
               izz="0.004250220367733372"/>
    </inertial>
  </link>
  <joint name="joint6" type="revolute">
    <parent link="base_link"/>
    <child link="link6"/>
    <origin xyz="0 0 0.2626145811462962" rpy="0 0 0"/>
    <axis xyz="0.26606172033996245 0.9474655175819661 0.17753944340026676"/>
    <dynamics damping="0.22654745826912925" friction="0.1"/>
    <limit lower="-0.41761036287403003" upper="1.7748438257456958" effort="100" velocity="100"/>
  </joint>
</robot>