<?xml version="1.0"?>
<robot name="evolved_robot">
  <material name="metal">
    <color rgba="0.7 0.7 0.7 1.0"/>
  </material>
  <material name="plastic">
    <color rgba="0.3 0.3 0.9 1.0"/>
  </material>
  <material name="rubber">
    <color rgba="0.1 0.1 0.1 1.0"/>
  </material>
  <material name="red">
    <color rgba="1.0 0.0 0.0 1.0"/>
  </material>
  <material name="wheel_material">
    <color rgba="0.2 0.2 0.2 1.0"/>
  </material>
  <link name="base_link">
    <visual>
      <geometry><box size="0.31891687218809406 0.3320667164369431 0.0881198514153188"/></geometry>
      <material name="plastic"/>
    </visual>
    <collision>
      <geometry><box size="0.31891687218809406 0.3320667164369431 0.0881198514153188"/></geometry>
    </collision>
    <inertial>
      <mass value="5.0"/>
      <inertia ixx="0.09836117698222585" ixy="0" ixz="0" 
               iyy="0.09122756631641249" iyz="0" 
               izz="0.17664689627620855"/>
    </inertial>
  </link>
  <link name="link1">
    <visual>
      <geometry>
        <cylinder radius="0.06324150669246592" length="0.04539867827197491"/>
      </geometry>
      <material name="wheel_material"/>
    </visual>
    <collision>
      <geometry>
        <cylinder radius="0.06324150669246592" length="0.04539867827197491"/>
      </geometry>
    </collision>
    <inertial>
      <mass value="1.0"/>
      <inertia ixx="0.001171625374586827" ixy="0" ixz="0" 
               iyy="0.001171625374586827" iyz="0" 
               izz="0.001999744084366606"/>
    </inertial>
  </link>
  <joint name="joint1" type="continuous">
    <parent link="base_link"/>
    <child link="link1"/>
    <origin xyz="0.13945843609404704 0.16603335821847154 -0.0440599257076594" rpy="1.5708 0 0"/>
    <axis xyz="0 0 1"/>
    <dynamics damping="0.9392346545116605" friction="0.1"/>
  </joint>
  <link name="link2">
    <visual>
      <geometry>
        <cylinder radius="0.07032401565002347" length="0.04882759219463949"/>
      </geometry>
      <material name="wheel_material"/>
    </visual>
    <collision>
      <geometry>
        <cylinder radius="0.07032401565002347" length="0.04882759219463949"/>
      </geometry>
    </collision>
    <inertial>
      <mass value="1.0"/>
      <inertia ixx="0.0014350446075800214" ixy="0" ixz="0" 
               iyy="0.0014350446075800214" iyz="0" 
               izz="0.002472733588572373"/>
    </inertial>
  </link>
  <joint name="joint2" type="continuous">
    <parent link="base_link"/>
    <child link="link2"/>
    <origin xyz="-0.13945843609404704 0.16603335821847154 -0.0440599257076594" rpy="1.5708 0 0"/>
    <axis xyz="0 0 1"/>
    <dynamics damping="0.7134914292086498" friction="0.1"/>
  </joint>
  <link name="link3">
    <visual>
      <geometry>
        <cylinder radius="0.0642425598231753" length="0.03823897410295343"/>
      </geometry>
      <material name="wheel_material"/>
    </visual>
    <collision>
      <geometry>
        <cylinder radius="0.0642425598231753" length="0.03823897410295343"/>
      </geometry>
    </collision>
    <inertial>
      <mass value="1.0"/>
      <inertia ixx="0.0011536282181957595" ixy="0" ixz="0" 
               iyy="0.0011536282181957595" iyz="0" 
               izz="0.0020635532463171282"/>
    </inertial>
  </link>
  <joint name="joint3" type="continuous">
    <parent link="base_link"/>
    <child link="link3"/>
    <origin xyz="-0.13945843609404704 -0.16603335821847154 -0.0440599257076594" rpy="1.5708 0 0"/>
    <axis xyz="0 0 1"/>
    <dynamics damping="0.6988423824039728" friction="0.1"/>
  </joint>
</robot>