<?xml version="1.0"?>
<robot name="evolved_robot">
  <material name="metal">
    <color rgba="0.7 0.7 0.7 1.0"/>
  </material>
  <material name="plastic">
    <color rgba="0.3 0.3 0.9 1.0"/>
  </material>
  <material name="rubber">
    <color rgba="0.1 0.1 0.1 1.0"/>
  </material>
  <material name="red">
    <color rgba="1.0 0.0 0.0 1.0"/>
  </material>
  <material name="wheel_material">
    <color rgba="0.2 0.2 0.2 1.0"/>
  </material>
  <link name="base_link">
    <visual>
      <geometry><box size="0.3500066648644581 0.2867757265282742 0.10696531036507993"/></geometry>
      <material name="metal"/>
    </visual>
    <collision>
      <geometry><box size="0.3500066648644581 0.2867757265282742 0.10696531036507993"/></geometry>
    </collision>
    <inertial>
      <mass value="5.0"/>
      <inertia ixx="0.07806824578943115" ixy="0" ixz="0" 
               iyy="0.11162186922586581" iyz="0" 
               izz="0.17062081897946715"/>
    </inertial>
  </link>
  <link name="link1">
    <visual>
      <geometry><sphere radius="0.038968192844657516"/></geometry>
      <material name="rubber"/>
    </visual>
    <collision>
      <geometry><sphere radius="0.038968192844657516"/></geometry>
    </collision>
    <inertial>
      <mass value="0.5"/>
      <inertia ixx="0.0006074080214313669" ixy="0" ixz="0" 
               iyy="0.0006074080214313669" iyz="0" 
               izz="0.0006074080214313669"/>
    </inertial>
  </link>
  <joint name="joint1" type="revolute">
    <parent link="base_link"/>
    <child link="link1"/>
    <origin xyz="0 0 0.053482655182539966" rpy="0 0 0"/>
    <axis xyz="0.6209072305563619 -0.706112610599677 -0.3404103291542989"/>
    <dynamics damping="0.7907198547146193" friction="0.1"/>
    <limit lower="-1.0519210964026422" upper="1.4084694643140252" effort="100" velocity="100"/>
  </joint>
  <link name="link2">
    <visual>
      <geometry>
        <cylinder radius="0.06309177534795424" length="0.058541667971812816"/>
      </geometry>
      <material name="wheel_material"/>
    </visual>
    <collision>
      <geometry>
        <cylinder radius="0.06309177534795424" length="0.058541667971812816"/>
      </geometry>
    </collision>
    <inertial>
      <mass value="1.0"/>
      <inertia ixx="0.001280736936549346" ixy="0" ixz="0" 
               iyy="0.001280736936549346" iyz="0" 
               izz="0.001990286058278363"/>
    </inertial>
  </link>
  <joint name="joint2" type="continuous">
    <parent link="base_link"/>
    <child link="link2"/>
    <origin xyz="0.15500333243222905 0.1433878632641371 -0.053482655182539966" rpy="1.5708 0 0"/>
    <axis xyz="0 1 0"/>
    <dynamics damping="0.6247021823949106" friction="0.1"/>
  </joint>
  <link name="link3">
    <visual>
      <geometry>
        <cylinder radius="0.05097653602202047" length="0.06395966676517956"/>
      </geometry>
      <material name="wheel_material"/>
    </visual>
    <collision>
      <geometry>
        <cylinder radius="0.05097653602202047" length="0.06395966676517956"/>
      </geometry>
    </collision>
    <inertial>
      <mass value="1.0"/>
      <inertia ixx="0.0009905550539271554" ixy="0" ixz="0" 
               iyy="0.0009905550539271554" iyz="0" 
               izz="0.0012993036124021753"/>
    </inertial>
  </link>
  <joint name="joint3" type="floating">
    <parent link="base_link"/>
    <child link="link3"/>
    <origin xyz="-0.15500333243222905 0.1433878632641371 -0.053482655182539966" rpy="1.5708 0 0"/>
    <axis xyz="0 1 0"/>
    <dynamics damping="0.9386368848209998" friction="0.1"/>
  </joint>
</robot>