<?xml version="1.0"?>
<robot name="evolved_robot">
  <material name="metal">
    <color rgba="0.7 0.7 0.7 1.0"/>
  </material>
  <material name="plastic">
    <color rgba="0.3 0.3 0.9 1.0"/>
  </material>
  <material name="rubber">
    <color rgba="0.1 0.1 0.1 1.0"/>
  </material>
  <material name="red">
    <color rgba="1.0 0.0 0.0 1.0"/>
  </material>
  <material name="wheel_material">
    <color rgba="0.2 0.2 0.2 1.0"/>
  </material>
  <link name="base_link">
    <visual>
      <geometry><box size="0.331214373255463 0.3792780450720862 0.07219952226686528"/></geometry>
      <material name="rubber"/>
    </visual>
    <collision>
      <geometry><box size="0.331214373255463 0.3792780450720862 0.07219952226686528"/></geometry>
    </collision>
    <inertial>
      <mass value="5.0"/>
      <inertia ixx="0.1242205054077225" ixy="0" ixz="0" 
               iyy="0.09576311005547727" iyz="0" 
               izz="0.21129566377059383"/>
    </inertial>
  </link>
  <link name="link1">
    <visual>
      <geometry><sphere radius="0.08547162820621959"/></geometry>
      <material name="plastic"/>
    </visual>
    <collision>
      <geometry><sphere radius="0.08547162820621959"/></geometry>
    </collision>
    <inertial>
      <mass value="0.5"/>
      <inertia ixx="0.002922159691288893" ixy="0" ixz="0" 
               iyy="0.002922159691288893" iyz="0" 
               izz="0.002922159691288893"/>
    </inertial>
  </link>
  <joint name="joint1" type="revolute">
    <parent link="base_link"/>
    <child link="link1"/>
    <origin xyz="0 0 0.03609976113343264" rpy="0 0 0"/>
    <axis xyz="-0.5267367742547657 -0.7517710228777881 0.3967224468176312"/>
    <dynamics damping="0.8212211505894433" friction="0.1"/>
    <limit lower="-0.715922973925807" upper="1.4960121739306087" effort="100" velocity="100"/>
  </joint>
  <link name="link2">
    <visual>
      <geometry>
        <cylinder radius="0.07120746322080293" length="0.0504971617062694"/>
      </geometry>
      <material name="wheel_material"/>
    </visual>
    <collision>
      <geometry>
        <cylinder radius="0.07120746322080293" length="0.0504971617062694"/>
      </geometry>
    </collision>
    <inertial>
      <mass value="1.0"/>
      <inertia ixx="0.0014801226496179273" ixy="0" ixz="0" 
               iyy="0.0014801226496179273" iyz="0" 
               izz="0.002535251409171001"/>
    </inertial>
  </link>
  <joint name="joint2" type="continuous">
    <parent link="base_link"/>
    <child link="link2"/>
    <origin xyz="0.1456071866277315 0.1896390225360431 -0.03609976113343264" rpy="1.5708 0 0"/>
    <axis xyz="0 1 0"/>
    <dynamics damping="0.9294504808875538" friction="0.1"/>
  </joint>
  <link name="link3">
    <visual>
      <geometry>
        <cylinder radius="0.07202321520114786" length="0.04571595030227395"/>
      </geometry>
      <material name="wheel_material"/>
    </visual>
    <collision>
      <geometry>
        <cylinder radius="0.07202321520114786" length="0.04571595030227395"/>
      </geometry>
    </collision>
    <inertial>
      <mass value="1.0"/>
      <inertia ixx="0.0014709982246477126" ixy="0" ixz="0" 
               iyy="0.0014709982246477126" iyz="0" 
               izz="0.0025936717639554285"/>
    </inertial>
  </link>
  <joint name="joint3" type="continuous">
    <parent link="base_link"/>
    <child link="link3"/>
    <origin xyz="-0.1456071866277315 0.1896390225360431 -0.03609976113343264" rpy="1.5708 0 0"/>
    <axis xyz="0 1 0"/>
    <dynamics damping="0.47926926660158287" friction="0.1"/>
  </joint>
</robot>