<?xml version="1.0"?>
<robot name="evolved_robot">
  <material name="metal">
    <color rgba="0.7 0.7 0.7 1.0"/>
  </material>
  <material name="plastic">
    <color rgba="0.3 0.3 0.9 1.0"/>
  </material>
  <material name="rubber">
    <color rgba="0.1 0.1 0.1 1.0"/>
  </material>
  <material name="red">
    <color rgba="1.0 0.0 0.0 1.0"/>
  </material>
  <material name="wheel_material">
    <color rgba="0.2 0.2 0.2 1.0"/>
  </material>
  <link name="base_link">
    <visual>
      <geometry><cylinder radius="0.16317729007139792" length="0.10747272156087857"/></geometry>
      <material name="metal"/>
    </visual>
    <collision>
      <geometry><cylinder radius="0.16317729007139792" length="0.10747272156087857"/></geometry>
    </collision>
    <inertial>
      <mass value="5.0"/>
      <inertia ixx="0.0761923915540313" ixy="0" ixz="0" 
               iyy="0.0761923915540313" iyz="0" 
               izz="0.1331341399752257"/>
    </inertial>
  </link>
  <link name="link1">
    <visual>
      <geometry><box size="0.10859280114039115 0.14967259158414847 0.13188925897552822"/></geometry>
      <material name="plastic"/>
    </visual>
    <collision>
      <geometry><box size="0.10859280114039115 0.14967259158414847 0.13188925897552822"/></geometry>
    </collision>
    <inertial>
      <mass value="0.5"/>
      <inertia ixx="0.0033163884420524385" ixy="0" ixz="0" 
               iyy="0.002432264424385874" iyz="0" 
               izz="0.002849523427585987"/>
    </inertial>
  </link>
  <joint name="joint1" type="revolute">
    <parent link="base_link"/>
    <child link="link1"/>
    <origin xyz="0 0 0.053736360780439286" rpy="0 0 0"/>
    <axis xyz="0.7087981219200725 0.38843262319564936 -0.5888338641755624"/>
    <dynamics damping="0.7919740599906379" friction="0.1"/>
    <limit lower="-1.6862155992679089" upper="1.099" effort="100" velocity="100"/>
  </joint>
  <link name="link2">
    <visual>
      <geometry><box size="0.06961514125302956 0.15089216763229235 0.1892245950092839"/></geometry>
      <material name="metal"/>
    </visual>
    <collision>
      <geometry><box size="0.06961514125302956 0.15089216763229235 0.1892245950092839"/></geometry>
    </collision>
    <inertial>
      <mass value="0.5"/>
      <inertia ixx="0.004881199467433277" ixy="0" ixz="0" 
               iyy="0.0033876846040088973" iyz="0" 
               izz="0.0023012261787042562"/>
    </inertial>
  </link>
  <joint name="joint2" type="revolute">
    <parent link="base_link"/>
    <child link="link2"/>
    <origin xyz="0 0 0.1037363607804393" rpy="0 0 0"/>
    <axis xyz="0.13005132187939997 0.990658626376977 -0.04101389596590046"/>
    <dynamics damping="0.7292250985731518" friction="0.1"/>
    <limit lower="-2.414115064041525" upper="0.3125473263987225" effort="100" velocity="100"/>
  </joint>
  <link name="link3">
    <visual>
      <geometry>
        <cylinder radius="0.06431311350259628" length="0.061136476487885186"/>
      </geometry>
      <material name="wheel_material"/>
    </visual>
    <collision>
      <geometry>
        <cylinder radius="0.06431311350259628" length="0.061136476487885186"/>
      </geometry>
    </collision>
    <inertial>
      <mass value="1.0"/>
      <inertia ixx="0.0013455165385456028" ixy="0" ixz="0" 
               iyy="0.0013455165385456028" iyz="0" 
               izz="0.0020680882841989157"/>
    </inertial>
  </link>
  <joint name="joint3" type="fixed">
    <parent link="base_link"/>
    <child link="link3"/>
    <origin xyz="0.1549984896757121 0.15135609046708376 -0.053736360780439286" rpy="1.5708 0 0"/>
    <axis xyz="0 1 0"/>
    <dynamics damping="0.5898181450742151" friction="0.1"/>
  </joint>
  <link name="link4">
    <visual>
      <geometry>
        <cylinder radius="0.0639880196653492" length="0.057628641242894116"/>
      </geometry>
      <material name="wheel_material"/>
    </visual>
    <collision>
      <geometry>
        <cylinder radius="0.0639880196653492" length="0.057628641242894116"/>
      </geometry>
    </collision>
    <inertial>
      <mass value="1.0"/>
      <inertia ixx="0.001300371689465129" ixy="0" ixz="0" 
               iyy="0.001300371689465129" iyz="0" 
               izz="0.002047233330346558"/>
    </inertial>
  </link>
  <joint name="joint4" type="continuous">
    <parent link="base_link"/>
    <child link="link4"/>
    <origin xyz="-0.1549984896757121 0.15135609046708376 -0.053736360780439286" rpy="1.5708 0 0"/>
    <axis xyz="0 1 0"/>
    <dynamics damping="0.7620209808535042" friction="0.1"/>
  </joint>
</robot>