<?xml version="1.0"?>
<robot name="evolved_robot">
  <material name="metal">
    <color rgba="0.7 0.7 0.7 1.0"/>
  </material>
  <material name="plastic">
    <color rgba="0.3 0.3 0.9 1.0"/>
  </material>
  <material name="rubber">
    <color rgba="0.1 0.1 0.1 1.0"/>
  </material>
  <material name="red">
    <color rgba="1.0 0.0 0.0 1.0"/>
  </material>
  <material name="wheel_material">
    <color rgba="0.2 0.2 0.2 1.0"/>
  </material>
  <link name="base_link">
    <visual>
      <geometry><sphere radius="0.11942848091650647"/></geometry>
      <material name="metal"/>
    </visual>
    <collision>
      <geometry><sphere radius="0.11942848091650647"/></geometry>
    </collision>
    <inertial>
      <mass value="5.0"/>
      <inertia ixx="0.0570526482160974" ixy="0" ixz="0" 
               iyy="0.0570526482160974" iyz="0" 
               izz="0.0570526482160974"/>
    </inertial>
  </link>
  <link name="link1">
    <visual>
      <geometry><cylinder radius="0.06919833656878091" length="0.19527266366108598"/></geometry>
      <material name="plastic"/>
    </visual>
    <collision>
      <geometry><cylinder radius="0.06919833656878091" length="0.19527266366108598"/></geometry>
    </collision>
    <inertial>
      <mass value="0.5"/>
      <inertia ixx="0.004374720210412871" ixy="0" ixz="0" 
               iyy="0.004374720210412871" iyz="0" 
               izz="0.002394204891943141"/>
    </inertial>
  </link>
  <joint name="joint1" type="floating">
    <parent link="base_link"/>
    <child link="link1"/>
    <origin xyz="0 0 0.06399612305471086" rpy="0 0 0"/>
    <axis xyz="0.06270219806951452 -0.307856244168261 0.9493645070697889"/>
    <dynamics damping="0.5331897106704347" friction="0.1"/>
  </joint>
  <link name="link2">
    <visual>
      <geometry><box size="0.12194952527116427 0.12146275649110785 0.09757899011843829"/></geometry>
      <material name="rubber"/>
    </visual>
    <collision>
      <geometry><box size="0.12194952527116427 0.12146275649110785 0.09757899011843829"/></geometry>
    </collision>
    <inertial>
      <mass value="0.5"/>
      <inertia ixx="0.0020229050439127035" ixy="0" ixz="0" 
               iyy="0.002032778835533051" iyz="0" 
               izz="0.0024687406606900414"/>
    </inertial>
  </link>
  <joint name="joint2" type="fixed">
    <parent link="base_link"/>
    <child link="link2"/>
    <origin xyz="0 0 0.11399612305471087" rpy="0 0 0"/>
    <axis xyz="0.7081003527551595 0.29546484055695876 0.6413223981919468"/>
    <dynamics damping="0.32217045040889225" friction="0.1"/>
  </joint>
  <link name="link3">
    <visual>
      <geometry><box size="0.19457475484833625 0.23927656319806395 0.1332925256875949"/></geometry>
      <material name="plastic"/>
    </visual>
    <collision>
      <geometry><box size="0.19457475484833625 0.23927656319806395 0.1332925256875949"/></geometry>
    </collision>
    <inertial>
      <mass value="0.5"/>
      <inertia ixx="0.006251680925004603" ixy="0" ixz="0" 
               iyy="0.004635519385705692" iyz="0" 
               izz="0.00792605074334727"/>
    </inertial>
  </link>
  <joint name="joint3" type="prismatic">
    <parent link="base_link"/>
    <child link="link3"/>
    <origin xyz="0 0 0.16399612305471087" rpy="0 0 0"/>
    <axis xyz="0.011830205973934867 0.7886813723134403 -0.6146883268717593"/>
    <dynamics damping="0.4117828208540274" friction="0.1"/>
    <limit lower="-2.8122618119626765" upper="1.692826469859871" effort="100" velocity="100"/>
  </joint>
  <link name="link4">
    <visual>
      <geometry><cylinder radius="0.07203057745592678" length="0.18469304526155383"/></geometry>
      <material name="rubber"/>
    </visual>
    <collision>
      <geometry><cylinder radius="0.07203057745592678" length="0.18469304526155383"/></geometry>
    </collision>
    <inertial>
      <mass value="0.5"/>
      <inertia ixx="0.004139727769490765" ixy="0" ixz="0" 
               iyy="0.004139727769490765" iyz="0" 
               izz="0.0025942020443171336"/>
    </inertial>
  </link>
  <joint name="joint4" type="prismatic">
    <parent link="base_link"/>
    <child link="link4"/>
    <origin xyz="0 0 0.21399612305471089" rpy="0 0 0"/>
    <axis xyz="-0.3806274694824718 -0.12688074684190223 0.9159825356174709"/>
    <dynamics damping="0.2888799852650854" friction="0.1"/>
    <limit lower="-1.4471671154645713" upper="3.1176989047034307" effort="100" velocity="100"/>
  </joint>
</robot>