<?xml version="1.0"?>
<robot name="evolved_robot">
  <material name="metal">
    <color rgba="0.7 0.7 0.7 1.0"/>
  </material>
  <material name="plastic">
    <color rgba="0.3 0.3 0.9 1.0"/>
  </material>
  <material name="rubber">
    <color rgba="0.1 0.1 0.1 1.0"/>
  </material>
  <material name="red">
    <color rgba="1.0 0.0 0.0 1.0"/>
  </material>
  <material name="wheel_material">
    <color rgba="0.2 0.2 0.2 1.0"/>
  </material>
  <link name="base_link">
    <visual>
      <geometry><sphere radius="0.11184482731263425"/></geometry>
      <material name="metal"/>
    </visual>
    <collision>
      <geometry><sphere radius="0.11184482731263425"/></geometry>
    </collision>
    <inertial>
      <mass value="5.0"/>
      <inertia ixx="0.0500370615863719" ixy="0" ixz="0" 
               iyy="0.0500370615863719" iyz="0" 
               izz="0.0500370615863719"/>
    </inertial>
  </link>
  <link name="link1">
    <visual>
      <geometry><cylinder radius="0.058852211180721245" length="0.14013211551273075"/></geometry>
      <material name="metal"/>
    </visual>
    <collision>
      <geometry><cylinder radius="0.058852211180721245" length="0.14013211551273075"/></geometry>
    </collision>
    <inertial>
      <mass value="0.5"/>
      <inertia ixx="0.0025023131733878288" ixy="0" ixz="0" 
               iyy="0.0025023131733878288" iyz="0" 
               izz="0.0017317913804301053"/>
    </inertial>
  </link>
  <joint name="joint1" type="prismatic">
    <parent link="base_link"/>
    <child link="link1"/>
    <origin xyz="0 0 0.040923881314346724" rpy="0 0 0"/>
    <axis xyz="0.6366138779369415 0.7699174097081446 0.044158268154332776"/>
    <dynamics damping="0.8607549115547044" friction="0.1"/>
    <limit lower="-1.482553113149272" upper="1.099" effort="100" velocity="100"/>
  </joint>
  <link name="link2">
    <visual>
      <geometry><cylinder radius="0.04493365824800573" length="0.15561033324587772"/></geometry>
      <material name="metal"/>
    </visual>
    <collision>
      <geometry><cylinder radius="0.04493365824800573" length="0.15561033324587772"/></geometry>
    </collision>
    <inertial>
      <mass value="0.5"/>
      <inertia ixx="0.0025226397286282364" ixy="0" ixz="0" 
               iyy="0.0025226397286282364" iyz="0" 
               izz="0.0010095168217742867"/>
    </inertial>
  </link>
  <joint name="joint2" type="revolute">
    <parent link="base_link"/>
    <child link="link2"/>
    <origin xyz="0 0 0.09092388131434673" rpy="0 0 0"/>
    <axis xyz="0.18339425658293437 0.7189674175317938 -0.6704121114509015"/>
    <dynamics damping="0.9327619503618296" friction="0.1"/>
    <limit lower="-0.9871077502605163" upper="1.132826093782976" effort="100" velocity="100"/>
  </joint>
  <link name="link3">
    <visual>
      <geometry><cylinder radius="0.05278646614073556" length="0.0822543906844797"/></geometry>
      <material name="plastic"/>
    </visual>
    <collision>
      <geometry><cylinder radius="0.05278646614073556" length="0.0822543906844797"/></geometry>
    </collision>
    <inertial>
      <mass value="0.5"/>
      <inertia ixx="0.0012604181508130074" ixy="0" ixz="0" 
               iyy="0.0012604181508130074" iyz="0" 
               izz="0.0013932055038135109"/>
    </inertial>
  </link>
  <joint name="joint3" type="revolute">
    <parent link="base_link"/>
    <child link="link3"/>
    <origin xyz="0 0 0.14092388131434674" rpy="0 0 0"/>
    <axis xyz="-0.5280588768682761 -0.5007090932902436 -0.685889368963448"/>
    <dynamics damping="0.9668446123790886" friction="0.1"/>
    <limit lower="-1.926969598478305" upper="0.31400000000000006" effort="100" velocity="100"/>
  </joint>
  <link name="link4">
    <visual>
      <geometry><cylinder radius="0.0561231846897353" length="0.15537972062271466"/></geometry>
      <material name="plastic"/>
    </visual>
    <collision>
      <geometry><cylinder radius="0.0561231846897353" length="0.15537972062271466"/></geometry>
    </collision>
    <inertial>
      <mass value="0.5"/>
      <inertia ixx="0.0027993577633289393" ixy="0" ixz="0" 
               iyy="0.0027993577633289393" iyz="0" 
               izz="0.0015749059298590697"/>
    </inertial>
  </link>
  <joint name="joint4" type="fixed">
    <parent link="base_link"/>
    <child link="link4"/>
    <origin xyz="0 0 0.19092388131434673" rpy="0 0 0"/>
    <axis xyz="-0.7990659587814878 -0.4390437446744402 0.41077266678646784"/>
    <dynamics damping="0.8729175469781931" friction="0.1"/>
  </joint>
  <link name="link5">
    <visual>
      <geometry>
        <cylinder radius="0.08119085705597621" length="0.03379608087213135"/>
      </geometry>
      <material name="wheel_material"/>
    </visual>
    <collision>
      <geometry>
        <cylinder radius="0.08119085705597621" length="0.03379608087213135"/>
      </geometry>
    </collision>
    <inertial>
      <mass value="1.0"/>
      <inertia ixx="0.0017431700742306276" ixy="0" ixz="0" 
               iyy="0.0017431700742306276" iyz="0" 
               izz="0.0032959776347419815"/>
    </inertial>
  </link>
  <joint name="joint5" type="continuous">
    <parent link="base_link"/>
    <child link="link5"/>
    <origin xyz="0 0 0" rpy="1.5708 0 0"/>
    <axis xyz="0 1 0"/>
    <dynamics damping="0.24513226797700774" friction="0.1"/>
  </joint>
  <link name="link6">
    <visual>
      <geometry><cylinder radius="0.036225027524409564" length="0.07634401187696929"/></geometry>
      <material name="metal"/>
    </visual>
    <collision>
      <geometry><cylinder radius="0.036225027524409564" length="0.07634401187696929"/></geometry>
    </collision>
    <inertial>
      <mass value="0.5"/>
      <inertia ixx="0.0008137638339086266" ixy="0" ixz="0" 
               iyy="0.0008137638339086266" iyz="0" 
               izz="0.0006561263095721153"/>
    </inertial>
  </link>
  <joint name="joint6" type="revolute">
    <parent link="base_link"/>
    <child link="link6"/>
    <origin xyz="0 0 0.24092388131434672" rpy="0 0 0"/>
    <axis xyz="-0.5467454852843303 0.3549565086859571 0.7583371619950311"/>
    <dynamics damping="0.9328317076675361" friction="0.1"/>
    <limit lower="-1.0303942892624502" upper="0.31400000000000006" effort="100" velocity="100"/>
  </joint>
</robot>