<?xml version="1.0"?>
<robot name="evolved_robot">
  <material name="metal">
    <color rgba="0.7 0.7 0.7 1.0"/>
  </material>
  <material name="plastic">
    <color rgba="0.3 0.3 0.9 1.0"/>
  </material>
  <material name="rubber">
    <color rgba="0.1 0.1 0.1 1.0"/>
  </material>
  <material name="red">
    <color rgba="1.0 0.0 0.0 1.0"/>
  </material>
  <material name="wheel_material">
    <color rgba="0.2 0.2 0.2 1.0"/>
  </material>
  <link name="base_link">
    <visual>
      <geometry><cylinder radius="0.11914373872814613" length="0.1222400662433975"/></geometry>
      <material name="metal"/>
    </visual>
    <collision>
      <geometry><cylinder radius="0.11914373872814613" length="0.1222400662433975"/></geometry>
    </collision>
    <inertial>
      <mass value="5.0"/>
      <inertia ixx="0.047940271024627036" ixy="0" ixz="0" 
               iyy="0.047940271024627036" iyz="0" 
               izz="0.07097615239060373"/>
    </inertial>
  </link>
  <link name="link1">
    <visual>
      <geometry><box size="0.18096636305530917 0.1505596901425931 0.13188925897552822"/></geometry>
      <material name="plastic"/>
    </visual>
    <collision>
      <geometry><box size="0.18096636305530917 0.1505596901425931 0.13188925897552822"/></geometry>
    </collision>
    <inertial>
      <mass value="0.5"/>
      <inertia ixx="0.0033385830774122997" ixy="0" ixz="0" 
               iyy="0.004178633432548326" iyz="0" 
               izz="0.0046180870711083006"/>
    </inertial>
  </link>
  <joint name="joint1" type="revolute">
    <parent link="base_link"/>
    <child link="link1"/>
    <origin xyz="0 0 0.06112003312169875" rpy="0 0 0"/>
    <axis xyz="0.9166748237849409 0.2111673642041393 -0.33928691653808846"/>
    <dynamics damping="0.7359971814790645" friction="0.1"/>
    <limit lower="-1.6878129517187643" upper="1.099" effort="100" velocity="100"/>
  </joint>
  <link name="link2">
    <visual>
      <geometry><box size="0.07242867081383741 0.11224938386190869 0.18783796745459674"/></geometry>
      <material name="rubber"/>
    </visual>
    <collision>
      <geometry><box size="0.07242867081383741 0.11224938386190869 0.18783796745459674"/></geometry>
    </collision>
    <inertial>
      <mass value="0.5"/>
      <inertia ixx="0.003990252182904355" ixy="0" ixz="0" 
               iyy="0.003377417864444447" iyz="0" 
               izz="0.0014871530444364462"/>
    </inertial>
  </link>
  <joint name="joint2" type="revolute">
    <parent link="base_link"/>
    <child link="link2"/>
    <origin xyz="0 0 0.11112003312169876" rpy="0 0 0"/>
    <axis xyz="0.19824972475011976 -0.34577405933792277 0.9171354025036197"/>
    <dynamics damping="0.7292250985731518" friction="0.1"/>
    <limit lower="-2.414115064041525" upper="0.31400000000000006" effort="100" velocity="100"/>
  </joint>
  <link name="link3">
    <visual>
      <geometry><cylinder radius="0.053343358383716066" length="0.20467690805826394"/></geometry>
      <material name="metal"/>
    </visual>
    <collision>
      <geometry><cylinder radius="0.053343358383716066" length="0.20467690805826394"/></geometry>
    </collision>
    <inertial>
      <mass value="0.5"/>
      <inertia ixx="0.004202431528604312" ixy="0" ixz="0" 
               iyy="0.004202431528604312" iyz="0" 
               izz="0.0014227569418267855"/>
    </inertial>
  </link>
  <joint name="joint3" type="fixed">
    <parent link="base_link"/>
    <child link="link3"/>
    <origin xyz="0 0 0.16112003312169876" rpy="0 0 0"/>
    <axis xyz="-0.22006502906516345 0.8806745142696449 -0.4195042108232927"/>
    <dynamics damping="0.757853448114933" friction="0.1"/>
  </joint>
  <link name="link4">
    <visual>
      <geometry>
        <cylinder radius="0.06204820854501594" length="0.054982276945663475"/>
      </geometry>
      <material name="wheel_material"/>
    </visual>
    <collision>
      <geometry>
        <cylinder radius="0.06204820854501594" length="0.054982276945663475"/>
      </geometry>
    </collision>
    <inertial>
      <mass value="1.0"/>
      <inertia ixx="0.0012144159440889172" ixy="0" ixz="0" 
               iyy="0.0012144159440889172" iyz="0" 
               izz="0.0019249900918228947"/>
    </inertial>
  </link>
  <joint name="joint4" type="continuous">
    <parent link="base_link"/>
    <child link="link4"/>
    <origin xyz="0 0 0" rpy="1.5708 0 0"/>
    <axis xyz="0 1 0"/>
    <dynamics damping="0.7586822519868953" friction="0.1"/>
  </joint>
</robot>