<?xml version="1.0"?>
<robot name="evolved_robot">
  <material name="metal">
    <color rgba="0.7 0.7 0.7 1.0"/>
  </material>
  <material name="plastic">
    <color rgba="0.3 0.3 0.9 1.0"/>
  </material>
  <material name="rubber">
    <color rgba="0.1 0.1 0.1 1.0"/>
  </material>
  <material name="red">
    <color rgba="1.0 0.0 0.0 1.0"/>
  </material>
  <material name="wheel_material">
    <color rgba="0.2 0.2 0.2 1.0"/>
  </material>
  <link name="base_link">
    <visual>
      <geometry><box size="0.31971039084063424 0.30339100369254823 0.08068832829829782"/></geometry>
      <material name="metal"/>
    </visual>
    <collision>
      <geometry><box size="0.31971039084063424 0.30339100369254823 0.08068832829829782"/></geometry>
    </collision>
    <inertial>
      <mass value="5.0"/>
      <inertia ixx="0.08213058953762142" ixy="0" ixz="0" 
               iyy="0.09060445027920416" iyz="0" 
               izz="0.16188402927753578"/>
    </inertial>
  </link>
  <link name="link1">
    <visual>
      <geometry><cylinder radius="0.0760733366416902" length="0.14081779537643838"/></geometry>
      <material name="rubber"/>
    </visual>
    <collision>
      <geometry><cylinder radius="0.0760733366416902" length="0.14081779537643838"/></geometry>
    </collision>
    <inertial>
      <mass value="0.5"/>
      <inertia ixx="0.00309925909484002" ixy="0" ixz="0" 
               iyy="0.00309925909484002" iyz="0" 
               izz="0.0028935762738999627"/>
    </inertial>
  </link>
  <joint name="joint1" type="revolute">
    <parent link="base_link"/>
    <child link="link1"/>
    <origin xyz="0 0 0.04034416414914891" rpy="0 0 0"/>
    <axis xyz="-0.7854588657445142 -0.3565487144176985 0.5058926610165715"/>
    <dynamics damping="0.7728480284695484" friction="0.1"/>
    <limit lower="-2.146331162029103" upper="1.2717079639294546" effort="100" velocity="100"/>
  </joint>
  <link name="link2">
    <visual>
      <geometry>
        <cylinder radius="0.06322985314573629" length="0.05091720566736713"/>
      </geometry>
      <material name="wheel_material"/>
    </visual>
    <collision>
      <geometry>
        <cylinder radius="0.06322985314573629" length="0.05091720566736713"/>
      </geometry>
    </collision>
    <inertial>
      <mass value="1.0"/>
      <inertia ixx="0.001215550401622258" ixy="0" ixz="0" 
               iyy="0.001215550401622258" iyz="0" 
               izz="0.0019990071644156887"/>
    </inertial>
  </link>
  <joint name="joint2" type="continuous">
    <parent link="base_link"/>
    <child link="link2"/>
    <origin xyz="0.13985519542031713 0.15169550184627412 -0.04034416414914891" rpy="1.5708 0 0"/>
    <axis xyz="0 1 0"/>
    <dynamics damping="0.6237323492205411" friction="0.1"/>
  </joint>
  <link name="link3">
    <visual>
      <geometry><box size="0.11700741769070341 0.1357253377311918 0.051297581895815625"/></geometry>
      <material name="plastic"/>
    </visual>
    <collision>
      <geometry><box size="0.11700741769070341 0.1357253377311918 0.051297581895815625"/></geometry>
    </collision>
    <inertial>
      <mass value="0.5"/>
      <inertia ixx="0.0017544007675503322" ixy="0" ixz="0" 
               iyy="0.001360181475250387" iyz="0" 
               izz="0.002676008591407734"/>
    </inertial>
  </link>
  <joint name="joint3" type="prismatic">
    <parent link="base_link"/>
    <child link="link3"/>
    <origin xyz="0 0 0.09034416414914892" rpy="0 0 0"/>
    <axis xyz="0.19374155992245015 0.8413395049450949 -0.5045909683868293"/>
    <dynamics damping="0.8242507383232369" friction="0.1"/>
    <limit lower="-0.7410082810901961" upper="1.2169395730998822" effort="100" velocity="100"/>
  </joint>
  <link name="link4">
    <visual>
      <geometry>
        <cylinder radius="0.07741305339524476" length="0.053381387694305824"/>
      </geometry>
      <material name="wheel_material"/>
    </visual>
    <collision>
      <geometry>
        <cylinder radius="0.07741305339524476" length="0.053381387694305824"/>
      </geometry>
    </collision>
    <inertial>
      <mass value="1.0"/>
      <inertia ixx="0.0017356595883412365" ixy="0" ixz="0" 
               iyy="0.0017356595883412365" iyz="0" 
               izz="0.0029963904179875086"/>
    </inertial>
  </link>
  <joint name="joint4" type="continuous">
    <parent link="base_link"/>
    <child link="link4"/>
    <origin xyz="0.13985519542031713 -0.15169550184627412 -0.04034416414914891" rpy="1.5708 0 0"/>
    <axis xyz="0 1 0"/>
    <dynamics damping="0.44569916604228654" friction="0.1"/>
  </joint>
  <link name="link5">
    <visual>
      <geometry>
        <cylinder radius="0.07342839007796728" length="0.04564237764543373"/>
      </geometry>
      <material name="wheel_material"/>
    </visual>
    <collision>
      <geometry>
        <cylinder radius="0.07342839007796728" length="0.04564237764543373"/>
      </geometry>
    </collision>
    <inertial>
      <mass value="1.0"/>
      <inertia ixx="0.0015215343371212302" ixy="0" ixz="0" 
               iyy="0.0015215343371212302" iyz="0" 
               izz="0.002695864234721062"/>
    </inertial>
  </link>
  <joint name="joint5" type="continuous">
    <parent link="base_link"/>
    <child link="link5"/>
    <origin xyz="-0.13985519542031713 0.15169550184627412 -0.04034416414914891" rpy="1.5708 0 0"/>
    <axis xyz="0 1 0"/>
    <dynamics damping="0.4505512195078252" friction="0.1"/>
  </joint>
  <link name="link6">
    <visual>
      <geometry>
        <cylinder radius="0.06328409715618377" length="0.05400195749273819"/>
      </geometry>
      <material name="wheel_material"/>
    </visual>
    <collision>
      <geometry>
        <cylinder radius="0.06328409715618377" length="0.05400195749273819"/>
      </geometry>
    </collision>
    <inertial>
      <mass value="1.0"/>
      <inertia ixx="0.0012442368559722854" ixy="0" ixz="0" 
               iyy="0.0012442368559722854" iyz="0" 
               izz="0.0020024384764366536"/>
    </inertial>
  </link>
  <joint name="joint6" type="continuous">
    <parent link="base_link"/>
    <child link="link6"/>
    <origin xyz="-0.13985519542031713 -0.15169550184627412 -0.04034416414914891" rpy="1.5708 0 0"/>
    <axis xyz="0 1 0"/>
    <dynamics damping="0.5123224953931355" friction="0.1"/>
  </joint>
</robot>