<?xml version="1.0"?>
<robot name="evolved_robot">
  <material name="metal">
    <color rgba="0.7 0.7 0.7 1.0"/>
  </material>
  <material name="plastic">
    <color rgba="0.3 0.3 0.9 1.0"/>
  </material>
  <material name="rubber">
    <color rgba="0.1 0.1 0.1 1.0"/>
  </material>
  <material name="red">
    <color rgba="1.0 0.0 0.0 1.0"/>
  </material>
  <material name="wheel_material">
    <color rgba="0.2 0.2 0.2 1.0"/>
  </material>
  <link name="base_link">
    <visual>
      <geometry><cylinder radius="0.2119564837054505" length="0.11022022719318435"/></geometry>
      <material name="metal"/>
    </visual>
    <collision>
      <geometry><cylinder radius="0.2119564837054505" length="0.11022022719318435"/></geometry>
    </collision>
    <inertial>
      <mass value="5.0"/>
      <inertia ixx="0.12243762619737825" ixy="0" ixz="0" 
               iyy="0.12243762619737825" iyz="0" 
               izz="0.22462775492389453"/>
    </inertial>
  </link>
  <link name="link1">
    <visual>
      <geometry><cylinder radius="0.08616022656691677" length="0.18558966583099729"/></geometry>
      <material name="plastic"/>
    </visual>
    <collision>
      <geometry><cylinder radius="0.08616022656691677" length="0.18558966583099729"/></geometry>
    </collision>
    <inertial>
      <mass value="0.5"/>
      <inertia ixx="0.0047261898324540445" ixy="0" ixz="0" 
               iyy="0.0047261898324540445" iyz="0" 
               izz="0.0037117923210312153"/>
    </inertial>
  </link>
  <joint name="joint1" type="revolute">
    <parent link="base_link"/>
    <child link="link1"/>
    <origin xyz="0 0 0.055110113596592174" rpy="0 0 0"/>
    <axis xyz="-0.5444661515122906 0.6200860717251769 0.5648449995439759"/>
    <dynamics damping="0.45826278524527186" friction="0.1"/>
    <limit lower="-0.6238944931265807" upper="1.298154958811977" effort="100" velocity="100"/>
  </joint>
  <link name="link2">
    <visual>
      <geometry>
        <cylinder radius="0.08902642884227707" length="0.06891353730799647"/>
      </geometry>
      <material name="wheel_material"/>
    </visual>
    <collision>
      <geometry>
        <cylinder radius="0.08902642884227707" length="0.06891353730799647"/>
      </geometry>
    </collision>
    <inertial>
      <mass value="1.0"/>
      <inertia ixx="0.0023771825601273076" ixy="0" ixz="0" 
               iyy="0.0023771825601273076" iyz="0" 
               izz="0.003962852516204512"/>
    </inertial>
  </link>
  <joint name="joint2" type="continuous">
    <parent link="base_link"/>
    <child link="link2"/>
    <origin xyz="0.1964758422275645 0.2074371251833365 -0.055110113596592174" rpy="1.5708 0 0"/>
    <axis xyz="0 1 0"/>
    <dynamics damping="0.2146818546384729" friction="0.1"/>
  </joint>
  <link name="link3">
    <visual>
      <geometry>
        <cylinder radius="0.09910625166411413" length="0.06812280513631964"/>
      </geometry>
      <material name="wheel_material"/>
    </visual>
    <collision>
      <geometry>
        <cylinder radius="0.09910625166411413" length="0.06812280513631964"/>
      </geometry>
    </collision>
    <inertial>
      <mass value="1.0"/>
      <inertia ixx="0.0028422386613644293" ixy="0" ixz="0" 
               iyy="0.0028422386613644293" iyz="0" 
               izz="0.004911024559455362"/>
    </inertial>
  </link>
  <joint name="joint3" type="continuous">
    <parent link="base_link"/>
    <child link="link3"/>
    <origin xyz="-0.1964758422275645 0.2074371251833365 -0.055110113596592174" rpy="1.5708 0 0"/>
    <axis xyz="0 1 0"/>
    <dynamics damping="0.8030647058584857" friction="0.1"/>
  </joint>
</robot>