<?xml version="1.0"?>
<robot name="evolved_robot">
  <material name="metal">
    <color rgba="0.7 0.7 0.7 1.0"/>
  </material>
  <material name="plastic">
    <color rgba="0.3 0.3 0.9 1.0"/>
  </material>
  <material name="rubber">
    <color rgba="0.1 0.1 0.1 1.0"/>
  </material>
  <material name="red">
    <color rgba="1.0 0.0 0.0 1.0"/>
  </material>
  <material name="wheel_material">
    <color rgba="0.2 0.2 0.2 1.0"/>
  </material>
  <link name="base_link">
    <visual>
      <geometry><box size="0.3729407074592106 0.3446729242588785 0.07690886759529983"/></geometry>
      <material name="metal"/>
    </visual>
    <collision>
      <geometry><box size="0.3729407074592106 0.3446729242588785 0.07690886759529983"/></geometry>
    </collision>
    <inertial>
      <mass value="5.0"/>
      <inertia ixx="0.10392866552663164" ixy="0" ixz="0" 
               iyy="0.12083312099580655" iyz="0" 
               izz="0.21490349666445255"/>
    </inertial>
  </link>
  <link name="link1">
    <visual>
      <geometry>
        <cylinder radius="0.03842956847556405" length="0.04115087025046166"/>
      </geometry>
      <material name="wheel_material"/>
    </visual>
    <collision>
      <geometry>
        <cylinder radius="0.03842956847556405" length="0.04115087025046166"/>
      </geometry>
    </collision>
    <inertial>
      <mass value="1.0"/>
      <inertia ixx="0.0005103241101687107" ixy="0" ixz="0" 
               iyy="0.0005103241101687107" iyz="0" 
               izz="0.0007384158666090331"/>
    </inertial>
  </link>
  <joint name="joint1" type="prismatic">
  <parent link="base_link"/>
  <child link="link1"/>
  <origin xyz="0.1664703537296053 0.17233646212943926 -0.038454433797649915" rpy="1.5708 0 0"/>
  <axis xyz="0 1 0"/>
  <limit lower="-0.1" upper="0.1" effort="10" velocity="1.0"/>
  <dynamics damping="0.9620773342175082" friction="0.1"/>
</joint>
  <link name="link2">
    <visual>
      <geometry>
        <cylinder radius="0.09411244893630778" length="0.06357497189143543"/>
      </geometry>
      <material name="wheel_material"/>
    </visual>
    <collision>
      <geometry>
        <cylinder radius="0.09411244893630778" length="0.06357497189143543"/>
      </geometry>
    </collision>
    <inertial>
      <mass value="1.0"/>
      <inertia ixx="0.002551103015447019" ixy="0" ixz="0" 
               iyy="0.002551103015447019" iyz="0" 
               izz="0.00442857652239457"/>
    </inertial>
  </link>
  <joint name="joint2" type="continuous">
    <parent link="base_link"/>
    <child link="link2"/>
    <origin xyz="0.1664703537296053 -0.17233646212943926 -0.038454433797649915" rpy="1.5708 0 0"/>
    <axis xyz="0 1 0"/>
    <dynamics damping="0.9511788792221783" friction="0.1"/>
  </joint>
  <link name="link3">
    <visual>
      <geometry>
        <cylinder radius="0.07843540050517425" length="0.06370499732642225"/>
      </geometry>
      <material name="wheel_material"/>
    </visual>
    <collision>
      <geometry>
        <cylinder radius="0.07843540050517425" length="0.06370499732642225"/>
      </geometry>
    </collision>
    <inertial>
      <mass value="1.0"/>
      <inertia ixx="0.0018762219034650612" ixy="0" ixz="0" 
               iyy="0.0018762219034650612" iyz="0" 
               izz="0.0030760560262035447"/>
    </inertial>
  </link>
  <joint name="joint3" type="continuous">
    <parent link="base_link"/>
    <child link="link3"/>
    <origin xyz="-0.1664703537296053 0.17233646212943926 -0.038454433797649915" rpy="1.5708 0 0"/>
    <axis xyz="0 1 0"/>
    <dynamics damping="0.7850074824219392" friction="0.1"/>
  </joint>
  <link name="link4">
    <visual>
      <geometry>
        <cylinder radius="0.06101189253650831" length="0.04117632854146757"/>
      </geometry>
      <material name="wheel_material"/>
    </visual>
    <collision>
      <geometry>
        <cylinder radius="0.06101189253650831" length="0.04117632854146757"/>
      </geometry>
    </collision>
    <inertial>
      <mass value="1.0"/>
      <inertia ixx="0.001071903593734516" ixy="0" ixz="0" 
               iyy="0.001071903593734516" iyz="0" 
               izz="0.0018612255154432191"/>
    </inertial>
  </link>
  <joint name="joint4" type="continuous">
    <parent link="base_link"/>
    <child link="link4"/>
    <origin xyz="-0.1664703537296053 -0.17233646212943926 -0.038454433797649915" rpy="1.5708 0 0"/>
    <axis xyz="0 1 0"/>
    <dynamics damping="0.724065632719656" friction="0.1"/>
  </joint>
  <link name="link5">
    <visual>
      <geometry>
        <cylinder radius="0.060127071290703785" length="0.07313775566668783"/>
      </geometry>
      <material name="wheel_material"/>
    </visual>
    <collision>
      <geometry>
        <cylinder radius="0.060127071290703785" length="0.07313775566668783"/>
      </geometry>
    </collision>
    <inertial>
      <mass value="1.0"/>
      <inertia ixx="0.0013495771174960212" ixy="0" ixz="0" 
               iyy="0.0013495771174960212" iyz="0" 
               izz="0.0018076323509986876"/>
    </inertial>
  </link>
  <joint name="joint5" type="continuous">
    <parent link="base_link"/>
    <child link="link5"/>
    <origin xyz="0 -0.22978194950591901 -0.038454433797649915" rpy="1.5708 0 0"/>
    <axis xyz="0 1 0"/>
    <dynamics damping="0.6407161603204423" friction="0.1"/>
  </joint>
  <link name="link6">
    <visual>
      <geometry>
        <cylinder radius="0.07032088423401835" length="0.04546005297529622"/>
      </geometry>
      <material name="wheel_material"/>
    </visual>
    <collision>
      <geometry>
        <cylinder radius="0.07032088423401835" length="0.04546005297529622"/>
      </geometry>
    </collision>
    <inertial>
      <mass value="1.0"/>
      <inertia ixx="0.0014084747245732808" ixy="0" ixz="0" 
               iyy="0.0014084747245732808" iyz="0" 
               izz="0.002472513379727105"/>
    </inertial>
  </link>
  <joint name="joint6" type="continuous">
    <parent link="base_link"/>
    <child link="link6"/>
    <origin xyz="0 1.770218050494081 -0.038454433797649915" rpy="1.5708 0 0"/>
    <axis xyz="0 1 0"/>
    <dynamics damping="0.9384190659020333" friction="0.1"/>
  </joint>
  <link name="link7">
    <visual>
      <geometry>
        <cylinder radius="0.04330185309388859" length="0.03747477836780498"/>
      </geometry>
      <material name="wheel_material"/>
    </visual>
    <collision>
      <geometry>
        <cylinder radius="0.04330185309388859" length="0.03747477836780498"/>
      </geometry>
    </collision>
    <inertial>
      <mass value="1.0"/>
      <inertia ixx="0.0005857925381508526" ixy="0" ixz="0" 
               iyy="0.0005857925381508526" iyz="0" 
               izz="0.0009375252406823545"/>
    </inertial>
  </link>
  <joint name="joint7" type="fixed">
    <parent link="base_link"/>
    <child link="link7"/>
    <origin xyz="0 -0.22978194950591901 -0.038454433797649915" rpy="1.5708 0 0"/>
    <!-- <axis xyz="0 1 0"/>
    <dynamics damping="0.1" friction="0.1"/> -->
  </joint>
</robot>