<?xml version="1.0"?>
<robot name="evolved_robot">
  <material name="metal">
    <color rgba="0.7 0.7 0.7 1.0"/>
  </material>
  <material name="plastic">
    <color rgba="0.3 0.3 0.9 1.0"/>
  </material>
  <material name="rubber">
    <color rgba="0.1 0.1 0.1 1.0"/>
  </material>
  <material name="red">
    <color rgba="1.0 0.0 0.0 1.0"/>
  </material>
  <material name="wheel_material">
    <color rgba="0.2 0.2 0.2 1.0"/>
  </material>
  <link name="base_link">
    <visual>
      <geometry><cylinder radius="0.1545791384574599" length="0.08068832829829782"/></geometry>
      <material name="metal"/>
    </visual>
    <collision>
      <geometry><cylinder radius="0.1545791384574599" length="0.08068832829829782"/></geometry>
    </collision>
    <inertial>
      <mass value="5.0"/>
      <inertia ixx="0.06516228038527132" ixy="0" ixz="0" 
               iyy="0.06516228038527132" iyz="0" 
               izz="0.1194735502312528"/>
    </inertial>
  </link>
  <link name="link1">
    <visual>
      <geometry><cylinder radius="0.07595597852159666" length="0.13990125952373855"/></geometry>
      <material name="rubber"/>
    </visual>
    <collision>
      <geometry><cylinder radius="0.07595597852159666" length="0.13990125952373855"/></geometry>
    </collision>
    <inertial>
      <mass value="0.5"/>
      <inertia ixx="0.0030733578696540177" ixy="0" ixz="0" 
               iyy="0.0030733578696540177" iyz="0" 
               izz="0.002884655336586627"/>
    </inertial>
  </link>
  <joint name="joint1" type="prismatic">
    <parent link="base_link"/>
    <child link="link1"/>
    <origin xyz="0 0 0.04034416414914891" rpy="0 0 0"/>
    <axis xyz="-0.7708418140991812 -0.36617926850726723 0.5212635043351548"/>
    <dynamics damping="0.7765132943335169" friction="0.1"/>
    <limit lower="-1.7815898141132733" upper="1.2717079639294546" effort="100" velocity="100"/>
  </joint>
  <link name="link2">
    <visual>
      <geometry>
        <cylinder radius="0.05962278007258792" length="0.05072902790486835"/>
      </geometry>
      <material name="wheel_material"/>
    </visual>
    <collision>
      <geometry>
        <cylinder radius="0.05962278007258792" length="0.05072902790486835"/>
      </geometry>
    </collision>
    <inertial>
      <mass value="1.0"/>
      <inertia ixx="0.0011031718319104561" ixy="0" ixz="0" 
               iyy="0.0011031718319104561" iyz="0" 
               izz="0.0017774379517920937"/>
    </inertial>
  </link>
  <joint name="joint2" type="continuous">
    <parent link="base_link"/>
    <child link="link2"/>
    <origin xyz="0.13822591133937293 0.15093236557554693 -0.04034416414914891" rpy="1.5708 0 0"/>
    <axis xyz="0 1 0"/>
    <dynamics damping="0.6237323492205411" friction="0.1"/>
  </joint>
  <link name="link3">
    <visual>
      <geometry><box size="0.11700741769070341 0.16250170005777426 0.05155470705773513"/></geometry>
      <material name="metal"/>
    </visual>
    <collision>
      <geometry><box size="0.11700741769070341 0.16250170005777426 0.05155470705773513"/></geometry>
    </collision>
    <inertial>
      <mass value="0.5"/>
      <inertia ixx="0.0024220575284563096" ixy="0" ixz="0" 
               iyy="0.0013623853012046348" iyz="0" 
               izz="0.003341461526359464"/>
    </inertial>
  </link>
  <joint name="joint3" type="prismatic">
    <parent link="base_link"/>
    <child link="link3"/>
    <origin xyz="0 0 0.09034416414914892" rpy="0 0 0"/>
    <axis xyz="0.17759231949657553 0.8700938337371786 -0.4597800436604063"/>
    <dynamics damping="0.8238408978236413" friction="0.1"/>
    <limit lower="-0.3965738918540924" upper="1.2014218395971734" effort="100" velocity="100"/>
  </joint>
  <link name="link4">
    <visual>
      <geometry>
        <cylinder radius="0.07741305339524476" length="0.04755214427637371"/>
      </geometry>
      <material name="wheel_material"/>
    </visual>
    <collision>
      <geometry>
        <cylinder radius="0.07741305339524476" length="0.04755214427637371"/>
      </geometry>
    </collision>
    <inertial>
      <mass value="1.0"/>
      <inertia ixx="0.001686629077767176" ixy="0" ixz="0" 
               iyy="0.001686629077767176" iyz="0" 
               izz="0.0029963904179875086"/>
    </inertial>
  </link>
  <joint name="joint4" type="continuous">
    <parent link="base_link"/>
    <child link="link4"/>
    <origin xyz="-0.13822591133937293 0.15093236557554693 -0.04034416414914891" rpy="1.5708 0 0"/>
    <axis xyz="0 1 0"/>
    <dynamics damping="0.4299996638720299" friction="0.1"/>
  </joint>
  <link name="link5">
    <visual>
      <geometry>
        <cylinder radius="0.07342839007796728" length="0.04546495489214325"/>
      </geometry>
      <material name="wheel_material"/>
    </visual>
    <collision>
      <geometry>
        <cylinder radius="0.07342839007796728" length="0.04546495489214325"/>
      </geometry>
    </collision>
    <inertial>
      <mass value="1.0"/>
      <inertia ixx="0.0015201872943059161" ixy="0" ixz="0" 
               iyy="0.0015201872943059161" iyz="0" 
               izz="0.002695864234721062"/>
    </inertial>
  </link>
  <joint name="joint5" type="continuous">
    <parent link="base_link"/>
    <child link="link5"/>
    <origin xyz="-0.13822591133937293 -0.15093236557554693 -0.04034416414914891" rpy="1.5708 0 0"/>
    <axis xyz="0 1 0"/>
    <dynamics damping="0.45649072620437836" friction="0.1"/>
  </joint>
  <link name="link6">
    <visual>
      <geometry><cylinder radius="0.0746792132322128" length="0.09481291345210449"/></geometry>
      <material name="rubber"/>
    </visual>
    <collision>
      <geometry><cylinder radius="0.0746792132322128" length="0.09481291345210449"/></geometry>
    </collision>
    <inertial>
      <mass value="0.5"/>
      <inertia ixx="0.002143370268685265" ixy="0" ixz="0" 
               iyy="0.002143370268685265" iyz="0" 
               izz="0.0027884924444911536"/>
    </inertial>
  </link>
  <joint name="joint6" type="revolute">
    <parent link="base_link"/>
    <child link="link6"/>
    <origin xyz="0 0 0.1403441641491489" rpy="0 0 0"/>
    <axis xyz="0.0 0.6444504999116089 -0.7646460312874693"/>
    <dynamics damping="0.5114113762203718" friction="0.1"/>
    <limit lower="-1.3845749974452444" upper="1.0457040159370472" effort="100" velocity="100"/>
  </joint>
</robot>