<?xml version="1.0"?>
<robot name="evolved_robot">
  <material name="metal">
    <color rgba="0.7 0.7 0.7 1.0"/>
  </material>
  <material name="plastic">
    <color rgba="0.3 0.3 0.9 1.0"/>
  </material>
  <material name="rubber">
    <color rgba="0.1 0.1 0.1 1.0"/>
  </material>
  <material name="red">
    <color rgba="1.0 0.0 0.0 1.0"/>
  </material>
  <material name="wheel_material">
    <color rgba="0.2 0.2 0.2 1.0"/>
  </material>
  <link name="base_link">
    <visual>
      <geometry><box size="0.31436242718777907 0.25497183005001967 0.08603545805012364"/></geometry>
      <material name="plastic"/>
    </visual>
    <collision>
      <geometry><box size="0.31436242718777907 0.25497183005001967 0.08603545805012364"/></geometry>
    </collision>
    <inertial>
      <mass value="5.0"/>
      <inertia ixx="0.060343945134125575" ixy="0" ixz="0" 
               iyy="0.08852152972440523" iyz="0" 
               izz="0.1365286414553732"/>
    </inertial>
  </link>
  <link name="link1">
    <visual>
      <geometry>
        <cylinder radius="0.06255185810306499" length="0.06940135782388658"/>
      </geometry>
      <material name="wheel_material"/>
    </visual>
    <collision>
      <geometry>
        <cylinder radius="0.06255185810306499" length="0.06940135782388658"/>
      </geometry>
    </collision>
    <inertial>
      <mass value="1.0"/>
      <inertia ixx="0.0013795627770197562" ixy="0" ixz="0" 
               iyy="0.0013795627770197562" iyz="0" 
               izz="0.0019563674760729884"/>
    </inertial>
  </link>
  <joint name="joint1" type="fixed">
    <parent link="base_link"/>
    <child link="link1"/>
    <origin xyz="0.13718121359388954 0.12748591502500983 -0.04301772902506182" rpy="1.5708 0 0"/>
    <axis xyz="0 0 1"/>
    <dynamics damping="0.39813594651655093" friction="0.1"/>
  </joint>
  <link name="link2">
    <visual>
      <geometry>
        <cylinder radius="0.07607386953367762" length="0.04574254402519221"/>
      </geometry>
      <material name="wheel_material"/>
    </visual>
    <collision>
      <geometry>
        <cylinder radius="0.07607386953367762" length="0.04574254402519221"/>
      </geometry>
    </collision>
    <inertial>
      <mass value="1.0"/>
      <inertia ixx="0.0016211734342814717" ixy="0" ixz="0" 
               iyy="0.0016211734342814717" iyz="0" 
               izz="0.002893616812913502"/>
    </inertial>
  </link>
  <joint name="joint2" type="fixed">
    <parent link="base_link"/>
    <child link="link2"/>
    <origin xyz="-0.13718121359388954 0.12748591502500983 -0.04301772902506182" rpy="1.5708 0 0"/>
    <axis xyz="0 0 1"/>
    <dynamics damping="0.9268370476860263" friction="0.1"/>
  </joint>
  <link name="link3">
    <visual>
      <geometry>
        <cylinder radius="0.06341371124760828" length="0.04654165172746007"/>
      </geometry>
      <material name="wheel_material"/>
    </visual>
    <collision>
      <geometry>
        <cylinder radius="0.06341371124760828" length="0.04654165172746007"/>
      </geometry>
    </collision>
    <inertial>
      <mass value="1.0"/>
      <inertia ixx="0.0011858351390087757" ixy="0" ixz="0" 
               iyy="0.0011858351390087757" iyz="0" 
               izz="0.0020106493870975205"/>
    </inertial>
  </link>
  <joint name="joint3" type="continuous">
    <parent link="base_link"/>
    <child link="link3"/>
    <origin xyz="-0.13718121359388954 -0.12748591502500983 -0.04301772902506182" rpy="1.5708 0 0"/>
    <axis xyz="0 0 1"/>
    <dynamics damping="0.6629699077834755" friction="0.1"/>
  </joint>
</robot>