<?xml version="1.0"?>
<robot name="evolved_robot">
  <material name="metal">
    <color rgba="0.7 0.7 0.7 1.0"/>
  </material>
  <material name="plastic">
    <color rgba="0.3 0.3 0.9 1.0"/>
  </material>
  <material name="rubber">
    <color rgba="0.1 0.1 0.1 1.0"/>
  </material>
  <material name="red">
    <color rgba="1.0 0.0 0.0 1.0"/>
  </material>
  <material name="wheel_material">
    <color rgba="0.2 0.2 0.2 1.0"/>
  </material>
  <link name="base_link">
    <visual>
      <geometry><box size="0.34027136548425513 0.3031946513906124 0.10747812692987997"/></geometry>
      <material name="metal"/>
    </visual>
    <collision>
      <geometry><box size="0.34027136548425513 0.3031946513906124 0.10747812692987997"/></geometry>
    </collision>
    <inertial>
      <mass value="5.0"/>
      <inertia ixx="0.08623212033352533" ixy="0" ixz="0" 
               iyy="0.1061134582807291" iyz="0" 
               izz="0.1730929990003288"/>
    </inertial>
  </link>
  <link name="link1">
    <visual>
      <geometry><cylinder radius="0.050041594297084685" length="0.0551596696567533"/></geometry>
      <material name="plastic"/>
    </visual>
    <collision>
      <geometry><cylinder radius="0.050041594297084685" length="0.0551596696567533"/></geometry>
    </collision>
    <inertial>
      <mass value="0.5"/>
      <inertia ixx="0.0008795893863353505" ixy="0" ixz="0" 
               iyy="0.0008795893863353505" iyz="0" 
               izz="0.0012520805798970091"/>
    </inertial>
  </link>
  <joint name="joint1" type="fixed">
    <parent link="base_link"/>
    <child link="link1"/>
    <origin xyz="0 0 0.053739063464939986" rpy="0 0 0"/>
    <axis xyz="-0.09344979423289478 -0.9427831852506745 0.32004218716666416"/>
    <dynamics damping="0.7561519102187328" friction="0.1"/>
  </joint>
  <link name="link2">
    <visual>
      <geometry><box size="0.15984581774312595 0.1637658213362068 0.05482141343289953"/></geometry>
      <material name="rubber"/>
    </visual>
    <collision>
      <geometry><box size="0.15984581774312595 0.1637658213362068 0.05482141343289953"/></geometry>
    </collision>
    <inertial>
      <mass value="0.5"/>
      <inertia ixx="0.002485385967391942" ixy="0" ixz="0" 
               iyy="0.002379672735062461" iyz="0" 
               izz="0.004364160807324254"/>
    </inertial>
  </link>
  <joint name="joint2" type="revolute">
    <parent link="base_link"/>
    <child link="link2"/>
    <origin xyz="0 0 0.10373906346494" rpy="0 0 0"/>
    <axis xyz="0.6013384473320394 -0.5707965277628373 0.5590915807398467"/>
    <dynamics damping="0.873036841141712" friction="0.1"/>
    <limit lower="-1.7587900716096077" upper="0.9873321275505671" effort="100" velocity="100"/>
  </joint>
  <link name="link3">
    <visual>
      <geometry>
        <cylinder radius="0.05702772458523453" length="0.05837642313947383"/>
      </geometry>
      <material name="wheel_material"/>
    </visual>
    <collision>
      <geometry>
        <cylinder radius="0.05702772458523453" length="0.05837642313947383"/>
      </geometry>
    </collision>
    <inertial>
      <mass value="1.0"/>
      <inertia ixx="0.001097024241055582" ixy="0" ixz="0" 
               iyy="0.001097024241055582" iyz="0" 
               izz="0.0016260806856846814"/>
    </inertial>
  </link>
  <joint name="joint3" type="continuous">
    <parent link="base_link"/>
    <child link="link3"/>
    <origin xyz="0.15013568274212757 0.1515973256953062 -0.053739063464939986" rpy="1.5708 0 0"/>
    <axis xyz="0 0 1"/>
    <dynamics damping="0.7441332332709308" friction="0.1"/>
  </joint>
  <link name="link4">
    <visual>
      <geometry>
        <cylinder radius="0.09534330464393713" length="0.02655889687480227"/>
      </geometry>
      <material name="wheel_material"/>
    </visual>
    <collision>
      <geometry>
        <cylinder radius="0.09534330464393713" length="0.02655889687480227"/>
      </geometry>
    </collision>
    <inertial>
      <mass value="1.0"/>
      <inertia ixx="0.0023313676853738492" ixy="0" ixz="0" 
               iyy="0.0023313676853738492" iyz="0" 
               izz="0.004545172870213302"/>
    </inertial>
  </link>
  <joint name="joint4" type="continuous">
    <parent link="base_link"/>
    <child link="link4"/>
    <origin xyz="-0.15013568274212757 0.1515973256953062 -0.053739063464939986" rpy="1.5708 0 0"/>
    <axis xyz="0 0 1"/>
    <dynamics damping="0.22581670034412085" friction="0.1"/>
  </joint>
  <link name="link5">
    <visual>
      <geometry><cylinder radius="0.07485252675953" length="0.053276958313873427"/></geometry>
      <material name="metal"/>
    </visual>
    <collision>
      <geometry><cylinder radius="0.07485252675953" length="0.053276958313873427"/></geometry>
    </collision>
    <inertial>
      <mass value="0.5"/>
      <inertia ixx="0.0016372613811697224" ixy="0" ixz="0" 
               iyy="0.0016372613811697224" iyz="0" 
               izz="0.002801450381143077"/>
    </inertial>
  </link>
  <joint name="joint5" type="revolute">
    <parent link="base_link"/>
    <child link="link5"/>
    <origin xyz="0 0 0.15373906346493998" rpy="0 0 0"/>
    <axis xyz="-0.8837852742331787 -0.24120500408464118 0.4009285909649165"/>
    <dynamics damping="0.3607509468545228" friction="0.1"/>
    <limit lower="-0.9801294114817961" upper="1.0594762417049612" effort="100" velocity="100"/>
  </joint>
</robot>