<?xml version="1.0"?>
<robot name="evolved_robot">
  <material name="metal">
    <color rgba="0.7 0.7 0.7 1.0"/>
  </material>
  <material name="plastic">
    <color rgba="0.3 0.3 0.9 1.0"/>
  </material>
  <material name="rubber">
    <color rgba="0.1 0.1 0.1 1.0"/>
  </material>
  <material name="red">
    <color rgba="1.0 0.0 0.0 1.0"/>
  </material>
  <material name="wheel_material">
    <color rgba="0.2 0.2 0.2 1.0"/>
  </material>
  <link name="base_link">
    <visual>
      <geometry><box size="0.3510706422823209 0.30322775093557175 0.08068832829829782"/></geometry>
      <material name="rubber"/>
    </visual>
    <collision>
      <geometry><box size="0.3510706422823209 0.30322775093557175 0.08068832829829782"/></geometry>
    </collision>
    <inertial>
      <mass value="5.0"/>
      <inertia ixx="0.08204806271751584" ixy="0" ixz="0" 
               iyy="0.10813433516341266" iyz="0" 
               izz="0.1793313873416387"/>
    </inertial>
  </link>
  <link name="link1">
    <visual>
      <geometry><cylinder radius="0.07697074631483639" length="0.21496696738229876"/></geometry>
      <material name="rubber"/>
    </visual>
    <collision>
      <geometry><cylinder radius="0.07697074631483639" length="0.21496696738229876"/></geometry>
    </collision>
    <inertial>
      <mass value="0.5"/>
      <inertia ixx="0.005332023702527583" ixy="0" ixz="0" 
               iyy="0.005332023702527583" iyz="0" 
               izz="0.0029622478941314493"/>
    </inertial>
  </link>
  <joint name="joint1" type="prismatic">
    <parent link="base_link"/>
    <child link="link1"/>
    <origin xyz="0 0 0.04034416414914891" rpy="0 0 0"/>
    <axis xyz="0.6133294922038455 -0.4602094076032439 0.6418989290740749"/>
    <dynamics damping="0.6515641129532233" friction="0.1"/>
    <limit lower="-1.7743907201818965" upper="1.2717079639294546" effort="100" velocity="100"/>
  </joint>
  <link name="link2">
    <visual>
      <geometry>
        <cylinder radius="0.05964186356133744" length="0.05091849446327726"/>
      </geometry>
      <material name="wheel_material"/>
    </visual>
    <collision>
      <geometry>
        <cylinder radius="0.05964186356133744" length="0.05091849446327726"/>
      </geometry>
    </collision>
    <inertial>
      <mass value="1.0"/>
      <inertia ixx="0.0011053457288011973" ixy="0" ixz="0" 
               iyy="0.0011053457288011973" iyz="0" 
               izz="0.0017785759445345952"/>
    </inertial>
  </link>
  <joint name="joint2" type="continuous">
    <parent link="base_link"/>
    <child link="link2"/>
    <origin xyz="0.15553532114116045 0.15161387546778587 -0.04034416414914891" rpy="1.5708 0 0"/>
    <axis xyz="0 1 0"/>
    <dynamics damping="0.6237323492205411" friction="0.1"/>
  </joint>
  <link name="link3">
    <visual>
      <geometry><box size="0.11700741769070341 0.16250170005777426 0.13750394350435952"/></geometry>
      <material name="rubber"/>
    </visual>
    <collision>
      <geometry><box size="0.11700741769070341 0.16250170005777426 0.13750394350435952"/></geometry>
    </collision>
    <inertial>
      <mass value="0.5"/>
      <inertia ixx="0.0037761780834097438" ixy="0" ixz="0" 
               iyy="0.002716505856158069" iyz="0" 
               izz="0.003341461526359464"/>
    </inertial>
  </link>
  <joint name="joint3" type="prismatic">
    <parent link="base_link"/>
    <child link="link3"/>
    <origin xyz="0 0 0.09034416414914892" rpy="0 0 0"/>
    <axis xyz="0.3120830582443221 0.9490216886831554 0.04429445976465996"/>
    <dynamics damping="0.9395296771943603" friction="0.1"/>
    <limit lower="-0.7345191566587939" upper="1.2169395730998822" effort="100" velocity="100"/>
  </joint>
  <link name="link4">
    <visual>
      <geometry>
        <cylinder radius="0.07741305339524476" length="0.046968017321943833"/>
      </geometry>
      <material name="wheel_material"/>
    </visual>
    <collision>
      <geometry>
        <cylinder radius="0.07741305339524476" length="0.046968017321943833"/>
      </geometry>
    </collision>
    <inertial>
      <mass value="1.0"/>
      <inertia ixx="0.0016820280965899556" ixy="0" ixz="0" 
               iyy="0.0016820280965899556" iyz="0" 
               izz="0.0029963904179875086"/>
    </inertial>
  </link>
  <joint name="joint4" type="continuous">
    <parent link="base_link"/>
    <child link="link4"/>
    <origin xyz="-0.15553532114116045 0.15161387546778587 -0.04034416414914891" rpy="1.5708 0 0"/>
    <axis xyz="0 1 0"/>
    <dynamics damping="0.4452985084493982" friction="0.1"/>
  </joint>
  <link name="link5">
    <visual>
      <geometry><box size="0.17408111450847796 0.13488318297381083 0.0653079719149393"/></geometry>
      <material name="plastic"/>
    </visual>
    <collision>
      <geometry><box size="0.17408111450847796 0.13488318297381083 0.0653079719149393"/></geometry>
    </collision>
    <inertial>
      <mass value="0.5"/>
      <inertia ixx="0.0018715503537324195" ixy="0" ixz="0" 
               iyy="0.002880780468679693" iyz="0" 
               izz="0.004041475623138362"/>
    </inertial>
  </link>
  <joint name="joint5" type="fixed">
    <parent link="base_link"/>
    <child link="link5"/>
    <origin xyz="0 0 0.1403441641491489" rpy="0 0 0"/>
    <axis xyz="0.44732216390069973 -0.8943725323173374 -0.0008093945075221636"/>
    <dynamics damping="0.4630596703110821" friction="0.1"/>
  </joint>
  <link name="link6">
    <visual>
      <geometry><cylinder radius="0.07603980650600112" length="0.22810087257028583"/></geometry>
      <material name="rubber"/>
    </visual>
    <collision>
      <geometry><cylinder radius="0.07603980650600112" length="0.22810087257028583"/></geometry>
    </collision>
    <inertial>
      <mass value="0.5"/>
      <inertia ixx="0.005781347048978004" ixy="0" ixz="0" 
               iyy="0.005781347048978004" iyz="0" 
               izz="0.002891026086735045"/>
    </inertial>
  </link>
  <joint name="joint6" type="revolute">
    <parent link="base_link"/>
    <child link="link6"/>
    <origin xyz="0 0 0.19034416414914893" rpy="0 0 0"/>
    <axis xyz="0.0 -1.0 0.0"/>
    <dynamics damping="0.4788067361366989" friction="0.1"/>
    <limit lower="-1.3912906195743806" upper="1.0618196051919588" effort="100" velocity="100"/>
  </joint>
</robot>