<?xml version="1.0"?>
<robot name="evolved_robot">
  <material name="metal">
    <color rgba="0.7 0.7 0.7 1.0"/>
  </material>
  <material name="plastic">
    <color rgba="0.3 0.3 0.9 1.0"/>
  </material>
  <material name="rubber">
    <color rgba="0.1 0.1 0.1 1.0"/>
  </material>
  <material name="red">
    <color rgba="1.0 0.0 0.0 1.0"/>
  </material>
  <material name="wheel_material">
    <color rgba="0.2 0.2 0.2 1.0"/>
  </material>
  <link name="base_link">
    <visual>
      <geometry><box size="0.30694219765450376 0.3014203492185933 0.09121875435821769"/></geometry>
      <material name="metal"/>
    </visual>
    <collision>
      <geometry><box size="0.30694219765450376 0.3014203492185933 0.09121875435821769"/></geometry>
    </collision>
    <inertial>
      <mass value="5.0"/>
      <inertia ixx="0.08264590672476967" ixy="0" ixz="0" 
               iyy="0.0854453115397011" iyz="0" 
               izz="0.15422311635336267"/>
    </inertial>
  </link>
  <link name="link1">
    <visual>
      <geometry><cylinder radius="0.0693888481214605" length="0.20992373954302018"/></geometry>
      <material name="rubber"/>
    </visual>
    <collision>
      <geometry><cylinder radius="0.0693888481214605" length="0.20992373954302018"/></geometry>
    </collision>
    <inertial>
      <mass value="0.5"/>
      <inertia ixx="0.0048760344295495925" ixy="0" ixz="0" 
               iyy="0.0048760344295495925" iyz="0" 
               izz="0.002407406121811556"/>
    </inertial>
  </link>
  <joint name="joint1" type="prismatic">
    <parent link="base_link"/>
    <child link="link1"/>
    <origin xyz="0 0 0.045609377179108845" rpy="0 0 0"/>
    <axis xyz="-0.006001300511877532 0.8579276199265342 -0.5137355188804433"/>
    <dynamics damping="0.8837598170592937" friction="0.1"/>
    <limit lower="-2.19055709544216" upper="0.942" effort="100" velocity="100"/>
  </joint>
  <link name="link2">
    <visual>
      <geometry>
        <cylinder radius="0.05431213354518122" length="0.04821138832144219"/>
      </geometry>
      <material name="wheel_material"/>
    </visual>
    <collision>
      <geometry>
        <cylinder radius="0.05431213354518122" length="0.04821138832144219"/>
      </geometry>
    </collision>
    <inertial>
      <mass value="1.0"/>
      <inertia ixx="0.0009311467928808074" ixy="0" ixz="0" 
               iyy="0.0009311467928808074" iyz="0" 
               izz="0.0014749039251147995"/>
    </inertial>
  </link>
  <joint name="joint2" type="continuous">
    <parent link="base_link"/>
    <child link="link2"/>
    <origin xyz="0 0 0" rpy="1.5708 0 0"/>
    <axis xyz="0 0 1"/>
    <dynamics damping="0.22772052215840985" friction="0.1"/>
  </joint>
  <link name="link3">
    <visual>
      <geometry><sphere radius="0.027888158222664793"/></geometry>
      <material name="plastic"/>
    </visual>
    <collision>
      <geometry><sphere radius="0.027888158222664793"/></geometry>
    </collision>
    <inertial>
      <mass value="0.5"/>
      <inertia ixx="0.00031109974762095436" ixy="0" ixz="0" 
               iyy="0.00031109974762095436" iyz="0" 
               izz="0.00031109974762095436"/>
    </inertial>
  </link>
  <joint name="joint3" type="fixed">
    <parent link="base_link"/>
    <child link="link3"/>
    <origin xyz="0 0 0.09560937717910885" rpy="0 0 0"/>
    <axis xyz="0.8829504837056774 -0.27215000628798625 0.382534727052799"/>
    <dynamics damping="0.8036165011211521" friction="0.1"/>
  </joint>
  <link name="link4">
    <visual>
      <geometry><cylinder radius="0.06603368923843765" length="0.23965232487031674"/></geometry>
      <material name="metal"/>
    </visual>
    <collision>
      <geometry><cylinder radius="0.06603368923843765" length="0.23965232487031674"/></geometry>
    </collision>
    <inertial>
      <mass value="0.5"/>
      <inertia ixx="0.005876215096588626" ixy="0" ixz="0" 
               iyy="0.005876215096588626" iyz="0" 
               izz="0.002180224057219278"/>
    </inertial>
  </link>
  <joint name="joint4" type="revolute">
    <parent link="base_link"/>
    <child link="link4"/>
    <origin xyz="0 0 0.14560937717910885" rpy="0 0 0"/>
    <axis xyz="0.008186361130485174 -0.6399150981040648 -0.7684020111308313"/>
    <dynamics damping="0.2837158774557361" friction="0.1"/>
    <limit lower="-1.7542596570890534" upper="0.39307273959162875" effort="100" velocity="100"/>
  </joint>
  <link name="link5">
    <visual>
      <geometry><box size="0.23017336174680952 0.12102854168484478 0.06424431091508509"/></geometry>
      <material name="rubber"/>
    </visual>
    <collision>
      <geometry><box size="0.23017336174680952 0.12102854168484478 0.06424431091508509"/></geometry>
    </collision>
    <inertial>
      <mass value="0.5"/>
      <inertia ixx="0.0015646032822761943" ixy="0" ixz="0" 
               iyy="0.00475892566189848" iyz="0" 
               izz="0.005635640363348987"/>
    </inertial>
  </link>
  <joint name="joint5" type="fixed">
    <parent link="base_link"/>
    <child link="link5"/>
    <origin xyz="0 0 0.19560937717910887" rpy="0 0 0"/>
    <axis xyz="0.6805495664572401 0.2977869350930787 0.6694589075385681"/>
    <dynamics damping="0.368804299831064" friction="0.1"/>
  </joint>
  <link name="link6">
    <visual>
      <geometry><cylinder radius="0.05715662929169568" length="0.06049280912689717"/></geometry>
      <material name="metal"/>
    </visual>
    <collision>
      <geometry><cylinder radius="0.05715662929169568" length="0.06049280912689717"/></geometry>
    </collision>
    <inertial>
      <mass value="0.5"/>
      <inertia ixx="0.0011216683976690157" ixy="0" ixz="0" 
               iyy="0.0011216683976690157" iyz="0" 
               izz="0.0016334401359941624"/>
    </inertial>
  </link>
  <joint name="joint6" type="fixed">
    <parent link="base_link"/>
    <child link="link6"/>
    <origin xyz="0 0 0.24560937717910886" rpy="0 0 0"/>
    <axis xyz="0.7650317490369187 0.2079484015157825 -0.6094947787081888"/>
    <dynamics damping="0.2158883880953235" friction="0.1"/>
  </joint>
</robot>