<?xml version="1.0"?>
<robot name="evolved_robot">
  <material name="metal">
    <color rgba="0.7 0.7 0.7 1.0"/>
  </material>
  <material name="plastic">
    <color rgba="0.3 0.3 0.9 1.0"/>
  </material>
  <material name="rubber">
    <color rgba="0.1 0.1 0.1 1.0"/>
  </material>
  <material name="red">
    <color rgba="1.0 0.0 0.0 1.0"/>
  </material>
  <material name="wheel_material">
    <color rgba="0.2 0.2 0.2 1.0"/>
  </material>
  <link name="base_link">
    <visual>
      <geometry><box size="0.28200543666407374 0.1960602003020291 0.09653921606559923"/></geometry>
      <material name="metal"/>
    </visual>
    <collision>
      <geometry><box size="0.28200543666407374 0.1960602003020291 0.09653921606559923"/></geometry>
    </collision>
    <inertial>
      <mass value="5.0"/>
      <inertia ixx="0.03979951865086018" ixy="0" ixz="0" 
               iyy="0.07403907212221279" iyz="0" 
               izz="0.09830555704213889"/>
    </inertial>
  </link>
  <link name="link1">
    <visual>
      <geometry>
        <cylinder radius="0.05276887741149976" length="0.040581285150848495"/>
      </geometry>
      <material name="wheel_material"/>
    </visual>
    <collision>
      <geometry>
        <cylinder radius="0.05276887741149976" length="0.040581285150848495"/>
      </geometry>
    </collision>
    <inertial>
      <mass value="1.0"/>
      <inertia ixx="0.000833375331192012" ixy="0" ixz="0" 
               iyy="0.000833375331192012" iyz="0" 
               izz="0.0013922772116349445"/>
    </inertial>
  </link>
  <joint name="joint1" type="continuous">
    <parent link="base_link"/>
    <child link="link1"/>
    <origin xyz="0.12100271833203687 0.09803010015101454 -0.048269608032799616" rpy="1.5708 0 0"/>
    <axis xyz="0 0 1"/>
    <dynamics damping="0.7812145894427714" friction="0.1"/>
  </joint>
  <link name="link2">
    <visual>
      <geometry>
        <cylinder radius="0.07899620941041051" length="0.04772637766097393"/>
      </geometry>
      <material name="wheel_material"/>
    </visual>
    <collision>
      <geometry>
        <cylinder radius="0.07899620941041051" length="0.04772637766097393"/>
      </geometry>
    </collision>
    <inertial>
      <mass value="1.0"/>
      <inertia ixx="0.00174991753568985" ixy="0" ixz="0" 
               iyy="0.00174991753568985" iyz="0" 
               izz="0.003120200550606715"/>
    </inertial>
  </link>
  <joint name="joint2" type="continuous">
    <parent link="base_link"/>
    <child link="link2"/>
    <origin xyz="0.12100271833203687 -0.09803010015101454 -0.048269608032799616" rpy="1.5708 0 0"/>
    <axis xyz="0 0 1"/>
    <dynamics damping="0.8652752464137597" friction="0.1"/>
  </joint>
  <link name="link3">
    <visual>
      <geometry>
        <cylinder radius="0.07063797436999575" length="0.042093354478068126"/>
      </geometry>
      <material name="wheel_material"/>
    </visual>
    <collision>
      <geometry>
        <cylinder radius="0.07063797436999575" length="0.042093354478068126"/>
      </geometry>
    </collision>
    <inertial>
      <mass value="1.0"/>
      <inertia ixx="0.001395085063375402" ixy="0" ixz="0" 
               iyy="0.001395085063375402" iyz="0" 
               izz="0.002494861711548088"/>
    </inertial>
  </link>
  <joint name="joint3" type="continuous">
    <parent link="base_link"/>
    <child link="link3"/>
    <origin xyz="-0.12100271833203687 0.09803010015101454 -0.048269608032799616" rpy="1.5708 0 0"/>
    <axis xyz="0 0 1"/>
    <dynamics damping="0.69190020288255" friction="0.1"/>
  </joint>
  <link name="link4">
    <visual>
      <geometry>
        <cylinder radius="0.07828401586055114" length="0.048557610339922924"/>
      </geometry>
      <material name="wheel_material"/>
    </visual>
    <collision>
      <geometry>
        <cylinder radius="0.07828401586055114" length="0.048557610339922924"/>
      </geometry>
    </collision>
    <inertial>
      <mass value="1.0"/>
      <inertia ixx="0.001728583578307405" ixy="0" ixz="0" 
               iyy="0.001728583578307405" iyz="0" 
               izz="0.0030641935696275116"/>
    </inertial>
  </link>
  <joint name="joint4" type="continuous">
    <parent link="base_link"/>
    <child link="link4"/>
    <origin xyz="-0.12100271833203687 -0.09803010015101454 -0.048269608032799616" rpy="1.5708 0 0"/>
    <axis xyz="0 0 1"/>
    <dynamics damping="0.6849628307493921" friction="0.1"/>
  </joint>
  <link name="link5">
    <visual>
      <geometry><sphere radius="0.04915514420561673"/></geometry>
      <material name="metal"/>
    </visual>
    <collision>
      <geometry><sphere radius="0.04915514420561673"/></geometry>
    </collision>
    <inertial>
      <mass value="0.5"/>
      <inertia ixx="0.0009664912807499903" ixy="0" ixz="0" 
               iyy="0.0009664912807499903" iyz="0" 
               izz="0.0009664912807499903"/>
    </inertial>
  </link>
  <joint name="joint5" type="prismatic">
    <parent link="base_link"/>
    <child link="link5"/>
    <origin xyz="0 0 0.048269608032799616" rpy="0 0 0"/>
    <axis xyz="-0.6400863788580589 0.5944352090492525 0.48676093705529505"/>
    <dynamics damping="0.7028373833923687" friction="0.1"/>
    <limit lower="-0.3644232264120007" upper="0.9926335345686322" effort="100" velocity="100"/>
  </joint>
  <link name="link6">
    <visual>
      <geometry>
        <cylinder radius="0.05738784063838424" length="0.05389435633647088"/>
      </geometry>
      <material name="wheel_material"/>
    </visual>
    <collision>
      <geometry>
        <cylinder radius="0.05738784063838424" length="0.05389435633647088"/>
      </geometry>
    </collision>
    <inertial>
      <mass value="1.0"/>
      <inertia ixx="0.0010653912003610213" ixy="0" ixz="0" 
               iyy="0.0010653912003610213" iyz="0" 
               izz="0.0016466821265682927"/>
    </inertial>
  </link>
  <joint name="joint6" type="continuous">
    <parent link="base_link"/>
    <child link="link6"/>
    <origin xyz="0 -0.13070680020135272 -0.048269608032799616" rpy="1.5708 0 0"/>
    <axis xyz="0 0 1"/>
    <dynamics damping="0.9270004068807279" friction="0.1"/>
  </joint>
  <link name="link7">
    <visual>
      <geometry>
        <cylinder radius="0.07308121912682697" length="0.06199596548694865"/>
      </geometry>
      <material name="wheel_material"/>
    </visual>
    <collision>
      <geometry>
        <cylinder radius="0.07308121912682697" length="0.06199596548694865"/>
      </geometry>
    </collision>
    <inertial>
      <mass value="1.0"/>
      <inertia ixx="0.0016555077919874024" ixy="0" ixz="0" 
               iyy="0.0016555077919874024" iyz="0" 
               izz="0.00267043229453165"/>
    </inertial>
  </link>
  <joint name="joint7" type="continuous">
    <parent link="base_link"/>
    <child link="link7"/>
    <origin xyz="0 1.8692931997986473 -0.048269608032799616" rpy="1.5708 0 0"/>
    <axis xyz="0 0 1"/>
    <dynamics damping="0.1" friction="0.1"/>
  </joint>
</robot>