<?xml version="1.0"?>
<robot name="evolved_robot">
  <material name="metal">
    <color rgba="0.7 0.7 0.7 1.0"/>
  </material>
  <material name="plastic">
    <color rgba="0.3 0.3 0.9 1.0"/>
  </material>
  <material name="rubber">
    <color rgba="0.1 0.1 0.1 1.0"/>
  </material>
  <material name="red">
    <color rgba="1.0 0.0 0.0 1.0"/>
  </material>
  <material name="wheel_material">
    <color rgba="0.2 0.2 0.2 1.0"/>
  </material>
  <link name="base_link">
    <visual>
      <geometry><box size="0.2741132233951309 0.3782451910526198 0.07050113474192646"/></geometry>
      <material name="rubber"/>
    </visual>
    <collision>
      <geometry><box size="0.2741132233951309 0.3782451910526198 0.07050113474192646"/></geometry>
    </collision>
    <inertial>
      <mass value="5.0"/>
      <inertia ixx="0.12336652879527676" ixy="0" ixz="0" 
               iyy="0.06675705769997349" iyz="0" 
               izz="0.1818395698287515"/>
    </inertial>
  </link>
  <link name="link1">
    <visual>
      <geometry>
        <cylinder radius="0.06917497728969586" length="0.05731022710153902"/>
      </geometry>
      <material name="wheel_material"/>
    </visual>
    <collision>
      <geometry>
        <cylinder radius="0.06917497728969586" length="0.05731022710153902"/>
      </geometry>
    </collision>
    <inertial>
      <mass value="1.0"/>
      <inertia ixx="0.0014699995482933162" ixy="0" ixz="0" 
               iyy="0.0014699995482933162" iyz="0" 
               izz="0.0023925887415149694"/>
    </inertial>
  </link>
  <joint name="joint1" type="continuous">
    <parent link="base_link"/>
    <child link="link1"/>
    <origin xyz="0.11705661169756544 0.1891225955263099 -0.03525056737096323" rpy="1.5708 0 0"/>
    <axis xyz="0 0 1"/>
    <dynamics damping="0.805317112352375" friction="0.1"/>
  </joint>
  <link name="link2">
    <visual>
      <geometry>
        <cylinder radius="0.062178066049735234" length="0.04033913570256879"/>
      </geometry>
      <material name="wheel_material"/>
    </visual>
    <collision>
      <geometry>
        <cylinder radius="0.062178066049735234" length="0.04033913570256879"/>
      </geometry>
    </collision>
    <inertial>
      <mass value="1.0"/>
      <inertia ixx="0.0011021317968571644" ixy="0" ixz="0" 
               iyy="0.0011021317968571644" iyz="0" 
               izz="0.0019330559488426186"/>
    </inertial>
  </link>
  <joint name="joint2" type="continuous">
    <parent link="base_link"/>
    <child link="link2"/>
    <origin xyz="-0.11705661169756544 0.1891225955263099 -0.03525056737096323" rpy="1.5708 0 0"/>
    <axis xyz="0 0 1"/>
    <dynamics damping="0.5280334568378223" friction="0.1"/>
  </joint>
  <link name="link3">
    <visual>
      <geometry><cylinder radius="0.08071392809666017" length="0.126978616476631"/></geometry>
      <material name="metal"/>
    </visual>
    <collision>
      <geometry><cylinder radius="0.08071392809666017" length="0.126978616476631"/></geometry>
    </collision>
    <inertial>
      <mass value="0.5"/>
      <inertia ixx="0.0029723153007248193" ixy="0" ixz="0" 
               iyy="0.0029723153007248193" iyz="0" 
               izz="0.003257369094396414"/>
    </inertial>
  </link>
  <joint name="joint3" type="revolute">
    <parent link="base_link"/>
    <child link="link3"/>
    <origin xyz="0 0 0.03525056737096323" rpy="0 0 0"/>
    <axis xyz="0.05798002608584343 0.9921891364986303 -0.11044923715982534"/>
    <dynamics damping="0.4617477917585071" friction="0.1"/>
    <limit lower="-0.9916100505187216" upper="2.186302406053063" effort="100" velocity="100"/>
  </joint>
</robot>