<?xml version="1.0"?>
<robot name="evolved_robot">
  <material name="metal">
    <color rgba="0.7 0.7 0.7 1.0"/>
  </material>
  <material name="plastic">
    <color rgba="0.3 0.3 0.9 1.0"/>
  </material>
  <material name="rubber">
    <color rgba="0.1 0.1 0.1 1.0"/>
  </material>
  <material name="red">
    <color rgba="1.0 0.0 0.0 1.0"/>
  </material>
  <material name="wheel_material">
    <color rgba="0.2 0.2 0.2 1.0"/>
  </material>
  <link name="base_link">
    <visual>
      <geometry><box size="0.30694219765450376 0.30203459907369534 0.09359906449021912"/></geometry>
      <material name="metal"/>
    </visual>
    <collision>
      <geometry><box size="0.30694219765450376 0.30203459907369534 0.09359906449021912"/></geometry>
    </collision>
    <inertial>
      <mass value="5.0"/>
      <inertia ixx="0.08332140325921007" ixy="0" ixz="0" 
               iyy="0.08581191464535054" iyz="0" 
               izz="0.15453200978215362"/>
    </inertial>
  </link>
  <link name="link1">
    <visual>
      <geometry><cylinder radius="0.07570620283655916" length="0.14422838366837537"/></geometry>
      <material name="rubber"/>
    </visual>
    <collision>
      <geometry><cylinder radius="0.07570620283655916" length="0.14422838366837537"/></geometry>
    </collision>
    <inertial>
      <mass value="0.5"/>
      <inertia ixx="0.003166342841615233" ixy="0" ixz="0" 
               iyy="0.003166342841615233" iyz="0" 
               izz="0.0028657145739651186"/>
    </inertial>
  </link>
  <joint name="joint1" type="fixed">
    <parent link="base_link"/>
    <child link="link1"/>
    <origin xyz="0 0 0.04679953224510956" rpy="0 0 0"/>
    <axis xyz="-0.0067937694288004455 0.8570903370472414 -0.5151213437989097"/>
    <dynamics damping="0.8994036855669686" friction="0.1"/>
  </joint>
  <link name="link2">
    <visual>
      <geometry>
        <cylinder radius="0.05414362154083399" length="0.04821138832144219"/>
      </geometry>
      <material name="wheel_material"/>
    </visual>
    <collision>
      <geometry>
        <cylinder radius="0.05414362154083399" length="0.04821138832144219"/>
      </geometry>
    </collision>
    <inertial>
      <mass value="1.0"/>
      <inertia ixx="0.0009265777687126733" ixy="0" ixz="0" 
               iyy="0.0009265777687126733" iyz="0" 
               izz="0.0014657658767785312"/>
    </inertial>
  </link>
  <joint name="joint2" type="continuous">
    <parent link="base_link"/>
    <child link="link2"/>
    <origin xyz="0 0 0" rpy="1.5708 0 0"/>
    <axis xyz="0 0 1"/>
    <dynamics damping="0.22772052215840985" friction="0.1"/>
  </joint>
  <link name="link3">
    <visual>
      <geometry><sphere radius="0.030409239613041976"/></geometry>
      <material name="plastic"/>
    </visual>
    <collision>
      <geometry><sphere radius="0.030409239613041976"/></geometry>
    </collision>
    <inertial>
      <mass value="0.5"/>
      <inertia ixx="0.00036988874153736056" ixy="0" ixz="0" 
               iyy="0.00036988874153736056" iyz="0" 
               izz="0.00036988874153736056"/>
    </inertial>
  </link>
  <joint name="joint3" type="fixed">
    <parent link="base_link"/>
    <child link="link3"/>
    <origin xyz="0 0 0.09679953224510957" rpy="0 0 0"/>
    <axis xyz="-0.9467403000623275 -0.265937407513569 -0.1815491655801703"/>
    <dynamics damping="0.8006336577116039" friction="0.1"/>
  </joint>
</robot>