<?xml version="1.0"?>
<robot name="evolved_robot">
  <material name="metal">
    <color rgba="0.7 0.7 0.7 1.0"/>
  </material>
  <material name="plastic">
    <color rgba="0.3 0.3 0.9 1.0"/>
  </material>
  <material name="rubber">
    <color rgba="0.1 0.1 0.1 1.0"/>
  </material>
  <material name="red">
    <color rgba="1.0 0.0 0.0 1.0"/>
  </material>
  <material name="wheel_material">
    <color rgba="0.2 0.2 0.2 1.0"/>
  </material>
  <link name="base_link">
    <visual>
      <geometry><box size="0.30885406755078415 0.4915286942678372 0.12962811502993388"/></geometry>
      <material name="metal"/>
    </visual>
    <collision>
      <geometry><box size="0.30885406755078415 0.4915286942678372 0.12962811502993388"/></geometry>
    </collision>
    <inertial>
      <mass value="5.0"/>
      <inertia ixx="0.2153365879123823" ixy="0" ixz="0" 
               iyy="0.09349523604073175" iyz="0" 
               izz="0.28082607694275774"/>
    </inertial>
  </link>
  <link name="link1">
    <visual>
      <geometry>
        <cylinder radius="0.059676739211379726" length="0.05124717731301573"/>
      </geometry>
      <material name="wheel_material"/>
    </visual>
    <collision>
      <geometry>
        <cylinder radius="0.059676739211379726" length="0.05124717731301573"/>
      </geometry>
    </collision>
    <inertial>
      <mass value="1.0"/>
      <inertia ixx="0.0011091843992717294" ixy="0" ixz="0" 
               iyy="0.0011091843992717294" iyz="0" 
               izz="0.0017806566014515132"/>
    </inertial>
  </link>
  <joint name="joint1" type="continuous">
    <parent link="base_link"/>
    <child link="link1"/>
    <origin xyz="0.13442703377539209 0.2457643471339186 -0.06481405751496694" rpy="1.5708 0 0"/>
    <axis xyz="0 1 0"/>
    <dynamics damping="0.800080736609337" friction="0.1"/>
  </joint>
  <link name="link2">
    <visual>
      <geometry>
        <cylinder radius="0.09034281748665449" length="0.0703710266601721"/>
      </geometry>
      <material name="wheel_material"/>
    </visual>
    <collision>
      <geometry>
        <cylinder radius="0.09034281748665449" length="0.0703710266601721"/>
      </geometry>
    </collision>
    <inertial>
      <mass value="1.0"/>
      <inertia ixx="0.002453129617290629" ixy="0" ixz="0" 
               iyy="0.002453129617290629" iyz="0" 
               izz="0.004080912335713482"/>
    </inertial>
  </link>
  <joint name="joint2" type="continuous">
    <parent link="base_link"/>
    <child link="link2"/>
    <origin xyz="0.13442703377539209 -0.2457643471339186 -0.06481405751496694" rpy="1.5708 0 0"/>
    <axis xyz="0 1 0"/>
    <dynamics damping="0.856863713544254" friction="0.1"/>
  </joint>
  <link name="link3">
    <visual>
      <geometry>
        <cylinder radius="0.08812191321684362" length="0.04105152901828271"/>
      </geometry>
      <material name="wheel_material"/>
    </visual>
    <collision>
      <geometry>
        <cylinder radius="0.08812191321684362" length="0.04105152901828271"/>
      </geometry>
    </collision>
    <inertial>
      <mass value="1.0"/>
      <inertia ixx="0.002081803566810805" ixy="0" ixz="0" 
               iyy="0.002081803566810805" iyz="0" 
               izz="0.003882735794498459"/>
    </inertial>
  </link>
  <joint name="joint3" type="continuous">
    <parent link="base_link"/>
    <child link="link3"/>
    <origin xyz="-0.13442703377539209 0.2457643471339186 -0.06481405751496694" rpy="1.5708 0 0"/>
    <axis xyz="0 1 0"/>
    <dynamics damping="0.8573772911950069" friction="0.1"/>
  </joint>
  <link name="link4">
    <visual>
      <geometry>
        <cylinder radius="0.0472550505728949" length="0.07738201819576407"/>
      </geometry>
      <material name="wheel_material"/>
    </visual>
    <collision>
      <geometry>
        <cylinder radius="0.0472550505728949" length="0.07738201819576407"/>
      </geometry>
    </collision>
    <inertial>
      <mass value="1.0"/>
      <inertia ixx="0.0010572580128325104" ixy="0" ixz="0" 
               iyy="0.0010572580128325104" iyz="0" 
               izz="0.0011165199023234272"/>
    </inertial>
  </link>
  <joint name="joint4" type="continuous">
    <parent link="base_link"/>
    <child link="link4"/>
    <origin xyz="-0.13442703377539209 -0.2457643471339186 -0.06481405751496694" rpy="1.5708 0 0"/>
    <axis xyz="0 1 0"/>
    <dynamics damping="0.3922138342915281" friction="0.1"/>
  </joint>
  <link name="link5">
    <visual>
      <geometry><box size="0.06285908252994726 0.23717176276530344 0.11067024599114919"/></geometry>
      <material name="metal"/>
    </visual>
    <collision>
      <geometry><box size="0.06285908252994726 0.23717176276530344 0.11067024599114919"/></geometry>
    </collision>
    <inertial>
      <mass value="0.5"/>
      <inertia ixx="0.005708195700078571" ixy="0" ixz="0" 
               iyy="0.0013499306336873494" iyz="0" 
               izz="0.0050168091091423415"/>
    </inertial>
  </link>
  <joint name="joint5" type="floating">
    <parent link="base_link"/>
    <child link="link5"/>
    <origin xyz="0 0 0.06481405751496694" rpy="0 0 0"/>
    <axis xyz="-0.8365680093027222 -0.5105697319091915 0.19867691025747547"/>
    <dynamics damping="0.6716022380027477" friction="0.1"/>
  </joint>
  <link name="link6">
    <visual>
      <geometry>
        <cylinder radius="0.055223486595465554" length="0.04658615893413927"/>
      </geometry>
      <material name="wheel_material"/>
    </visual>
    <collision>
      <geometry>
        <cylinder radius="0.055223486595465554" length="0.04658615893413927"/>
      </geometry>
    </collision>
    <inertial>
      <mass value="1.0"/>
      <inertia ixx="0.0009432642182929646" ixy="0" ixz="0" 
               iyy="0.0009432642182929646" iyz="0" 
               izz="0.0015248167358797818"/>
    </inertial>
  </link>
  <joint name="joint6" type="continuous">
    <parent link="base_link"/>
    <child link="link6"/>
    <origin xyz="0 -0.32768579617855814 -0.06481405751496694" rpy="1.5708 0 0"/>
    <axis xyz="0 1 0"/>
    <dynamics damping="0.2508458617578207" friction="0.1"/>
  </joint>
</robot>