<?xml version="1.0"?>
<robot name="evolved_robot">
  <material name="metal">
    <color rgba="0.7 0.7 0.7 1.0"/>
  </material>
  <material name="plastic">
    <color rgba="0.3 0.3 0.9 1.0"/>
  </material>
  <material name="rubber">
    <color rgba="0.1 0.1 0.1 1.0"/>
  </material>
  <material name="red">
    <color rgba="1.0 0.0 0.0 1.0"/>
  </material>
  <material name="wheel_material">
    <color rgba="0.2 0.2 0.2 1.0"/>
  </material>
  <link name="base_link">
    <visual>
      <geometry><box size="0.30893827926748496 0.4898287477294404 0.11293765763393286"/></geometry>
      <material name="metal"/>
    </visual>
    <collision>
      <geometry><box size="0.30893827926748496 0.4898287477294404 0.11293765763393286"/></geometry>
    </collision>
    <inertial>
      <mass value="5.0"/>
      <inertia ixx="0.21057259717835933" ixy="0" ixz="0" 
               iyy="0.0901648124238283" iyz="0" 
               izz="0.2794792187491219"/>
    </inertial>
  </link>
  <link name="link1">
    <visual>
      <geometry>
        <cylinder radius="0.03925161292799869" length="0.051373417723952305"/>
      </geometry>
      <material name="wheel_material"/>
    </visual>
    <collision>
      <geometry>
        <cylinder radius="0.03925161292799869" length="0.051373417723952305"/>
      </geometry>
    </collision>
    <inertial>
      <mass value="1.0"/>
      <inertia ixx="0.0006051079500823332" ixy="0" ixz="0" 
               iyy="0.0006051079500823332" iyz="0" 
               izz="0.000770344558724717"/>
    </inertial>
  </link>
  <joint name="joint1" type="continuous">
    <parent link="base_link"/>
    <child link="link1"/>
    <origin xyz="0.1344691396337425 0.2449143738647202 -0.05646882881696643" rpy="1.5708 0 0"/>
    <axis xyz="0 1 0"/>
    <dynamics damping="0.800080736609337" friction="0.1"/>
  </joint>
  <link name="link2">
    <visual>
      <geometry><cylinder radius="0.11280514407771092" length="0.05"/></geometry>
      <material name="rubber"/>
    </visual>
    <collision>
      <geometry><cylinder radius="0.11280514407771092" length="0.05"/></geometry>
    </collision>
    <inertial>
      <mass value="0.5"/>
      <inertia ixx="0.003389583465931613" ixy="0" ixz="0" 
               iyy="0.003389583465931613" iyz="0" 
               izz="0.006362500265196559"/>
    </inertial>
  </link>
  <joint name="joint2" type="revolute">
    <parent link="base_link"/>
    <child link="link2"/>
    <origin xyz="0 0 0.05646882881696643" rpy="0 0 0"/>
    <axis xyz="0.0 0.9935421703900417 0.11346345515911926"/>
    <dynamics damping="0.856863713544254" friction="0.1"/>
    <limit lower="-1.2962509201736314" upper="1.1738453587504467" effort="100" velocity="100"/>
  </joint>
  <link name="link3">
    <visual>
      <geometry>
        <cylinder radius="0.08836949261706521" length="0.04105152901828271"/>
      </geometry>
      <material name="wheel_material"/>
    </visual>
    <collision>
      <geometry>
        <cylinder radius="0.08836949261706521" length="0.04105152901828271"/>
      </geometry>
    </collision>
    <inertial>
      <mass value="1.0"/>
      <inertia ixx="0.0020927274759109616" ixy="0" ixz="0" 
               iyy="0.0020927274759109616" iyz="0" 
               izz="0.0039045836126987716"/>
    </inertial>
  </link>
  <joint name="joint3" type="continuous">
    <parent link="base_link"/>
    <child link="link3"/>
    <origin xyz="0.1344691396337425 -0.2449143738647202 -0.05646882881696643" rpy="1.5708 0 0"/>
    <axis xyz="0 1 0"/>
    <dynamics damping="0.8573772911950069" friction="0.1"/>
  </joint>
  <link name="link4">
    <visual>
      <geometry>
        <cylinder radius="0.044752373852259414" length="0.0763337533559313"/>
      </geometry>
      <material name="wheel_material"/>
    </visual>
    <collision>
      <geometry>
        <cylinder radius="0.044752373852259414" length="0.0763337533559313"/>
      </geometry>
    </collision>
    <inertial>
      <mass value="1.0"/>
      <inertia ixx="0.0009862638998034442" ixy="0" ixz="0" 
               iyy="0.0009862638998034442" iyz="0" 
               izz="0.001001387482706196"/>
    </inertial>
  </link>
  <joint name="joint4" type="continuous">
    <parent link="base_link"/>
    <child link="link4"/>
    <origin xyz="-0.1344691396337425 0.2449143738647202 -0.05646882881696643" rpy="1.5708 0 0"/>
    <axis xyz="0 1 0"/>
    <dynamics damping="0.7077504342362109" friction="0.1"/>
  </joint>
  <link name="link5">
    <visual>
      <geometry><cylinder radius="0.09326353907995685" length="0.11067024599114919"/></geometry>
      <material name="metal"/>
    </visual>
    <collision>
      <geometry><cylinder radius="0.09326353907995685" length="0.11067024599114919"/></geometry>
    </collision>
    <inertial>
      <mass value="0.5"/>
      <inertia ixx="0.0031951805427414496" ixy="0" ixz="0" 
               iyy="0.0031951805427414496" iyz="0" 
               izz="0.00434904386085932"/>
    </inertial>
  </link>
  <joint name="joint5" type="floating">
    <parent link="base_link"/>
    <child link="link5"/>
    <origin xyz="0 0 0.10646882881696643" rpy="0 0 0"/>
    <axis xyz="-0.9070817309889379 -0.37770951426540966 0.1858447097431092"/>
    <dynamics damping="0.6722266996412448" friction="0.1"/>
  </joint>
  <link name="link6">
    <visual>
      <geometry>
        <cylinder radius="0.056216930861431924" length="0.04559188145222981"/>
      </geometry>
      <material name="wheel_material"/>
    </visual>
    <collision>
      <geometry>
        <cylinder radius="0.056216930861431924" length="0.04559188145222981"/>
      </geometry>
    </collision>
    <inertial>
      <mass value="1.0"/>
      <inertia ixx="0.000963304133399269" ixy="0" ixz="0" 
               iyy="0.000963304133399269" iyz="0" 
               izz="0.0015801716577395085"/>
    </inertial>
  </link>
  <joint name="joint6" type="continuous">
    <parent link="base_link"/>
    <child link="link6"/>
    <origin xyz="-0.1344691396337425 -0.2449143738647202 -0.05646882881696643" rpy="1.5708 0 0"/>
    <axis xyz="0 1 0"/>
    <dynamics damping="0.47291917500060554" friction="0.1"/>
  </joint>
</robot>