<?xml version="1.0"?>
<robot name="evolved_robot">
  <material name="metal">
    <color rgba="0.7 0.7 0.7 1.0"/>
  </material>
  <material name="plastic">
    <color rgba="0.3 0.3 0.9 1.0"/>
  </material>
  <material name="rubber">
    <color rgba="0.1 0.1 0.1 1.0"/>
  </material>
  <material name="red">
    <color rgba="1.0 0.0 0.0 1.0"/>
  </material>
  <material name="wheel_material">
    <color rgba="0.2 0.2 0.2 1.0"/>
  </material>
  <link name="base_link">
    <visual>
      <geometry><box size="0.30885406755078415 0.33433320111197223 0.1030862180188385"/></geometry>
      <material name="metal"/>
    </visual>
    <collision>
      <geometry><box size="0.30885406755078415 0.33433320111197223 0.1030862180188385"/></geometry>
    </collision>
    <inertial>
      <mass value="5.0"/>
      <inertia ixx="0.10200454809267163" ixy="0" ixz="0" 
               iyy="0.08834800282340986" iyz="0" 
               izz="0.17264127034036902"/>
    </inertial>
  </link>
  <link name="link1">
    <visual>
      <geometry>
        <cylinder radius="0.06276374789163566" length="0.03204948349955457"/>
      </geometry>
      <material name="wheel_material"/>
    </visual>
    <collision>
      <geometry>
        <cylinder radius="0.06276374789163566" length="0.03204948349955457"/>
      </geometry>
    </collision>
    <inertial>
      <mass value="1.0"/>
      <inertia ixx="0.0010704194617335515" ixy="0" ixz="0" 
               iyy="0.0010704194617335515" iyz="0" 
               izz="0.0019696440247024"/>
    </inertial>
  </link>
  <joint name="joint1" type="continuous">
    <parent link="base_link"/>
    <child link="link1"/>
    <origin xyz="0.13442703377539209 0.16716660055598612 -0.05154310900941925" rpy="1.5708 0 0"/>
    <axis xyz="0 1 0"/>
    <dynamics damping="0.800080736609337" friction="0.1"/>
  </joint>
  <link name="link2">
    <visual>
      <geometry><cylinder radius="0.11009293519549607" length="0.05"/></geometry>
      <material name="rubber"/>
    </visual>
    <collision>
      <geometry><cylinder radius="0.11009293519549607" length="0.05"/></geometry>
    </collision>
    <inertial>
      <mass value="0.5"/>
      <inertia ixx="0.0032384469283232575" ixy="0" ixz="0" 
               iyy="0.0032384469283232575" iyz="0" 
               izz="0.006060227189979848"/>
    </inertial>
  </link>
  <joint name="joint2" type="revolute">
    <parent link="base_link"/>
    <child link="link2"/>
    <origin xyz="0 0 0.05154310900941925" rpy="0 0 0"/>
    <axis xyz="0.010541613143239006 0.8034662202744688 -0.5952570094255062"/>
    <dynamics damping="0.856863713544254" friction="0.1"/>
    <limit lower="-1.2667756610529117" upper="2.629439545554526" effort="100" velocity="100"/>
  </joint>
  <link name="link3">
    <visual>
      <geometry><cylinder radius="0.08443651913870599" length="0.18446132048527597"/></geometry>
      <material name="rubber"/>
    </visual>
    <collision>
      <geometry><cylinder radius="0.08443651913870599" length="0.18446132048527597"/></geometry>
    </collision>
    <inertial>
      <mass value="0.5"/>
      <inertia ixx="0.004617879670662907" ixy="0" ixz="0" 
               iyy="0.004617879670662907" iyz="0" 
               izz="0.0035647628821305318"/>
    </inertial>
  </link>
  <joint name="joint3" type="floating">
    <parent link="base_link"/>
    <child link="link3"/>
    <origin xyz="0 0 0.10154310900941925" rpy="0 0 0"/>
    <axis xyz="0.4966704444239126 0.867053655901334 0.03919728847617302"/>
    <dynamics damping="0.5866365968341491" friction="0.1"/>
  </joint>
  <link name="link4">
    <visual>
      <geometry>
        <cylinder radius="0.04364683632620496" length="0.07712029603936439"/>
      </geometry>
      <material name="wheel_material"/>
    </visual>
    <collision>
      <geometry>
        <cylinder radius="0.04364683632620496" length="0.07712029603936439"/>
      </geometry>
    </collision>
    <inertial>
      <mass value="1.0"/>
      <inertia ixx="0.0009718899187548981" ixy="0" ixz="0" 
               iyy="0.0009718899187548981" iyz="0" 
               izz="0.0009525231606432624"/>
    </inertial>
  </link>
  <joint name="joint4" type="continuous">
    <parent link="base_link"/>
    <child link="link4"/>
    <origin xyz="-0.13442703377539209 0.16716660055598612 -0.05154310900941925" rpy="1.5708 0 0"/>
    <axis xyz="0 1 0"/>
    <dynamics damping="0.4050655886768495" friction="0.1"/>
  </joint>
  <link name="link5">
    <visual>
      <geometry><box size="0.0593176866318296 0.23598735471050247 0.055380896419339465"/></geometry>
      <material name="metal"/>
    </visual>
    <collision>
      <geometry><box size="0.0593176866318296 0.23598735471050247 0.055380896419339465"/></geometry>
    </collision>
    <inertial>
      <mass value="0.5"/>
      <inertia ixx="0.004896422939289176" ixy="0" ixz="0" 
               iyy="0.0005488026362967952" iyz="0" 
               izz="0.004934051627551037"/>
    </inertial>
  </link>
  <joint name="joint5" type="floating">
    <parent link="base_link"/>
    <child link="link5"/>
    <origin xyz="0 0 0.15154310900941925" rpy="0 0 0"/>
    <axis xyz="-0.8363879706747075 -0.510825839400452 0.19877656881903408"/>
    <dynamics damping="0.6149782857398248" friction="0.1"/>
  </joint>
  <link name="link6">
    <visual>
      <geometry>
        <cylinder radius="0.056118941032870365" length="0.06478545656171525"/>
      </geometry>
      <material name="wheel_material"/>
    </visual>
    <collision>
      <geometry>
        <cylinder radius="0.056118941032870365" length="0.06478545656171525"/>
      </geometry>
    </collision>
    <inertial>
      <mass value="1.0"/>
      <inertia ixx="0.0011370968341551865" ixy="0" ixz="0" 
               iyy="0.0011370968341551865" iyz="0" 
               izz="0.0015746677713253906"/>
    </inertial>
  </link>
  <joint name="joint6" type="fixed">
    <parent link="base_link"/>
    <child link="link6"/>
    <origin xyz="-0.13442703377539209 -0.16716660055598612 -0.05154310900941925" rpy="1.5708 0 0"/>
    <axis xyz="0 1 0"/>
    <dynamics damping="0.47206363896173986" friction="0.1"/>
  </joint>
</robot>