<?xml version="1.0"?>
<robot name="evolved_robot">
  <material name="metal">
    <color rgba="0.7 0.7 0.7 1.0"/>
  </material>
  <material name="plastic">
    <color rgba="0.3 0.3 0.9 1.0"/>
  </material>
  <material name="rubber">
    <color rgba="0.1 0.1 0.1 1.0"/>
  </material>
  <material name="red">
    <color rgba="1.0 0.0 0.0 1.0"/>
  </material>
  <material name="wheel_material">
    <color rgba="0.2 0.2 0.2 1.0"/>
  </material>
  <link name="base_link">
    <visual>
      <geometry><box size="0.2774935077257512 0.3082985615882441 0.1301065557292387"/></geometry>
      <material name="metal"/>
    </visual>
    <collision>
      <geometry><box size="0.2774935077257512 0.3082985615882441 0.1301065557292387"/></geometry>
    </collision>
    <inertial>
      <mass value="5.0"/>
      <inertia ixx="0.09331309910092152" ixy="0" ixz="0" 
               iyy="0.07827530222805587" iyz="0" 
               izz="0.1433755415894349"/>
    </inertial>
  </link>
  <link name="link1">
    <visual>
      <geometry><sphere radius="0.06709433510121224"/></geometry>
      <material name="rubber"/>
    </visual>
    <collision>
      <geometry><sphere radius="0.06709433510121224"/></geometry>
    </collision>
    <inertial>
      <mass value="0.5"/>
      <inertia ixx="0.0018006599210695043" ixy="0" ixz="0" 
               iyy="0.0018006599210695043" iyz="0" 
               izz="0.0018006599210695043"/>
    </inertial>
  </link>
  <joint name="joint1" type="fixed">
    <parent link="base_link"/>
    <child link="link1"/>
    <origin xyz="0 0 0.06505327786461935" rpy="0 0 0"/>
    <axis xyz="-0.5403932146525947 -0.6949516636056303 0.4743599464638657"/>
    <dynamics damping="0.1029057953056492" friction="0.1"/>
  </joint>
  <link name="link2">
    <visual>
      <geometry><cylinder radius="0.09310622068510907" length="0.19182219904361414"/></geometry>
      <material name="metal"/>
    </visual>
    <collision>
      <geometry><cylinder radius="0.09310622068510907" length="0.19182219904361414"/></geometry>
    </collision>
    <inertial>
      <mass value="0.5"/>
      <inertia ixx="0.005233505086393385" ixy="0" ixz="0" 
               iyy="0.005233505086393385" iyz="0" 
               izz="0.0043343841651321165"/>
    </inertial>
  </link>
  <joint name="joint2" type="fixed">
    <parent link="base_link"/>
    <child link="link2"/>
    <origin xyz="0 0 0.11505327786461936" rpy="0 0 0"/>
    <axis xyz="-0.39149593450402964 0.7353320091404717 -0.5531887287357306"/>
    <dynamics damping="0.13388949896992422" friction="0.1"/>
  </joint>
  <link name="link3">
    <visual>
      <geometry><cylinder radius="0.06835333975303788" length="0.16976906113014034"/></geometry>
      <material name="rubber"/>
    </visual>
    <collision>
      <geometry><cylinder radius="0.06835333975303788" length="0.16976906113014034"/></geometry>
    </collision>
    <inertial>
      <mass value="0.5"/>
      <inertia ixx="0.0035698392735993346" ixy="0" ixz="0" 
               iyy="0.0035698392735993346" iyz="0" 
               izz="0.0023360895276971143"/>
    </inertial>
  </link>
  <joint name="joint3" type="floating">
    <parent link="base_link"/>
    <child link="link3"/>
    <origin xyz="0 0 0.16505327786461937" rpy="0 0 0"/>
    <axis xyz="0.5069762699313762 0.7675227707907584 0.3922803309422299"/>
    <dynamics damping="0.6115244172497906" friction="0.1"/>
  </joint>
  <link name="link4">
    <visual>
      <geometry><sphere radius="0.04329670488096678"/></geometry>
      <material name="metal"/>
    </visual>
    <collision>
      <geometry><sphere radius="0.04329670488096678"/></geometry>
    </collision>
    <inertial>
      <mass value="0.5"/>
      <inertia ixx="0.000749841861419813" ixy="0" ixz="0" 
               iyy="0.000749841861419813" iyz="0" 
               izz="0.000749841861419813"/>
    </inertial>
  </link>
  <joint name="joint4" type="prismatic">
    <parent link="base_link"/>
    <child link="link4"/>
    <origin xyz="0 0 0.21505327786461936" rpy="0 0 0"/>
    <axis xyz="-0.4356537823973222 0.7024474871757282 0.5628261806662975"/>
    <dynamics damping="0.39116741689795687" friction="0.1"/>
    <limit lower="-1.7139746193075147" upper="2.6350249001616186" effort="100" velocity="100"/>
  </joint>
  <link name="link5">
    <visual>
      <geometry>
        <cylinder radius="0.06366403618806651" length="0.03477122871502391"/>
      </geometry>
      <material name="wheel_material"/>
    </visual>
    <collision>
      <geometry>
        <cylinder radius="0.06366403618806651" length="0.03477122871502391"/>
      </geometry>
    </collision>
    <inertial>
      <mass value="1.0"/>
      <inertia ixx="0.001114030571468236" ixy="0" ixz="0" 
               iyy="0.001114030571468236" iyz="0" 
               izz="0.0020265547518777214"/>
    </inertial>
  </link>
  <joint name="joint5" type="floating">
    <parent link="base_link"/>
    <child link="link5"/>
    <origin xyz="0 0 0" rpy="1.5708 0 0"/>
    <axis xyz="0 1 0"/>
    <dynamics damping="0.8122243216133482" friction="0.1"/>
  </joint>
  <link name="link6">
    <visual>
      <geometry><cylinder radius="0.0856100540579352" length="0.12185583155343152"/></geometry>
      <material name="metal"/>
    </visual>
    <collision>
      <geometry><cylinder radius="0.0856100540579352" length="0.12185583155343152"/></geometry>
    </collision>
    <inertial>
      <mass value="0.5"/>
      <inertia ixx="0.0030696739792488367" ixy="0" ixz="0" 
               iyy="0.0030696739792488367" iyz="0" 
               izz="0.0036645406779012937"/>
    </inertial>
  </link>
  <joint name="joint6" type="fixed">
    <parent link="base_link"/>
    <child link="link6"/>
    <origin xyz="0 0 0.26505327786461935" rpy="0 0 0"/>
    <axis xyz="0.019632654301994693 0.8606938693900898 0.5087441617152706"/>
    <dynamics damping="0.47740478372994777" friction="0.1"/>
  </joint>
</robot>