<?xml version="1.0"?>
<robot name="evolved_robot">
  <material name="metal">
    <color rgba="0.7 0.7 0.7 1.0"/>
  </material>
  <material name="plastic">
    <color rgba="0.3 0.3 0.9 1.0"/>
  </material>
  <material name="rubber">
    <color rgba="0.1 0.1 0.1 1.0"/>
  </material>
  <material name="red">
    <color rgba="1.0 0.0 0.0 1.0"/>
  </material>
  <material name="wheel_material">
    <color rgba="0.2 0.2 0.2 1.0"/>
  </material>
  <link name="base_link">
    <visual>
      <geometry><cylinder radius="0.2093413448606743" length="0.11022022719318435"/></geometry>
      <material name="metal"/>
    </visual>
    <collision>
      <geometry><cylinder radius="0.2093413448606743" length="0.11022022719318435"/></geometry>
    </collision>
    <inertial>
      <mass value="5.0"/>
      <inertia ixx="0.1196832454056204" ixy="0" ixz="0" 
               iyy="0.1196832454056204" iyz="0" 
               izz="0.21911899334037882"/>
    </inertial>
  </link>
  <link name="link1">
    <visual>
      <geometry>
        <cylinder radius="0.04978469807219235" length="0.07401096701120638"/>
      </geometry>
      <material name="wheel_material"/>
    </visual>
    <collision>
      <geometry>
        <cylinder radius="0.04978469807219235" length="0.07401096701120638"/>
      </geometry>
    </collision>
    <inertial>
      <mass value="1.0"/>
      <inertia ixx="0.0010760976436959948" ixy="0" ixz="0" 
               iyy="0.0010760976436959948" iyz="0" 
               izz="0.0012392580810696764"/>
    </inertial>
  </link>
  <joint name="joint1" type="continuous">
    <parent link="base_link"/>
    <child link="link1"/>
    <origin xyz="0 0 0" rpy="1.5708 0 0"/>
    <axis xyz="0 1 0"/>
    <dynamics damping="0.14939620959536964" friction="0.1"/>
  </joint>
  <link name="link2">
    <visual>
      <geometry><sphere radius="0.02696266330325602"/></geometry>
      <material name="rubber"/>
    </visual>
    <collision>
      <geometry><sphere radius="0.02696266330325602"/></geometry>
    </collision>
    <inertial>
      <mass value="0.5"/>
      <inertia ixx="0.0002907940849618995" ixy="0" ixz="0" 
               iyy="0.0002907940849618995" iyz="0" 
               izz="0.0002907940849618995"/>
    </inertial>
  </link>
  <joint name="joint2" type="revolute">
    <parent link="base_link"/>
    <child link="link2"/>
    <origin xyz="0 0 0.055110113596592174" rpy="0 0 0"/>
    <axis xyz="-0.7545267094459136 0.6562693385590416 0.0"/>
    <dynamics damping="0.2146818546384729" friction="0.1"/>
    <limit lower="-0.7706767376466127" upper="1.463842672214915" effort="100" velocity="100"/>
  </joint>
  <link name="link3">
    <visual>
      <geometry><cylinder radius="0.06975386762857602" length="0.15594249872497107"/></geometry>
      <material name="rubber"/>
    </visual>
    <collision>
      <geometry><cylinder radius="0.06975386762857602" length="0.15594249872497107"/></geometry>
    </collision>
    <inertial>
      <mass value="0.5"/>
      <inertia ixx="0.0032429057546685264" ixy="0" ixz="0" 
               iyy="0.0032429057546685264" iyz="0" 
               izz="0.002432801024572453"/>
    </inertial>
  </link>
  <joint name="joint3" type="revolute">
    <parent link="base_link"/>
    <child link="link3"/>
    <origin xyz="0 0 0.10511011359659217" rpy="0 0 0"/>
    <axis xyz="-0.03160115722213499 0.7246690232864017 0.6883721185168343"/>
    <dynamics damping="0.8030647058584857" friction="0.1"/>
    <limit lower="-1.032985044499204" upper="0.24972828961249283" effort="100" velocity="100"/>
  </joint>
</robot>