<?xml version="1.0"?>
<robot name="evolved_robot">
  <material name="metal">
    <color rgba="0.7 0.7 0.7 1.0"/>
  </material>
  <material name="plastic">
    <color rgba="0.3 0.3 0.9 1.0"/>
  </material>
  <material name="rubber">
    <color rgba="0.1 0.1 0.1 1.0"/>
  </material>
  <material name="red">
    <color rgba="1.0 0.0 0.0 1.0"/>
  </material>
  <material name="wheel_material">
    <color rgba="0.2 0.2 0.2 1.0"/>
  </material>
  <link name="base_link">
    <visual>
      <geometry><box size="0.2606868513748192 0.2867757265282742 0.09088184607299822"/></geometry>
      <material name="metal"/>
    </visual>
    <collision>
      <geometry><box size="0.2606868513748192 0.2867757265282742 0.09088184607299822"/></geometry>
    </collision>
    <inertial>
      <mass value="5.0"/>
      <inertia ixx="0.07541652272621305" ixy="0" ixz="0" 
               iyy="0.06351428702112767" iyz="0" 
               izz="0.12516495983794715"/>
    </inertial>
  </link>
  <link name="link1">
    <visual>
      <geometry><sphere radius="0.038968192844657516"/></geometry>
      <material name="rubber"/>
    </visual>
    <collision>
      <geometry><sphere radius="0.038968192844657516"/></geometry>
    </collision>
    <inertial>
      <mass value="0.5"/>
      <inertia ixx="0.0006074080214313669" ixy="0" ixz="0" 
               iyy="0.0006074080214313669" iyz="0" 
               izz="0.0006074080214313669"/>
    </inertial>
  </link>
  <joint name="joint1" type="revolute">
    <parent link="base_link"/>
    <child link="link1"/>
    <origin xyz="0 0 0.04544092303649911" rpy="0 0 0"/>
    <axis xyz="-0.7869295096763519 -0.5598300733294514 -0.2594845579152587"/>
    <dynamics damping="0.6497527362487487" friction="0.1"/>
    <limit lower="-1.0535184502773653" upper="1.4084694643140252" effort="100" velocity="100"/>
  </joint>
  <link name="link2">
    <visual>
      <geometry>
        <cylinder radius="0.06408738979676629" length="0.05851877251396469"/>
      </geometry>
      <material name="wheel_material"/>
    </visual>
    <collision>
      <geometry>
        <cylinder radius="0.06408738979676629" length="0.05851877251396469"/>
      </geometry>
    </collision>
    <inertial>
      <mass value="1.0"/>
      <inertia ixx="0.001312168944119095" ixy="0" ixz="0" 
               iyy="0.001312168944119095" iyz="0" 
               izz="0.002053596765481332"/>
    </inertial>
  </link>
  <joint name="joint2" type="continuous">
    <parent link="base_link"/>
    <child link="link2"/>
    <origin xyz="0 0 0" rpy="1.5708 0 0"/>
    <axis xyz="0 1 0"/>
    <dynamics damping="0.6247021823949106" friction="0.1"/>
  </joint>
  <link name="link3">
    <visual>
      <geometry><sphere radius="0.05530700378083017"/></geometry>
      <material name="metal"/>
    </visual>
    <collision>
      <geometry><sphere radius="0.05530700378083017"/></geometry>
    </collision>
    <inertial>
      <mass value="0.5"/>
      <inertia ixx="0.0012235458668851053" ixy="0" ixz="0" 
               iyy="0.0012235458668851053" iyz="0" 
               izz="0.0012235458668851053"/>
    </inertial>
  </link>
  <joint name="joint3" type="floating">
    <parent link="base_link"/>
    <child link="link3"/>
    <origin xyz="0 0 0.09544092303649912" rpy="0 0 0"/>
    <axis xyz="0.8424799735549517 0.5385787966439699 0.012663884253302955"/>
    <dynamics damping="0.9386368848209998" friction="0.1"/>
  </joint>
</robot>