<?xml version="1.0"?>
<robot name="evolved_robot">
  <material name="metal">
    <color rgba="0.7 0.7 0.7 1.0"/>
  </material>
  <material name="plastic">
    <color rgba="0.3 0.3 0.9 1.0"/>
  </material>
  <material name="rubber">
    <color rgba="0.1 0.1 0.1 1.0"/>
  </material>
  <material name="red">
    <color rgba="1.0 0.0 0.0 1.0"/>
  </material>
  <material name="wheel_material">
    <color rgba="0.2 0.2 0.2 1.0"/>
  </material>
  <link name="base_link">
    <visual>
      <geometry><cylinder radius="0.15889236903595824" length="0.12138160494244313"/></geometry>
      <material name="rubber"/>
    </visual>
    <collision>
      <geometry><cylinder radius="0.15889236903595824" length="0.12138160494244313"/></geometry>
    </collision>
    <inertial>
      <mass value="5.0"/>
      <inertia ixx="0.07539487402665063" ixy="0" ixz="0" 
               iyy="0.07539487402665063" iyz="0" 
               izz="0.1262339246892957"/>
    </inertial>
  </link>
  <link name="link1">
    <visual>
      <geometry><sphere radius="0.03874693411800107"/></geometry>
      <material name="plastic"/>
    </visual>
    <collision>
      <geometry><sphere radius="0.03874693411800107"/></geometry>
    </collision>
    <inertial>
      <mass value="0.5"/>
      <inertia ixx="0.0006005299614178862" ixy="0" ixz="0" 
               iyy="0.0006005299614178862" iyz="0" 
               izz="0.0006005299614178862"/>
    </inertial>
  </link>
  <joint name="joint1" type="prismatic">
    <parent link="base_link"/>
    <child link="link1"/>
    <origin xyz="0 0 0.060690802471221564" rpy="0 0 0"/>
    <axis xyz="0.7727812368223396 -0.5309084471866125 -0.34777202406351654"/>
    <dynamics damping="0.7528451803201905" friction="0.1"/>
    <limit lower="-1.8032658256657146" upper="1.0936309539748783" effort="100" velocity="100"/>
  </joint>
  <link name="link2">
    <visual>
      <geometry>
        <cylinder radius="0.05948470227480589" length="0.04130148012113678"/>
      </geometry>
      <material name="wheel_material"/>
    </visual>
    <collision>
      <geometry>
        <cylinder radius="0.05948470227480589" length="0.04130148012113678"/>
      </geometry>
    </collision>
    <inertial>
      <mass value="1.0"/>
      <inertia ixx="0.001026758472863629" ixy="0" ixz="0" 
               iyy="0.001026758472863629" iyz="0" 
               izz="0.0017692149023611483"/>
    </inertial>
  </link>
  <joint name="joint2" type="continuous">
    <parent link="base_link"/>
    <child link="link2"/>
    <origin xyz="0 0 0" rpy="1.5708 0 0"/>
    <axis xyz="0 1 0"/>
    <dynamics damping="0.8580717811056615" friction="0.1"/>
  </joint>
  <link name="link3">
    <visual>
      <geometry><sphere radius="0.05531625910761198"/></geometry>
      <material name="metal"/>
    </visual>
    <collision>
      <geometry><sphere radius="0.05531625910761198"/></geometry>
    </collision>
    <inertial>
      <mass value="0.5"/>
      <inertia ixx="0.0012239554086641861" ixy="0" ixz="0" 
               iyy="0.0012239554086641861" iyz="0" 
               izz="0.0012239554086641861"/>
    </inertial>
  </link>
  <joint name="joint3" type="floating">
    <parent link="base_link"/>
    <child link="link3"/>
    <origin xyz="0 0 0.11069080247122157" rpy="0 0 0"/>
    <axis xyz="0.371069022942112 0.2378058121655181 -0.8976392236935085"/>
    <dynamics damping="0.7715747739978984" friction="0.1"/>
  </joint>
</robot>