<?xml version="1.0"?>
<robot name="evolved_robot">
  <material name="metal">
    <color rgba="0.7 0.7 0.7 1.0"/>
  </material>
  <material name="plastic">
    <color rgba="0.3 0.3 0.9 1.0"/>
  </material>
  <material name="rubber">
    <color rgba="0.1 0.1 0.1 1.0"/>
  </material>
  <material name="red">
    <color rgba="1.0 0.0 0.0 1.0"/>
  </material>
  <material name="wheel_material">
    <color rgba="0.2 0.2 0.2 1.0"/>
  </material>
  <link name="base_link">
    <visual>
      <geometry><box size="0.3520523177774143 0.28830199906972864 0.12138160494244313"/></geometry>
      <material name="rubber"/>
    </visual>
    <collision>
      <geometry><box size="0.3520523177774143 0.28830199906972864 0.12138160494244313"/></geometry>
    </collision>
    <inertial>
      <mass value="5.0"/>
      <inertia ixx="0.08154294723833762" ixy="0" ixz="0" 
               iyy="0.11556194039237737" iyz="0" 
               izz="0.17254906426670943"/>
    </inertial>
  </link>
  <link name="link1">
    <visual>
      <geometry><sphere radius="0.038968192844657516"/></geometry>
      <material name="plastic"/>
    </visual>
    <collision>
      <geometry><sphere radius="0.038968192844657516"/></geometry>
    </collision>
    <inertial>
      <mass value="0.5"/>
      <inertia ixx="0.0006074080214313669" ixy="0" ixz="0" 
               iyy="0.0006074080214313669" iyz="0" 
               izz="0.0006074080214313669"/>
    </inertial>
  </link>
  <joint name="joint1" type="revolute">
    <parent link="base_link"/>
    <child link="link1"/>
    <origin xyz="0 0 0.060690802471221564" rpy="0 0 0"/>
    <axis xyz="0.7558472171279608 -0.5480777980783323 -0.3581978665675218"/>
    <dynamics damping="0.7491799144562219" friction="0.1"/>
    <limit lower="-2.1680071736017976" upper="1.0936309539748783" effort="100" velocity="100"/>
  </joint>
  <link name="link2">
    <visual>
      <geometry>
        <cylinder radius="0.06309177534795424" length="0.041489657885270634"/>
      </geometry>
      <material name="wheel_material"/>
    </visual>
    <collision>
      <geometry>
        <cylinder radius="0.06309177534795424" length="0.041489657885270634"/>
      </geometry>
    </collision>
    <inertial>
      <mass value="1.0"/>
      <inertia ixx="0.0011385923384255815" ixy="0" ixz="0" 
               iyy="0.0011385923384255815" iyz="0" 
               izz="0.001990286058278363"/>
    </inertial>
  </link>
  <joint name="joint2" type="continuous">
    <parent link="base_link"/>
    <child link="link2"/>
    <origin xyz="0 0 0" rpy="1.5708 0 0"/>
    <axis xyz="0 1 0"/>
    <dynamics damping="0.8580717811056615" friction="0.1"/>
  </joint>
  <link name="link3">
    <visual>
      <geometry><sphere radius="0.05531625910761198"/></geometry>
      <material name="plastic"/>
    </visual>
    <collision>
      <geometry><sphere radius="0.05531625910761198"/></geometry>
    </collision>
    <inertial>
      <mass value="0.5"/>
      <inertia ixx="0.0012239554086641861" ixy="0" ixz="0" 
               iyy="0.0012239554086641861" iyz="0" 
               izz="0.0012239554086641861"/>
    </inertial>
  </link>
  <joint name="joint3" type="floating">
    <parent link="base_link"/>
    <child link="link3"/>
    <origin xyz="0 0 0.11069080247122157" rpy="0 0 0"/>
    <axis xyz="0.37031706622392374 0.23203050056101004 -0.8994593472040374"/>
    <dynamics damping="0.7719846144977497" friction="0.1"/>
  </joint>
</robot>