<?xml version="1.0"?>
<robot name="evolved_robot">
  <material name="metal">
    <color rgba="0.7 0.7 0.7 1.0"/>
  </material>
  <material name="plastic">
    <color rgba="0.3 0.3 0.9 1.0"/>
  </material>
  <material name="rubber">
    <color rgba="0.1 0.1 0.1 1.0"/>
  </material>
  <material name="red">
    <color rgba="1.0 0.0 0.0 1.0"/>
  </material>
  <material name="wheel_material">
    <color rgba="0.2 0.2 0.2 1.0"/>
  </material>
  <link name="base_link">
    <visual>
      <geometry><box size="0.27966689876816897 0.3130306021335339 0.0939747855253997"/></geometry>
      <material name="plastic"/>
    </visual>
    <collision>
      <geometry><box size="0.27966689876816897 0.3130306021335339 0.0939747855253997"/></geometry>
    </collision>
    <inertial>
      <mass value="5.0"/>
      <inertia ixx="0.08901618182218973" ixy="0" ixz="0" 
               iyy="0.07253736215095845" iyz="0" 
               izz="0.14683477678224005"/>
    </inertial>
  </link>
  <link name="link1">
    <visual>
      <geometry><cylinder radius="0.07158522055848092" length="0.11932034292552557"/></geometry>
      <material name="rubber"/>
    </visual>
    <collision>
      <geometry><cylinder radius="0.07158522055848092" length="0.11932034292552557"/></geometry>
    </collision>
    <inertial>
      <mass value="0.5"/>
      <inertia ixx="0.0024675563035903413" ixy="0" ixz="0" 
               iyy="0.0024675563035903413" iyz="0" 
               izz="0.0025622219012031797"/>
    </inertial>
  </link>
  <joint name="joint1" type="prismatic">
    <parent link="base_link"/>
    <child link="link1"/>
    <origin xyz="0 0 0.04698739276269985" rpy="0 0 0"/>
    <axis xyz="0.9162275239977837 0.0 -0.40065836353293605"/>
    <dynamics damping="0.6661406666244551" friction="0.1"/>
    <limit lower="-2.463205702204663" upper="0.942" effort="100" velocity="100"/>
  </joint>
  <link name="link2">
    <visual>
      <geometry><cylinder radius="0.0729829788216498" length="0.23801301163442995"/></geometry>
      <material name="plastic"/>
    </visual>
    <collision>
      <geometry><cylinder radius="0.0729829788216498" length="0.23801301163442995"/></geometry>
    </collision>
    <inertial>
      <mass value="0.5"/>
      <inertia ixx="0.006052478275027953" ixy="0" ixz="0" 
               iyy="0.006052478275027953" iyz="0" 
               izz="0.002663257598840691"/>
    </inertial>
  </link>
  <joint name="joint2" type="revolute">
    <parent link="base_link"/>
    <child link="link2"/>
    <origin xyz="0 0 0.09698739276269985" rpy="0 0 0"/>
    <axis xyz="0.0 0.7095216342913799 -0.7046836527637698"/>
    <dynamics damping="0.4562130730949524" friction="0.1"/>
    <limit lower="-1.3571484268149911" upper="0.31400000000000006" effort="100" velocity="100"/>
  </joint>
  <link name="link3">
    <visual>
      <geometry><box size="0.13897668636447152 0.24785417138997268 0.24799067398548424"/></geometry>
      <material name="plastic"/>
    </visual>
    <collision>
      <geometry><box size="0.13897668636447152 0.24785417138997268 0.24799067398548424"/></geometry>
    </collision>
    <inertial>
      <mass value="0.5"/>
      <inertia ixx="0.010244255388265391" ixy="0" ixz="0" 
               iyy="0.006734491144718618" iyz="0" 
               izz="0.006728850802354886"/>
    </inertial>
  </link>
  <joint name="joint3" type="fixed">
    <parent link="base_link"/>
    <child link="link3"/>
    <origin xyz="0 0 0.14698739276269984" rpy="0 0 0"/>
    <axis xyz="0.6221623465747899 -0.6567903462991199 -0.42607564529415815"/>
    <dynamics damping="0.7675710804531435" friction="0.1"/>
  </joint>
</robot>