<?xml version="1.0"?>
<robot name="evolved_robot">
  <material name="metal">
    <color rgba="0.7 0.7 0.7 1.0"/>
  </material>
  <material name="plastic">
    <color rgba="0.3 0.3 0.9 1.0"/>
  </material>
  <material name="rubber">
    <color rgba="0.1 0.1 0.1 1.0"/>
  </material>
  <material name="red">
    <color rgba="1.0 0.0 0.0 1.0"/>
  </material>
  <material name="wheel_material">
    <color rgba="0.2 0.2 0.2 1.0"/>
  </material>
  <link name="base_link">
    <visual>
      <geometry><cylinder radius="0.11914373872814613" length="0.1222400662433975"/></geometry>
      <material name="metal"/>
    </visual>
    <collision>
      <geometry><cylinder radius="0.11914373872814613" length="0.1222400662433975"/></geometry>
    </collision>
    <inertial>
      <mass value="5.0"/>
      <inertia ixx="0.047940271024627036" ixy="0" ixz="0" 
               iyy="0.047940271024627036" iyz="0" 
               izz="0.07097615239060373"/>
    </inertial>
  </link>
  <link name="link1">
    <visual>
      <geometry><cylinder radius="0.08198830787742387" length="0.13188925897552822"/></geometry>
      <material name="plastic"/>
    </visual>
    <collision>
      <geometry><cylinder radius="0.08198830787742387" length="0.13188925897552822"/></geometry>
    </collision>
    <inertial>
      <mass value="0.5"/>
      <inertia ixx="0.0031300853765769735" ixy="0" ixz="0" 
               iyy="0.0031300853765769735" iyz="0" 
               izz="0.003361041314301622"/>
    </inertial>
  </link>
  <joint name="joint1" type="revolute">
    <parent link="base_link"/>
    <child link="link1"/>
    <origin xyz="0 0 0.06112003312169875" rpy="0 0 0"/>
    <axis xyz="0.9129993566837745 0.3296026305840588 0.24040441053999465"/>
    <dynamics damping="0.7359971814790645" friction="0.1"/>
    <limit lower="-1.6878129517187643" upper="0.9260778014596435" effort="100" velocity="100"/>
  </joint>
  <link name="link2">
    <visual>
      <geometry><box size="0.07242867081383741 0.11224938386190869 0.18783796745459674"/></geometry>
      <material name="rubber"/>
    </visual>
    <collision>
      <geometry><box size="0.07242867081383741 0.11224938386190869 0.18783796745459674"/></geometry>
    </collision>
    <inertial>
      <mass value="0.5"/>
      <inertia ixx="0.003990252182904355" ixy="0" ixz="0" 
               iyy="0.003377417864444447" iyz="0" 
               izz="0.0014871530444364462"/>
    </inertial>
  </link>
  <joint name="joint2" type="revolute">
    <parent link="base_link"/>
    <child link="link2"/>
    <origin xyz="0 0 0.11112003312169876" rpy="0 0 0"/>
    <axis xyz="0.4967984064063378 -0.8664829263810957 -0.0489763379824961"/>
    <dynamics damping="0.7292250985731518" friction="0.1"/>
    <limit lower="-2.414115064041525" upper="0.34416536407093423" effort="100" velocity="100"/>
  </joint>
  <link name="link3">
    <visual>
      <geometry><cylinder radius="0.06493263360332116" length="0.06972589290644436"/></geometry>
      <material name="metal"/>
    </visual>
    <collision>
      <geometry><cylinder radius="0.06493263360332116" length="0.06972589290644436"/></geometry>
    </collision>
    <inertial>
      <mass value="0.5"/>
      <inertia ixx="0.0014592034051325337" ixy="0" ixz="0" 
               iyy="0.0014592034051325337" iyz="0" 
               izz="0.002108123453331576"/>
    </inertial>
  </link>
  <joint name="joint3" type="fixed">
    <parent link="base_link"/>
    <child link="link3"/>
    <origin xyz="0 0 0.16112003312169876" rpy="0 0 0"/>
    <axis xyz="0.35211363984873595 0.8152725844333524 0.45972448020943696"/>
    <dynamics damping="0.5669098995162578" friction="0.1"/>
  </joint>
  <link name="link4">
    <visual>
      <geometry><cylinder radius="0.08833531434849853" length="0.051915120252672614"/></geometry>
      <material name="plastic"/>
    </visual>
    <collision>
      <geometry><cylinder radius="0.08833531434849853" length="0.051915120252672614"/></geometry>
    </collision>
    <inertial>
      <mass value="0.5"/>
      <inertia ixx="0.0021753802494994677" ixy="0" ixz="0" 
               iyy="0.0021753802494994677" iyz="0" 
               izz="0.0039015638805240255"/>
    </inertial>
  </link>
  <joint name="joint4" type="revolute">
    <parent link="base_link"/>
    <child link="link4"/>
    <origin xyz="0 0 0.21112003312169877" rpy="0 0 0"/>
    <axis xyz="0.0 1.0 0.0"/>
    <dynamics damping="0.7586822519868953" friction="0.1"/>
    <limit lower="-2.2870075350351278" upper="1.0957559901947327" effort="100" velocity="100"/>
  </joint>
</robot>