<?xml version="1.0"?>
<robot name="evolved_robot">
  <material name="metal">
    <color rgba="0.7 0.7 0.7 1.0"/>
  </material>
  <material name="plastic">
    <color rgba="0.3 0.3 0.9 1.0"/>
  </material>
  <material name="rubber">
    <color rgba="0.1 0.1 0.1 1.0"/>
  </material>
  <material name="red">
    <color rgba="1.0 0.0 0.0 1.0"/>
  </material>
  <material name="wheel_material">
    <color rgba="0.2 0.2 0.2 1.0"/>
  </material>
  <link name="base_link">
    <visual>
      <geometry><box size="0.314937614659212 0.3361883288096972 0.08684391380071729"/></geometry>
      <material name="plastic"/>
    </visual>
    <collision>
      <geometry><box size="0.314937614659212 0.3361883288096972 0.08684391380071729"/></geometry>
    </collision>
    <inertial>
      <mass value="5.0"/>
      <inertia ixx="0.10047038149340291" ixy="0" ixz="0" 
               iyy="0.08893963874288395" iyz="0" 
               izz="0.17684024462924278"/>
    </inertial>
  </link>
  <link name="link1">
    <visual>
      <geometry>
        <cylinder radius="0.06255185810306499" length="0.06011304128127823"/>
      </geometry>
      <material name="wheel_material"/>
    </visual>
    <collision>
      <geometry>
        <cylinder radius="0.06255185810306499" length="0.06011304128127823"/>
      </geometry>
    </collision>
    <inertial>
      <mass value="1.0"/>
      <inertia ixx="0.0012793152157102158" ixy="0" ixz="0" 
               iyy="0.0012793152157102158" iyz="0" 
               izz="0.0019563674760729884"/>
    </inertial>
  </link>
  <joint name="joint1" type="continuous">
    <parent link="base_link"/>
    <child link="link1"/>
    <origin xyz="0.137468807329606 0.1680941644048486 -0.043421956900358646" rpy="1.5708 0 0"/>
    <axis xyz="0 0 1"/>
    <dynamics damping="0.8500411419634986" friction="0.1"/>
  </joint>
  <link name="link2">
    <visual>
      <geometry>
        <cylinder radius="0.07578756342487761" length="0.042797147168368375"/>
      </geometry>
      <material name="wheel_material"/>
    </visual>
    <collision>
      <geometry>
        <cylinder radius="0.07578756342487761" length="0.042797147168368375"/>
      </geometry>
    </collision>
    <inertial>
      <mass value="1.0"/>
      <inertia ixx="0.0015885716762825432" ixy="0" ixz="0" 
               iyy="0.0015885716762825432" iyz="0" 
               izz="0.002871877384939923"/>
    </inertial>
  </link>
  <joint name="joint2" type="continuous">
    <parent link="base_link"/>
    <child link="link2"/>
    <origin xyz="-0.137468807329606 0.1680941644048486 -0.043421956900358646" rpy="1.5708 0 0"/>
    <axis xyz="0 0 1"/>
    <dynamics damping="0.9332973929305248" friction="0.1"/>
  </joint>
  <link name="link3">
    <visual>
      <geometry>
        <cylinder radius="0.06341371124760828" length="0.04616174105648255"/>
      </geometry>
      <material name="wheel_material"/>
    </visual>
    <collision>
      <geometry>
        <cylinder radius="0.06341371124760828" length="0.04616174105648255"/>
      </geometry>
    </collision>
    <inertial>
      <mass value="1.0"/>
      <inertia ixx="0.0011829002216625724" ixy="0" ixz="0" 
               iyy="0.0011829002216625724" iyz="0" 
               izz="0.0020106493870975205"/>
    </inertial>
  </link>
  <joint name="joint3" type="continuous">
    <parent link="base_link"/>
    <child link="link3"/>
    <origin xyz="-0.137468807329606 -0.1680941644048486 -0.043421956900358646" rpy="1.5708 0 0"/>
    <axis xyz="0 0 1"/>
    <dynamics damping="0.43936669472471734" friction="0.1"/>
  </joint>
  <link name="link4">
    <visual>
      <geometry><sphere radius="0.06352190067907698"/></geometry>
      <material name="metal"/>
    </visual>
    <collision>
      <geometry><sphere radius="0.06352190067907698"/></geometry>
    </collision>
    <inertial>
      <mass value="0.5"/>
      <inertia ixx="0.0016140127463530082" ixy="0" ixz="0" 
               iyy="0.0016140127463530082" iyz="0" 
               izz="0.0016140127463530082"/>
    </inertial>
  </link>
  <joint name="joint4" type="revolute">
    <parent link="base_link"/>
    <child link="link4"/>
    <origin xyz="0 0 0.043421956900358646" rpy="0 0 0"/>
    <axis xyz="0.5330463325691726 0.7851356607893004 -0.31531508287981364"/>
    <dynamics damping="0.6057419292639447" friction="0.1"/>
    <limit lower="-1.4255993078430136" upper="1.4453509454170275" effort="100" velocity="100"/>
  </joint>
</robot>