<?xml version="1.0"?>
<robot name="evolved_robot">
  <material name="metal">
    <color rgba="0.7 0.7 0.7 1.0"/>
  </material>
  <material name="plastic">
    <color rgba="0.3 0.3 0.9 1.0"/>
  </material>
  <material name="rubber">
    <color rgba="0.1 0.1 0.1 1.0"/>
  </material>
  <material name="red">
    <color rgba="1.0 0.0 0.0 1.0"/>
  </material>
  <material name="wheel_material">
    <color rgba="0.2 0.2 0.2 1.0"/>
  </material>
  <link name="base_link">
    <visual>
      <geometry><cylinder radius="0.11914373872814613" length="0.12442829490669932"/></geometry>
      <material name="metal"/>
    </visual>
    <collision>
      <geometry><cylinder radius="0.11914373872814613" length="0.12442829490669932"/></geometry>
    </collision>
    <inertial>
      <mass value="5.0"/>
      <inertia ixx="0.04839007667312565" ixy="0" ixz="0" 
               iyy="0.04839007667312565" iyz="0" 
               izz="0.07097615239060373"/>
    </inertial>
  </link>
  <link name="link1">
    <visual>
      <geometry><box size="0.11662271331401174 0.1505596901425931 0.13188925897552822"/></geometry>
      <material name="plastic"/>
    </visual>
    <collision>
      <geometry><box size="0.11662271331401174 0.1505596901425931 0.13188925897552822"/></geometry>
    </collision>
    <inertial>
      <mass value="0.5"/>
      <inertia ixx="0.0033385830774122997" ixy="0" ixz="0" 
               iyy="0.0025829694911530103" iyz="0" 
               izz="0.0030224231297129845"/>
    </inertial>
  </link>
  <joint name="joint1" type="revolute">
    <parent link="base_link"/>
    <child link="link1"/>
    <origin xyz="0 0 0.06221414745334966" rpy="0 0 0"/>
    <axis xyz="0.9134203482828432 0.22663538062713712 -0.3380823443938506"/>
    <dynamics damping="0.7368814650449035" friction="0.1"/>
    <limit lower="-1.6878129517187643" upper="1.099" effort="100" velocity="100"/>
  </joint>
  <link name="link2">
    <visual>
      <geometry>
        <cylinder radius="0.06187990215402424" length="0.0386748151585726"/>
      </geometry>
      <material name="wheel_material"/>
    </visual>
    <collision>
      <geometry>
        <cylinder radius="0.06187990215402424" length="0.0386748151585726"/>
      </geometry>
    </collision>
    <inertial>
      <mass value="1.0"/>
      <inertia ixx="0.0010819256832770498" ixy="0" ixz="0" 
               iyy="0.0010819256832770498" iyz="0" 
               izz="0.0019145611452958068"/>
    </inertial>
  </link>
  <joint name="joint2" type="continuous">
    <parent link="base_link"/>
    <child link="link2"/>
    <origin xyz="0.08240792650231374 0.13587955095397852 -0.06221414745334966" rpy="1.5708 0 0"/>
    <axis xyz="0 1 0"/>
    <dynamics damping="0.7292250985731518" friction="0.1"/>
  </joint>
  <link name="link3">
    <visual>
      <geometry><cylinder radius="0.06672999116592493" length="0.05250902600688522"/></geometry>
      <material name="metal"/>
    </visual>
    <collision>
      <geometry><cylinder radius="0.06672999116592493" length="0.05250902600688522"/></geometry>
    </collision>
    <inertial>
      <mass value="0.5"/>
      <inertia ixx="0.0013429894146004169" ixy="0" ixz="0" 
               iyy="0.0013429894146004169" iyz="0" 
               izz="0.0022264458605022095"/>
    </inertial>
  </link>
  <joint name="joint3" type="revolute">
    <parent link="base_link"/>
    <child link="link3"/>
    <origin xyz="0 0 0.11221414745334966" rpy="0 0 0"/>
    <axis xyz="-0.22808564634430187 0.9537868952691053 -0.1956207973213043"/>
    <dynamics damping="0.8238974772228634" friction="0.1"/>
    <limit lower="-1.4281660174715174" upper="1.1222627562905743" effort="100" velocity="100"/>
  </joint>
  <link name="link4">
    <visual>
      <geometry>
        <cylinder radius="0.06129515850623454" length="0.054982276945663475"/>
      </geometry>
      <material name="wheel_material"/>
    </visual>
    <collision>
      <geometry>
        <cylinder radius="0.06129515850623454" length="0.054982276945663475"/>
      </geometry>
    </collision>
    <inertial>
      <mass value="1.0"/>
      <inertia ixx="0.001191195012253574" ixy="0" ixz="0" 
               iyy="0.001191195012253574" iyz="0" 
               izz="0.0018785482281522083"/>
    </inertial>
  </link>
  <joint name="joint4" type="continuous">
    <parent link="base_link"/>
    <child link="link4"/>
    <origin xyz="-0.08240792650231374 0.13587955095397852 -0.06221414745334966" rpy="1.5708 0 0"/>
    <axis xyz="0 1 0"/>
    <dynamics damping="0.7533931194174213" friction="0.1"/>
  </joint>
</robot>