<?xml version="1.0"?>
<robot name="evolved_robot">
  <material name="metal">
    <color rgba="0.7 0.7 0.7 1.0"/>
  </material>
  <material name="plastic">
    <color rgba="0.3 0.3 0.9 1.0"/>
  </material>
  <material name="rubber">
    <color rgba="0.1 0.1 0.1 1.0"/>
  </material>
  <material name="red">
    <color rgba="1.0 0.0 0.0 1.0"/>
  </material>
  <material name="wheel_material">
    <color rgba="0.2 0.2 0.2 1.0"/>
  </material>
  <link name="base_link">
    <visual>
      <geometry><box size="0.34879374961555876 0.2867757265282742 0.12138160494244313"/></geometry>
      <material name="metal"/>
    </visual>
    <collision>
      <geometry><box size="0.34879374961555876 0.2867757265282742 0.12138160494244313"/></geometry>
    </collision>
    <inertial>
      <mass value="5.0"/>
      <inertia ixx="0.08081150945351905" ixy="0" ixz="0" 
               iyy="0.11365881149107036" iyz="0" 
               izz="0.16991449758058386"/>
    </inertial>
  </link>
  <link name="link1">
    <visual>
      <geometry><sphere radius="0.038968192844657516"/></geometry>
      <material name="plastic"/>
    </visual>
    <collision>
      <geometry><sphere radius="0.038968192844657516"/></geometry>
    </collision>
    <inertial>
      <mass value="0.5"/>
      <inertia ixx="0.0006074080214313669" ixy="0" ixz="0" 
               iyy="0.0006074080214313669" iyz="0" 
               izz="0.0006074080214313669"/>
    </inertial>
  </link>
  <joint name="joint1" type="revolute">
    <parent link="base_link"/>
    <child link="link1"/>
    <origin xyz="0 0 0.060690802471221564" rpy="0 0 0"/>
    <axis xyz="0.7590999362456892 -0.5425448325609833 -0.35973933820638143"/>
    <dynamics damping="0.7491799144562219" friction="0.1"/>
    <limit lower="-2.1680071736017976" upper="1.0936309539748783" effort="100" velocity="100"/>
  </joint>
  <link name="link2">
    <visual>
      <geometry>
        <cylinder radius="0.06309177534795424" length="0.04130148012113678"/>
      </geometry>
      <material name="wheel_material"/>
    </visual>
    <collision>
      <geometry>
        <cylinder radius="0.06309177534795424" length="0.04130148012113678"/>
      </geometry>
    </collision>
    <inertial>
      <mass value="1.0"/>
      <inertia ixx="0.0011372940508222362" ixy="0" ixz="0" 
               iyy="0.0011372940508222362" iyz="0" 
               izz="0.001990286058278363"/>
    </inertial>
  </link>
  <joint name="joint2" type="continuous">
    <parent link="base_link"/>
    <child link="link2"/>
    <origin xyz="0 0 0" rpy="1.5708 0 0"/>
    <axis xyz="0 1 0"/>
    <dynamics damping="0.8580717811056615" friction="0.1"/>
  </joint>
  <link name="link3">
    <visual>
      <geometry><sphere radius="0.05531625910761198"/></geometry>
      <material name="plastic"/>
    </visual>
    <collision>
      <geometry><sphere radius="0.05531625910761198"/></geometry>
    </collision>
    <inertial>
      <mass value="0.5"/>
      <inertia ixx="0.0012239554086641861" ixy="0" ixz="0" 
               iyy="0.0012239554086641861" iyz="0" 
               izz="0.0012239554086641861"/>
    </inertial>
  </link>
  <joint name="joint3" type="floating">
    <parent link="base_link"/>
    <child link="link3"/>
    <origin xyz="0 0 0.11069080247122157" rpy="0 0 0"/>
    <axis xyz="0.36290759364685826 0.23275981439638746 -0.9022865106359542"/>
    <dynamics damping="0.7719846144977497" friction="0.1"/>
  </joint>
</robot>