<?xml version="1.0"?>
<robot name="evolved_robot">
  <material name="metal">
    <color rgba="0.7 0.7 0.7 1.0"/>
  </material>
  <material name="plastic">
    <color rgba="0.3 0.3 0.9 1.0"/>
  </material>
  <material name="rubber">
    <color rgba="0.1 0.1 0.1 1.0"/>
  </material>
  <material name="red">
    <color rgba="1.0 0.0 0.0 1.0"/>
  </material>
  <material name="wheel_material">
    <color rgba="0.2 0.2 0.2 1.0"/>
  </material>
  <link name="base_link">
    <visual>
      <geometry><cylinder radius="0.15991811036551018" length="0.1023509380452807"/></geometry>
      <material name="metal"/>
    </visual>
    <collision>
      <geometry><cylinder radius="0.15991811036551018" length="0.1023509380452807"/></geometry>
    </collision>
    <inertial>
      <mass value="5.0"/>
      <inertia ixx="0.07266426715614614" ixy="0" ixz="0" 
               iyy="0.07266426715614614" iyz="0" 
               izz="0.12786901011437746"/>
    </inertial>
  </link>
  <link name="link1">
    <visual>
      <geometry><box size="0.113441418210562 0.07945974443179676 0.23563188659145184"/></geometry>
      <material name="rubber"/>
    </visual>
    <collision>
      <geometry><box size="0.113441418210562 0.07945974443179676 0.23563188659145184"/></geometry>
    </collision>
    <inertial>
      <mass value="0.5"/>
      <inertia ixx="0.0051530197469844405" ixy="0" ixz="0" 
               iyy="0.0056992784453558714" iyz="0" 
               izz="0.0015985671958991738"/>
    </inertial>
  </link>
  <joint name="joint1" type="prismatic">
    <parent link="base_link"/>
    <child link="link1"/>
    <origin xyz="0 0 0.05117546902264035" rpy="0 0 0"/>
    <axis xyz="0.7413132133729508 0.48069321680617366 0.4683895291263493"/>
    <dynamics damping="0.23143663430366734" friction="0.1"/>
    <limit lower="-1.6182145099100538" upper="2.6608742781213874" effort="100" velocity="100"/>
  </joint>
  <link name="link2">
    <visual>
      <geometry><box size="0.22179826410941372 0.16207127394998422 0.20487811919291604"/></geometry>
      <material name="metal"/>
    </visual>
    <collision>
      <geometry><box size="0.22179826410941372 0.16207127394998422 0.20487811919291604"/></geometry>
    </collision>
    <inertial>
      <mass value="0.5"/>
      <inertia ixx="0.005686845130316462" ixy="0" ixz="0" 
               iyy="0.007597459473831329" iyz="0" 
               izz="0.006288463983476674"/>
    </inertial>
  </link>
  <joint name="joint2" type="floating">
    <parent link="base_link"/>
    <child link="link2"/>
    <origin xyz="0 0 0.10117546902264035" rpy="0 0 0"/>
    <axis xyz="-0.9341409314151112 0.3549378761105128 -0.03741422666669626"/>
    <dynamics damping="0.6410822183068076" friction="0.1"/>
  </joint>
  <link name="link3">
    <visual>
      <geometry>
        <cylinder radius="0.08166747481168654" length="0.06891363721656031"/>
      </geometry>
      <material name="wheel_material"/>
    </visual>
    <collision>
      <geometry>
        <cylinder radius="0.08166747481168654" length="0.06891363721656031"/>
      </geometry>
    </collision>
    <inertial>
      <mass value="1.0"/>
      <inertia ixx="0.0020631515600640043" ixy="0" ixz="0" 
               iyy="0.0020631515600640043" iyz="0" 
               izz="0.0033347882210587277"/>
    </inertial>
  </link>
  <joint name="joint3" type="continuous">
    <parent link="base_link"/>
    <child link="link3"/>
    <origin xyz="0.13346351956695493 0.16637270116406544 -0.05117546902264035" rpy="1.5708 0 0"/>
    <axis xyz="0 1 0"/>
    <dynamics damping="0.8588994804943139" friction="0.1"/>
  </joint>
  <link name="link4">
    <visual>
      <geometry>
        <cylinder radius="0.06337681127266628" length="0.06788191875677616"/>
      </geometry>
      <material name="wheel_material"/>
    </visual>
    <collision>
      <geometry>
        <cylinder radius="0.06337681127266628" length="0.06788191875677616"/>
      </geometry>
    </collision>
    <inertial>
      <mass value="1.0"/>
      <inertia ixx="0.00138815129294792" ixy="0" ixz="0" 
               iyy="0.00138815129294792" iyz="0" 
               izz="0.0020083101035455802"/>
    </inertial>
  </link>
  <joint name="joint4" type="continuous">
    <parent link="base_link"/>
    <child link="link4"/>
    <origin xyz="-0.13346351956695493 0.16637270116406544 -0.05117546902264035" rpy="1.5708 0 0"/>
    <axis xyz="0 1 0"/>
    <dynamics damping="0.6803936122012411" friction="0.1"/>
  </joint>
  <link name="link5">
    <visual>
      <geometry><box size="0.1735853947968115 0.0795026568640948 0.21633961171458604"/></geometry>
      <material name="metal"/>
    </visual>
    <collision>
      <geometry><box size="0.1735853947968115 0.0795026568640948 0.21633961171458604"/></geometry>
    </collision>
    <inertial>
      <mass value="0.5"/>
      <inertia ixx="0.004426958337105655" ixy="0" ixz="0" 
               iyy="0.006411226406965231" iyz="0" 
               izz="0.0030377134779345765"/>
    </inertial>
  </link>
  <joint name="joint5" type="fixed">
    <parent link="base_link"/>
    <child link="link5"/>
    <origin xyz="0 0 0.15117546902264034" rpy="0 0 0"/>
    <axis xyz="-0.9911563891040165 -0.04710145978600313 0.12405831219355974"/>
    <dynamics damping="0.5869721733704075" friction="0.1"/>
  </joint>
  <link name="link6">
    <visual>
      <geometry>
        <cylinder radius="0.058810175419209576" length="0.057469037743392584"/>
      </geometry>
      <material name="wheel_material"/>
    </visual>
    <collision>
      <geometry>
        <cylinder radius="0.058810175419209576" length="0.057469037743392584"/>
      </geometry>
    </collision>
    <inertial>
      <mass value="1.0"/>
      <inertia ixx="0.0011398833748055073" ixy="0" ixz="0" 
               iyy="0.0011398833748055073" iyz="0" 
               izz="0.001729318366419101"/>
    </inertial>
  </link>
  <joint name="joint6" type="continuous">
    <parent link="base_link"/>
    <child link="link6"/>
    <origin xyz="-0.13346351956695493 -0.16637270116406544 -0.05117546902264035" rpy="1.5708 0 0"/>
    <axis xyz="0 1 0"/>
    <dynamics damping="0.7100066042512578" friction="0.1"/>
  </joint>
</robot>