<?xml version="1.0"?>
<robot name="evolved_robot">
  <material name="metal">
    <color rgba="0.7 0.7 0.7 1.0"/>
  </material>
  <material name="plastic">
    <color rgba="0.3 0.3 0.9 1.0"/>
  </material>
  <material name="rubber">
    <color rgba="0.1 0.1 0.1 1.0"/>
  </material>
  <material name="red">
    <color rgba="1.0 0.0 0.0 1.0"/>
  </material>
  <material name="wheel_material">
    <color rgba="0.2 0.2 0.2 1.0"/>
  </material>
  <link name="base_link">
    <visual>
      <geometry><box size="0.20539480586904316 0.28830199906972864 0.08798855919073341"/></geometry>
      <material name="rubber"/>
    </visual>
    <collision>
      <geometry><box size="0.20539480586904316 0.28830199906972864 0.08798855919073341"/></geometry>
    </collision>
    <inertial>
      <mass value="5.0"/>
      <inertia ixx="0.07571669101338584" ixy="0" ixz="0" 
               iyy="0.0416075106887026" iyz="0" 
               izz="0.10442089078798644"/>
    </inertial>
  </link>
  <link name="link1">
    <visual>
      <geometry><sphere radius="0.038968192844657516"/></geometry>
      <material name="plastic"/>
    </visual>
    <collision>
      <geometry><sphere radius="0.038968192844657516"/></geometry>
    </collision>
    <inertial>
      <mass value="0.5"/>
      <inertia ixx="0.0006074080214313669" ixy="0" ixz="0" 
               iyy="0.0006074080214313669" iyz="0" 
               izz="0.0006074080214313669"/>
    </inertial>
  </link>
  <joint name="joint1" type="revolute">
    <parent link="base_link"/>
    <child link="link1"/>
    <origin xyz="0 0 0.043994279595366705" rpy="0 0 0"/>
    <axis xyz="0.7570411343229608 -0.5469219437961488 -0.35744245458149954"/>
    <dynamics damping="0.7491799144562219" friction="0.1"/>
    <limit lower="-0.9535321087279074" upper="1.0936309539748783" effort="100" velocity="100"/>
  </joint>
  <link name="link2">
    <visual>
      <geometry><cylinder radius="0.0805378644486722" length="0.05007529541319325"/></geometry>
      <material name="rubber"/>
    </visual>
    <collision>
      <geometry><cylinder radius="0.0805378644486722" length="0.05007529541319325"/></geometry>
    </collision>
    <inertial>
      <mass value="0.5"/>
      <inertia ixx="0.0018305481700480553" ixy="0" ixz="0" 
               iyy="0.0018305481700480553" iyz="0" 
               izz="0.0032431738049763484"/>
    </inertial>
  </link>
  <joint name="joint2" type="revolute">
    <parent link="base_link"/>
    <child link="link2"/>
    <origin xyz="0 0 0.09399427959536671" rpy="0 0 0"/>
    <axis xyz="0.13126381985011018 0.9863902866756853 0.09901521070127245"/>
    <dynamics damping="0.8573928434698203" friction="0.1"/>
    <limit lower="-1.5066574809286484" upper="2.7611606731638587" effort="100" velocity="100"/>
  </joint>
  <link name="link3">
    <visual>
      <geometry><box size="0.15388767266685266 0.15544684601993203 0.1391277063413761"/></geometry>
      <material name="plastic"/>
    </visual>
    <collision>
      <geometry><box size="0.15388767266685266 0.15544684601993203 0.1391277063413761"/></geometry>
    </collision>
    <inertial>
      <mass value="0.5"/>
      <inertia ixx="0.003626686717446387" ixy="0" ixz="0" 
               iyy="0.0035864945392193814" iyz="0" 
               izz="0.0039870948113637375"/>
    </inertial>
  </link>
  <joint name="joint3" type="floating">
    <parent link="base_link"/>
    <child link="link3"/>
    <origin xyz="0 0 0.1439942795953667" rpy="0 0 0"/>
    <axis xyz="0.8336688159648046 0.5219967018625398 0.18032123705340855"/>
    <dynamics damping="0.7730691088616651" friction="0.1"/>
  </joint>
  <link name="link4">
    <visual>
      <geometry><cylinder radius="0.07448072173327173" length="0.05"/></geometry>
      <material name="rubber"/>
    </visual>
    <collision>
      <geometry><cylinder radius="0.07448072173327173" length="0.05"/></geometry>
    </collision>
    <inertial>
      <mass value="0.5"/>
      <inertia ixx="0.0015951778108105972" ixy="0" ixz="0" 
               iyy="0.0015951778108105972" iyz="0" 
               izz="0.002773688954954528"/>
    </inertial>
  </link>
  <joint name="joint4" type="revolute">
    <parent link="base_link"/>
    <child link="link4"/>
    <origin xyz="0 0 0.19399427959536672" rpy="0 0 0"/>
    <axis xyz="0.0005765084372069552 0.999999833818997 0.0"/>
    <dynamics damping="0.8798366179505495" friction="0.1"/>
    <limit lower="-1.4170258104124724" upper="2.02824565428228" effort="100" velocity="100"/>
  </joint>
</robot>