<?xml version="1.0"?>
<robot name="evolved_robot">
  <material name="metal">
    <color rgba="0.7 0.7 0.7 1.0"/>
  </material>
  <material name="plastic">
    <color rgba="0.3 0.3 0.9 1.0"/>
  </material>
  <material name="rubber">
    <color rgba="0.1 0.1 0.1 1.0"/>
  </material>
  <material name="red">
    <color rgba="1.0 0.0 0.0 1.0"/>
  </material>
  <material name="wheel_material">
    <color rgba="0.2 0.2 0.2 1.0"/>
  </material>
  <link name="base_link">
    <visual>
      <geometry><cylinder radius="0.14085266315607908" length="0.09138925726701656"/></geometry>
      <material name="rubber"/>
    </visual>
    <collision>
      <geometry><cylinder radius="0.14085266315607908" length="0.09138925726701656"/></geometry>
    </collision>
    <inertial>
      <mass value="5.0"/>
      <inertia ixx="0.056558678748580477" ixy="0" ixz="0" 
               iyy="0.056558678748580477" iyz="0" 
               izz="0.09919736359079939"/>
    </inertial>
  </link>
  <link name="link1">
    <visual>
      <geometry><box size="0.18198384974795667 0.13686239572351105 0.13267137856886718"/></geometry>
      <material name="plastic"/>
    </visual>
    <collision>
      <geometry><box size="0.18198384974795667 0.13686239572351105 0.13267137856886718"/></geometry>
    </collision>
    <inertial>
      <mass value="0.5"/>
      <inertia ixx="0.0030277508378785505" ixy="0" ixz="0" 
               iyy="0.004226651355037545" iyz="0" 
               izz="0.00432078641102215"/>
    </inertial>
  </link>
  <joint name="joint1" type="revolute">
    <parent link="base_link"/>
    <child link="link1"/>
    <origin xyz="0 0 0.04569462863350828" rpy="0 0 0"/>
    <axis xyz="-0.8338834693940972 0.29222576366843844 -0.4682333419564028"/>
    <dynamics damping="0.6511572326139334" friction="0.1"/>
    <limit lower="-0.9488740928505366" upper="1.0952959756736282" effort="100" velocity="100"/>
  </joint>
  <link name="link2">
    <visual>
      <geometry>
        <cylinder radius="0.0378500347848431" length="0.05027075810642652"/>
      </geometry>
      <material name="wheel_material"/>
    </visual>
    <collision>
      <geometry>
        <cylinder radius="0.0378500347848431" length="0.05027075810642652"/>
      </geometry>
    </collision>
    <inertial>
      <mass value="1.0"/>
      <inertia ixx="0.0005687520433530287" ixy="0" ixz="0" 
               iyy="0.0005687520433530287" iyz="0" 
               izz="0.0007163125666069162"/>
    </inertial>
  </link>
  <joint name="joint2" type="continuous">
    <parent link="base_link"/>
    <child link="link2"/>
    <origin xyz="0.11033858297275585 0.1513667433394023 -0.04569462863350828" rpy="1.5708 0 0"/>
    <axis xyz="0 1 0"/>
    <dynamics damping="0.7292250985731518" friction="0.1"/>
  </joint>
  <link name="link3">
    <visual>
      <geometry><cylinder radius="0.06510872908280813" length="0.058784437134318024"/></geometry>
      <material name="rubber"/>
    </visual>
    <collision>
      <geometry><cylinder radius="0.06510872908280813" length="0.058784437134318024"/></geometry>
    </collision>
    <inertial>
      <mass value="0.5"/>
      <inertia ixx="0.0013477541547945084" ixy="0" ixz="0" 
               iyy="0.0013477541547945084" iyz="0" 
               izz="0.002119573301389252"/>
    </inertial>
  </link>
  <joint name="joint3" type="fixed">
    <parent link="base_link"/>
    <child link="link3"/>
    <origin xyz="0 0 0.09569462863350828" rpy="0 0 0"/>
    <axis xyz="0.4052345524445542 0.27341202409417853 -0.8723708056702644"/>
    <dynamics damping="0.588789481023749" friction="0.1"/>
  </joint>
  <link name="link4">
    <visual>
      <geometry>
        <cylinder radius="0.07737525363854317" length="0.05801574256786164"/>
      </geometry>
      <material name="wheel_material"/>
    </visual>
    <collision>
      <geometry>
        <cylinder radius="0.07737525363854317" length="0.05801574256786164"/>
      </geometry>
    </collision>
    <inertial>
      <mass value="1.0"/>
      <inertia ixx="0.0017772180010489213" ixy="0" ixz="0" 
               iyy="0.0017772180010489213" iyz="0" 
               izz="0.0029934649378144437"/>
    </inertial>
  </link>
  <joint name="joint4" type="continuous">
    <parent link="base_link"/>
    <child link="link4"/>
    <origin xyz="-0.11033858297275585 0.1513667433394023 -0.04569462863350828" rpy="1.5708 0 0"/>
    <axis xyz="0 1 0"/>
    <dynamics damping="0.7620209808535042" friction="0.1"/>
  </joint>
</robot>