<?xml version="1.0"?>
<robot name="evolved_robot">
  <material name="metal">
    <color rgba="0.7 0.7 0.7 1.0"/>
  </material>
  <material name="plastic">
    <color rgba="0.3 0.3 0.9 1.0"/>
  </material>
  <material name="rubber">
    <color rgba="0.1 0.1 0.1 1.0"/>
  </material>
  <material name="red">
    <color rgba="1.0 0.0 0.0 1.0"/>
  </material>
  <material name="wheel_material">
    <color rgba="0.2 0.2 0.2 1.0"/>
  </material>
  <link name="base_link">
    <visual>
      <geometry><box size="0.30536499040144494 0.2637592270063851 0.0975152016376033"/></geometry>
      <material name="metal"/>
    </visual>
    <collision>
      <geometry><box size="0.30536499040144494 0.2637592270063851 0.0975152016376033"/></geometry>
    </collision>
    <inertial>
      <mass value="5.0"/>
      <inertia ixx="0.0658984536511902" ixy="0" ixz="0" 
               iyy="0.08563082659441416" iyz="0" 
               izz="0.13568058932823365"/>
    </inertial>
  </link>
  <link name="link1">
    <visual>
      <geometry>
        <cylinder radius="0.03486520265155107" length="0.04042928028853386"/>
      </geometry>
      <material name="wheel_material"/>
    </visual>
    <collision>
      <geometry>
        <cylinder radius="0.03486520265155107" length="0.04042928028853386"/>
      </geometry>
    </collision>
    <inertial>
      <mass value="1.0"/>
      <inertia ixx="0.00044010614770416694" ixy="0" ixz="0" 
               iyy="0.00044010614770416694" iyz="0" 
               izz="0.0006077911779668618"/>
    </inertial>
  </link>
  <joint name="joint1" type="continuous">
    <parent link="base_link"/>
    <child link="link1"/>
    <origin xyz="0.13268249520072248 0.13187961350319255 -0.04875760081880165" rpy="1.5708 0 0"/>
    <axis xyz="0 0 1"/>
    <dynamics damping="0.41966141190574124" friction="0.1"/>
  </joint>
  <link name="link2">
    <visual>
      <geometry><cylinder radius="0.05792883747138949" length="0.16266508112525707"/></geometry>
      <material name="plastic"/>
    </visual>
    <collision>
      <geometry><cylinder radius="0.05792883747138949" length="0.16266508112525707"/></geometry>
    </collision>
    <inertial>
      <mass value="0.5"/>
      <inertia ixx="0.0030439316041538703" ixy="0" ixz="0" 
               iyy="0.0030439316041538703" iyz="0" 
               izz="0.0016778751053933294"/>
    </inertial>
  </link>
  <joint name="joint2" type="fixed">
    <parent link="base_link"/>
    <child link="link2"/>
    <origin xyz="0 0 0.04875760081880165" rpy="0 0 0"/>
    <axis xyz="0.07297607362543809 -0.5236043186173205 -0.8488303777572445"/>
    <dynamics damping="0.2891134390323462" friction="0.1"/>
  </joint>
  <link name="link3">
    <visual>
      <geometry>
        <cylinder radius="0.045686839615627195" length="0.03907104858418741"/>
      </geometry>
      <material name="wheel_material"/>
    </visual>
    <collision>
      <geometry>
        <cylinder radius="0.045686839615627195" length="0.03907104858418741"/>
      </geometry>
    </collision>
    <inertial>
      <mass value="1.0"/>
      <inertia ixx="0.0006490340649716716" ixy="0" ixz="0" 
               iyy="0.0006490340649716716" iyz="0" 
               izz="0.0010436436570320212"/>
    </inertial>
  </link>
  <joint name="joint3" type="fixed">
    <parent link="base_link"/>
    <child link="link3"/>
    <origin xyz="-0.13268249520072248 0.13187961350319255 -0.04875760081880165" rpy="1.5708 0 0"/>
    <axis xyz="0 0 1"/>
    <dynamics damping="0.692067010481422" friction="0.1"/>
  </joint>
  <link name="link4">
    <visual>
      <geometry><box size="0.09246010463648308 0.15026105879309354 0.17369657943749678"/></geometry>
      <material name="metal"/>
    </visual>
    <collision>
      <geometry><box size="0.09246010463648308 0.15026105879309354 0.17369657943749678"/></geometry>
    </collision>
    <inertial>
      <mass value="0.5"/>
      <inertia ixx="0.004395740624825679" ixy="0" ixz="0" 
               iyy="0.003226614388139669" iyz="0" 
               izz="0.002593938061584243"/>
    </inertial>
  </link>
  <joint name="joint4" type="revolute">
    <parent link="base_link"/>
    <child link="link4"/>
    <origin xyz="0 0 0.09875760081880165" rpy="0 0 0"/>
    <axis xyz="0.7886949112418226 0.0 -0.6147847891589817"/>
    <dynamics damping="0.7867909126212331" friction="0.1"/>
    <limit lower="-1.5929920037548284" upper="2.0410000000000004" effort="100" velocity="100"/>
  </joint>
  <link name="link5">
    <visual>
      <geometry><sphere radius="0.04981282979123626"/></geometry>
      <material name="rubber"/>
    </visual>
    <collision>
      <geometry><sphere radius="0.04981282979123626"/></geometry>
    </collision>
    <inertial>
      <mass value="0.5"/>
      <inertia ixx="0.0009925272047242699" ixy="0" ixz="0" 
               iyy="0.0009925272047242699" iyz="0" 
               izz="0.0009925272047242699"/>
    </inertial>
  </link>
  <joint name="joint5" type="prismatic">
    <parent link="base_link"/>
    <child link="link5"/>
    <origin xyz="0 0 0.14875760081880166" rpy="0 0 0"/>
    <axis xyz="-0.7992335607473434 0.0 -0.6010205615244145"/>
    <dynamics damping="0.6921864212040522" friction="0.1"/>
    <limit lower="-0.37870818825010766" upper="0.9599811186487808" effort="100" velocity="100"/>
  </joint>
  <link name="link6">
    <visual>
      <geometry><cylinder radius="0.05929679321498707" length="0.24130320195547167"/></geometry>
      <material name="plastic"/>
    </visual>
    <collision>
      <geometry><cylinder radius="0.05929679321498707" length="0.24130320195547167"/></geometry>
    </collision>
    <inertial>
      <mass value="0.5"/>
      <inertia ixx="0.00573129702755883" ixy="0" ixz="0" 
               iyy="0.00573129702755883" iyz="0" 
               izz="0.0017580548427904683"/>
    </inertial>
  </link>
  <joint name="joint6" type="revolute">
    <parent link="base_link"/>
    <child link="link6"/>
    <origin xyz="0 0 0.19875760081880167" rpy="0 0 0"/>
    <axis xyz="0.7585826307000118 0.1652752159852939 -0.6302670032464528"/>
    <dynamics damping="0.2025334459637101" friction="0.1"/>
    <limit lower="-1.4203628528110093" upper="0.27579334299403435" effort="100" velocity="100"/>
  </joint>
  <link name="link7">
    <visual>
      <geometry><sphere radius="0.05156707607986047"/></geometry>
      <material name="plastic"/>
    </visual>
    <collision>
      <geometry><sphere radius="0.05156707607986047"/></geometry>
    </collision>
    <inertial>
      <mass value="0.5"/>
      <inertia ixx="0.001063665334170447" ixy="0" ixz="0" 
               iyy="0.001063665334170447" iyz="0" 
               izz="0.001063665334170447"/>
    </inertial>
  </link>
  <joint name="joint7" type="fixed">
    <parent link="base_link"/>
    <child link="link7"/>
    <origin xyz="0 0 0.24875760081880166" rpy="0 0 0"/>
    <axis xyz="0.7191401399235109 0.2821288928712869 0.6350123990584869"/>
    <dynamics damping="0.1" friction="0.1"/>
  </joint>
</robot>