<?xml version="1.0"?>
<robot name="evolved_robot">
  <material name="metal">
    <color rgba="0.7 0.7 0.7 1.0"/>
  </material>
  <material name="plastic">
    <color rgba="0.3 0.3 0.9 1.0"/>
  </material>
  <material name="rubber">
    <color rgba="0.1 0.1 0.1 1.0"/>
  </material>
  <material name="red">
    <color rgba="1.0 0.0 0.0 1.0"/>
  </material>
  <material name="wheel_material">
    <color rgba="0.2 0.2 0.2 1.0"/>
  </material>
  <link name="base_link">
    <visual>
      <geometry><cylinder radius="0.20975155643814744" length="0.11039709175699786"/></geometry>
      <material name="metal"/>
    </visual>
    <collision>
      <geometry><cylinder radius="0.20975155643814744" length="0.11039709175699786"/></geometry>
    </collision>
    <inertial>
      <mass value="5.0"/>
      <inertia ixx="0.12014555346089921" ixy="0" ixz="0" 
               iyy="0.12014555346089921" iyz="0" 
               izz="0.21997857714112673"/>
    </inertial>
  </link>
  <link name="link1">
    <visual>
      <geometry>
        <cylinder radius="0.08711925243107854" length="0.059151969912863825"/>
      </geometry>
      <material name="wheel_material"/>
    </visual>
    <collision>
      <geometry>
        <cylinder radius="0.08711925243107854" length="0.059151969912863825"/>
      </geometry>
    </collision>
    <inertial>
      <mass value="1.0"/>
      <inertia ixx="0.0021890206647518584" ixy="0" ixz="0" 
               iyy="0.0021890206647518584" iyz="0" 
               izz="0.003794882072074992"/>
    </inertial>
  </link>
  <joint name="joint1" type="continuous">
    <parent link="base_link"/>
    <child link="link1"/>
    <origin xyz="0.19910758744443133 0.20039552543186356 -0.05519854587849893" rpy="1.5708 0 0"/>
    <axis xyz="0 1 0"/>
    <dynamics damping="0.14939620959536964" friction="0.1"/>
  </joint>
  <link name="link2">
    <visual>
      <geometry>
        <cylinder radius="0.08430237953468384" length="0.06891353730799647"/>
      </geometry>
      <material name="wheel_material"/>
    </visual>
    <collision>
      <geometry>
        <cylinder radius="0.08430237953468384" length="0.06891353730799647"/>
      </geometry>
    </collision>
    <inertial>
      <mass value="1.0"/>
      <inertia ixx="0.002172479100827522" ixy="0" ixz="0" 
               iyy="0.002172479100827522" iyz="0" 
               izz="0.00355344559760494"/>
    </inertial>
  </link>
  <joint name="joint2" type="continuous">
    <parent link="base_link"/>
    <child link="link2"/>
    <origin xyz="0.19910758744443133 -0.20039552543186356 -0.05519854587849893" rpy="1.5708 0 0"/>
    <axis xyz="0 1 0"/>
    <dynamics damping="0.8760423411983852" friction="0.1"/>
  </joint>
  <link name="link3">
    <visual>
      <geometry>
        <cylinder radius="0.09781885605301584" length="0.07281740256203384"/>
      </geometry>
      <material name="wheel_material"/>
    </visual>
    <collision>
      <geometry>
        <cylinder radius="0.09781885605301584" length="0.07281740256203384"/>
      </geometry>
    </collision>
    <inertial>
      <mass value="1.0"/>
      <inertia ixx="0.0028339966595369325" ixy="0" ixz="0" 
               iyy="0.0028339966595369325" iyz="0" 
               izz="0.004784264299760316"/>
    </inertial>
  </link>
  <joint name="joint3" type="continuous">
    <parent link="base_link"/>
    <child link="link3"/>
    <origin xyz="-0.19910758744443133 0.20039552543186356 -0.05519854587849893" rpy="1.5708 0 0"/>
    <axis xyz="0 1 0"/>
    <dynamics damping="0.8020730030961195" friction="0.1"/>
  </joint>
  <link name="link4">
    <visual>
      <geometry>
        <cylinder radius="0.09164968573840071" length="0.06982136232657024"/>
      </geometry>
      <material name="wheel_material"/>
    </visual>
    <collision>
      <geometry>
        <cylinder radius="0.09164968573840071" length="0.06982136232657024"/>
      </geometry>
    </collision>
    <inertial>
      <mass value="1.0"/>
      <inertia ixx="0.0025061681104150864" ixy="0" ixz="0" 
               iyy="0.0025061681104150864" iyz="0" 
               izz="0.004199832447973805"/>
    </inertial>
  </link>
  <joint name="joint4" type="continuous">
    <parent link="base_link"/>
    <child link="link4"/>
    <origin xyz="-0.19910758744443133 -0.20039552543186356 -0.05519854587849893" rpy="1.5708 0 0"/>
    <axis xyz="0 1 0"/>
    <dynamics damping="0.7599283069278768" friction="0.1"/>
  </joint>
  <link name="link5">
    <visual>
      <geometry><cylinder radius="0.05826317757477067" length="0.11052951426080167"/></geometry>
      <material name="rubber"/>
    </visual>
    <collision>
      <geometry><cylinder radius="0.05826317757477067" length="0.11052951426080167"/></geometry>
    </collision>
    <inertial>
      <mass value="0.5"/>
      <inertia ixx="0.0018667139255047116" ixy="0" ixz="0" 
               iyy="0.0018667139255047116" iyz="0" 
               izz="0.0016972989305546297"/>
    </inertial>
  </link>
  <joint name="joint5" type="revolute">
    <parent link="base_link"/>
    <child link="link5"/>
    <origin xyz="0 0 0.05519854587849893" rpy="0 0 0"/>
    <axis xyz="-0.5586181763287494 0.8293660339366284 0.009885081050211728"/>
    <dynamics damping="0.8070610720656851" friction="0.1"/>
    <limit lower="-1.4907740569465753" upper="1.0783039553562597" effort="100" velocity="100"/>
  </joint>
  <link name="link6">
    <visual>
      <geometry>
        <cylinder radius="0.09294359597280032" length="0.050745151158266846"/>
      </geometry>
      <material name="wheel_material"/>
    </visual>
    <collision>
      <geometry>
        <cylinder radius="0.09294359597280032" length="0.050745151158266846"/>
      </geometry>
    </collision>
    <inertial>
      <mass value="1.0"/>
      <inertia ixx="0.0023742172052617317" ixy="0" ixz="0" 
               iyy="0.0023742172052617317" iyz="0" 
               izz="0.004319256016177572"/>
    </inertial>
  </link>
  <joint name="joint6" type="continuous">
    <parent link="base_link"/>
    <child link="link6"/>
    <origin xyz="0 -0.2671940339091514 -0.05519854587849893" rpy="1.5708 0 0"/>
    <axis xyz="0 1 0"/>
    <dynamics damping="0.6162223426084045" friction="0.1"/>
  </joint>
</robot>