<?xml version="1.0"?>
<robot name="evolved_robot">
  <material name="metal">
    <color rgba="0.7 0.7 0.7 1.0"/>
  </material>
  <material name="plastic">
    <color rgba="0.3 0.3 0.9 1.0"/>
  </material>
  <material name="rubber">
    <color rgba="0.1 0.1 0.1 1.0"/>
  </material>
  <material name="red">
    <color rgba="1.0 0.0 0.0 1.0"/>
  </material>
  <material name="wheel_material">
    <color rgba="0.2 0.2 0.2 1.0"/>
  </material>
  <link name="base_link">
    <visual>
      <geometry><box size="0.28200543666407374 0.3092717348062436 0.09638835181839425"/></geometry>
      <material name="metal"/>
    </visual>
    <collision>
      <geometry><box size="0.28200543666407374 0.3092717348062436 0.09638835181839425"/></geometry>
    </collision>
    <inertial>
      <mass value="5.0"/>
      <inertia ixx="0.08744976693027501" ixy="0" ixz="0" 
               iyy="0.07401481722863455" iyz="0" 
               izz="0.14598006021513196"/>
    </inertial>
  </link>
  <link name="link1">
    <visual>
      <geometry>
        <cylinder radius="0.05276887741149976" length="0.040581285150848495"/>
      </geometry>
      <material name="wheel_material"/>
    </visual>
    <collision>
      <geometry>
        <cylinder radius="0.05276887741149976" length="0.040581285150848495"/>
      </geometry>
    </collision>
    <inertial>
      <mass value="1.0"/>
      <inertia ixx="0.000833375331192012" ixy="0" ixz="0" 
               iyy="0.000833375331192012" iyz="0" 
               izz="0.0013922772116349445"/>
    </inertial>
  </link>
  <joint name="joint1" type="continuous">
    <parent link="base_link"/>
    <child link="link1"/>
    <origin xyz="0.12100271833203687 0.1546358674031218 -0.048194175909197126" rpy="1.5708 0 0"/>
    <axis xyz="0 0 1"/>
    <dynamics damping="0.7812145894427714" friction="0.1"/>
  </joint>
  <link name="link2">
    <visual>
      <geometry>
        <cylinder radius="0.07899620941041051" length="0.04772637766097393"/>
      </geometry>
      <material name="wheel_material"/>
    </visual>
    <collision>
      <geometry>
        <cylinder radius="0.07899620941041051" length="0.04772637766097393"/>
      </geometry>
    </collision>
    <inertial>
      <mass value="1.0"/>
      <inertia ixx="0.00174991753568985" ixy="0" ixz="0" 
               iyy="0.00174991753568985" iyz="0" 
               izz="0.003120200550606715"/>
    </inertial>
  </link>
  <joint name="joint2" type="continuous">
    <parent link="base_link"/>
    <child link="link2"/>
    <origin xyz="0.12100271833203687 -0.1546358674031218 -0.048194175909197126" rpy="1.5708 0 0"/>
    <axis xyz="0 0 1"/>
    <dynamics damping="0.8652752464137597" friction="0.1"/>
  </joint>
  <link name="link3">
    <visual>
      <geometry>
        <cylinder radius="0.03833049783173354" length="0.04153130015957846"/>
      </geometry>
      <material name="wheel_material"/>
    </visual>
    <collision>
      <geometry>
        <cylinder radius="0.03833049783173354" length="0.04153130015957846"/>
      </geometry>
    </collision>
    <inertial>
      <mass value="1.0"/>
      <inertia ixx="0.0005110441737525492" ixy="0" ixz="0" 
               iyy="0.0005110441737525492" iyz="0" 
               izz="0.0007346135320142648"/>
    </inertial>
  </link>
  <joint name="joint3" type="fixed">
    <parent link="base_link"/>
    <child link="link3"/>
    <origin xyz="-0.12100271833203687 0.1546358674031218 -0.048194175909197126" rpy="1.5708 0 0"/>
    <axis xyz="0 0 1"/>
    <dynamics damping="0.69190020288255" friction="0.1"/>
  </joint>
  <link name="link4">
    <visual>
      <geometry>
        <cylinder radius="0.07828401586055114" length="0.06825893183821084"/>
      </geometry>
      <material name="wheel_material"/>
    </visual>
    <collision>
      <geometry>
        <cylinder radius="0.07828401586055114" length="0.06825893183821084"/>
      </geometry>
    </collision>
    <inertial>
      <mass value="1.0"/>
      <inertia ixx="0.0019203702661215486" ixy="0" ixz="0" 
               iyy="0.0019203702661215486" iyz="0" 
               izz="0.0030641935696275116"/>
    </inertial>
  </link>
  <joint name="joint4" type="continuous">
    <parent link="base_link"/>
    <child link="link4"/>
    <origin xyz="-0.12100271833203687 -0.1546358674031218 -0.048194175909197126" rpy="1.5708 0 0"/>
    <axis xyz="0 0 1"/>
    <dynamics damping="0.6849628307493921" friction="0.1"/>
  </joint>
  <link name="link5">
    <visual>
      <geometry><sphere radius="0.045236008522552544"/></geometry>
      <material name="metal"/>
    </visual>
    <collision>
      <geometry><sphere radius="0.045236008522552544"/></geometry>
    </collision>
    <inertial>
      <mass value="0.5"/>
      <inertia ixx="0.0008185185868209786" ixy="0" ixz="0" 
               iyy="0.0008185185868209786" iyz="0" 
               izz="0.0008185185868209786"/>
    </inertial>
  </link>
  <joint name="joint5" type="prismatic">
    <parent link="base_link"/>
    <child link="link5"/>
    <origin xyz="0 0 0.048194175909197126" rpy="0 0 0"/>
    <axis xyz="-0.6312336843756502 0.6089167266362758 0.4803794913733358"/>
    <dynamics damping="0.6997437828580996" friction="0.1"/>
    <limit lower="-0.3644232264120007" upper="0.9926335345686322" effort="100" velocity="100"/>
  </joint>
  <link name="link6">
    <visual>
      <geometry>
        <cylinder radius="0.05738806713836159" length="0.035615665538883054"/>
      </geometry>
      <material name="wheel_material"/>
    </visual>
    <collision>
      <geometry>
        <cylinder radius="0.05738806713836159" length="0.035615665538883054"/>
      </geometry>
    </collision>
    <inertial>
      <mass value="1.0"/>
      <inertia ixx="0.0009290538651174061" ixy="0" ixz="0" 
               iyy="0.0009290538651174061" iyz="0" 
               izz="0.0016466951249385485"/>
    </inertial>
  </link>
  <joint name="joint6" type="continuous">
    <parent link="base_link"/>
    <child link="link6"/>
    <origin xyz="0 -0.20618115653749572 -0.048194175909197126" rpy="1.5708 0 0"/>
    <axis xyz="0 0 1"/>
    <dynamics damping="0.9290833390612818" friction="0.1"/>
  </joint>
  <link name="link7">
    <visual>
      <geometry>
        <cylinder radius="0.052164150246627745" length="0.06331306911389174"/>
      </geometry>
      <material name="wheel_material"/>
    </visual>
    <collision>
      <geometry>
        <cylinder radius="0.052164150246627745" length="0.06331306911389174"/>
      </geometry>
    </collision>
    <inertial>
      <mass value="1.0"/>
      <inertia ixx="0.0010143200361232244" ixy="0" ixz="0" 
               iyy="0.0010143200361232244" iyz="0" 
               izz="0.0013605492854763767"/>
    </inertial>
  </link>
  <joint name="joint7" type="continuous">
    <parent link="base_link"/>
    <child link="link7"/>
    <origin xyz="0 1.7938188434625042 -0.048194175909197126" rpy="1.5708 0 0"/>
    <axis xyz="0 0 1"/>
    <dynamics damping="0.1" friction="0.1"/>
  </joint>
</robot>