<?xml version="1.0"?>
<robot name="evolved_robot">
  <material name="metal">
    <color rgba="0.7 0.7 0.7 1.0"/>
  </material>
  <material name="plastic">
    <color rgba="0.3 0.3 0.9 1.0"/>
  </material>
  <material name="rubber">
    <color rgba="0.1 0.1 0.1 1.0"/>
  </material>
  <material name="red">
    <color rgba="1.0 0.0 0.0 1.0"/>
  </material>
  <material name="wheel_material">
    <color rgba="0.2 0.2 0.2 1.0"/>
  </material>
  <link name="base_link">
    <visual>
      <geometry><cylinder radius="0.20620974485377241" length="0.1301065557292387"/></geometry>
      <material name="metal"/>
    </visual>
    <collision>
      <geometry><cylinder radius="0.20620974485377241" length="0.1301065557292387"/></geometry>
    </collision>
    <inertial>
      <mass value="5.0"/>
      <inertia ixx="0.12041257705141602" ixy="0" ixz="0" 
               iyy="0.12041257705141602" iyz="0" 
               izz="0.2126122943632896"/>
    </inertial>
  </link>
  <link name="link1">
    <visual>
      <geometry>
        <cylinder radius="0.059466034570848564" length="0.030775727067827097"/>
      </geometry>
      <material name="wheel_material"/>
    </visual>
    <collision>
      <geometry>
        <cylinder radius="0.059466034570848564" length="0.030775727067827097"/>
      </geometry>
    </collision>
    <inertial>
      <mass value="1.0"/>
      <inertia ixx="0.000962981098274788" ixy="0" ixz="0" 
               iyy="0.000962981098274788" iyz="0" 
               izz="0.0017681046337906783"/>
    </inertial>
  </link>
  <joint name="joint1" type="fixed">
    <parent link="base_link"/>
    <child link="link1"/>
    <origin xyz="0.15134624011971906 0.24107324958782578 -0.06505327786461935" rpy="1.5708 0 0"/>
    <axis xyz="0 1 0"/>
    <dynamics damping="0.1029057953056492" friction="0.1"/>
  </joint>
  <link name="link2">
    <visual>
      <geometry>
        <cylinder radius="0.08407692713004995" length="0.07364071116378197"/>
      </geometry>
      <material name="wheel_material"/>
    </visual>
    <collision>
      <geometry>
        <cylinder radius="0.08407692713004995" length="0.07364071116378197"/>
      </geometry>
    </collision>
    <inertial>
      <mass value="1.0"/>
      <inertia ixx="0.002219145280633563" ixy="0" ixz="0" 
               iyy="0.002219145280633563" iyz="0" 
               izz="0.003534464837815865"/>
    </inertial>
  </link>
  <joint name="joint2" type="continuous">
    <parent link="base_link"/>
    <child link="link2"/>
    <origin xyz="-0.15134624011971906 0.24107324958782578 -0.06505327786461935" rpy="1.5708 0 0"/>
    <axis xyz="0 1 0"/>
    <dynamics damping="0.16940986315664458" friction="0.1"/>
  </joint>
  <link name="link3">
    <visual>
      <geometry>
        <cylinder radius="0.05278188144654643" length="0.06835710106827347"/>
      </geometry>
      <material name="wheel_material"/>
    </visual>
    <collision>
      <geometry>
        <cylinder radius="0.05278188144654643" length="0.06835710106827347"/>
      </geometry>
    </collision>
    <inertial>
      <mass value="1.0"/>
      <inertia ixx="0.0010858728577975" ixy="0" ixz="0" 
               iyy="0.0010858728577975" iyz="0" 
               izz="0.001392963504518641"/>
    </inertial>
  </link>
  <joint name="joint3" type="floating">
    <parent link="base_link"/>
    <child link="link3"/>
    <origin xyz="-0.15134624011971906 -0.24107324958782578 -0.06505327786461935" rpy="1.5708 0 0"/>
    <axis xyz="0 1 0"/>
    <dynamics damping="0.812262278098456" friction="0.1"/>
  </joint>
  <link name="link4">
    <visual>
      <geometry><cylinder radius="0.09075330899418887" length="0.11922553858749281"/></geometry>
      <material name="plastic"/>
    </visual>
    <collision>
      <geometry><cylinder radius="0.09075330899418887" length="0.11922553858749281"/></geometry>
    </collision>
    <inertial>
      <mass value="0.5"/>
      <inertia ixx="0.0032436015276384924" ixy="0" ixz="0" 
               iyy="0.0032436015276384924" iyz="0" 
               izz="0.004118081546697362"/>
    </inertial>
  </link>
  <joint name="joint4" type="prismatic">
    <parent link="base_link"/>
    <child link="link4"/>
    <origin xyz="0 0 0.06505327786461935" rpy="0 0 0"/>
    <axis xyz="-0.0070540339977822625 0.9999729260305753 0.0020947100533780572"/>
    <dynamics damping="0.29067086599526093" friction="0.1"/>
    <limit lower="-1.714564015738163" upper="2.9217880489281463" effort="100" velocity="100"/>
  </joint>
  <link name="link5">
    <visual>
      <geometry><cylinder radius="0.0742881723678044" length="0.11226855661961216"/></geometry>
      <material name="plastic"/>
    </visual>
    <collision>
      <geometry><cylinder radius="0.0742881723678044" length="0.11226855661961216"/></geometry>
    </collision>
    <inertial>
      <mass value="0.5"/>
      <inertia ixx="0.0024300355388914095" ixy="0" ixz="0" 
               iyy="0.0024300355388914095" iyz="0" 
               izz="0.0027593662768743083"/>
    </inertial>
  </link>
  <joint name="joint5" type="floating">
    <parent link="base_link"/>
    <child link="link5"/>
    <origin xyz="0 0 0.11505327786461936" rpy="0 0 0"/>
    <axis xyz="-0.4786716533999747 0.8048167272710316 0.3509180584354134"/>
    <dynamics damping="0.6162391592865825" friction="0.1"/>
  </joint>
  <link name="link6">
    <visual>
      <geometry><sphere radius="0.060388191690617266"/></geometry>
      <material name="rubber"/>
    </visual>
    <collision>
      <geometry><sphere radius="0.060388191690617266"/></geometry>
    </collision>
    <inertial>
      <mass value="0.5"/>
      <inertia ixx="0.0014586934782650945" ixy="0" ixz="0" 
               iyy="0.0014586934782650945" iyz="0" 
               izz="0.0014586934782650945"/>
    </inertial>
  </link>
  <joint name="joint6" type="fixed">
    <parent link="base_link"/>
    <child link="link6"/>
    <origin xyz="0 0 0.16505327786461937" rpy="0 0 0"/>
    <axis xyz="-0.25561495641874504 0.7807583470521493 0.5701555906622672"/>
    <dynamics damping="0.2872431319024277" friction="0.1"/>
  </joint>
</robot>