<?xml version="1.0"?>
<robot name="evolved_robot">
  <material name="metal">
    <color rgba="0.7 0.7 0.7 1.0"/>
  </material>
  <material name="plastic">
    <color rgba="0.3 0.3 0.9 1.0"/>
  </material>
  <material name="rubber">
    <color rgba="0.1 0.1 0.1 1.0"/>
  </material>
  <material name="red">
    <color rgba="1.0 0.0 0.0 1.0"/>
  </material>
  <material name="wheel_material">
    <color rgba="0.2 0.2 0.2 1.0"/>
  </material>
  <link name="base_link">
    <visual>
      <geometry><box size="0.3461818460600068 0.27719624380797636 0.102205314231111"/></geometry>
      <material name="metal"/>
    </visual>
    <collision>
      <geometry><box size="0.3461818460600068 0.27719624380797636 0.102205314231111"/></geometry>
    </collision>
    <inertial>
      <mass value="5.0"/>
      <inertia ixx="0.07273640319860934" ixy="0" ixz="0" 
               iyy="0.10857316399882865" iyz="0" 
               izz="0.1638996901023044"/>
    </inertial>
  </link>
  <link name="link1">
    <visual>
      <geometry>
        <cylinder radius="0.0668137406327812" length="0.04833046047246495"/>
      </geometry>
      <material name="wheel_material"/>
    </visual>
    <collision>
      <geometry>
        <cylinder radius="0.0668137406327812" length="0.04833046047246495"/>
      </geometry>
    </collision>
    <inertial>
      <mass value="1.0"/>
      <inertia ixx="0.0013106717684595141" ixy="0" ixz="0" 
               iyy="0.0013106717684595141" iyz="0" 
               izz="0.0022320379686722788"/>
    </inertial>
  </link>
  <joint name="joint1" type="continuous">
    <parent link="base_link"/>
    <child link="link1"/>
    <origin xyz="0.1530909230300034 0.13859812190398818 -0.0511026571155555" rpy="1.5708 0 0"/>
    <axis xyz="0 0 1"/>
    <dynamics damping="0.9212135507331041" friction="0.1"/>
  </joint>
  <link name="link2">
    <visual>
      <geometry>
        <cylinder radius="0.0673993369519961" length="0.05501051008698092"/>
      </geometry>
      <material name="wheel_material"/>
    </visual>
    <collision>
      <geometry>
        <cylinder radius="0.0673993369519961" length="0.05501051008698092"/>
      </geometry>
    </collision>
    <inertial>
      <mass value="1.0"/>
      <inertia ixx="0.0013878473403946625" ixy="0" ixz="0" 
               iyy="0.0013878473403946625" iyz="0" 
               izz="0.0022713353107843533"/>
    </inertial>
  </link>
  <joint name="joint2" type="continuous">
    <parent link="base_link"/>
    <child link="link2"/>
    <origin xyz="0.1530909230300034 -0.13859812190398818 -0.0511026571155555" rpy="1.5708 0 0"/>
    <axis xyz="0 0 1"/>
    <dynamics damping="0.9355285045725612" friction="0.1"/>
  </joint>
  <link name="link3">
    <visual>
      <geometry>
        <cylinder radius="0.07479972298396817" length="0.03695333377069471"/>
      </geometry>
      <material name="wheel_material"/>
    </visual>
    <collision>
      <geometry>
        <cylinder radius="0.07479972298396817" length="0.03695333377069471"/>
      </geometry>
    </collision>
    <inertial>
      <mass value="1.0"/>
      <inertia ixx="0.001512545379350291" ixy="0" ixz="0" 
               iyy="0.001512545379350291" iyz="0" 
               izz="0.002797499279239188"/>
    </inertial>
  </link>
  <joint name="joint3" type="continuous">
    <parent link="base_link"/>
    <child link="link3"/>
    <origin xyz="-0.1530909230300034 0.13859812190398818 -0.0511026571155555" rpy="1.5708 0 0"/>
    <axis xyz="0 0 1"/>
    <dynamics damping="0.856282222827785" friction="0.1"/>
  </joint>
  <link name="link4">
    <visual>
      <geometry><box size="0.18874158753518278 0.14396991138942847 0.18117790979842452"/></geometry>
      <material name="metal"/>
    </visual>
    <collision>
      <geometry><box size="0.18874158753518278 0.14396991138942847 0.18117790979842452"/></geometry>
    </collision>
    <inertial>
      <mass value="0.5"/>
      <inertia ixx="0.004462730865367161" ixy="0" ixz="0" 
               iyy="0.0057040684886855925" iyz="0" 
               izz="0.004695893520898412"/>
    </inertial>
  </link>
  <joint name="joint4" type="revolute">
    <parent link="base_link"/>
    <child link="link4"/>
    <origin xyz="0 0 0.0511026571155555" rpy="0 0 0"/>
    <axis xyz="0.0008555534780209659 -0.5457763396818011 0.8379304595679653"/>
    <dynamics damping="0.2659470000410941" friction="0.1"/>
    <limit lower="-1.3276892507506428" upper="1.479267732639967" effort="100" velocity="100"/>
  </joint>
  <link name="link5">
    <visual>
      <geometry>
        <cylinder radius="0.05302810832666559" length="0.04356300161681845"/>
      </geometry>
      <material name="wheel_material"/>
    </visual>
    <collision>
      <geometry>
        <cylinder radius="0.05302810832666559" length="0.04356300161681845"/>
      </geometry>
    </collision>
    <inertial>
      <mass value="1.0"/>
      <inertia ixx="0.0008611396606650556" ixy="0" ixz="0" 
               iyy="0.0008611396606650556" iyz="0" 
               izz="0.0014059901363522901"/>
    </inertial>
  </link>
  <joint name="joint5" type="continuous">
    <parent link="base_link"/>
    <child link="link5"/>
    <origin xyz="-0.1530909230300034 -0.13859812190398818 -0.0511026571155555" rpy="1.5708 0 0"/>
    <axis xyz="0 0 1"/>
    <dynamics damping="0.4669252455130477" friction="0.1"/>
  </joint>
  <link name="link6">
    <visual>
      <geometry><sphere radius="0.0822106456195616"/></geometry>
      <material name="rubber"/>
    </visual>
    <collision>
      <geometry><sphere radius="0.0822106456195616"/></geometry>
    </collision>
    <inertial>
      <mass value="0.5"/>
      <inertia ixx="0.002703436101274057" ixy="0" ixz="0" 
               iyy="0.002703436101274057" iyz="0" 
               izz="0.002703436101274057"/>
    </inertial>
  </link>
  <joint name="joint6" type="fixed">
    <parent link="base_link"/>
    <child link="link6"/>
    <origin xyz="0 0 0.1011026571155555" rpy="0 0 0"/>
    <axis xyz="-0.9977149862780083 -0.06640984222796405 0.012431372069520346"/>
    <dynamics damping="0.8425074372490632" friction="0.1"/>
  </joint>
</robot>