<?xml version="1.0"?>
<robot name="evolved_robot">
  <material name="metal">
    <color rgba="0.7 0.7 0.7 1.0"/>
  </material>
  <material name="plastic">
    <color rgba="0.3 0.3 0.9 1.0"/>
  </material>
  <material name="rubber">
    <color rgba="0.1 0.1 0.1 1.0"/>
  </material>
  <material name="red">
    <color rgba="1.0 0.0 0.0 1.0"/>
  </material>
  <material name="wheel_material">
    <color rgba="0.2 0.2 0.2 1.0"/>
  </material>
  <link name="base_link">
    <visual>
      <geometry><cylinder radius="0.24047146738611977" length="0.1301065557292387"/></geometry>
      <material name="metal"/>
    </visual>
    <collision>
      <geometry><cylinder radius="0.24047146738611977" length="0.1301065557292387"/></geometry>
    </collision>
    <inertial>
      <mass value="5.0"/>
      <inertia ixx="0.1586727464368554" ixy="0" ixz="0" 
               iyy="0.1586727464368554" iyz="0" 
               izz="0.2891326331341683"/>
    </inertial>
  </link>
  <link name="link1">
    <visual>
      <geometry><box size="0.13418867020242448 0.15060253068151586 0.14734954374294912"/></geometry>
      <material name="rubber"/>
    </visual>
    <collision>
      <geometry><box size="0.13418867020242448 0.15060253068151586 0.14734954374294912"/></geometry>
    </collision>
    <inertial>
      <mass value="0.5"/>
      <inertia ixx="0.0036994175240776836" ixy="0" ixz="0" 
               iyy="0.0033098739376625267" iyz="0" 
               izz="0.0033906434548643307"/>
    </inertial>
  </link>
  <joint name="joint1" type="fixed">
    <parent link="base_link"/>
    <child link="link1"/>
    <origin xyz="0 0 0.06505327786461935" rpy="0 0 0"/>
    <axis xyz="-0.35727440947117334 0.9327201935862031 0.048867543559506954"/>
    <dynamics damping="0.1029057953056492" friction="0.1"/>
  </joint>
  <link name="link2">
    <visual>
      <geometry>
        <cylinder radius="0.08411760931171484" length="0.07361360930740203"/>
      </geometry>
      <material name="wheel_material"/>
    </visual>
    <collision>
      <geometry>
        <cylinder radius="0.08411760931171484" length="0.07361360930740203"/>
      </geometry>
    </collision>
    <inertial>
      <mass value="1.0"/>
      <inertia ixx="0.0022205233386848097" ixy="0" ixz="0" 
               iyy="0.0022205233386848097" iyz="0" 
               izz="0.003537886098159148"/>
    </inertial>
  </link>
  <joint name="joint2" type="floating">
    <parent link="base_link"/>
    <child link="link2"/>
    <origin xyz="0.21524329800132383 0.24569963677091572 -0.06505327786461935" rpy="1.5708 0 0"/>
    <axis xyz="0 1 0"/>
    <dynamics damping="0.13317693757816318" friction="0.1"/>
  </joint>
  <link name="link3">
    <visual>
      <geometry>
        <cylinder radius="0.05278188144654643" length="0.06902675987666469"/>
      </geometry>
      <material name="wheel_material"/>
    </visual>
    <collision>
      <geometry>
        <cylinder radius="0.05278188144654643" length="0.06902675987666469"/>
      </geometry>
    </collision>
    <inertial>
      <mass value="1.0"/>
      <inertia ixx="0.0010935395505152143" ixy="0" ixz="0" 
               iyy="0.0010935395505152143" iyz="0" 
               izz="0.001392963504518641"/>
    </inertial>
  </link>
  <joint name="joint3" type="prismatic">
    <parent link="base_link"/>
    <child link="link3"/>
    <origin xyz="-0.21524329800132383 0.24569963677091572 -0.06505327786461935" rpy="1.5708 0 0"/>
    <axis xyz="0 1 0"/>
    <dynamics damping="0.8843240228193913" friction="0.1"/>
  </joint>
</robot>