<?xml version="1.0"?>
<robot name="evolved_robot">
  <material name="metal">
    <color rgba="0.7 0.7 0.7 1.0"/>
  </material>
  <material name="plastic">
    <color rgba="0.3 0.3 0.9 1.0"/>
  </material>
  <material name="rubber">
    <color rgba="0.1 0.1 0.1 1.0"/>
  </material>
  <material name="red">
    <color rgba="1.0 0.0 0.0 1.0"/>
  </material>
  <material name="wheel_material">
    <color rgba="0.2 0.2 0.2 1.0"/>
  </material>
  <link name="base_link">
    <visual>
      <geometry><box size="0.31868811290000654 0.3792780450720862 0.07231409833017642"/></geometry>
      <material name="rubber"/>
    </visual>
    <collision>
      <geometry><box size="0.31868811290000654 0.3792780450720862 0.07231409833017642"/></geometry>
    </collision>
    <inertial>
      <mass value="5.0"/>
      <inertia ixx="0.12423430357584153" ixy="0" ixz="0" 
               iyy="0.08899286843422811" iyz="0" 
               izz="0.2045116239812256"/>
    </inertial>
  </link>
  <link name="link1">
    <visual>
      <geometry><sphere radius="0.08527737862329111"/></geometry>
      <material name="plastic"/>
    </visual>
    <collision>
      <geometry><sphere radius="0.08527737862329111"/></geometry>
    </collision>
    <inertial>
      <mass value="0.5"/>
      <inertia ixx="0.0029088925219440593" ixy="0" ixz="0" 
               iyy="0.0029088925219440593" iyz="0" 
               izz="0.0029088925219440593"/>
    </inertial>
  </link>
  <joint name="joint1" type="revolute">
    <parent link="base_link"/>
    <child link="link1"/>
    <origin xyz="0 0 0.03615704916508821" rpy="0 0 0"/>
    <axis xyz="-0.4916056793405732 -0.6820093759715992 0.5414675125313831"/>
    <dynamics damping="0.8212211505894433" friction="0.1"/>
    <limit lower="-1.7792998006709766" upper="1.4960121739306087" effort="100" velocity="100"/>
  </joint>
  <link name="link2">
    <visual>
      <geometry>
        <cylinder radius="0.07097114032061219" length="0.050351103594577395"/>
      </geometry>
      <material name="wheel_material"/>
    </visual>
    <collision>
      <geometry>
        <cylinder radius="0.07097114032061219" length="0.050351103594577395"/>
      </geometry>
    </collision>
    <inertial>
      <mass value="1.0"/>
      <inertia ixx="0.0014704951590346618" ixy="0" ixz="0" 
               iyy="0.0014704951590346618" iyz="0" 
               izz="0.002518451379204013"/>
    </inertial>
  </link>
  <joint name="joint2" type="continuous">
    <parent link="base_link"/>
    <child link="link2"/>
    <origin xyz="0.13934405645000328 0.1896390225360431 -0.03615704916508821" rpy="1.5708 0 0"/>
    <axis xyz="0 1 0"/>
    <dynamics damping="0.9114541544746585" friction="0.1"/>
  </joint>
  <link name="link3">
    <visual>
      <geometry>
        <cylinder radius="0.07202321520114786" length="0.04571595030227395"/>
      </geometry>
      <material name="wheel_material"/>
    </visual>
    <collision>
      <geometry>
        <cylinder radius="0.07202321520114786" length="0.04571595030227395"/>
      </geometry>
    </collision>
    <inertial>
      <mass value="1.0"/>
      <inertia ixx="0.0014709982246477126" ixy="0" ixz="0" 
               iyy="0.0014709982246477126" iyz="0" 
               izz="0.0025936717639554285"/>
    </inertial>
  </link>
  <joint name="joint3" type="continuous">
    <parent link="base_link"/>
    <child link="link3"/>
    <origin xyz="0.13934405645000328 -0.1896390225360431 -0.03615704916508821" rpy="1.5708 0 0"/>
    <axis xyz="0 1 0"/>
    <dynamics damping="0.47926926660158287" friction="0.1"/>
  </joint>
  <link name="link4">
    <visual>
      <geometry><cylinder radius="0.07517385326990765" length="0.11537410210458039"/></geometry>
      <material name="metal"/>
    </visual>
    <collision>
      <geometry><cylinder radius="0.07517385326990765" length="0.11537410210458039"/></geometry>
    </collision>
    <inertial>
      <mass value="0.5"/>
      <inertia ixx="0.0025220423402312463" ixy="0" ixz="0" 
               iyy="0.0025220423402312463" iyz="0" 
               izz="0.0028255541077228026"/>
    </inertial>
  </link>
  <joint name="joint4" type="revolute">
    <parent link="base_link"/>
    <child link="link4"/>
    <origin xyz="0 0 0.0861570491650882" rpy="0 0 0"/>
    <axis xyz="0.01314496839488213 0.9990852397421637 -0.04069267176336153"/>
    <dynamics damping="0.9696960948946988" friction="0.1"/>
    <limit lower="-1.364467053086561" upper="1.4241059923867079" effort="100" velocity="100"/>
  </joint>
  <link name="link5">
    <visual>
      <geometry>
        <cylinder radius="0.07305448652505409" length="0.03844728117570642"/>
      </geometry>
      <material name="wheel_material"/>
    </visual>
    <collision>
      <geometry>
        <cylinder radius="0.07305448652505409" length="0.03844728117570642"/>
      </geometry>
    </collision>
    <inertial>
      <mass value="1.0"/>
      <inertia ixx="0.001457422286176813" ixy="0" ixz="0" 
               iyy="0.001457422286176813" iyz="0" 
               izz="0.0026684790007196544"/>
    </inertial>
  </link>
  <joint name="joint5" type="continuous">
    <parent link="base_link"/>
    <child link="link5"/>
    <origin xyz="-0.13934405645000328 0.1896390225360431 -0.03615704916508821" rpy="1.5708 0 0"/>
    <axis xyz="0 1 0"/>
    <dynamics damping="0.7473237405493297" friction="0.1"/>
  </joint>
  <link name="link6">
    <visual>
      <geometry>
        <cylinder radius="0.05277191906879772" length="0.05907795725705198"/>
      </geometry>
      <material name="wheel_material"/>
    </visual>
    <collision>
      <geometry>
        <cylinder radius="0.05277191906879772" length="0.05907795725705198"/>
      </geometry>
    </collision>
    <inertial>
      <mass value="1.0"/>
      <inertia ixx="0.0009870692800231058" ixy="0" ixz="0" 
               iyy="0.0009870692800231058" iyz="0" 
               izz="0.0013924377211018682"/>
    </inertial>
  </link>
  <joint name="joint6" type="continuous">
    <parent link="base_link"/>
    <child link="link6"/>
    <origin xyz="-0.13934405645000328 -0.1896390225360431 -0.03615704916508821" rpy="1.5708 0 0"/>
    <axis xyz="0 1 0"/>
    <dynamics damping="0.5175901269922821" friction="0.1"/>
  </joint>
</robot>