<?xml version="1.0"?>
<robot name="evolved_robot">
  <material name="metal">
    <color rgba="0.7 0.7 0.7 1.0"/>
  </material>
  <material name="plastic">
    <color rgba="0.3 0.3 0.9 1.0"/>
  </material>
  <material name="rubber">
    <color rgba="0.1 0.1 0.1 1.0"/>
  </material>
  <material name="red">
    <color rgba="1.0 0.0 0.0 1.0"/>
  </material>
  <material name="wheel_material">
    <color rgba="0.2 0.2 0.2 1.0"/>
  </material>
  <link name="base_link">
    <visual>
      <geometry><box size="0.37285649571072044 0.34530183067010234 0.07314797569869443"/></geometry>
      <material name="metal"/>
    </visual>
    <collision>
      <geometry><box size="0.37285649571072044 0.34530183067010234 0.07314797569869443"/></geometry>
    </collision>
    <inertial>
      <mass value="5.0"/>
      <inertia ixx="0.10381998384411735" ixy="0" ixz="0" 
               iyy="0.12031049395207938" iyz="0" 
               izz="0.2152127672148354"/>
    </inertial>
  </link>
  <link name="link1">
    <visual>
      <geometry>
        <cylinder radius="0.06194328107442594" length="0.04123180843500207"/>
      </geometry>
      <material name="wheel_material"/>
    </visual>
    <collision>
      <geometry>
        <cylinder radius="0.06194328107442594" length="0.04123180843500207"/>
      </geometry>
    </collision>
    <inertial>
      <mass value="1.0"/>
      <inertia ixx="0.001100914353134726" ixy="0" ixz="0" 
               iyy="0.001100914353134726" iyz="0" 
               izz="0.0019184850351326675"/>
    </inertial>
  </link>
  <joint name="joint1" type="prismatic">
    <parent link="base_link"/>
    <child link="link1"/>
    <origin xyz="0.16642824785536023 0.17265091533505117 -0.03657398784934721" rpy="1.5708 0 0"/>
    <axis xyz="0 1 0"/>
    <dynamics damping="0.9620773342175082" friction="0.1"/>
  </joint>
  <link name="link2">
    <visual>
      <geometry>
        <cylinder radius="0.09029426245970104" length="0.06357497189143543"/>
      </geometry>
      <material name="wheel_material"/>
    </visual>
    <collision>
      <geometry>
        <cylinder radius="0.09029426245970104" length="0.06357497189143543"/>
      </geometry>
    </collision>
    <inertial>
      <mass value="1.0"/>
      <inertia ixx="0.002375078212535078" ixy="0" ixz="0" 
               iyy="0.002375078212535078" iyz="0" 
               izz="0.004076526916570689"/>
    </inertial>
  </link>
  <joint name="joint2" type="continuous">
    <parent link="base_link"/>
    <child link="link2"/>
    <origin xyz="0.16642824785536023 -0.17265091533505117 -0.03657398784934721" rpy="1.5708 0 0"/>
    <axis xyz="0 1 0"/>
    <dynamics damping="0.9511788792221783" friction="0.1"/>
  </joint>
  <link name="link3">
    <visual>
      <geometry>
        <cylinder radius="0.07871691692940436" length="0.06370499732642225"/>
      </geometry>
      <material name="wheel_material"/>
    </visual>
    <collision>
      <geometry>
        <cylinder radius="0.07871691692940436" length="0.06370499732642225"/>
      </geometry>
    </collision>
    <inertial>
      <mass value="1.0"/>
      <inertia ixx="0.0018872821430809753" ixy="0" ixz="0" 
               iyy="0.0018872821430809753" iyz="0" 
               izz="0.003098176505435373"/>
    </inertial>
  </link>
  <joint name="joint3" type="continuous">
    <parent link="base_link"/>
    <child link="link3"/>
    <origin xyz="-0.16642824785536023 0.17265091533505117 -0.03657398784934721" rpy="1.5708 0 0"/>
    <axis xyz="0 1 0"/>
    <dynamics damping="0.7850074824219392" friction="0.1"/>
  </joint>
  <link name="link4">
    <visual>
      <geometry>
        <cylinder radius="0.05990636558940121" length="0.04180201214859394"/>
      </geometry>
      <material name="wheel_material"/>
    </visual>
    <collision>
      <geometry>
        <cylinder radius="0.05990636558940121" length="0.04180201214859394"/>
      </geometry>
    </collision>
    <inertial>
      <mass value="1.0"/>
      <inertia ixx="0.0010428105111720146" ixy="0" ixz="0" 
               iyy="0.0010428105111720146" iyz="0" 
               izz="0.0017943863190654967"/>
    </inertial>
  </link>
  <joint name="joint4" type="continuous">
    <parent link="base_link"/>
    <child link="link4"/>
    <origin xyz="-0.16642824785536023 -0.17265091533505117 -0.03657398784934721" rpy="1.5708 0 0"/>
    <axis xyz="0 1 0"/>
    <dynamics damping="0.41545656516918195" friction="0.1"/>
  </joint>
  <link name="link5">
    <visual>
      <geometry>
        <cylinder radius="0.03281856213288084" length="0.07313775566668783"/>
      </geometry>
      <material name="wheel_material"/>
    </visual>
    <collision>
      <geometry>
        <cylinder radius="0.03281856213288084" length="0.07313775566668783"/>
      </geometry>
    </collision>
    <inertial>
      <mass value="1.0"/>
      <inertia ixx="0.0007150254471141174" ixy="0" ixz="0" 
               iyy="0.0007150254471141174" iyz="0" 
               izz="0.0005385290102348802"/>
    </inertial>
  </link>
  <joint name="joint5" type="continuous">
    <parent link="base_link"/>
    <child link="link5"/>
    <origin xyz="0 -0.23020122044673488 -0.03657398784934721" rpy="1.5708 0 0"/>
    <axis xyz="0 1 0"/>
    <dynamics damping="0.6407161603204423" friction="0.1"/>
  </joint>
  <link name="link6">
    <visual>
      <geometry>
        <cylinder radius="0.07032088423401835" length="0.04645433045720568"/>
      </geometry>
      <material name="wheel_material"/>
    </visual>
    <collision>
      <geometry>
        <cylinder radius="0.07032088423401835" length="0.04645433045720568"/>
      </geometry>
    </collision>
    <inertial>
      <mass value="1.0"/>
      <inertia ixx="0.0014160904247158248" ixy="0" ixz="0" 
               iyy="0.0014160904247158248" iyz="0" 
               izz="0.002472513379727105"/>
    </inertial>
  </link>
  <joint name="joint6" type="continuous">
    <parent link="base_link"/>
    <child link="link6"/>
    <origin xyz="0 1.769798779553265 -0.03657398784934721" rpy="1.5708 0 0"/>
    <axis xyz="0 1 0"/>
    <dynamics damping="0.9384190659020333" friction="0.1"/>
  </joint>
  <link name="link7">
    <visual>
      <geometry>
        <cylinder radius="0.04330185309388859" length="0.03712460767066635"/>
      </geometry>
      <material name="wheel_material"/>
    </visual>
    <collision>
      <geometry>
        <cylinder radius="0.04330185309388859" length="0.03712460767066635"/>
      </geometry>
    </collision>
    <inertial>
      <mass value="1.0"/>
      <inertia ixx="0.0005836156615662522" ixy="0" ixz="0" 
               iyy="0.0005836156615662522" iyz="0" 
               izz="0.0009375252406823545"/>
    </inertial>
  </link>
  <joint name="joint7" type="fixed">
    <parent link="base_link"/>
    <child link="link7"/>
    <origin xyz="0 -0.23020122044673488 -0.03657398784934721" rpy="1.5708 0 0"/>
    <axis xyz="0 1 0"/>
    <dynamics damping="0.1" friction="0.1"/>
  </joint>
</robot>