<?xml version="1.0"?>
<robot name="evolved_robot">
  <material name="metal">
    <color rgba="0.7 0.7 0.7 1.0"/>
  </material>
  <material name="plastic">
    <color rgba="0.3 0.3 0.9 1.0"/>
  </material>
  <material name="rubber">
    <color rgba="0.1 0.1 0.1 1.0"/>
  </material>
  <material name="red">
    <color rgba="1.0 0.0 0.0 1.0"/>
  </material>
  <material name="wheel_material">
    <color rgba="0.2 0.2 0.2 1.0"/>
  </material>
  <link name="base_link">
    <visual>
      <geometry><cylinder radius="0.21050239946779015" length="0.12805940470670749"/></geometry>
      <material name="rubber"/>
    </visual>
    <collision>
      <geometry><cylinder radius="0.21050239946779015" length="0.12805940470670749"/></geometry>
    </collision>
    <inertial>
      <mass value="5.0"/>
      <inertia ixx="0.12444415973243968" ixy="0" ixz="0" 
               iyy="0.12444415973243968" iyz="0" 
               izz="0.2215563009084855"/>
    </inertial>
  </link>
  <link name="link1">
    <visual>
      <geometry><cylinder radius="0.05935357784268451" length="0.07570931910548462"/></geometry>
      <material name="plastic"/>
    </visual>
    <collision>
      <geometry><cylinder radius="0.05935357784268451" length="0.07570931910548462"/></geometry>
    </collision>
    <inertial>
      <mass value="0.5"/>
      <inertia ixx="0.0013583702172999107" ixy="0" ixz="0" 
               iyy="0.0013583702172999107" iyz="0" 
               izz="0.001761423601363805"/>
    </inertial>
  </link>
  <joint name="joint1" type="revolute">
    <parent link="base_link"/>
    <child link="link1"/>
    <origin xyz="0 0 0.06402970235335374" rpy="0 0 0"/>
    <axis xyz="-0.7525576835677988 -0.20111363708303587 0.627064779653826"/>
    <dynamics damping="0.1061254823494493" friction="0.1"/>
    <limit lower="-2.445429088284025" upper="2.5833382780369245" effort="100" velocity="100"/>
  </joint>
  <link name="link2">
    <visual>
      <geometry><box size="0.09019671667807586 0.11283898377872704 0.24986356730430942"/></geometry>
      <material name="plastic"/>
    </visual>
    <collision>
      <geometry><box size="0.09019671667807586 0.11283898377872704 0.24986356730430942"/></geometry>
    </collision>
    <inertial>
      <mass value="0.5"/>
      <inertia ixx="0.006263703210520916" ixy="0" ixz="0" 
               iyy="0.00588060416379502" iyz="0" 
               izz="0.0017390069966434095"/>
    </inertial>
  </link>
  <joint name="joint2" type="floating">
    <parent link="base_link"/>
    <child link="link2"/>
    <origin xyz="0 0 0.11402970235335375" rpy="0 0 0"/>
    <axis xyz="0.27964030066089113 0.8414221423711573 0.4623960213646072"/>
    <dynamics damping="0.8918216140598217" friction="0.1"/>
  </joint>
  <link name="link3">
    <visual>
      <geometry><sphere radius="0.0887240861987725"/></geometry>
      <material name="plastic"/>
    </visual>
    <collision>
      <geometry><sphere radius="0.0887240861987725"/></geometry>
    </collision>
    <inertial>
      <mass value="0.5"/>
      <inertia ixx="0.0031487853887228858" ixy="0" ixz="0" 
               iyy="0.0031487853887228858" iyz="0" 
               izz="0.0031487853887228858"/>
    </inertial>
  </link>
  <joint name="joint3" type="fixed">
    <parent link="base_link"/>
    <child link="link3"/>
    <origin xyz="0 0 0.16402970235335373" rpy="0 0 0"/>
    <axis xyz="0.41695542645110933 0.8915817599302395 0.17672050733480366"/>
    <dynamics damping="0.21045667114747402" friction="0.1"/>
  </joint>
  <link name="link4">
    <visual>
      <geometry><sphere radius="0.025425095013624312"/></geometry>
      <material name="rubber"/>
    </visual>
    <collision>
      <geometry><sphere radius="0.025425095013624312"/></geometry>
    </collision>
    <inertial>
      <mass value="0.5"/>
      <inertia ixx="0.00025857418258072953" ixy="0" ixz="0" 
               iyy="0.00025857418258072953" iyz="0" 
               izz="0.00025857418258072953"/>
    </inertial>
  </link>
  <joint name="joint4" type="revolute">
    <parent link="base_link"/>
    <child link="link4"/>
    <origin xyz="0 0 0.21402970235335378" rpy="0 0 0"/>
    <axis xyz="0.9071062299619108 0.22442864154778938 0.3560759363075565"/>
    <dynamics damping="0.29303774938440097" friction="0.1"/>
    <limit lower="-0.0" upper="1.8389894793553705" effort="100" velocity="100"/>
  </joint>
  <link name="link5">
    <visual>
      <geometry><box size="0.12442227178542456 0.23575565926848085 0.14258513625908223"/></geometry>
      <material name="rubber"/>
    </visual>
    <collision>
      <geometry><box size="0.12442227178542456 0.23575565926848085 0.14258513625908223"/></geometry>
    </collision>
    <inertial>
      <mass value="0.5"/>
      <inertia ixx="0.006325937663261424" ixy="0" ixz="0" 
               iyy="0.002984285233188925" iyz="0" 
               izz="0.005921802716113508"/>
    </inertial>
  </link>
  <joint name="joint5" type="prismatic">
    <parent link="base_link"/>
    <child link="link5"/>
    <origin xyz="0 0 0.26402970235335377" rpy="0 0 0"/>
    <axis xyz="0.49569120238020364 -0.6321817240558768 0.5955136435486656"/>
    <dynamics damping="0.9217738192160089" friction="0.1"/>
    <limit lower="-0.06631870370802115" upper="0.8725966209718942" effort="100" velocity="100"/>
  </joint>
  <link name="link6">
    <visual>
      <geometry><cylinder radius="0.07907879835616652" length="0.13223527445061792"/></geometry>
      <material name="metal"/>
    </visual>
    <collision>
      <geometry><cylinder radius="0.07907879835616652" length="0.13223527445061792"/></geometry>
    </collision>
    <inertial>
      <mass value="0.5"/>
      <inertia ixx="0.0030205447381163315" ixy="0" ixz="0" 
               iyy="0.0030205447381163315" iyz="0" 
               izz="0.003126728174727622"/>
    </inertial>
  </link>
  <joint name="joint6" type="revolute">
    <parent link="base_link"/>
    <child link="link6"/>
    <origin xyz="0 0 0.31402970235335376" rpy="0 0 0"/>
    <axis xyz="0.24620687406655126 0.9551432005333206 0.1645710838432511"/>
    <dynamics damping="0.4601416217431744" friction="0.1"/>
    <limit lower="-0.45957136471378096" upper="1.5631693636868569" effort="100" velocity="100"/>
  </joint>
</robot>