<?xml version="1.0"?>
<robot name="evolved_robot">
  <material name="metal">
    <color rgba="0.7 0.7 0.7 1.0"/>
  </material>
  <material name="plastic">
    <color rgba="0.3 0.3 0.9 1.0"/>
  </material>
  <material name="rubber">
    <color rgba="0.1 0.1 0.1 1.0"/>
  </material>
  <material name="red">
    <color rgba="1.0 0.0 0.0 1.0"/>
  </material>
  <material name="wheel_material">
    <color rgba="0.2 0.2 0.2 1.0"/>
  </material>
  <link name="base_link">
    <visual>
      <geometry><box size="0.27681445085347733 0.34240536522699816 0.08528316909664546"/></geometry>
      <material name="rubber"/>
    </visual>
    <collision>
      <geometry><box size="0.27681445085347733 0.34240536522699816 0.08528316909664546"/></geometry>
    </collision>
    <inertial>
      <mass value="5.0"/>
      <inertia ixx="0.10376221088950087" ixy="0" ixz="0" 
               iyy="0.06991621594373269" iyz="0" 
               izz="0.1615563952812885"/>
    </inertial>
  </link>
  <link name="link1">
    <visual>
      <geometry>
        <cylinder radius="0.06669969075575738" length="0.054827935651982254"/>
      </geometry>
      <material name="wheel_material"/>
    </visual>
    <collision>
      <geometry>
        <cylinder radius="0.06669969075575738" length="0.054827935651982254"/>
      </geometry>
    </collision>
    <inertial>
      <mass value="1.0"/>
      <inertia ixx="0.0013627207307165756" ixy="0" ixz="0" 
               iyy="0.0013627207307165756" iyz="0" 
               izz="0.002224424373456833"/>
    </inertial>
  </link>
  <joint name="joint1" type="continuous">
    <parent link="base_link"/>
    <child link="link1"/>
    <origin xyz="0 0 0" rpy="1.5708 0 0"/>
    <axis xyz="0 1 0"/>
    <dynamics damping="0.6679796607289551" friction="0.1"/>
  </joint>
  <link name="link2">
    <visual>
      <geometry><box size="0.12521376474294132 0.15726580780305835 0.1911825894407161"/></geometry>
      <material name="metal"/>
    </visual>
    <collision>
      <geometry><box size="0.12521376474294132 0.15726580780305835 0.1911825894407161"/></geometry>
    </collision>
    <inertial>
      <mass value="0.5"/>
      <inertia ixx="0.005106943067433825" ixy="0" ixz="0" 
               iyy="0.004352439115529839" iyz="0" 
               izz="0.003367585098754096"/>
    </inertial>
  </link>
  <joint name="joint2" type="prismatic">
    <parent link="base_link"/>
    <child link="link2"/>
    <origin xyz="0 0 0.04264158454832273" rpy="0 0 0"/>
    <axis xyz="0.6356562384763904 -0.7670835808562472 0.08674056990130805"/>
    <dynamics damping="0.6447357456982021" friction="0.1"/>
    <limit lower="-1.6972199480639334" upper="1.8754259888622902" effort="100" velocity="100"/>
  </joint>
  <link name="link3">
    <visual>
      <geometry><sphere radius="0.07767720841728659"/></geometry>
      <material name="rubber"/>
    </visual>
    <collision>
      <geometry><sphere radius="0.07767720841728659"/></geometry>
    </collision>
    <inertial>
      <mass value="0.5"/>
      <inertia ixx="0.002413499483001032" ixy="0" ixz="0" 
               iyy="0.002413499483001032" iyz="0" 
               izz="0.002413499483001032"/>
    </inertial>
  </link>
  <joint name="joint3" type="prismatic">
    <parent link="base_link"/>
    <child link="link3"/>
    <origin xyz="0 0 0.09264158454832273" rpy="0 0 0"/>
    <axis xyz="-0.3656384771534133 0.8991751851725522 -0.24040068717630436"/>
    <dynamics damping="0.8377555201922987" friction="0.1"/>
    <limit lower="-0.6856849405748834" upper="1.1332464150860828" effort="100" velocity="100"/>
  </joint>
</robot>