<?xml version="1.0"?>
<robot name="evolved_robot">
  <material name="metal">
    <color rgba="0.7 0.7 0.7 1.0"/>
  </material>
  <material name="plastic">
    <color rgba="0.3 0.3 0.9 1.0"/>
  </material>
  <material name="rubber">
    <color rgba="0.1 0.1 0.1 1.0"/>
  </material>
  <material name="red">
    <color rgba="1.0 0.0 0.0 1.0"/>
  </material>
  <material name="wheel_material">
    <color rgba="0.2 0.2 0.2 1.0"/>
  </material>
  <link name="base_link">
    <visual>
      <geometry><sphere radius="0.11098939436055556"/></geometry>
      <material name="plastic"/>
    </visual>
    <collision>
      <geometry><sphere radius="0.11098939436055556"/></geometry>
    </collision>
    <inertial>
      <mass value="5.0"/>
      <inertia ixx="0.04927458264209169" ixy="0" ixz="0" 
               iyy="0.04927458264209169" iyz="0" 
               izz="0.04927458264209169"/>
    </inertial>
  </link>
  <link name="link1">
    <visual>
      <geometry><sphere radius="0.06682383555541732"/></geometry>
      <material name="plastic"/>
    </visual>
    <collision>
      <geometry><sphere radius="0.06682383555541732"/></geometry>
    </collision>
    <inertial>
      <mass value="0.5"/>
      <inertia ixx="0.0017861699993349824" ixy="0" ixz="0" 
               iyy="0.0017861699993349824" iyz="0" 
               izz="0.0017861699993349824"/>
    </inertial>
  </link>
  <joint name="joint1" type="revolute">
    <parent link="base_link"/>
    <child link="link1"/>
    <origin xyz="0 0 0.05395942355574325" rpy="0 0 0"/>
    <axis xyz="-0.43898483183120707 -0.6520992561879158 -0.61810911455931"/>
    <dynamics damping="0.6507322579426503" friction="0.1"/>
    <limit lower="-1.256164154549568" upper="1.4150721101817274" effort="100" velocity="100"/>
  </joint>
  <link name="link2">
    <visual>
      <geometry>
        <cylinder radius="0.054725586248147544" length="0.05017284003282977"/>
      </geometry>
      <material name="wheel_material"/>
    </visual>
    <collision>
      <geometry>
        <cylinder radius="0.054725586248147544" length="0.05017284003282977"/>
      </geometry>
    </collision>
    <inertial>
      <mass value="1.0"/>
      <inertia ixx="0.000958498603964186" ixy="0" ixz="0" 
               iyy="0.000958498603964186" iyz="0" 
               izz="0.0014974448951017177"/>
    </inertial>
  </link>
  <joint name="joint2" type="continuous">
    <parent link="base_link"/>
    <child link="link2"/>
    <origin xyz="0.16026085789164765 0.09874790163427583 -0.05395942355574325" rpy="1.5708 0 0"/>
    <axis xyz="0 1 0"/>
    <dynamics damping="0.5427877111602113" friction="0.1"/>
  </joint>
  <link name="link3">
    <visual>
      <geometry>
        <cylinder radius="0.06910428393601839" length="0.06481733612685017"/>
      </geometry>
      <material name="wheel_material"/>
    </visual>
    <collision>
      <geometry>
        <cylinder radius="0.06910428393601839" length="0.06481733612685017"/>
      </geometry>
    </collision>
    <inertial>
      <mass value="1.0"/>
      <inertia ixx="0.001543957769792552" ixy="0" ixz="0" 
               iyy="0.001543957769792552" iyz="0" 
               izz="0.002387701029154925"/>
    </inertial>
  </link>
  <joint name="joint3" type="continuous">
    <parent link="base_link"/>
    <child link="link3"/>
    <origin xyz="0.16026085789164765 -0.09874790163427583 -0.05395942355574325" rpy="1.5708 0 0"/>
    <axis xyz="0 1 0"/>
    <dynamics damping="0.9361071883416644" friction="0.1"/>
  </joint>
  <link name="link4">
    <visual>
      <geometry>
        <cylinder radius="0.08875857303974351" length="0.025222020492338057"/>
      </geometry>
      <material name="wheel_material"/>
    </visual>
    <collision>
      <geometry>
        <cylinder radius="0.08875857303974351" length="0.025222020492338057"/>
      </geometry>
    </collision>
    <inertial>
      <mass value="1.0"/>
      <inertia ixx="0.0020225335984891974" ixy="0" ixz="0" 
               iyy="0.0020225335984891974" iyz="0" 
               izz="0.003939042144025741"/>
    </inertial>
  </link>
  <joint name="joint4" type="continuous">
    <parent link="base_link"/>
    <child link="link4"/>
    <origin xyz="-0.16026085789164765 0.09874790163427583 -0.05395942355574325" rpy="1.5708 0 0"/>
    <axis xyz="0 1 0"/>
    <dynamics damping="0.6503558228353199" friction="0.1"/>
  </joint>
  <link name="link5">
    <visual>
      <geometry><box size="0.1224750609236127 0.07212238901574441 0.1283965184327871"/></geometry>
      <material name="rubber"/>
    </visual>
    <collision>
      <geometry><box size="0.1224750609236127 0.07212238901574441 0.1283965184327871"/></geometry>
    </collision>
    <inertial>
      <mass value="0.5"/>
      <inertia ixx="0.001807275411916617" ixy="0" ixz="0" 
               iyy="0.0026238172078253065" iyz="0" 
               izz="0.0016834816287984178"/>
    </inertial>
  </link>
  <joint name="joint5" type="fixed">
    <parent link="base_link"/>
    <child link="link5"/>
    <origin xyz="0 0 0.10395942355574325" rpy="0 0 0"/>
    <axis xyz="-0.5677213251139246 -0.7027704675307052 0.4287262144744169"/>
    <dynamics damping="0.7872694871185734" friction="0.1"/>
  </joint>
  <link name="link6">
    <visual>
      <geometry>
        <cylinder radius="0.07533663714733194" length="0.052724950445477134"/>
      </geometry>
      <material name="wheel_material"/>
    </visual>
    <collision>
      <geometry>
        <cylinder radius="0.07533663714733194" length="0.052724950445477134"/>
      </geometry>
    </collision>
    <inertial>
      <mass value="1.0"/>
      <inertia ixx="0.0016505622574570235" ixy="0" ixz="0" 
               iyy="0.0016505622574570235" iyz="0" 
               izz="0.002837804448334377"/>
    </inertial>
  </link>
  <joint name="joint6" type="continuous">
    <parent link="base_link"/>
    <child link="link6"/>
    <origin xyz="-0.16026085789164765 -0.09874790163427583 -0.05395942355574325" rpy="1.5708 0 0"/>
    <axis xyz="0 1 0"/>
    <dynamics damping="0.9270203448565811" friction="0.1"/>
  </joint>
  <link name="link7">
    <visual>
      <geometry><cylinder radius="0.026624046953579884" length="0.23802857992927146"/></geometry>
      <material name="metal"/>
    </visual>
    <collision>
      <geometry><cylinder radius="0.026624046953579884" length="0.23802857992927146"/></geometry>
    </collision>
    <inertial>
      <mass value="0.5"/>
      <inertia ixx="0.004898677040975404" ixy="0" ixz="0" 
               iyy="0.004898677040975404" iyz="0" 
               izz="0.00035441993809321316"/>
    </inertial>
  </link>
  <joint name="joint7" type="revolute">
    <parent link="base_link"/>
    <child link="link7"/>
    <origin xyz="0 0 0.15395942355574327" rpy="0 0 0"/>
    <axis xyz="0.23544593404821332 -0.5528013912505194 0.7993596399441584"/>
    <dynamics damping="0.1" friction="0.1"/>
    <limit lower="-2.1282907022556143" upper="0.0" effort="100" velocity="100"/>
  </joint>
</robot>