<?xml version="1.0"?>
<robot name="evolved_robot">
  <material name="metal">
    <color rgba="0.7 0.7 0.7 1.0"/>
  </material>
  <material name="plastic">
    <color rgba="0.3 0.3 0.9 1.0"/>
  </material>
  <material name="rubber">
    <color rgba="0.1 0.1 0.1 1.0"/>
  </material>
  <material name="red">
    <color rgba="1.0 0.0 0.0 1.0"/>
  </material>
  <material name="wheel_material">
    <color rgba="0.2 0.2 0.2 1.0"/>
  </material>
  <link name="base_link">
    <visual>
      <geometry><cylinder radius="0.2015375313686143" length="0.1301065557292387"/></geometry>
      <material name="metal"/>
    </visual>
    <collision>
      <geometry><cylinder radius="0.2015375313686143" length="0.1301065557292387"/></geometry>
    </collision>
    <inertial>
      <mass value="5.0"/>
      <inertia ixx="0.11564987124515923" ixy="0" ixz="0" 
               iyy="0.11564987124515923" iyz="0" 
               izz="0.20308688275077594"/>
    </inertial>
  </link>
  <link name="link1">
    <visual>
      <geometry><box size="0.13418867020242448 0.08591909022609032 0.14734954374294912"/></geometry>
      <material name="rubber"/>
    </visual>
    <collision>
      <geometry><box size="0.13418867020242448 0.08591909022609032 0.14734954374294912"/></geometry>
    </collision>
    <inertial>
      <mass value="0.5"/>
      <inertia ixx="0.002424498175544527" ixy="0" ixz="0" 
               iyy="0.0033098739376625267" iyz="0" 
               izz="0.002115724106331174"/>
    </inertial>
  </link>
  <joint name="joint1" type="fixed">
    <parent link="base_link"/>
    <child link="link1"/>
    <origin xyz="0 0 0.06505327786461935" rpy="0 0 0"/>
    <axis xyz="0.8882332876763923 0.45936544820475755 0.005001165787037002"/>
    <dynamics damping="0.1029057953056492" friction="0.1"/>
  </joint>
  <link name="link2">
    <visual>
      <geometry>
        <cylinder radius="0.08411760931171484" length="0.07363168989511291"/>
      </geometry>
      <material name="wheel_material"/>
    </visual>
    <collision>
      <geometry>
        <cylinder radius="0.08411760931171484" length="0.07363168989511291"/>
      </geometry>
    </collision>
    <inertial>
      <mass value="1.0"/>
      <inertia ixx="0.0022207451954804136" ixy="0" ixz="0" 
               iyy="0.0022207451954804136" iyz="0" 
               izz="0.003537886098159148"/>
    </inertial>
  </link>
  <joint name="joint2" type="floating">
    <parent link="base_link"/>
    <child link="link2"/>
    <origin xyz="0 0 0" rpy="1.5708 0 0"/>
    <axis xyz="0 1 0"/>
    <dynamics damping="0.13317693757816318" friction="0.1"/>
  </joint>
  <link name="link3">
    <visual>
      <geometry><cylinder radius="0.08212840569237279" length="0.18297875091889787"/></geometry>
      <material name="rubber"/>
    </visual>
    <collision>
      <geometry><cylinder radius="0.08212840569237279" length="0.18297875091889787"/></geometry>
    </collision>
    <inertial>
      <mass value="0.5"/>
      <inertia ixx="0.004476370696046081" ixy="0" ixz="0" 
               iyy="0.004476370696046081" iyz="0" 
               izz="0.003372537510785485"/>
    </inertial>
  </link>
  <joint name="joint3" type="floating">
    <parent link="base_link"/>
    <child link="link3"/>
    <origin xyz="0 0 0.11505327786461936" rpy="0 0 0"/>
    <axis xyz="0.033475649078025534 0.8745205975360438 0.4838316911943716"/>
    <dynamics damping="0.6136062229199455" friction="0.1"/>
  </joint>
</robot>