<?xml version="1.0"?>
<robot name="evolved_robot">
  <material name="metal">
    <color rgba="0.7 0.7 0.7 1.0"/>
  </material>
  <material name="plastic">
    <color rgba="0.3 0.3 0.9 1.0"/>
  </material>
  <material name="rubber">
    <color rgba="0.1 0.1 0.1 1.0"/>
  </material>
  <material name="red">
    <color rgba="1.0 0.0 0.0 1.0"/>
  </material>
  <material name="wheel_material">
    <color rgba="0.2 0.2 0.2 1.0"/>
  </material>
  <link name="base_link">
    <visual>
      <geometry><cylinder radius="0.15382927939700256" length="0.08068832829829782"/></geometry>
      <material name="metal"/>
    </visual>
    <collision>
      <geometry><cylinder radius="0.15382927939700256" length="0.08068832829829782"/></geometry>
    </collision>
    <inertial>
      <mass value="5.0"/>
      <inertia ixx="0.0645841232691476" ixy="0" ixz="0" 
               iyy="0.0645841232691476" iyz="0" 
               izz="0.11831723599900537"/>
    </inertial>
  </link>
  <link name="link1">
    <visual>
      <geometry><cylinder radius="0.07361392834338261" length="0.17115775961517782"/></geometry>
      <material name="rubber"/>
    </visual>
    <collision>
      <geometry><cylinder radius="0.07361392834338261" length="0.17115775961517782"/></geometry>
    </collision>
    <inertial>
      <mass value="0.5"/>
      <inertia ixx="0.00379600083457675" ixy="0" ixz="0" 
               iyy="0.00379600083457675" iyz="0" 
               izz="0.0027095052230723345"/>
    </inertial>
  </link>
  <joint name="joint1" type="prismatic">
    <parent link="base_link"/>
    <child link="link1"/>
    <origin xyz="0 0 0.04034416414914891" rpy="0 0 0"/>
    <axis xyz="-0.5931464711903321 -0.4738167359431905 0.6509031913077378"/>
    <dynamics damping="0.7765132943335169" friction="0.1"/>
    <limit lower="-1.0513520664820588" upper="1.2616069225743036" effort="100" velocity="100"/>
  </joint>
  <link name="link2">
    <visual>
      <geometry>
        <cylinder radius="0.05978355010138645" length="0.05844196811389643"/>
      </geometry>
      <material name="wheel_material"/>
    </visual>
    <collision>
      <geometry>
        <cylinder radius="0.05978355010138645" length="0.05844196811389643"/>
      </geometry>
    </collision>
    <inertial>
      <mass value="1.0"/>
      <inertia ixx="0.0011781401854333866" ixy="0" ixz="0" 
               iyy="0.0011781401854333866" iyz="0" 
               izz="0.001787036431362492"/>
    </inertial>
  </link>
  <joint name="joint2" type="continuous">
    <parent link="base_link"/>
    <child link="link2"/>
    <origin xyz="0.13985519542031713 0.147803363373688 -0.04034416414914891" rpy="1.5708 0 0"/>
    <axis xyz="0 1 0"/>
    <dynamics damping="0.6237323492205411" friction="0.1"/>
  </joint>
  <link name="link3">
    <visual>
      <geometry><cylinder radius="0.06992649016010882" length="0.052851479769380164"/></geometry>
      <material name="metal"/>
    </visual>
    <collision>
      <geometry><cylinder radius="0.06992649016010882" length="0.052851479769380164"/></geometry>
    </collision>
    <inertial>
      <mass value="0.5"/>
      <inertia ixx="0.0014552017493457156" ixy="0" ixz="0" 
               iyy="0.0014552017493457156" iyz="0" 
               izz="0.002444857013055898"/>
    </inertial>
  </link>
  <joint name="joint3" type="revolute">
    <parent link="base_link"/>
    <child link="link3"/>
    <origin xyz="0 0 0.09034416414914892" rpy="0 0 0"/>
    <axis xyz="-0.44042942929741047 0.7937768989942029 -0.41945220518183507"/>
    <dynamics damping="0.8416779145876575" friction="0.1"/>
    <limit lower="-0.7345191566587939" upper="1.2169395730998822" effort="100" velocity="100"/>
  </joint>
  <link name="link4">
    <visual>
      <geometry>
        <cylinder radius="0.07364674738813795" length="0.0474288740082876"/>
      </geometry>
      <material name="wheel_material"/>
    </visual>
    <collision>
      <geometry>
        <cylinder radius="0.07364674738813795" length="0.0474288740082876"/>
      </geometry>
    </collision>
    <inertial>
      <mass value="1.0"/>
      <inertia ixx="0.0015434190243542192" ixy="0" ixz="0" 
               iyy="0.0015434190243542192" iyz="0" 
               izz="0.002711921700426102"/>
    </inertial>
  </link>
  <joint name="joint4" type="continuous">
    <parent link="base_link"/>
    <child link="link4"/>
    <origin xyz="-0.13985519542031713 0.147803363373688 -0.04034416414914891" rpy="1.5708 0 0"/>
    <axis xyz="0 1 0"/>
    <dynamics damping="0.4452985084493982" friction="0.1"/>
  </joint>
  <link name="link5">
    <visual>
      <geometry><box size="0.17494639463942896 0.13218542554824703 0.0653079719149393"/></geometry>
      <material name="plastic"/>
    </visual>
    <collision>
      <geometry><box size="0.17494639463942896 0.13218542554824703 0.0653079719149393"/></geometry>
    </collision>
    <inertial>
      <mass value="0.5"/>
      <inertia ixx="0.001811509826917805" ixy="0" ixz="0" 
               iyy="0.00290594768274811" iyz="0" 
               izz="0.004006602310392165"/>
    </inertial>
  </link>
  <joint name="joint5" type="revolute">
    <parent link="base_link"/>
    <child link="link5"/>
    <origin xyz="0 0 0.1403441641491489" rpy="0 0 0"/>
    <axis xyz="-0.6775291648128731 0.26977987840232037 0.6842317210106531"/>
    <dynamics damping="0.9085849821180177" friction="0.1"/>
    <limit lower="-0.9449634106549294" upper="1.0316253842274055" effort="100" velocity="100"/>
  </joint>
  <link name="link6">
    <visual>
      <geometry>
        <cylinder radius="0.06308729785767267" length="0.05400195749273819"/>
      </geometry>
      <material name="wheel_material"/>
    </visual>
    <collision>
      <geometry>
        <cylinder radius="0.06308729785767267" length="0.05400195749273819"/>
      </geometry>
    </collision>
    <inertial>
      <mass value="1.0"/>
      <inertia ixx="0.0012380194054996362" ixy="0" ixz="0" 
               iyy="0.0012380194054996362" iyz="0" 
               izz="0.0019900035754913553"/>
    </inertial>
  </link>
  <joint name="joint6" type="continuous">
    <parent link="base_link"/>
    <child link="link6"/>
    <origin xyz="-0.13985519542031713 -0.147803363373688 -0.04034416414914891" rpy="1.5708 0 0"/>
    <axis xyz="0 1 0"/>
    <dynamics damping="0.9112450712681742" friction="0.1"/>
  </joint>
</robot>