<?xml version="1.0"?>
<robot name="evolved_robot">
  <material name="metal">
    <color rgba="0.7 0.7 0.7 1.0"/>
  </material>
  <material name="plastic">
    <color rgba="0.3 0.3 0.9 1.0"/>
  </material>
  <material name="rubber">
    <color rgba="0.1 0.1 0.1 1.0"/>
  </material>
  <material name="red">
    <color rgba="1.0 0.0 0.0 1.0"/>
  </material>
  <material name="wheel_material">
    <color rgba="0.2 0.2 0.2 1.0"/>
  </material>
  <link name="base_link">
    <visual>
      <geometry><cylinder radius="0.16386570159937627" length="0.12306404708306033"/></geometry>
      <material name="rubber"/>
    </visual>
    <collision>
      <geometry><cylinder radius="0.16386570159937627" length="0.12306404708306033"/></geometry>
    </collision>
    <inertial>
      <mass value="5.0"/>
      <inertia ixx="0.07975055347202432" ixy="0" ixz="0" 
               iyy="0.07975055347202432" iyz="0" 
               izz="0.13425984080327916"/>
    </inertial>
  </link>
  <link name="link1">
    <visual>
      <geometry><cylinder radius="0.06400245244877761" length="0.1427863277072362"/></geometry>
      <material name="plastic"/>
    </visual>
    <collision>
      <geometry><cylinder radius="0.06400245244877761" length="0.1427863277072362"/></geometry>
    </collision>
    <inertial>
      <mass value="0.5"/>
      <inertia ixx="0.0027230730948743643" ixy="0" ixz="0" 
               iyy="0.0027230730948743643" iyz="0" 
               izz="0.00204815695972902"/>
    </inertial>
  </link>
  <joint name="joint1" type="prismatic">
    <parent link="base_link"/>
    <child link="link1"/>
    <origin xyz="0 0 0.061532023541530166" rpy="0 0 0"/>
    <axis xyz="0.9058000039644485 -0.3594897046685945 0.22426213468905498"/>
    <dynamics damping="0.733667224739957" friction="0.1"/>
    <limit lower="-2.170013336969622" upper="0.9438424306910559" effort="100" velocity="100"/>
  </joint>
  <link name="link2">
    <visual>
      <geometry>
        <cylinder radius="0.06369424036554744" length="0.041327053455679844"/>
      </geometry>
      <material name="wheel_material"/>
    </visual>
    <collision>
      <geometry>
        <cylinder radius="0.06369424036554744" length="0.041327053455679844"/>
      </geometry>
    </collision>
    <inertial>
      <mass value="1.0"/>
      <inertia ixx="0.0011565661762134181" ixy="0" ixz="0" 
               iyy="0.0011565661762134181" iyz="0" 
               izz="0.0020284781278720665"/>
    </inertial>
  </link>
  <joint name="joint2" type="continuous">
    <parent link="base_link"/>
    <child link="link2"/>
    <origin xyz="0 0 0" rpy="1.5708 0 0"/>
    <axis xyz="0 1 0"/>
    <dynamics damping="0.6969955237251776" friction="0.1"/>
  </joint>
  <link name="link3">
    <visual>
      <geometry><sphere radius="0.033866837791019656"/></geometry>
      <material name="rubber"/>
    </visual>
    <collision>
      <geometry><sphere radius="0.033866837791019656"/></geometry>
    </collision>
    <inertial>
      <mass value="0.5"/>
      <inertia ixx="0.00045878508078529487" ixy="0" ixz="0" 
               iyy="0.00045878508078529487" iyz="0" 
               izz="0.00045878508078529487"/>
    </inertial>
  </link>
  <joint name="joint3" type="fixed">
    <parent link="base_link"/>
    <child link="link3"/>
    <origin xyz="0 0 0.11153202354153016" rpy="0 0 0"/>
    <axis xyz="0.160765495126054 0.12929547315913087 -0.9784871671092225"/>
    <dynamics damping="0.5877010532053121" friction="0.1"/>
  </joint>
</robot>