<?xml version="1.0"?>
<robot name="evolved_robot">
  <material name="metal">
    <color rgba="0.7 0.7 0.7 1.0"/>
  </material>
  <material name="plastic">
    <color rgba="0.3 0.3 0.9 1.0"/>
  </material>
  <material name="rubber">
    <color rgba="0.1 0.1 0.1 1.0"/>
  </material>
  <material name="red">
    <color rgba="1.0 0.0 0.0 1.0"/>
  </material>
  <material name="wheel_material">
    <color rgba="0.2 0.2 0.2 1.0"/>
  </material>
  <link name="base_link">
    <visual>
      <geometry><sphere radius="0.14801879682677654"/></geometry>
      <material name="metal"/>
    </visual>
    <collision>
      <geometry><sphere radius="0.14801879682677654"/></geometry>
    </collision>
    <inertial>
      <mass value="5.0"/>
      <inertia ixx="0.08763825685618622" ixy="0" ixz="0" 
               iyy="0.08763825685618622" iyz="0" 
               izz="0.08763825685618622"/>
    </inertial>
  </link>
  <link name="link1">
    <visual>
      <geometry><cylinder radius="0.08010638938315645" length="0.195552933887443"/></geometry>
      <material name="metal"/>
    </visual>
    <collision>
      <geometry><cylinder radius="0.08010638938315645" length="0.195552933887443"/></geometry>
    </collision>
    <inertial>
      <mass value="0.5"/>
      <inertia ixx="0.004791004234333691" ixy="0" ixz="0" 
               iyy="0.004791004234333691" iyz="0" 
               izz="0.0032085168100029404"/>
    </inertial>
  </link>
  <joint name="joint1" type="revolute">
    <parent link="base_link"/>
    <child link="link1"/>
    <origin xyz="0 0 0.06258100184765333" rpy="0 0 0"/>
    <axis xyz="-0.5543264736661804 0.568623496870576 0.6077742009986074"/>
    <dynamics damping="0.4910693301975285" friction="0.1"/>
    <limit lower="-0.6915089248139569" upper="0.26213722827720204" effort="100" velocity="100"/>
  </joint>
  <link name="link2">
    <visual>
      <geometry><box size="0.12106848288341883 0.12178832091926753 0.09757899011843829"/></geometry>
      <material name="rubber"/>
    </visual>
    <collision>
      <geometry><box size="0.12106848288341883 0.12178832091926753 0.09757899011843829"/></geometry>
    </collision>
    <inertial>
      <mass value="0.5"/>
      <inertia ixx="0.002029504535405731" ixy="0" ixz="0" 
               iyy="0.002014936405018913" iyz="0" 
               izz="0.002457497721668931"/>
    </inertial>
  </link>
  <joint name="joint2" type="fixed">
    <parent link="base_link"/>
    <child link="link2"/>
    <origin xyz="0 0 0.11258100184765334" rpy="0 0 0"/>
    <axis xyz="0.778146167861676 0.2492365113412111 0.576515136710781"/>
    <dynamics damping="0.30361649380013533" friction="0.1"/>
  </joint>
  <link name="link3">
    <visual>
      <geometry><sphere radius="0.06664626284379745"/></geometry>
      <material name="plastic"/>
    </visual>
    <collision>
      <geometry><sphere radius="0.06664626284379745"/></geometry>
    </collision>
    <inertial>
      <mass value="0.5"/>
      <inertia ixx="0.0017766897404178146" ixy="0" ixz="0" 
               iyy="0.0017766897404178146" iyz="0" 
               izz="0.0017766897404178146"/>
    </inertial>
  </link>
  <joint name="joint3" type="prismatic">
    <parent link="base_link"/>
    <child link="link3"/>
    <origin xyz="0 0 0.16258100184765334" rpy="0 0 0"/>
    <axis xyz="0.006181603176551261 0.7887214977433933 -0.6147196001264204"/>
    <dynamics damping="0.4117828208540274" friction="0.1"/>
    <limit lower="-0.8462198498702073" upper="1.72438105948074" effort="100" velocity="100"/>
  </joint>
  <link name="link4">
    <visual>
      <geometry>
        <cylinder radius="0.04151706606872396" length="0.06681529329872621"/>
      </geometry>
      <material name="wheel_material"/>
    </visual>
    <collision>
      <geometry>
        <cylinder radius="0.04151706606872396" length="0.06681529329872621"/>
      </geometry>
    </collision>
    <inertial>
      <mass value="1.0"/>
      <inertia ixx="0.0008029403119549316" ixy="0" ixz="0" 
               iyy="0.0008029403119549316" iyz="0" 
               izz="0.0008618333874773953"/>
    </inertial>
  </link>
  <joint name="joint4" type="prismatic">
    <parent link="base_link"/>
    <child link="link4"/>
    <origin xyz="0 0 0" rpy="1.5708 0 0"/>
    <axis xyz="0 1 0"/>
    <dynamics damping="0.5038903502025431" friction="0.1"/>
  </joint>
</robot>