<?xml version="1.0"?>
<robot name="evolved_robot">
  <material name="metal">
    <color rgba="0.7 0.7 0.7 1.0"/>
  </material>
  <material name="plastic">
    <color rgba="0.3 0.3 0.9 1.0"/>
  </material>
  <material name="rubber">
    <color rgba="0.1 0.1 0.1 1.0"/>
  </material>
  <material name="red">
    <color rgba="1.0 0.0 0.0 1.0"/>
  </material>
  <material name="wheel_material">
    <color rgba="0.2 0.2 0.2 1.0"/>
  </material>
  <link name="base_link">
    <visual>
      <geometry><box size="0.3450938513911531 0.31446107182327965 0.08684391380071729"/></geometry>
      <material name="plastic"/>
    </visual>
    <collision>
      <geometry><box size="0.3450938513911531 0.31446107182327965 0.08684391380071729"/></geometry>
    </collision>
    <inertial>
      <mass value="5.0"/>
      <inertia ixx="0.08868969254706022" ixy="0" ixz="0" 
               iyy="0.10552635969350475" iyz="0" 
               izz="0.18164627663352095"/>
    </inertial>
  </link>
  <link name="link1">
    <visual>
      <geometry>
        <cylinder radius="0.06675973785468586" length="0.059851785901877536"/>
      </geometry>
      <material name="wheel_material"/>
    </visual>
    <collision>
      <geometry>
        <cylinder radius="0.06675973785468586" length="0.059851785901877536"/>
      </geometry>
    </collision>
    <inertial>
      <mass value="1.0"/>
      <inertia ixx="0.0014127353392436098" ixy="0" ixz="0" 
               iyy="0.0014127353392436098" iyz="0" 
               izz="0.0022284312992131884"/>
    </inertial>
  </link>
  <joint name="joint1" type="continuous">
    <parent link="base_link"/>
    <child link="link1"/>
    <origin xyz="0.15254692569557657 0.15723053591163982 -0.043421956900358646" rpy="1.5708 0 0"/>
    <axis xyz="0 0 1"/>
    <dynamics damping="0.7795040315595899" friction="0.1"/>
  </joint>
  <link name="link2">
    <visual>
      <geometry>
        <cylinder radius="0.07578756342487761" length="0.05521397968701486"/>
      </geometry>
      <material name="wheel_material"/>
    </visual>
    <collision>
      <geometry>
        <cylinder radius="0.07578756342487761" length="0.05521397968701486"/>
      </geometry>
    </collision>
    <inertial>
      <mass value="1.0"/>
      <inertia ixx="0.0016899873218764688" ixy="0" ixz="0" 
               iyy="0.0016899873218764688" iyz="0" 
               izz="0.002871877384939923"/>
    </inertial>
  </link>
  <joint name="joint2" type="continuous">
    <parent link="base_link"/>
    <child link="link2"/>
    <origin xyz="-0.15254692569557657 0.15723053591163982 -0.043421956900358646" rpy="1.5708 0 0"/>
    <axis xyz="0 0 1"/>
    <dynamics damping="0.9333958952129529" friction="0.1"/>
  </joint>
  <link name="link3">
    <visual>
      <geometry>
        <cylinder radius="0.06341371124760828" length="0.07953457771954003"/>
      </geometry>
      <material name="wheel_material"/>
    </visual>
    <collision>
      <geometry>
        <cylinder radius="0.06341371124760828" length="0.07953457771954003"/>
      </geometry>
    </collision>
    <inertial>
      <mass value="1.0"/>
      <inertia ixx="0.0015324704479675565" ixy="0" ixz="0" 
               iyy="0.0015324704479675565" iyz="0" 
               izz="0.0020106493870975205"/>
    </inertial>
  </link>
  <joint name="joint3" type="continuous">
    <parent link="base_link"/>
    <child link="link3"/>
    <origin xyz="-0.15254692569557657 -0.15723053591163982 -0.043421956900358646" rpy="1.5708 0 0"/>
    <axis xyz="0 0 1"/>
    <dynamics damping="0.44477635903812607" friction="0.1"/>
  </joint>
  <link name="link4">
    <visual>
      <geometry><box size="0.17811013926056457 0.16652620539872703 0.24737045482485343"/></geometry>
      <material name="rubber"/>
    </visual>
    <collision>
      <geometry><box size="0.17811013926056457 0.16652620539872703 0.24737045482485343"/></geometry>
    </collision>
    <inertial>
      <mass value="0.5"/>
      <inertia ixx="0.007410259917062823" ixy="0" ixz="0" 
               iyy="0.0077429469689727125" iyz="0" 
               izz="0.0049545165659930605"/>
    </inertial>
  </link>
  <joint name="joint4" type="revolute">
    <parent link="base_link"/>
    <child link="link4"/>
    <origin xyz="0 0 0.043421956900358646" rpy="0 0 0"/>
    <axis xyz="0.3759741500163819 -0.38356584780333974 -0.84351685159122"/>
    <dynamics damping="0.7055236229433179" friction="0.1"/>
    <limit lower="-1.4276637334588047" upper="1.481166460750073" effort="100" velocity="100"/>
  </joint>
  <link name="link5">
    <visual>
      <geometry><cylinder radius="0.070999322876352" length="0.05117332176221254"/></geometry>
      <material name="rubber"/>
    </visual>
    <collision>
      <geometry><cylinder radius="0.070999322876352" length="0.05117332176221254"/></geometry>
    </collision>
    <inertial>
      <mass value="0.5"/>
      <inertia ixx="0.0014784517005733645" ixy="0" ixz="0" 
               iyy="0.0014784517005733645" iyz="0" 
               izz="0.00252045192445024"/>
    </inertial>
  </link>
  <joint name="joint5" type="revolute">
    <parent link="base_link"/>
    <child link="link5"/>
    <origin xyz="0 0 0.09342195690035865" rpy="0 0 0"/>
    <axis xyz="0.0008187969276834712 0.48946958674342583 -0.8720199844182537"/>
    <dynamics damping="0.679806887575297" friction="0.1"/>
    <limit lower="-0.8443760477989789" upper="1.1447330603144588" effort="100" velocity="100"/>
  </joint>
</robot>