<?xml version="1.0"?>
<robot name="evolved_robot">
  <material name="metal">
    <color rgba="0.7 0.7 0.7 1.0"/>
  </material>
  <material name="plastic">
    <color rgba="0.3 0.3 0.9 1.0"/>
  </material>
  <material name="rubber">
    <color rgba="0.1 0.1 0.1 1.0"/>
  </material>
  <material name="red">
    <color rgba="1.0 0.0 0.0 1.0"/>
  </material>
  <material name="wheel_material">
    <color rgba="0.2 0.2 0.2 1.0"/>
  </material>
  <link name="base_link">
    <visual>
      <geometry><box size="0.31007424185339777 0.2637592270063851 0.09384700153046605"/></geometry>
      <material name="plastic"/>
    </visual>
    <collision>
      <geometry><box size="0.31007424185339777 0.2637592270063851 0.09384700153046605"/></geometry>
    </collision>
    <inertial>
      <mass value="5.0"/>
      <inertia ixx="0.06531349127272092" ixy="0" ixz="0" 
               iyy="0.08746107929768226" iyz="0" 
               izz="0.13809580440997102"/>
    </inertial>
  </link>
  <link name="link1">
    <visual>
      <geometry>
        <cylinder radius="0.03486520265155107" length="0.07009535717521732"/>
      </geometry>
      <material name="wheel_material"/>
    </visual>
    <collision>
      <geometry>
        <cylinder radius="0.03486520265155107" length="0.07009535717521732"/>
      </geometry>
    </collision>
    <inertial>
      <mass value="1.0"/>
      <inertia ixx="0.0007133421804435384" ixy="0" ixz="0" 
               iyy="0.0007133421804435384" iyz="0" 
               izz="0.0006077911779668618"/>
    </inertial>
  </link>
  <joint name="joint1" type="fixed">
    <parent link="base_link"/>
    <child link="link1"/>
    <origin xyz="0 0 0" rpy="1.5708 0 0"/>
    <axis xyz="0 0 1"/>
    <dynamics damping="0.8605186917281632" friction="0.1"/>
  </joint>
  <link name="link2">
    <visual>
      <geometry><cylinder radius="0.07940316327069605" length="0.05104070290595315"/></geometry>
      <material name="plastic"/>
    </visual>
    <collision>
      <geometry><cylinder radius="0.07940316327069605" length="0.05104070290595315"/></geometry>
    </collision>
    <inertial>
      <mass value="0.5"/>
      <inertia ixx="0.0017933116971093515" ixy="0" ixz="0" 
               iyy="0.0017933116971093515" iyz="0" 
               izz="0.003152431168696407"/>
    </inertial>
  </link>
  <joint name="joint2" type="fixed">
    <parent link="base_link"/>
    <child link="link2"/>
    <origin xyz="0 0 0.04692350076523302" rpy="0 0 0"/>
    <axis xyz="0.18604024470602387 -0.9368951270360836 0.2960009261569358"/>
    <dynamics damping="0.32429681390972" friction="0.1"/>
  </joint>
  <link name="link3">
    <visual>
      <geometry><cylinder radius="0.03788598198868927" length="0.06036328961391901"/></geometry>
      <material name="plastic"/>
    </visual>
    <collision>
      <geometry><cylinder radius="0.03788598198868927" length="0.06036328961391901"/></geometry>
    </collision>
    <inertial>
      <mass value="0.5"/>
      <inertia ixx="0.0006624808022296438" ixy="0" ixz="0" 
               iyy="0.0006624808022296438" iyz="0" 
               izz="0.0007176738156236439"/>
    </inertial>
  </link>
  <joint name="joint3" type="revolute">
    <parent link="base_link"/>
    <child link="link3"/>
    <origin xyz="0 0 0.09692350076523303" rpy="0 0 0"/>
    <axis xyz="0.9818633592503528 -0.14382473688380953 -0.12352647012651045"/>
    <dynamics damping="0.6617432306237528" friction="0.1"/>
    <limit lower="-2.230233953395558" upper="0.9605639705156569" effort="100" velocity="100"/>
  </joint>
  <link name="link4">
    <visual>
      <geometry><box size="0.09246010463648308 0.1646332722257985 0.23097902591593228"/></geometry>
      <material name="metal"/>
    </visual>
    <collision>
      <geometry><box size="0.09246010463648308 0.1646332722257985 0.23097902591593228"/></geometry>
    </collision>
    <inertial>
      <mass value="0.5"/>
      <inertia ixx="0.0067046187280705655" ixy="0" ixz="0" 
               iyy="0.00515834844687186" iyz="0" 
               izz="0.002971082106096939"/>
    </inertial>
  </link>
  <joint name="joint4" type="revolute">
    <parent link="base_link"/>
    <child link="link4"/>
    <origin xyz="0 0 0.14692350076523303" rpy="0 0 0"/>
    <axis xyz="0.7122312604972002 0.31913159411021674 -0.6252052920531312"/>
    <dynamics damping="0.7941454157241027" friction="0.1"/>
    <limit lower="-1.577408963519323" upper="2.0410000000000004" effort="100" velocity="100"/>
  </joint>
</robot>