<?xml version="1.0"?>
<robot name="evolved_robot">
  <material name="metal">
    <color rgba="0.7 0.7 0.7 1.0"/>
  </material>
  <material name="plastic">
    <color rgba="0.3 0.3 0.9 1.0"/>
  </material>
  <material name="rubber">
    <color rgba="0.1 0.1 0.1 1.0"/>
  </material>
  <material name="red">
    <color rgba="1.0 0.0 0.0 1.0"/>
  </material>
  <material name="wheel_material">
    <color rgba="0.2 0.2 0.2 1.0"/>
  </material>
  <link name="base_link">
    <visual>
      <geometry><box size="0.314937614659212 0.3361883288096972 0.08684391380071729"/></geometry>
      <material name="plastic"/>
    </visual>
    <collision>
      <geometry><box size="0.314937614659212 0.3361883288096972 0.08684391380071729"/></geometry>
    </collision>
    <inertial>
      <mass value="5.0"/>
      <inertia ixx="0.10047038149340291" ixy="0" ixz="0" 
               iyy="0.08893963874288395" iyz="0" 
               izz="0.17684024462924278"/>
    </inertial>
  </link>
  <link name="link1">
    <visual>
      <geometry>
        <cylinder radius="0.05250731627988842" length="0.059354048234470755"/>
      </geometry>
      <material name="wheel_material"/>
    </visual>
    <collision>
      <geometry>
        <cylinder radius="0.05250731627988842" length="0.059354048234470755"/>
      </geometry>
    </collision>
    <inertial>
      <mass value="1.0"/>
      <inertia ixx="0.0009828298192140492" ixy="0" ixz="0" 
               iyy="0.0009828298192140492" iyz="0" 
               izz="0.001378509131458118"/>
    </inertial>
  </link>
  <joint name="joint1" type="continuous">
    <parent link="base_link"/>
    <child link="link1"/>
    <origin xyz="0.137468807329606 0.1680941644048486 -0.043421956900358646" rpy="1.5708 0 0"/>
    <axis xyz="0 0 1"/>
    <dynamics damping="0.7784165874908638" friction="0.1"/>
  </joint>
  <link name="link2">
    <visual>
      <geometry>
        <cylinder radius="0.07597663445765272" length="0.04272438068433486"/>
      </geometry>
      <material name="wheel_material"/>
    </visual>
    <collision>
      <geometry>
        <cylinder radius="0.07597663445765272" length="0.04272438068433486"/>
      </geometry>
    </collision>
    <inertial>
      <mass value="1.0"/>
      <inertia ixx="0.0015952266379496095" ixy="0" ixz="0" 
               iyy="0.0015952266379496095" iyz="0" 
               izz="0.0028862244917558914"/>
    </inertial>
  </link>
  <joint name="joint2" type="continuous">
    <parent link="base_link"/>
    <child link="link2"/>
    <origin xyz="-0.137468807329606 0.1680941644048486 -0.043421956900358646" rpy="1.5708 0 0"/>
    <axis xyz="0 0 1"/>
    <dynamics damping="0.9332973929305248" friction="0.1"/>
  </joint>
  <link name="link3">
    <visual>
      <geometry>
        <cylinder radius="0.06387249660562594" length="0.045823926981774545"/>
      </geometry>
      <material name="wheel_material"/>
    </visual>
    <collision>
      <geometry>
        <cylinder radius="0.06387249660562594" length="0.045823926981774545"/>
      </geometry>
    </collision>
    <inertial>
      <mass value="1.0"/>
      <inertia ixx="0.0011949099793281746" ixy="0" ixz="0" 
               iyy="0.0011949099793281746" iyz="0" 
               izz="0.0020398479113178485"/>
    </inertial>
  </link>
  <joint name="joint3" type="continuous">
    <parent link="base_link"/>
    <child link="link3"/>
    <origin xyz="-0.137468807329606 -0.1680941644048486 -0.043421956900358646" rpy="1.5708 0 0"/>
    <axis xyz="0 0 1"/>
    <dynamics damping="0.4557383346281597" friction="0.1"/>
  </joint>
</robot>