<?xml version="1.0"?>
<robot name="evolved_robot">
  <material name="metal">
    <color rgba="0.7 0.7 0.7 1.0"/>
  </material>
  <material name="plastic">
    <color rgba="0.3 0.3 0.9 1.0"/>
  </material>
  <material name="rubber">
    <color rgba="0.1 0.1 0.1 1.0"/>
  </material>
  <material name="red">
    <color rgba="1.0 0.0 0.0 1.0"/>
  </material>
  <material name="wheel_material">
    <color rgba="0.2 0.2 0.2 1.0"/>
  </material>
  <link name="base_link">
    <visual>
      <geometry><box size="0.34439248250865495 0.3053804344445662 0.1023509380452807"/></geometry>
      <material name="metal"/>
    </visual>
    <collision>
      <geometry><box size="0.34439248250865495 0.3053804344445662 0.1023509380452807"/></geometry>
    </collision>
    <inertial>
      <mass value="5.0"/>
      <inertia ixx="0.08644410355025073" ixy="0" ixz="0" 
               iyy="0.10756824710601925" iyz="0" 
               izz="0.1765528264583552"/>
    </inertial>
  </link>
  <link name="link1">
    <visual>
      <geometry><sphere radius="0.056720709105281"/></geometry>
      <material name="rubber"/>
    </visual>
    <collision>
      <geometry><sphere radius="0.056720709105281"/></geometry>
    </collision>
    <inertial>
      <mass value="0.5"/>
      <inertia ixx="0.0012868955365623628" ixy="0" ixz="0" 
               iyy="0.0012868955365623628" iyz="0" 
               izz="0.0012868955365623628"/>
    </inertial>
  </link>
  <joint name="joint1" type="prismatic">
    <parent link="base_link"/>
    <child link="link1"/>
    <origin xyz="0 0 0.05117546902264035" rpy="0 0 0"/>
    <axis xyz="0.036645387097136856 0.9992631250150266 -0.011415891980237186"/>
    <dynamics damping="0.23143663430366734" friction="0.1"/>
    <limit lower="-1.1598970419332362" upper="0.36846683275504616" effort="100" velocity="100"/>
  </joint>
  <link name="link2">
    <visual>
      <geometry><box size="0.15448439191207008 0.23039288727358748 0.053485899125817596"/></geometry>
      <material name="rubber"/>
    </visual>
    <collision>
      <geometry><box size="0.15448439191207008 0.23039288727358748 0.053485899125817596"/></geometry>
    </collision>
    <inertial>
      <mass value="0.5"/>
      <inertia ixx="0.004661801992629761" ixy="0" ixz="0" 
               iyy="0.0022271807291449337" iyz="0" 
               izz="0.006412192487558505"/>
    </inertial>
  </link>
  <joint name="joint2" type="fixed">
    <parent link="base_link"/>
    <child link="link2"/>
    <origin xyz="0 0 0.10117546902264035" rpy="0 0 0"/>
    <axis xyz="-0.7885547507812889 0.6140011411589732 -0.0344093544801093"/>
    <dynamics damping="0.6447135498514903" friction="0.1"/>
  </joint>
  <link name="link3">
    <visual>
      <geometry>
        <cylinder radius="0.0796496763331537" length="0.05484881468768034"/>
      </geometry>
      <material name="wheel_material"/>
    </visual>
    <collision>
      <geometry>
        <cylinder radius="0.0796496763331537" length="0.05484881468768034"/>
      </geometry>
    </collision>
    <inertial>
      <mass value="1.0"/>
      <inertia ixx="0.0018367171077143278" ixy="0" ixz="0" 
               iyy="0.0018367171077143278" iyz="0" 
               izz="0.0031720354699880725"/>
    </inertial>
  </link>
  <joint name="joint3" type="continuous">
    <parent link="base_link"/>
    <child link="link3"/>
    <origin xyz="0.15219624125432749 0.1526902172222831 -0.05117546902264035" rpy="1.5708 0 0"/>
    <axis xyz="0 1 0"/>
    <dynamics damping="0.8567749116372217" friction="0.1"/>
  </joint>
  <link name="link4">
    <visual>
      <geometry>
        <cylinder radius="0.06299066332634884" length="0.05903397976793874"/>
      </geometry>
      <material name="wheel_material"/>
    </visual>
    <collision>
      <geometry>
        <cylinder radius="0.06299066332634884" length="0.05903397976793874"/>
      </geometry>
    </collision>
    <inertial>
      <mass value="1.0"/>
      <inertia ixx="0.0012823734805101406" ixy="0" ixz="0" 
               iyy="0.0012823734805101406" iyz="0" 
               izz="0.0019839118331467145"/>
    </inertial>
  </link>
  <joint name="joint4" type="continuous">
    <parent link="base_link"/>
    <child link="link4"/>
    <origin xyz="0.15219624125432749 -0.1526902172222831 -0.05117546902264035" rpy="1.5708 0 0"/>
    <axis xyz="0 1 0"/>
    <dynamics damping="0.6803936122012411" friction="0.1"/>
  </joint>
  <link name="link5">
    <visual>
      <geometry>
        <cylinder radius="0.07325488817888404" length="0.035417443451675835"/>
      </geometry>
      <material name="wheel_material"/>
    </visual>
    <collision>
      <geometry>
        <cylinder radius="0.07325488817888404" length="0.035417443451675835"/>
      </geometry>
    </collision>
    <inertial>
      <mass value="1.0"/>
      <inertia ixx="0.0014461026022462558" ixy="0" ixz="0" 
               iyy="0.0014461026022462558" iyz="0" 
               izz="0.002683139321050402"/>
    </inertial>
  </link>
  <joint name="joint5" type="fixed">
    <parent link="base_link"/>
    <child link="link5"/>
    <origin xyz="-0.15219624125432749 0.1526902172222831 -0.05117546902264035" rpy="1.5708 0 0"/>
    <axis xyz="0 1 0"/>
    <dynamics damping="0.8084040287101422" friction="0.1"/>
  </joint>
  <link name="link6">
    <visual>
      <geometry>
        <cylinder radius="0.08286843383143416" length="0.057170271976782414"/>
      </geometry>
      <material name="wheel_material"/>
    </visual>
    <collision>
      <geometry>
        <cylinder radius="0.08286843383143416" length="0.057170271976782414"/>
      </geometry>
    </collision>
    <inertial>
      <mass value="1.0"/>
      <inertia ixx="0.001989164331243635" ixy="0" ixz="0" 
               iyy="0.001989164331243635" iyz="0" 
               izz="0.003433588662837391"/>
    </inertial>
  </link>
  <joint name="joint6" type="continuous">
    <parent link="base_link"/>
    <child link="link6"/>
    <origin xyz="-0.15219624125432749 -0.1526902172222831 -0.05117546902264035" rpy="1.5708 0 0"/>
    <axis xyz="0 1 0"/>
    <dynamics damping="0.7100066042512578" friction="0.1"/>
  </joint>
</robot>