<?xml version="1.0"?>
<robot name="evolved_robot">
  <material name="metal">
    <color rgba="0.7 0.7 0.7 1.0"/>
  </material>
  <material name="plastic">
    <color rgba="0.3 0.3 0.9 1.0"/>
  </material>
  <material name="rubber">
    <color rgba="0.1 0.1 0.1 1.0"/>
  </material>
  <material name="red">
    <color rgba="1.0 0.0 0.0 1.0"/>
  </material>
  <material name="wheel_material">
    <color rgba="0.2 0.2 0.2 1.0"/>
  </material>
  <link name="base_link">
    <visual>
      <geometry><box size="0.34419402284880096 0.4915286942678372 0.10917641224025697"/></geometry>
      <material name="metal"/>
    </visual>
    <collision>
      <geometry><box size="0.34419402284880096 0.4915286942678372 0.10917641224025697"/></geometry>
    </collision>
    <inertial>
      <mass value="5.0"/>
      <inertia ixx="0.21126662189858292" ixy="0" ixz="0" 
               iyy="0.10865751196207955" iyz="0" 
               izz="0.3000583188779049"/>
    </inertial>
  </link>
  <link name="link1">
    <visual>
      <geometry>
        <cylinder radius="0.06276374789163566" length="0.0514543559049874"/>
      </geometry>
      <material name="wheel_material"/>
    </visual>
    <collision>
      <geometry>
        <cylinder radius="0.06276374789163566" length="0.0514543559049874"/>
      </geometry>
    </collision>
    <inertial>
      <mass value="1.0"/>
      <inertia ixx="0.001205451240817626" ixy="0" ixz="0" 
               iyy="0.001205451240817626" iyz="0" 
               izz="0.0019696440247024"/>
    </inertial>
  </link>
  <joint name="joint1" type="continuous">
    <parent link="base_link"/>
    <child link="link1"/>
    <origin xyz="0.1520970114244005 0.2457643471339186 -0.054588206120128484" rpy="1.5708 0 0"/>
    <axis xyz="0 1 0"/>
    <dynamics damping="0.800080736609337" friction="0.1"/>
  </joint>
  <link name="link2">
    <visual>
      <geometry>
        <cylinder radius="0.08990331684480049" length="0.07344813941414054"/>
      </geometry>
      <material name="wheel_material"/>
    </visual>
    <collision>
      <geometry>
        <cylinder radius="0.08990331684480049" length="0.07344813941414054"/>
      </geometry>
    </collision>
    <inertial>
      <mass value="1.0"/>
      <inertia ixx="0.0024702040268740656" ixy="0" ixz="0" 
               iyy="0.0024702040268740656" iyz="0" 
               izz="0.004041303189848294"/>
    </inertial>
  </link>
  <joint name="joint2" type="continuous">
    <parent link="base_link"/>
    <child link="link2"/>
    <origin xyz="0.1520970114244005 -0.2457643471339186 -0.054588206120128484" rpy="1.5708 0 0"/>
    <axis xyz="0 1 0"/>
    <dynamics damping="0.856863713544254" friction="0.1"/>
  </joint>
  <link name="link3">
    <visual>
      <geometry>
        <cylinder radius="0.08863821844379499" length="0.04105246299968013"/>
      </geometry>
      <material name="wheel_material"/>
    </visual>
    <collision>
      <geometry>
        <cylinder radius="0.08863821844379499" length="0.04105246299968013"/>
      </geometry>
    </collision>
    <inertial>
      <mass value="1.0"/>
      <inertia ixx="0.0021046255020841552" ixy="0" ixz="0" 
               iyy="0.0021046255020841552" iyz="0" 
               izz="0.003928366884444959"/>
    </inertial>
  </link>
  <joint name="joint3" type="continuous">
    <parent link="base_link"/>
    <child link="link3"/>
    <origin xyz="-0.1520970114244005 0.2457643471339186 -0.054588206120128484" rpy="1.5708 0 0"/>
    <axis xyz="0 1 0"/>
    <dynamics damping="0.8563358081099343" friction="0.1"/>
  </joint>
  <link name="link4">
    <visual>
      <geometry>
        <cylinder radius="0.09012320174228113" length="0.059033102302507565"/>
      </geometry>
      <material name="wheel_material"/>
    </visual>
    <collision>
      <geometry>
        <cylinder radius="0.09012320174228113" length="0.059033102302507565"/>
      </geometry>
    </collision>
    <inertial>
      <mass value="1.0"/>
      <inertia ixx="0.002320956803691503" ixy="0" ixz="0" 
               iyy="0.002320956803691503" iyz="0" 
               izz="0.004061095746139952"/>
    </inertial>
  </link>
  <joint name="joint4" type="continuous">
    <parent link="base_link"/>
    <child link="link4"/>
    <origin xyz="-0.1520970114244005 -0.2457643471339186 -0.054588206120128484" rpy="1.5708 0 0"/>
    <axis xyz="0 1 0"/>
    <dynamics damping="0.847315345816548" friction="0.1"/>
  </joint>
  <link name="link5">
    <visual>
      <geometry><box size="0.05759607160511873 0.23717176276530344 0.11067024599114919"/></geometry>
      <material name="plastic"/>
    </visual>
    <collision>
      <geometry><box size="0.05759607160511873 0.23717176276530344 0.11067024599114919"/></geometry>
    </collision>
    <inertial>
      <mass value="0.5"/>
      <inertia ixx="0.005708195700078571" ixy="0" ixz="0" 
               iyy="0.001297100901006953" iyz="0" 
               izz="0.004963979376461945"/>
    </inertial>
  </link>
  <joint name="joint5" type="floating">
    <parent link="base_link"/>
    <child link="link5"/>
    <origin xyz="0 0 0.054588206120128484" rpy="0 0 0"/>
    <axis xyz="-0.7502531274434568 -0.4120682590603893 0.5170299746013302"/>
    <dynamics damping="0.6742539525682554" friction="0.1"/>
  </joint>
  <link name="link6">
    <visual>
      <geometry>
        <cylinder radius="0.05618938792943427" length="0.07746693340063038"/>
      </geometry>
      <material name="wheel_material"/>
    </visual>
    <collision>
      <geometry>
        <cylinder radius="0.05618938792943427" length="0.07746693340063038"/>
      </geometry>
    </collision>
    <inertial>
      <mass value="1.0"/>
      <inertia ixx="0.0012894056431792555" ixy="0" ixz="0" 
               iyy="0.0012894056431792555" iyz="0" 
               izz="0.001578623657942227"/>
    </inertial>
  </link>
  <joint name="joint6" type="continuous">
    <parent link="base_link"/>
    <child link="link6"/>
    <origin xyz="0 -0.32768579617855814 -0.054588206120128484" rpy="1.5708 0 0"/>
    <axis xyz="0 1 0"/>
    <dynamics damping="0.29333186413917367" friction="0.1"/>
  </joint>
</robot>