<?xml version="1.0"?>
<robot name="evolved_robot">
  <material name="metal">
    <color rgba="0.7 0.7 0.7 1.0"/>
  </material>
  <material name="plastic">
    <color rgba="0.3 0.3 0.9 1.0"/>
  </material>
  <material name="rubber">
    <color rgba="0.1 0.1 0.1 1.0"/>
  </material>
  <material name="red">
    <color rgba="1.0 0.0 0.0 1.0"/>
  </material>
  <material name="wheel_material">
    <color rgba="0.2 0.2 0.2 1.0"/>
  </material>
  <link name="base_link">
    <visual>
      <geometry><sphere radius="0.12823623912300278"/></geometry>
      <material name="metal"/>
    </visual>
    <collision>
      <geometry><sphere radius="0.12823623912300278"/></geometry>
    </collision>
    <inertial>
      <mass value="5.0"/>
      <inertia ixx="0.0657781320976478" ixy="0" ixz="0" 
               iyy="0.0657781320976478" iyz="0" 
               izz="0.0657781320976478"/>
    </inertial>
  </link>
  <link name="link1">
    <visual>
      <geometry><sphere radius="0.06796551032297707"/></geometry>
      <material name="plastic"/>
    </visual>
    <collision>
      <geometry><sphere radius="0.06796551032297707"/></geometry>
    </collision>
    <inertial>
      <mass value="0.5"/>
      <inertia ixx="0.001847724237385081" ixy="0" ixz="0" 
               iyy="0.001847724237385081" iyz="0" 
               izz="0.001847724237385081"/>
    </inertial>
  </link>
  <joint name="joint1" type="revolute">
    <parent link="base_link"/>
    <child link="link1"/>
    <origin xyz="0 0 0.05395942355574325" rpy="0 0 0"/>
    <axis xyz="-0.43895263898983183 -0.6521106710845593 -0.6181199344637803"/>
    <dynamics damping="0.6507322579426503" friction="0.1"/>
    <limit lower="-1.2543507210500946" upper="1.2636909180375597" effort="100" velocity="100"/>
  </joint>
  <link name="link2">
    <visual>
      <geometry>
        <cylinder radius="0.054725586248147544" length="0.05017284003282977"/>
      </geometry>
      <material name="wheel_material"/>
    </visual>
    <collision>
      <geometry>
        <cylinder radius="0.054725586248147544" length="0.05017284003282977"/>
      </geometry>
    </collision>
    <inertial>
      <mass value="1.0"/>
      <inertia ixx="0.000958498603964186" ixy="0" ixz="0" 
               iyy="0.000958498603964186" iyz="0" 
               izz="0.0014974448951017177"/>
    </inertial>
  </link>
  <joint name="joint2" type="continuous">
    <parent link="base_link"/>
    <child link="link2"/>
    <origin xyz="0.16212409656386137 0.14862519724940376 -0.05395942355574325" rpy="1.5708 0 0"/>
    <axis xyz="0 1 0"/>
    <dynamics damping="0.5353756054625594" friction="0.1"/>
  </joint>
  <link name="link3">
    <visual>
      <geometry>
        <cylinder radius="0.06910428393601839" length="0.06481733612685017"/>
      </geometry>
      <material name="wheel_material"/>
    </visual>
    <collision>
      <geometry>
        <cylinder radius="0.06910428393601839" length="0.06481733612685017"/>
      </geometry>
    </collision>
    <inertial>
      <mass value="1.0"/>
      <inertia ixx="0.001543957769792552" ixy="0" ixz="0" 
               iyy="0.001543957769792552" iyz="0" 
               izz="0.002387701029154925"/>
    </inertial>
  </link>
  <joint name="joint3" type="continuous">
    <parent link="base_link"/>
    <child link="link3"/>
    <origin xyz="0.16212409656386137 -0.14862519724940376 -0.05395942355574325" rpy="1.5708 0 0"/>
    <axis xyz="0 1 0"/>
    <dynamics damping="0.9361071883416644" friction="0.1"/>
  </joint>
  <link name="link4">
    <visual>
      <geometry>
        <cylinder radius="0.07188699764978237" length="0.047103208370051206"/>
      </geometry>
      <material name="wheel_material"/>
    </visual>
    <collision>
      <geometry>
        <cylinder radius="0.07188699764978237" length="0.047103208370051206"/>
      </geometry>
    </collision>
    <inertial>
      <mass value="1.0"/>
      <inertia ixx="0.0014768277943376595" ixy="0" ixz="0" 
               iyy="0.0014768277943376595" iyz="0" 
               izz="0.0025838702155499085"/>
    </inertial>
  </link>
  <joint name="joint4" type="continuous">
    <parent link="base_link"/>
    <child link="link4"/>
    <origin xyz="-0.16212409656386137 0.14862519724940376 -0.05395942355574325" rpy="1.5708 0 0"/>
    <axis xyz="0 1 0"/>
    <dynamics damping="0.6299214264204668" friction="0.1"/>
  </joint>
  <link name="link5">
    <visual>
      <geometry><box size="0.1224750609236127 0.07212238901574441 0.0708134460902181"/></geometry>
      <material name="rubber"/>
    </visual>
    <collision>
      <geometry><box size="0.1224750609236127 0.07212238901574441 0.0708134460902181"/></geometry>
    </collision>
    <inertial>
      <mass value="0.5"/>
      <inertia ixx="0.0008513485953758829" ixy="0" ixz="0" 
               iyy="0.0016678903912845724" iyz="0" 
               izz="0.0016834816287984178"/>
    </inertial>
  </link>
  <joint name="joint5" type="fixed">
    <parent link="base_link"/>
    <child link="link5"/>
    <origin xyz="0 0 0.10395942355574325" rpy="0 0 0"/>
    <axis xyz="-0.5677213251139246 -0.7027704675307052 0.4287262144744169"/>
    <dynamics damping="0.8033408798466991" friction="0.1"/>
  </joint>
  <link name="link6">
    <visual>
      <geometry>
        <cylinder radius="0.0756692764888888" length="0.052724950445477134"/>
      </geometry>
      <material name="wheel_material"/>
    </visual>
    <collision>
      <geometry>
        <cylinder radius="0.0756692764888888" length="0.052724950445477134"/>
      </geometry>
    </collision>
    <inertial>
      <mass value="1.0"/>
      <inertia ixx="0.0016631198843778097" ixy="0" ixz="0" 
               iyy="0.0016631198843778097" iyz="0" 
               izz="0.0028629197021759496"/>
    </inertial>
  </link>
  <joint name="joint6" type="continuous">
    <parent link="base_link"/>
    <child link="link6"/>
    <origin xyz="-0.16212409656386137 -0.14862519724940376 -0.05395942355574325" rpy="1.5708 0 0"/>
    <axis xyz="0 1 0"/>
    <dynamics damping="0.9271685352918507" friction="0.1"/>
  </joint>
</robot>