<?xml version="1.0"?>
<robot name="evolved_robot">
  <material name="metal">
    <color rgba="0.7 0.7 0.7 1.0"/>
  </material>
  <material name="plastic">
    <color rgba="0.3 0.3 0.9 1.0"/>
  </material>
  <material name="rubber">
    <color rgba="0.1 0.1 0.1 1.0"/>
  </material>
  <material name="red">
    <color rgba="1.0 0.0 0.0 1.0"/>
  </material>
  <material name="wheel_material">
    <color rgba="0.2 0.2 0.2 1.0"/>
  </material>
  <link name="base_link">
    <visual>
      <geometry><cylinder radius="0.1272388989605983" length="0.08906482229332736"/></geometry>
      <material name="rubber"/>
    </visual>
    <collision>
      <geometry><cylinder radius="0.1272388989605983" length="0.08906482229332736"/></geometry>
    </collision>
    <inertial>
      <mass value="5.0"/>
      <inertia ixx="0.04708479566354836" ixy="0" ixz="0" 
               iyy="0.04708479566354836" iyz="0" 
               izz="0.08094868704352673"/>
    </inertial>
  </link>
  <link name="link1">
    <visual>
      <geometry><cylinder radius="0.06399652453522651" length="0.1427863277072362"/></geometry>
      <material name="plastic"/>
    </visual>
    <collision>
      <geometry><cylinder radius="0.06399652453522651" length="0.1427863277072362"/></geometry>
    </collision>
    <inertial>
      <mass value="0.5"/>
      <inertia ixx="0.0027228834031568163" ixy="0" ixz="0" 
               iyy="0.0027228834031568163" iyz="0" 
               izz="0.0020477775762939247"/>
    </inertial>
  </link>
  <joint name="joint1" type="prismatic">
    <parent link="base_link"/>
    <child link="link1"/>
    <origin xyz="0 0 0.04453241114666368" rpy="0 0 0"/>
    <axis xyz="-0.742464210832582 -0.5326631871505938 0.40622262946237053"/>
    <dynamics damping="0.648240366738078" friction="0.1"/>
    <limit lower="-0.9303338955994896" upper="0.9438424306910559" effort="100" velocity="100"/>
  </joint>
  <link name="link2">
    <visual>
      <geometry>
        <cylinder radius="0.0721658289576909" length="0.05085709238639688"/>
      </geometry>
      <material name="wheel_material"/>
    </visual>
    <collision>
      <geometry>
        <cylinder radius="0.0721658289576909" length="0.05085709238639688"/>
      </geometry>
    </collision>
    <inertial>
      <mass value="1.0"/>
      <inertia ixx="0.0015175137044542168" ixy="0" ixz="0" 
               iyy="0.0015175137044542168" iyz="0" 
               izz="0.0026039534345753492"/>
    </inertial>
  </link>
  <joint name="joint2" type="continuous">
    <parent link="base_link"/>
    <child link="link2"/>
    <origin xyz="0 0 0" rpy="1.5708 0 0"/>
    <axis xyz="0 1 0"/>
    <dynamics damping="0.6987285557382152" friction="0.1"/>
  </joint>
  <link name="link3">
    <visual>
      <geometry><box size="0.15197306139109826 0.15755732544313733 0.06773367558203931"/></geometry>
      <material name="rubber"/>
    </visual>
    <collision>
      <geometry><box size="0.15197306139109826 0.15755732544313733 0.06773367558203931"/></geometry>
    </collision>
    <inertial>
      <mass value="0.5"/>
      <inertia ixx="0.002451013467387303" ixy="0" ixz="0" 
               iyy="0.0023069718497029557" iyz="0" 
               izz="0.003993343515781434"/>
    </inertial>
  </link>
  <joint name="joint3" type="prismatic">
    <parent link="base_link"/>
    <child link="link3"/>
    <origin xyz="0 0 0.09453241114666369" rpy="0 0 0"/>
    <axis xyz="0.45716278544646854 0.601431115929411 0.6551967646400045"/>
    <dynamics damping="0.5887855533223098" friction="0.1"/>
    <limit lower="-1.6464221671866734" upper="1.9719597524889452" effort="100" velocity="100"/>
  </joint>
  <link name="link4">
    <visual>
      <geometry><sphere radius="0.08847717009439582"/></geometry>
      <material name="plastic"/>
    </visual>
    <collision>
      <geometry><sphere radius="0.08847717009439582"/></geometry>
    </collision>
    <inertial>
      <mass value="0.5"/>
      <inertia ixx="0.0031312838511650598" ixy="0" ixz="0" 
               iyy="0.0031312838511650598" iyz="0" 
               izz="0.0031312838511650598"/>
    </inertial>
  </link>
  <joint name="joint4" type="prismatic">
    <parent link="base_link"/>
    <child link="link4"/>
    <origin xyz="0 0 0.14453241114666368" rpy="0 0 0"/>
    <axis xyz="-0.09979474454398629 -0.8527791981310462 -0.5126486596065287"/>
    <dynamics damping="0.7617778135493298" friction="0.1"/>
    <limit lower="-0.6705610024174679" upper="1.0869618474153977" effort="100" velocity="100"/>
  </joint>
</robot>