<?xml version="1.0"?>
<robot name="evolved_robot">
  <material name="metal">
    <color rgba="0.7 0.7 0.7 1.0"/>
  </material>
  <material name="plastic">
    <color rgba="0.3 0.3 0.9 1.0"/>
  </material>
  <material name="rubber">
    <color rgba="0.1 0.1 0.1 1.0"/>
  </material>
  <material name="red">
    <color rgba="1.0 0.0 0.0 1.0"/>
  </material>
  <material name="wheel_material">
    <color rgba="0.2 0.2 0.2 1.0"/>
  </material>
  <link name="base_link">
    <visual>
      <geometry><box size="0.49788532302984734 0.3987362303383032 0.0831707420564455"/></geometry>
      <material name="metal"/>
    </visual>
    <collision>
      <geometry><box size="0.49788532302984734 0.3987362303383032 0.0831707420564455"/></geometry>
    </collision>
    <inertial>
      <mass value="5.0"/>
      <inertia ixx="0.13825662809885012" ixy="0" ixz="0" 
               iyy="0.21233930601896267" iyz="0" 
               izz="0.33906698022744647"/>
    </inertial>
  </link>
  <link name="link1">
    <visual>
      <geometry>
        <cylinder radius="0.08872452583210874" length="0.06684909936539539"/>
      </geometry>
      <material name="wheel_material"/>
    </visual>
    <collision>
      <geometry>
        <cylinder radius="0.08872452583210874" length="0.06684909936539539"/>
      </geometry>
    </collision>
    <inertial>
      <mass value="1.0"/>
      <inertia ixx="0.0023404105448635083" ixy="0" ixz="0" 
               iyy="0.0023404105448635083" iyz="0" 
               izz="0.003936020742066265"/>
    </inertial>
  </link>
  <joint name="joint1" type="continuous">
    <parent link="base_link"/>
    <child link="link1"/>
    <origin xyz="0.22894266151492368 0.1993681151691516 -0.04158537102822275" rpy="1.5708 0 0"/>
    <axis xyz="0 1 0"/>
    <dynamics damping="0.6857329972548736" friction="0.1"/>
  </joint>
  <link name="link2">
    <visual>
      <geometry>
        <cylinder radius="0.06908914466058469" length="0.05595963335028588"/>
      </geometry>
      <material name="wheel_material"/>
    </visual>
    <collision>
      <geometry>
        <cylinder radius="0.06908914466058469" length="0.05595963335028588"/>
      </geometry>
    </collision>
    <inertial>
      <mass value="1.0"/>
      <inertia ixx="0.0014542841912076685" ixy="0" ixz="0" 
               iyy="0.0014542841912076685" iyz="0" 
               izz="0.002386654954965599"/>
    </inertial>
  </link>
  <joint name="joint2" type="continuous">
    <parent link="base_link"/>
    <child link="link2"/>
    <origin xyz="-0.22894266151492368 0.1993681151691516 -0.04158537102822275" rpy="1.5708 0 0"/>
    <axis xyz="0 1 0"/>
    <dynamics damping="0.27209279435767353" friction="0.1"/>
  </joint>
  <link name="link3">
    <visual>
      <geometry><box size="0.07260950542269651 0.13759779449251275 0.15752603910154817"/></geometry>
      <material name="metal"/>
    </visual>
    <collision>
      <geometry><box size="0.07260950542269651 0.13759779449251275 0.15752603910154817"/></geometry>
    </collision>
    <inertial>
      <mass value="0.5"/>
      <inertia ixx="0.0036456338370188545" ixy="0" ixz="0" 
               iyy="0.0025072161060625893" iyz="0" 
               izz="0.0020171077772443637"/>
    </inertial>
  </link>
  <joint name="joint3" type="floating">
    <parent link="base_link"/>
    <child link="link3"/>
    <origin xyz="0 0 0.04158537102822275" rpy="0 0 0"/>
    <axis xyz="0.05526330704976644 0.9966884420658388 -0.0596499484182018"/>
    <dynamics damping="0.8851749196689321" friction="0.1"/>
  </joint>
</robot>