<?xml version="1.0"?>
<robot name="evolved_robot">
  <material name="metal">
    <color rgba="0.7 0.7 0.7 1.0"/>
  </material>
  <material name="plastic">
    <color rgba="0.3 0.3 0.9 1.0"/>
  </material>
  <material name="rubber">
    <color rgba="0.1 0.1 0.1 1.0"/>
  </material>
  <material name="red">
    <color rgba="1.0 0.0 0.0 1.0"/>
  </material>
  <material name="wheel_material">
    <color rgba="0.2 0.2 0.2 1.0"/>
  </material>
  <link name="base_link">
    <visual>
      <geometry><cylinder radius="0.08677881008750149" length="0.09984610889985508"/></geometry>
      <material name="plastic"/>
    </visual>
    <collision>
      <geometry><cylinder radius="0.08677881008750149" length="0.09984610889985508"/></geometry>
    </collision>
    <inertial>
      <mass value="5.0"/>
      <inertia ixx="0.02713410925254139" ixy="0" ixz="0" 
               iyy="0.02713410925254139" iyz="0" 
               izz="0.03765280940101325"/>
    </inertial>
  </link>
  <link name="link1">
    <visual>
      <geometry>
        <cylinder radius="0.07544682483184864" length="0.036683301107865565"/>
      </geometry>
      <material name="wheel_material"/>
    </visual>
    <collision>
      <geometry>
        <cylinder radius="0.07544682483184864" length="0.036683301107865565"/>
      </geometry>
    </collision>
    <inertial>
      <mass value="1.0"/>
      <inertia ixx="0.0015351945593161075" ixy="0" ixz="0" 
               iyy="0.0015351945593161075" iyz="0" 
               izz="0.0028461116886038264"/>
    </inertial>
  </link>
  <joint name="joint1" type="fixed">
    <parent link="base_link"/>
    <child link="link1"/>
    <origin xyz="0.0760064735393962 0.07755114663560678 -0.04992305444992754" rpy="1.5708 0 0"/>
    <axis xyz="0 0 1"/>
    <dynamics damping="0.5680302453970015" friction="0.1"/>
  </joint>
  <link name="link2">
    <visual>
      <geometry>
        <cylinder radius="0.03809037664811293" length="0.03628294202152932"/>
      </geometry>
      <material name="wheel_material"/>
    </visual>
    <collision>
      <geometry>
        <cylinder radius="0.03809037664811293" length="0.03628294202152932"/>
      </geometry>
    </collision>
    <inertial>
      <mass value="1.0"/>
      <inertia ixx="0.00047242352177691483" ixy="0" ixz="0" 
               iyy="0.00047242352177691483" iyz="0" 
               izz="0.0007254383965975533"/>
    </inertial>
  </link>
  <joint name="joint2" type="continuous">
    <parent link="base_link"/>
    <child link="link2"/>
    <origin xyz="0.0760064735393962 -0.07755114663560678 -0.04992305444992754" rpy="1.5708 0 0"/>
    <axis xyz="0 0 1"/>
    <dynamics damping="0.603502608594885" friction="0.1"/>
  </joint>
  <link name="link3">
    <visual>
      <geometry>
        <cylinder radius="0.046287769108827904" length="0.07738407145717115"/>
      </geometry>
      <material name="wheel_material"/>
    </visual>
    <collision>
      <geometry>
        <cylinder radius="0.046287769108827904" length="0.07738407145717115"/>
      </geometry>
    </collision>
    <inertial>
      <mass value="1.0"/>
      <inertia ixx="0.001034663935208755" ixy="0" ixz="0" 
               iyy="0.001034663935208755" iyz="0" 
               izz="0.0010712787845360814"/>
    </inertial>
  </link>
  <joint name="joint3" type="continuous">
    <parent link="base_link"/>
    <child link="link3"/>
    <origin xyz="-0.0760064735393962 0.07755114663560678 -0.04992305444992754" rpy="1.5708 0 0"/>
    <axis xyz="0 0 1"/>
    <dynamics damping="0.44035563465329497" friction="0.1"/>
  </joint>
  <link name="link4">
    <visual>
      <geometry>
        <cylinder radius="0.0303374511320148" length="0.050036607329009525"/>
      </geometry>
      <material name="wheel_material"/>
    </visual>
    <collision>
      <geometry>
        <cylinder radius="0.0303374511320148" length="0.050036607329009525"/>
      </geometry>
    </collision>
    <inertial>
      <mass value="1.0"/>
      <inertia ixx="0.00043872874137997064" ixy="0" ixz="0" 
               iyy="0.00043872874137997064" iyz="0" 
               izz="0.000460180470593693"/>
    </inertial>
  </link>
  <joint name="joint4" type="continuous">
    <parent link="base_link"/>
    <child link="link4"/>
    <origin xyz="-0.0760064735393962 -0.07755114663560678 -0.04992305444992754" rpy="1.5708 0 0"/>
    <axis xyz="0 0 1"/>
    <dynamics damping="0.7139288390313729" friction="0.1"/>
  </joint>
  <link name="link5">
    <visual>
      <geometry>
        <cylinder radius="0.09943577300283463" length="0.06359383482550715"/>
      </geometry>
      <material name="wheel_material"/>
    </visual>
    <collision>
      <geometry>
        <cylinder radius="0.09943577300283463" length="0.06359383482550715"/>
      </geometry>
    </collision>
    <inertial>
      <mass value="1.0"/>
      <inertia ixx="0.002808882890485638" ixy="0" ixz="0" 
               iyy="0.002808882890485638" iyz="0" 
               izz="0.004943736476335628"/>
    </inertial>
  </link>
  <joint name="joint5" type="continuous">
    <parent link="base_link"/>
    <child link="link5"/>
    <origin xyz="0 -0.10340152884747571 -0.04992305444992754" rpy="1.5708 0 0"/>
    <axis xyz="0 0 1"/>
    <dynamics damping="0.9834179956332504" friction="0.1"/>
  </joint>
  <link name="link6">
    <visual>
      <geometry>
        <cylinder radius="0.07433079664888893" length="0.02955512183487513"/>
      </geometry>
      <material name="wheel_material"/>
    </visual>
    <collision>
      <geometry>
        <cylinder radius="0.07433079664888893" length="0.02955512183487513"/>
      </geometry>
    </collision>
    <inertial>
      <mass value="1.0"/>
      <inertia ixx="0.001454058934837479" ixy="0" ixz="0" 
               iyy="0.001454058934837479" iyz="0" 
               izz="0.002762533665229239"/>
    </inertial>
  </link>
  <joint name="joint6" type="continuous">
    <parent link="base_link"/>
    <child link="link6"/>
    <origin xyz="0 1.8965984711525243 -0.04992305444992754" rpy="1.5708 0 0"/>
    <axis xyz="0 0 1"/>
    <dynamics damping="0.4642967952902768" friction="0.1"/>
  </joint>
  <link name="link7">
    <visual>
      <geometry>
        <cylinder radius="0.07694952667099247" length="0.05841259185245727"/>
      </geometry>
      <material name="wheel_material"/>
    </visual>
    <collision>
      <geometry>
        <cylinder radius="0.07694952667099247" length="0.05841259185245727"/>
      </geometry>
    </collision>
    <inertial>
      <mass value="1.0"/>
      <inertia ixx="0.0017646433209659255" ixy="0" ixz="0" 
               iyy="0.0017646433209659255" iyz="0" 
               izz="0.002960614827444891"/>
    </inertial>
  </link>
  <joint name="joint7" type="fixed">
    <parent link="base_link"/>
    <child link="link7"/>
    <origin xyz="0 -0.10340152884747571 -0.04992305444992754" rpy="1.5708 0 0"/>
    <axis xyz="0 0 1"/>
    <dynamics damping="0.7175411785894925" friction="0.1"/>
  </joint>
</robot>