<?xml version="1.0"?>
<robot name="evolved_robot">
  <material name="metal">
    <color rgba="0.7 0.7 0.7 1.0"/>
  </material>
  <material name="plastic">
    <color rgba="0.3 0.3 0.9 1.0"/>
  </material>
  <material name="rubber">
    <color rgba="0.1 0.1 0.1 1.0"/>
  </material>
  <material name="red">
    <color rgba="1.0 0.0 0.0 1.0"/>
  </material>
  <material name="wheel_material">
    <color rgba="0.2 0.2 0.2 1.0"/>
  </material>
  <link name="base_link">
    <visual>
      <geometry><box size="0.1271172208650771 0.22646237024302251 0.10104113379321872"/></geometry>
      <material name="rubber"/>
    </visual>
    <collision>
      <geometry><box size="0.1271172208650771 0.22646237024302251 0.10104113379321872"/></geometry>
    </collision>
    <inertial>
      <mass value="5.0"/>
      <inertia ixx="0.051245429878589106" ixy="0" ixz="0" 
               iyy="0.0219734154655666" iyz="0" 
               izz="0.056203327480457164"/>
    </inertial>
  </link>
  <link name="link1">
    <visual>
      <geometry>
        <cylinder radius="0.04656425696884797" length="0.06288432887679209"/>
      </geometry>
      <material name="wheel_material"/>
    </visual>
    <collision>
      <geometry>
        <cylinder radius="0.04656425696884797" length="0.06288432887679209"/>
      </geometry>
    </collision>
    <inertial>
      <mass value="1.0"/>
      <inertia ixx="0.0008715940749556057" ixy="0" ixz="0" 
               iyy="0.0008715940749556057" iyz="0" 
               izz="0.0010841150135304535"/>
    </inertial>
  </link>
  <joint name="joint1" type="continuous">
    <parent link="base_link"/>
    <child link="link1"/>
    <origin xyz="0.043558610432538544 0.11323118512151126 -0.05052056689660936" rpy="1.5708 0 0"/>
    <axis xyz="0 0 1"/>
    <dynamics damping="0.37027403209200527" friction="0.1"/>
  </joint>
  <link name="link2">
    <visual>
      <geometry>
        <cylinder radius="0.03082077912235869" length="0.05281932802182139"/>
      </geometry>
      <material name="wheel_material"/>
    </visual>
    <collision>
      <geometry>
        <cylinder radius="0.03082077912235869" length="0.05281932802182139"/>
      </geometry>
    </collision>
    <inertial>
      <mass value="1.0"/>
      <inertia ixx="0.00046997022415036917" ixy="0" ixz="0" 
               iyy="0.00046997022415036917" iyz="0" 
               izz="0.0004749602128546106"/>
    </inertial>
  </link>
  <joint name="joint2" type="continuous">
    <parent link="base_link"/>
    <child link="link2"/>
    <origin xyz="0.043558610432538544 -0.11323118512151126 -0.05052056689660936" rpy="1.5708 0 0"/>
    <axis xyz="0 0 1"/>
    <dynamics damping="0.5035738824087321" friction="0.1"/>
  </joint>
  <link name="link3">
    <visual>
      <geometry>
        <cylinder radius="0.0450669920423055" length="0.04177477213593593"/>
      </geometry>
      <material name="wheel_material"/>
    </visual>
    <collision>
      <geometry>
        <cylinder radius="0.0450669920423055" length="0.04177477213593593"/>
      </geometry>
    </collision>
    <inertial>
      <mass value="1.0"/>
      <inertia ixx="0.0006531860751860875" ixy="0" ixz="0" 
               iyy="0.0006531860751860875" iyz="0" 
               izz="0.0010155168858706136"/>
    </inertial>
  </link>
  <joint name="joint3" type="fixed">
    <parent link="base_link"/>
    <child link="link3"/>
    <origin xyz="-0.043558610432538544 0.11323118512151126 -0.05052056689660936" rpy="1.5708 0 0"/>
    <axis xyz="0 0 1"/>
    <dynamics damping="0.4859637834183663" friction="0.1"/>
  </joint>
  <link name="link4">
    <visual>
      <geometry>
        <cylinder radius="0.043726578781473284" length="0.04440150144429221"/>
      </geometry>
      <material name="wheel_material"/>
    </visual>
    <collision>
      <geometry>
        <cylinder radius="0.043726578781473284" length="0.04440150144429221"/>
      </geometry>
    </collision>
    <inertial>
      <mass value="1.0"/>
      <inertia ixx="0.000642294533858721" ixy="0" ixz="0" 
               iyy="0.000642294533858721" iyz="0" 
               izz="0.0009560068459661948"/>
    </inertial>
  </link>
  <joint name="joint4" type="fixed">
    <parent link="base_link"/>
    <child link="link4"/>
    <origin xyz="-0.043558610432538544 -0.11323118512151126 -0.05052056689660936" rpy="1.5708 0 0"/>
    <axis xyz="0 0 1"/>
    <dynamics damping="0.49021788711415504" friction="0.1"/>
  </joint>
  <link name="link5">
    <visual>
      <geometry>
        <cylinder radius="0.033314466189741966" length="0.05685122888841561"/>
      </geometry>
      <material name="wheel_material"/>
    </visual>
    <collision>
      <geometry>
        <cylinder radius="0.033314466189741966" length="0.05685122888841561"/>
      </geometry>
    </collision>
    <inertial>
      <mass value="1.0"/>
      <inertia ixx="0.0005468019332204503" ixy="0" ixz="0" 
               iyy="0.0005468019332204503" iyz="0" 
               izz="0.0005549268287537303"/>
    </inertial>
  </link>
  <joint name="joint5" type="fixed">
    <parent link="base_link"/>
    <child link="link5"/>
    <origin xyz="0 -0.15097491349534833 -0.05052056689660936" rpy="1.5708 0 0"/>
    <axis xyz="0 0 1"/>
    <dynamics damping="0.5833446966596528" friction="0.1"/>
  </joint>
  <link name="link6">
    <visual>
      <geometry>
        <cylinder radius="0.09687750135639556" length="0.06665745577700463"/>
      </geometry>
      <material name="wheel_material"/>
    </visual>
    <collision>
      <geometry>
        <cylinder radius="0.09687750135639556" length="0.06665745577700463"/>
      </geometry>
    </collision>
    <inertial>
      <mass value="1.0"/>
      <inertia ixx="0.0027165806014865495" ixy="0" ixz="0" 
               iyy="0.0027165806014865495" iyz="0" 
               izz="0.004692625134529211"/>
    </inertial>
  </link>
  <joint name="joint6" type="fixed">
    <parent link="base_link"/>
    <child link="link6"/>
    <origin xyz="0 1.8490250865046516 -0.05052056689660936" rpy="1.5708 0 0"/>
    <axis xyz="0 0 1"/>
    <dynamics damping="0.11757343095940734" friction="0.1"/>
  </joint>
  <link name="link7">
    <visual>
      <geometry>
        <cylinder radius="0.06938348610648991" length="0.07205880593907205"/>
      </geometry>
      <material name="wheel_material"/>
    </visual>
    <collision>
      <geometry>
        <cylinder radius="0.06938348610648991" length="0.07205880593907205"/>
      </geometry>
    </collision>
    <inertial>
      <mass value="1.0"/>
      <inertia ixx="0.00163622299551944" ixy="0" ixz="0" 
               iyy="0.00163622299551944" iyz="0" 
               izz="0.002407034072144739"/>
    </inertial>
  </link>
  <joint name="joint7" type="continuous">
    <parent link="base_link"/>
    <child link="link7"/>
    <origin xyz="0 -0.15097491349534833 -0.05052056689660936" rpy="1.5708 0 0"/>
    <axis xyz="0 0 1"/>
    <dynamics damping="0.11791119014952496" friction="0.1"/>
  </joint>
</robot>