<?xml version="1.0"?>
<robot name="evolved_robot">
  <material name="metal">
    <color rgba="0.7 0.7 0.7 1.0"/>
  </material>
  <material name="plastic">
    <color rgba="0.3 0.3 0.9 1.0"/>
  </material>
  <material name="rubber">
    <color rgba="0.1 0.1 0.1 1.0"/>
  </material>
  <material name="red">
    <color rgba="1.0 0.0 0.0 1.0"/>
  </material>
  <material name="wheel_material">
    <color rgba="0.2 0.2 0.2 1.0"/>
  </material>
  <link name="base_link">
    <visual>
      <geometry><cylinder radius="0.05588898639542036" length="0.07639821005748276"/></geometry>
      <material name="metal"/>
    </visual>
    <collision>
      <geometry><cylinder radius="0.05588898639542036" length="0.07639821005748276"/></geometry>
    </collision>
    <inertial>
      <mass value="5.0"/>
      <inertia ixx="0.012672852417424755" ixy="0" ixz="0" 
               iyy="0.012672852417424755" iyz="0" 
               izz="0.01561789400153741"/>
    </inertial>
  </link>
  <link name="link1">
    <visual>
      <geometry><box size="0.11917431337635126 0.11061178327480387 0.2294809829607225"/></geometry>
      <material name="rubber"/>
    </visual>
    <collision>
      <geometry><box size="0.11917431337635126 0.11061178327480387 0.2294809829607225"/></geometry>
    </collision>
    <inertial>
      <mass value="0.5"/>
      <inertia ixx="0.005408040678320966" ixy="0" ixz="0" 
               iyy="0.005572003209112016" iyz="0" 
               izz="0.0022031236306630795"/>
    </inertial>
  </link>
  <joint name="joint1" type="prismatic">
    <parent link="base_link"/>
    <child link="link1"/>
    <origin xyz="-0.02002385730227043 0.0649827344271927 -0.026906907739256587" rpy="0 0 0"/>
    <axis xyz="-0.31939640161322247 -0.734801204132005 0.5983754081199197"/>
    <dynamics damping="0.91" friction="0.1"/>
    <limit lower="-2.6669289893398638" upper="1.3212163734831894" effort="100" velocity="100"/>
  </joint>
  <link name="link2">
    <visual>
      <geometry>
        <cylinder radius="0.04036086922406924" length="0.04460145721950509"/>
      </geometry>
      <material name="wheel_material"/>
    </visual>
    <collision>
      <geometry>
        <cylinder radius="0.04036086922406924" length="0.04460145721950509"/>
      </geometry>
    </collision>
    <inertial>
      <mass value="1.0"/>
      <inertia ixx="0.0005730241066392169" ixy="0" ixz="0" 
               iyy="0.0005730241066392169" iyz="0" 
               izz="0.0008144998822612099"/>
    </inertial>
  </link>
  <joint name="joint2" type="continuous">
    <parent link="base_link"/>
    <child link="link2"/>
    <origin xyz="0.08096304352146494 -0.05882309431509322 0.0547200042663707" rpy="1.5708 0.5003718691182113 -0.6283185307179588"/>
    <axis xyz="0 0 1"/>
    <dynamics damping="0.13657292100048057" friction="0.1"/>
  </joint>
  <link name="link3">
    <visual>
      <geometry><box size="0.15703034311371555 0.22925244393886302 0.08"/></geometry>
      <material name="plastic"/>
    </visual>
    <collision>
      <geometry><box size="0.15703034311371555 0.22925244393886302 0.08"/></geometry>
    </collision>
    <inertial>
      <mass value="0.5"/>
      <inertia ixx="0.004913056920995127" ixy="0" ixz="0" 
               iyy="0.0025882107215342695" iyz="0" 
               izz="0.0064346009758627296"/>
    </inertial>
  </link>
  <joint name="joint3" type="fixed">
    <parent link="link1"/>
    <child link="link3"/>
    <origin xyz="0.06958715668817562 -0.06667316978904815 0" rpy="0 0 0"/>
    <axis xyz="-0.12036308692576936 -0.7880062421866469 -0.6037871227349744"/>
    <dynamics damping="0.24508194084643747" friction="0.1"/>
  </joint>
  <link name="link4">
    <visual>
      <geometry><cylinder radius="0.06642194101370963" length="0.1485855096572608"/></geometry>
      <material name="metal"/>
    </visual>
    <collision>
      <geometry><cylinder radius="0.06642194101370963" length="0.1485855096572608"/></geometry>
    </collision>
    <inertial>
      <mass value="0.5"/>
      <inertia ixx="0.002942773035349509" ixy="0" ixz="0" 
               iyy="0.002942773035349509" iyz="0" 
               izz="0.0022059371240143607"/>
    </inertial>
  </link>
  <joint name="joint4" type="fixed">
    <parent link="link3"/>
    <child link="link4"/>
    <origin xyz="0.08851517155685777 0.2242194162003283 0" rpy="0 0 0"/>
    <axis xyz="-0.5367192651573203 -0.7936743974657241 -0.2863797849297436"/>
    <dynamics damping="0.8005474401665198" friction="0.1"/>
  </joint>
  <link name="link5">
    <visual>
      <geometry><box size="0.06773954950073251 0.08095161333561414 0.16200251282294512"/></geometry>
      <material name="metal"/>
    </visual>
    <collision>
      <geometry><box size="0.06773954950073251 0.08095161333561414 0.16200251282294512"/></geometry>
    </collision>
    <inertial>
      <mass value="0.5"/>
      <inertia ixx="0.0027331648218822733" ixy="0" ixz="0" 
               iyy="0.00256945506062589" iyz="0" 
               izz="0.0009284841890167475"/>
    </inertial>
  </link>
  <joint name="joint5" type="fixed">
    <parent link="link1"/>
    <child link="link5"/>
    <origin xyz="0.05059464853824552 0 0.12474049148036125" rpy="0 0 0"/>
    <axis xyz="0.30200667254420793 -0.337913532036312 0.8914069859528363"/>
    <dynamics damping="0.9520378779889687" friction="0.1"/>
  </joint>
  <link name="link6">
    <visual>
      <geometry>
        <cylinder radius="0.057427748730224985" length="0.02803689590286614"/>
      </geometry>
      <material name="wheel_material"/>
    </visual>
    <collision>
      <geometry>
        <cylinder radius="0.057427748730224985" length="0.02803689590286614"/>
      </geometry>
    </collision>
    <inertial>
      <mass value="1.0"/>
      <inertia ixx="0.0008899922087111437" ixy="0" ixz="0" 
               iyy="0.0008899922087111437" iyz="0" 
               izz="0.0016489731621109286"/>
    </inertial>
  </link>
  <joint name="joint6" type="continuous">
    <parent link="link4"/>
    <child link="link6"/>
    <origin xyz="0.0 0.0 0.1417205035588554" rpy="1.5708 0 0"/>
    <axis xyz="0 0 1"/>
    <dynamics damping="0.6715153224590337" friction="0.1"/>
  </joint>
</robot>