<?xml version="1.0"?>
<robot name="evolved_robot">
  <material name="metal">
    <color rgba="0.7 0.7 0.7 1.0"/>
  </material>
  <material name="plastic">
    <color rgba="0.3 0.3 0.9 1.0"/>
  </material>
  <material name="rubber">
    <color rgba="0.1 0.1 0.1 1.0"/>
  </material>
  <material name="red">
    <color rgba="1.0 0.0 0.0 1.0"/>
  </material>
  <material name="wheel_material">
    <color rgba="0.2 0.2 0.2 1.0"/>
  </material>
  <link name="base_link">
    <visual>
      <geometry><cylinder radius="0.07269533506851564" length="0.10007193374064825"/></geometry>
      <material name="rubber"/>
    </visual>
    <collision>
      <geometry><cylinder radius="0.07269533506851564" length="0.10007193374064825"/></geometry>
    </collision>
    <inertial>
      <mass value="5.0"/>
      <inertia ixx="0.021556855953969976" ixy="0" ixz="0" 
               iyy="0.021556855953969976" iyz="0" 
               izz="0.026423058703618794"/>
    </inertial>
  </link>
  <link name="link1">
    <visual>
      <geometry>
        <cylinder radius="0.05214025867629787" length="0.03031114947637049"/>
      </geometry>
      <material name="wheel_material"/>
    </visual>
    <collision>
      <geometry>
        <cylinder radius="0.05214025867629787" length="0.03031114947637049"/>
      </geometry>
    </collision>
    <inertial>
      <mass value="1.0"/>
      <inertia ixx="0.00075621545892272" ixy="0" ixz="0" 
               iyy="0.00075621545892272" iyz="0" 
               izz="0.0013593032874156274"/>
    </inertial>
  </link>
  <joint name="joint1" type="continuous">
    <parent link="base_link"/>
    <child link="link1"/>
    <origin xyz="0.0032224206013737955 -0.13131611167280846 0.04591191137455542" rpy="1.5708 0.3362504404858386 -1.546261835443665"/>
    <axis xyz="0 0 1"/>
    <dynamics damping="0.6753970721001072" friction="0.1"/>
  </joint>
  <link name="link2">
    <visual>
      <geometry><box size="0.23054837252279953 0.17981343760225754 0.12058673170067208"/></geometry>
      <material name="metal"/>
    </visual>
    <collision>
      <geometry><box size="0.23054837252279953 0.17981343760225754 0.12058673170067208"/></geometry>
    </collision>
    <inertial>
      <mass value="0.5"/>
      <inertia ixx="0.00390616935038257" ixy="0" ixz="0" 
               iyy="0.005641142661263451" iyz="0" 
               izz="0.007123785367937709"/>
    </inertial>
  </link>
  <joint name="joint2" type="fixed">
    <parent link="link1"/>
    <child link="link2"/>
    <origin xyz="-0.026702130811409583 -0.03001725430888004 0.014223254884806177" rpy="0 0 0"/>
    <axis xyz="0.0 -0.689676294589373 -0.7241178140893045"/>
    <dynamics damping="0.3258790567233705" friction="0.1"/>
  </joint>
  <link name="link3">
    <visual>
      <geometry><sphere radius="0.025446154204827334"/></geometry>
      <material name="metal"/>
    </visual>
    <collision>
      <geometry><sphere radius="0.025446154204827334"/></geometry>
    </collision>
    <inertial>
      <mass value="0.5"/>
      <inertia ixx="0.00025900270552634073" ixy="0" ixz="0" 
               iyy="0.00025900270552634073" iyz="0" 
               izz="0.00025900270552634073"/>
    </inertial>
  </link>
  <joint name="joint3" type="prismatic">
    <parent link="base_link"/>
    <child link="link3"/>
    <origin xyz="-0.00044612655569093774 0.08269396613075988 -0.034920240206078285" rpy="0 0 0"/>
    <axis xyz="0.5469116664712553 -0.7043008913203906 -0.452601241230001"/>
    <dynamics damping="0.6482445580607439" friction="0.1"/>
    <limit lower="-2.1308947666522116" upper="-0.8292186910605803" effort="100" velocity="100"/>
  </joint>
  <link name="link4">
    <visual>
      <geometry>
        <cylinder radius="0.0895" length="0.025267423952858584"/>
      </geometry>
      <material name="wheel_material"/>
    </visual>
    <collision>
      <geometry>
        <cylinder radius="0.0895" length="0.025267423952858584"/>
      </geometry>
    </collision>
    <inertial>
      <mass value="1.0"/>
      <inertia ixx="0.0020557660594344575" ixy="0" ixz="0" 
               iyy="0.0020557660594344575" iyz="0" 
               izz="0.004005125"/>
    </inertial>
  </link>
  <joint name="joint4" type="continuous">
    <parent link="link1"/>
    <child link="link4"/>
    <origin xyz="-0.09656146348466758 -0.07902851605615759 0.015836684214794727" rpy="1.5708 0.1262436125820197 -2.4557162494591074"/>
    <axis xyz="0 0 1"/>
    <dynamics damping="0.9450024965749885" friction="0.1"/>
  </joint>
  <link name="link5">
    <visual>
      <geometry><box size="0.061172526026808276 0.06964577405473282 0.08051643147900987"/></geometry>
      <material name="metal"/>
    </visual>
    <collision>
      <geometry><box size="0.061172526026808276 0.06964577405473282 0.08051643147900987"/></geometry>
    </collision>
    <inertial>
      <mass value="0.5"/>
      <inertia ixx="0.000944452465149749" ixy="0" ixz="0" 
               iyy="0.0008520811398845524" iyz="0" 
               izz="0.000716050982015286"/>
    </inertial>
  </link>
  <joint name="joint5" type="revolute">
    <parent link="link1"/>
    <child link="link5"/>
    <origin xyz="0 0 0.025155574738185246" rpy="0 0 0"/>
    <axis xyz="0.18219961964578923 -0.9753931029193896 0.12414343872398015"/>
    <dynamics damping="0.175058310904952" friction="0.1"/>
    <limit lower="-1.7736099802043057" upper="2.8245042813917514" effort="100" velocity="100"/>
  </joint>
  <link name="link6">
    <visual>
      <geometry><cylinder radius="0.08476179049470603" length="0.22881364831296847"/></geometry>
      <material name="plastic"/>
    </visual>
    <collision>
      <geometry><cylinder radius="0.08476179049470603" length="0.22881364831296847"/></geometry>
    </collision>
    <inertial>
      <mass value="0.5"/>
      <inertia ixx="0.006159114086491345" ixy="0" ixz="0" 
               iyy="0.006159114086491345" iyz="0" 
               izz="0.0035922805639342185"/>
    </inertial>
  </link>
  <joint name="joint6" type="fixed">
    <parent link="link5"/>
    <child link="link6"/>
    <origin xyz="0.040586263013404136 5.41481081495171e-05 0" rpy="0 0 0"/>
    <axis xyz="0.6329793027989111 -0.6018350666187141 -0.4869617590902311"/>
    <dynamics damping="0.7839327916945371" friction="0.1"/>
  </joint>
</robot>